WARNING 2025-09-09 00:33:46,395 log 34388 1228 Unauthorized: /api/v1/auth/users/
WARNING 2025-09-09 00:33:46,637 log 34388 1228 Bad Request: /api/v1/auth/users/
WARNING 2025-09-09 00:34:35,108 log 23120 30212 Unauthorized: /api/v1/auth/users/
WARNING 2025-09-09 00:34:35,346 log 23120 30212 Bad Request: /api/v1/auth/users/
WARNING 2025-09-09 00:35:39,687 log 832 34972 Unauthorized: /api/v1/auth/users/
WARNING 2025-09-09 00:36:57,248 log 33476 8528 Unauthorized: /api/v1/auth/users/
WARNING 2025-09-09 00:38:40,046 log 35400 38376 Unauthorized: /api/v1/auth/users/
WARNING 2025-09-09 00:40:20,742 log 14860 33068 Unauthorized: /api/v1/gamification/badges/
WARNING 2025-09-09 00:40:21,175 log 14860 33068 Unauthorized: /api/v1/gamification/badges/
WARNING 2025-09-09 00:40:22,911 log 14860 33068 Unauthorized: /api/v1/gamification/point-transactions/
WARNING 2025-09-09 00:40:24,891 log 14860 33068 Unauthorized: /api/v1/auth/users/
WARNING 2025-09-09 00:41:54,981 log 25664 11128 Unauthorized: /api/v1/gamification/badges/
WARNING 2025-09-09 00:41:55,442 log 25664 11128 Unauthorized: /api/v1/gamification/badges/
WARNING 2025-09-09 00:41:55,890 log 25664 11128 Unauthorized: /api/v1/gamification/leaderboards/
WARNING 2025-09-09 00:41:56,321 log 25664 11128 Unauthorized: /api/v1/gamification/leaderboards/
WARNING 2025-09-09 00:41:57,194 log 25664 11128 Unauthorized: /api/v1/gamification/point-transactions/
WARNING 2025-09-09 00:41:59,225 log 25664 11128 Unauthorized: /api/v1/auth/users/
WARNING 2025-09-09 00:42:34,000 log 39836 30388 Unauthorized: /api/v1/gamification/badges/
WARNING 2025-09-09 00:42:34,606 log 39836 30388 Unauthorized: /api/v1/gamification/badges/
WARNING 2025-09-09 00:42:35,207 log 39836 30388 Unauthorized: /api/v1/gamification/leaderboards/
WARNING 2025-09-09 00:42:35,796 log 39836 30388 Unauthorized: /api/v1/gamification/leaderboards/
WARNING 2025-09-09 00:42:36,902 log 39836 30388 Unauthorized: /api/v1/gamification/point-transactions/
WARNING 2025-09-09 00:42:39,544 log 39836 30388 Unauthorized: /api/v1/auth/users/
WARNING 2025-09-09 00:43:35,117 log 34460 2700 Unauthorized: /api/v1/gamification/badges/
WARNING 2025-09-09 00:43:35,749 log 34460 2700 Unauthorized: /api/v1/gamification/badges/
WARNING 2025-09-09 00:43:38,170 log 34460 2700 Unauthorized: /api/v1/gamification/point-transactions/
WARNING 2025-09-09 00:43:41,011 log 34460 2700 Unauthorized: /api/v1/auth/users/
WARNING 2025-09-09 00:44:29,856 log 39952 25124 Unauthorized: /api/v1/gamification/badges/
WARNING 2025-09-09 00:44:32,153 log 39952 25124 Unauthorized: /api/v1/gamification/point-transactions/
WARNING 2025-09-09 00:44:34,193 log 39952 25124 Unauthorized: /api/v1/auth/users/
WARNING 2025-09-09 00:45:52,323 log 39424 19352 Unauthorized: /api/v1/gamification/badges/
WARNING 2025-09-09 00:45:55,461 log 39424 19352 Unauthorized: /api/v1/gamification/point-transactions/
WARNING 2025-09-09 00:45:58,195 log 39424 19352 Unauthorized: /api/v1/auth/users/
WARNING 2025-09-09 00:46:41,524 log 9728 18560 Unauthorized: /api/v1/gamification/badges/
WARNING 2025-09-09 00:46:44,219 log 9728 18560 Unauthorized: /api/v1/gamification/point-transactions/
WARNING 2025-09-09 00:46:47,255 log 9728 18560 Unauthorized: /api/v1/auth/users/
WARNING 2025-09-09 00:48:24,846 log 21124 22576 Not Found: /api/v1/content/quizzes/1/
WARNING 2025-09-09 00:48:26,838 log 21124 22576 Unauthorized: /api/v1/gamification/badges/
WARNING 2025-09-09 00:48:29,643 log 21124 22576 Unauthorized: /api/v1/gamification/point-transactions/
WARNING 2025-09-09 00:50:09,169 log 36568 960 Unauthorized: /api/v1/gamification/badges/
WARNING 2025-09-09 00:50:12,173 log 36568 960 Unauthorized: /api/v1/gamification/point-transactions/
WARNING 2025-09-09 00:50:14,973 log 36568 960 Unauthorized: /api/v1/auth/users/
WARNING 2025-09-09 00:51:29,042 log 19056 24588 Not Found: /api/v1/content/quizzes/1/
WARNING 2025-09-09 00:51:30,805 log 19056 24588 Unauthorized: /api/v1/gamification/badges/
WARNING 2025-09-09 00:51:33,367 log 19056 24588 Unauthorized: /api/v1/gamification/point-transactions/
WARNING 2025-09-09 00:51:35,692 log 19056 24588 Unauthorized: /api/v1/auth/users/
WARNING 2025-09-09 00:52:35,561 log 40952 32632 Unauthorized: /api/v1/content/lessons/
WARNING 2025-09-09 00:52:36,253 log 40952 32632 Not Found: /api/v1/content/lessons/1/
WARNING 2025-09-09 00:52:38,984 log 40952 32632 Not Found: /api/v1/content/quizzes/1/
WARNING 2025-09-09 00:52:41,270 log 40952 32632 Unauthorized: /api/v1/gamification/badges/
WARNING 2025-09-09 00:52:44,157 log 40952 32632 Unauthorized: /api/v1/gamification/point-transactions/
WARNING 2025-09-09 00:52:46,180 log 40952 32632 Unauthorized: /api/v1/auth/users/
WARNING 2025-09-09 00:53:47,473 log 28120 28692 Unauthorized: /api/v1/content/lessons/
WARNING 2025-09-09 00:53:52,366 log 28120 28692 Unauthorized: /api/v1/gamification/badges/
WARNING 2025-09-09 00:53:55,944 log 28120 28692 Unauthorized: /api/v1/gamification/point-transactions/
WARNING 2025-09-09 00:53:59,096 log 28120 28692 Unauthorized: /api/v1/auth/users/
WARNING 2025-09-09 00:54:31,557 log 19840 39712 Unauthorized: /api/v1/content/lessons/
WARNING 2025-09-09 00:54:36,183 log 19840 39712 Unauthorized: /api/v1/gamification/badges/
WARNING 2025-09-09 00:54:40,281 log 19840 39712 Unauthorized: /api/v1/gamification/point-transactions/
WARNING 2025-09-09 00:54:45,301 log 19840 39712 Unauthorized: /api/v1/auth/users/
WARNING 2025-09-09 00:56:06,069 log 26156 32480 Forbidden: /api/v1/challenges/challenges/
WARNING 2025-09-09 00:56:06,551 log 26156 32480 Unauthorized: /api/v1/challenges/challenges/
WARNING 2025-09-09 00:56:07,028 log 26156 32480 Not Found: /api/v1/challenges/challenges/1/
WARNING 2025-09-09 00:56:10,663 log 26156 32480 Bad Request: /api/v1/challenges/submissions/
WARNING 2025-09-09 00:56:11,163 log 26156 32480 Unauthorized: /api/v1/challenges/submissions/
WARNING 2025-09-09 00:56:12,690 log 26156 32480 Unauthorized: /api/v1/content/lessons/
WARNING 2025-09-09 00:56:18,202 log 26156 32480 Unauthorized: /api/v1/gamification/badges/
WARNING 2025-09-09 00:56:21,530 log 26156 32480 Unauthorized: /api/v1/gamification/point-transactions/
WARNING 2025-09-09 00:56:24,457 log 26156 32480 Unauthorized: /api/v1/auth/users/
WARNING 2025-09-09 00:57:32,995 log 5512 29044 Forbidden: /api/v1/challenges/challenges/
WARNING 2025-09-09 00:57:33,491 log 5512 29044 Unauthorized: /api/v1/challenges/challenges/
WARNING 2025-09-09 00:57:34,005 log 5512 29044 Not Found: /api/v1/challenges/challenges/1/
WARNING 2025-09-09 00:57:38,603 log 5512 29044 Bad Request: /api/v1/challenges/submissions/
WARNING 2025-09-09 00:57:39,375 log 5512 29044 Unauthorized: /api/v1/challenges/submissions/
WARNING 2025-09-09 00:57:41,463 log 5512 29044 Unauthorized: /api/v1/content/lessons/
WARNING 2025-09-09 00:57:47,785 log 5512 29044 Unauthorized: /api/v1/gamification/badges/
WARNING 2025-09-09 00:57:51,536 log 5512 29044 Unauthorized: /api/v1/gamification/point-transactions/
WARNING 2025-09-09 00:57:54,645 log 5512 29044 Unauthorized: /api/v1/auth/users/
WARNING 2025-09-09 00:58:47,197 log 25148 16620 Forbidden: /api/v1/challenges/challenges/
WARNING 2025-09-09 00:58:47,691 log 25148 16620 Unauthorized: /api/v1/challenges/challenges/
ERROR 2025-09-09 00:58:48,244 log 25148 16620 Internal Server Error: /api/v1/challenges/challenges/1/
Traceback (most recent call last):
  File "C:\Users\ASHISH KUMAR\AppData\Local\Packages\PythonSoftwareFoundation.Python.3.11_qbz5n2kfra8p0\LocalCache\local-packages\Python311\site-packages\django\core\handlers\exception.py", line 55, in inner
    response = get_response(request)
               ^^^^^^^^^^^^^^^^^^^^^
  File "C:\Users\ASHISH KUMAR\AppData\Local\Packages\PythonSoftwareFoundation.Python.3.11_qbz5n2kfra8p0\LocalCache\local-packages\Python311\site-packages\django\core\handlers\base.py", line 197, in _get_response
    response = wrapped_callback(request, *callback_args, **callback_kwargs)
               ^^^^^^^^^^^^^^^^^^^^^^^^^^^^^^^^^^^^^^^^^^^^^^^^^^^^^^^^^^^^
  File "C:\Users\ASHISH KUMAR\AppData\Local\Packages\PythonSoftwareFoundation.Python.3.11_qbz5n2kfra8p0\LocalCache\local-packages\Python311\site-packages\django\views\decorators\csrf.py", line 56, in wrapper_view
    return view_func(*args, **kwargs)
           ^^^^^^^^^^^^^^^^^^^^^^^^^^
  File "C:\Users\ASHISH KUMAR\AppData\Local\Packages\PythonSoftwareFoundation.Python.3.11_qbz5n2kfra8p0\LocalCache\local-packages\Python311\site-packages\rest_framework\viewsets.py", line 125, in view
    return self.dispatch(request, *args, **kwargs)
           ^^^^^^^^^^^^^^^^^^^^^^^^^^^^^^^^^^^^^^^
  File "C:\Users\ASHISH KUMAR\AppData\Local\Packages\PythonSoftwareFoundation.Python.3.11_qbz5n2kfra8p0\LocalCache\local-packages\Python311\site-packages\rest_framework\views.py", line 509, in dispatch
    response = self.handle_exception(exc)
               ^^^^^^^^^^^^^^^^^^^^^^^^^^
  File "C:\Users\ASHISH KUMAR\AppData\Local\Packages\PythonSoftwareFoundation.Python.3.11_qbz5n2kfra8p0\LocalCache\local-packages\Python311\site-packages\rest_framework\views.py", line 469, in handle_exception
    self.raise_uncaught_exception(exc)
  File "C:\Users\ASHISH KUMAR\AppData\Local\Packages\PythonSoftwareFoundation.Python.3.11_qbz5n2kfra8p0\LocalCache\local-packages\Python311\site-packages\rest_framework\views.py", line 480, in raise_uncaught_exception
    raise exc
  File "C:\Users\ASHISH KUMAR\AppData\Local\Packages\PythonSoftwareFoundation.Python.3.11_qbz5n2kfra8p0\LocalCache\local-packages\Python311\site-packages\rest_framework\views.py", line 506, in dispatch
    response = handler(request, *args, **kwargs)
               ^^^^^^^^^^^^^^^^^^^^^^^^^^^^^^^^^
  File "C:\Users\ASHISH KUMAR\AppData\Local\Packages\PythonSoftwareFoundation.Python.3.11_qbz5n2kfra8p0\LocalCache\local-packages\Python311\site-packages\rest_framework\mixins.py", line 56, in retrieve
    return Response(serializer.data)
                    ^^^^^^^^^^^^^^^
  File "C:\Users\ASHISH KUMAR\AppData\Local\Packages\PythonSoftwareFoundation.Python.3.11_qbz5n2kfra8p0\LocalCache\local-packages\Python311\site-packages\rest_framework\serializers.py", line 555, in data
    ret = super().data
          ^^^^^^^^^^^^
  File "C:\Users\ASHISH KUMAR\AppData\Local\Packages\PythonSoftwareFoundation.Python.3.11_qbz5n2kfra8p0\LocalCache\local-packages\Python311\site-packages\rest_framework\serializers.py", line 253, in data
    self._data = self.to_representation(self.instance)
                 ^^^^^^^^^^^^^^^^^^^^^^^^^^^^^^^^^^^^^
  File "C:\Users\ASHISH KUMAR\AppData\Local\Packages\PythonSoftwareFoundation.Python.3.11_qbz5n2kfra8p0\LocalCache\local-packages\Python311\site-packages\rest_framework\serializers.py", line 522, in to_representation
    ret[field.field_name] = field.to_representation(attribute)
                            ^^^^^^^^^^^^^^^^^^^^^^^^^^^^^^^^^^
  File "C:\Users\ASHISH KUMAR\AppData\Local\Packages\PythonSoftwareFoundation.Python.3.11_qbz5n2kfra8p0\LocalCache\local-packages\Python311\site-packages\rest_framework\serializers.py", line 507, in to_representation
    for field in fields:
  File "C:\Users\ASHISH KUMAR\AppData\Local\Packages\PythonSoftwareFoundation.Python.3.11_qbz5n2kfra8p0\LocalCache\local-packages\Python311\site-packages\rest_framework\serializers.py", line 368, in _readable_fields
    for field in self.fields.values():
                 ^^^^^^^^^^^
  File "C:\Users\ASHISH KUMAR\AppData\Local\Packages\PythonSoftwareFoundation.Python.3.11_qbz5n2kfra8p0\LocalCache\local-packages\Python311\site-packages\django\utils\functional.py", line 57, in __get__
    res = instance.__dict__[self.name] = self.func(instance)
                                         ^^^^^^^^^^^^^^^^^^^
  File "C:\Users\ASHISH KUMAR\AppData\Local\Packages\PythonSoftwareFoundation.Python.3.11_qbz5n2kfra8p0\LocalCache\local-packages\Python311\site-packages\rest_framework\serializers.py", line 356, in fields
    for key, value in self.get_fields().items():
                      ^^^^^^^^^^^^^^^^^
  File "C:\Users\ASHISH KUMAR\AppData\Local\Packages\PythonSoftwareFoundation.Python.3.11_qbz5n2kfra8p0\LocalCache\local-packages\Python311\site-packages\rest_framework\serializers.py", line 1076, in get_fields
    field_class, field_kwargs = self.build_field(
                                ^^^^^^^^^^^^^^^^^
  File "C:\Users\ASHISH KUMAR\AppData\Local\Packages\PythonSoftwareFoundation.Python.3.11_qbz5n2kfra8p0\LocalCache\local-packages\Python311\site-packages\rest_framework\serializers.py", line 1222, in build_field
    return self.build_unknown_field(field_name, model_class)
           ^^^^^^^^^^^^^^^^^^^^^^^^^^^^^^^^^^^^^^^^^^^^^^^^^
  File "C:\Users\ASHISH KUMAR\AppData\Local\Packages\PythonSoftwareFoundation.Python.3.11_qbz5n2kfra8p0\LocalCache\local-packages\Python311\site-packages\rest_framework\serializers.py", line 1340, in build_unknown_field
    raise ImproperlyConfigured(
django.core.exceptions.ImproperlyConfigured: Field name `current_streak` is not valid for model `UserProfile`.
ERROR 2025-09-09 00:58:48,771 log 25148 16620 Internal Server Error: /api/v1/challenges/challenges/
Traceback (most recent call last):
  File "C:\Users\ASHISH KUMAR\AppData\Local\Packages\PythonSoftwareFoundation.Python.3.11_qbz5n2kfra8p0\LocalCache\local-packages\Python311\site-packages\django\core\handlers\exception.py", line 55, in inner
    response = get_response(request)
               ^^^^^^^^^^^^^^^^^^^^^
  File "C:\Users\ASHISH KUMAR\AppData\Local\Packages\PythonSoftwareFoundation.Python.3.11_qbz5n2kfra8p0\LocalCache\local-packages\Python311\site-packages\django\core\handlers\base.py", line 197, in _get_response
    response = wrapped_callback(request, *callback_args, **callback_kwargs)
               ^^^^^^^^^^^^^^^^^^^^^^^^^^^^^^^^^^^^^^^^^^^^^^^^^^^^^^^^^^^^
  File "C:\Users\ASHISH KUMAR\AppData\Local\Packages\PythonSoftwareFoundation.Python.3.11_qbz5n2kfra8p0\LocalCache\local-packages\Python311\site-packages\django\views\decorators\csrf.py", line 56, in wrapper_view
    return view_func(*args, **kwargs)
           ^^^^^^^^^^^^^^^^^^^^^^^^^^
  File "C:\Users\ASHISH KUMAR\AppData\Local\Packages\PythonSoftwareFoundation.Python.3.11_qbz5n2kfra8p0\LocalCache\local-packages\Python311\site-packages\rest_framework\viewsets.py", line 125, in view
    return self.dispatch(request, *args, **kwargs)
           ^^^^^^^^^^^^^^^^^^^^^^^^^^^^^^^^^^^^^^^
  File "C:\Users\ASHISH KUMAR\AppData\Local\Packages\PythonSoftwareFoundation.Python.3.11_qbz5n2kfra8p0\LocalCache\local-packages\Python311\site-packages\rest_framework\views.py", line 509, in dispatch
    response = self.handle_exception(exc)
               ^^^^^^^^^^^^^^^^^^^^^^^^^^
  File "C:\Users\ASHISH KUMAR\AppData\Local\Packages\PythonSoftwareFoundation.Python.3.11_qbz5n2kfra8p0\LocalCache\local-packages\Python311\site-packages\rest_framework\views.py", line 469, in handle_exception
    self.raise_uncaught_exception(exc)
  File "C:\Users\ASHISH KUMAR\AppData\Local\Packages\PythonSoftwareFoundation.Python.3.11_qbz5n2kfra8p0\LocalCache\local-packages\Python311\site-packages\rest_framework\views.py", line 480, in raise_uncaught_exception
    raise exc
  File "C:\Users\ASHISH KUMAR\AppData\Local\Packages\PythonSoftwareFoundation.Python.3.11_qbz5n2kfra8p0\LocalCache\local-packages\Python311\site-packages\rest_framework\views.py", line 506, in dispatch
    response = handler(request, *args, **kwargs)
               ^^^^^^^^^^^^^^^^^^^^^^^^^^^^^^^^^
  File "C:\Users\ASHISH KUMAR\AppData\Local\Packages\PythonSoftwareFoundation.Python.3.11_qbz5n2kfra8p0\LocalCache\local-packages\Python311\site-packages\rest_framework\mixins.py", line 43, in list
    return self.get_paginated_response(serializer.data)
                                       ^^^^^^^^^^^^^^^
  File "C:\Users\ASHISH KUMAR\AppData\Local\Packages\PythonSoftwareFoundation.Python.3.11_qbz5n2kfra8p0\LocalCache\local-packages\Python311\site-packages\rest_framework\serializers.py", line 768, in data
    ret = super().data
          ^^^^^^^^^^^^
  File "C:\Users\ASHISH KUMAR\AppData\Local\Packages\PythonSoftwareFoundation.Python.3.11_qbz5n2kfra8p0\LocalCache\local-packages\Python311\site-packages\rest_framework\serializers.py", line 253, in data
    self._data = self.to_representation(self.instance)
                 ^^^^^^^^^^^^^^^^^^^^^^^^^^^^^^^^^^^^^
  File "C:\Users\ASHISH KUMAR\AppData\Local\Packages\PythonSoftwareFoundation.Python.3.11_qbz5n2kfra8p0\LocalCache\local-packages\Python311\site-packages\rest_framework\serializers.py", line 686, in to_representation
    return [
           ^
  File "C:\Users\ASHISH KUMAR\AppData\Local\Packages\PythonSoftwareFoundation.Python.3.11_qbz5n2kfra8p0\LocalCache\local-packages\Python311\site-packages\rest_framework\serializers.py", line 687, in <listcomp>
    self.child.to_representation(item) for item in iterable
    ^^^^^^^^^^^^^^^^^^^^^^^^^^^^^^^^^^
  File "C:\Users\ASHISH KUMAR\AppData\Local\Packages\PythonSoftwareFoundation.Python.3.11_qbz5n2kfra8p0\LocalCache\local-packages\Python311\site-packages\rest_framework\serializers.py", line 522, in to_representation
    ret[field.field_name] = field.to_representation(attribute)
                            ^^^^^^^^^^^^^^^^^^^^^^^^^^^^^^^^^^
  File "C:\Users\ASHISH KUMAR\AppData\Local\Packages\PythonSoftwareFoundation.Python.3.11_qbz5n2kfra8p0\LocalCache\local-packages\Python311\site-packages\rest_framework\serializers.py", line 507, in to_representation
    for field in fields:
  File "C:\Users\ASHISH KUMAR\AppData\Local\Packages\PythonSoftwareFoundation.Python.3.11_qbz5n2kfra8p0\LocalCache\local-packages\Python311\site-packages\rest_framework\serializers.py", line 368, in _readable_fields
    for field in self.fields.values():
                 ^^^^^^^^^^^
  File "C:\Users\ASHISH KUMAR\AppData\Local\Packages\PythonSoftwareFoundation.Python.3.11_qbz5n2kfra8p0\LocalCache\local-packages\Python311\site-packages\django\utils\functional.py", line 57, in __get__
    res = instance.__dict__[self.name] = self.func(instance)
                                         ^^^^^^^^^^^^^^^^^^^
  File "C:\Users\ASHISH KUMAR\AppData\Local\Packages\PythonSoftwareFoundation.Python.3.11_qbz5n2kfra8p0\LocalCache\local-packages\Python311\site-packages\rest_framework\serializers.py", line 356, in fields
    for key, value in self.get_fields().items():
                      ^^^^^^^^^^^^^^^^^
  File "C:\Users\ASHISH KUMAR\AppData\Local\Packages\PythonSoftwareFoundation.Python.3.11_qbz5n2kfra8p0\LocalCache\local-packages\Python311\site-packages\rest_framework\serializers.py", line 1076, in get_fields
    field_class, field_kwargs = self.build_field(
                                ^^^^^^^^^^^^^^^^^
  File "C:\Users\ASHISH KUMAR\AppData\Local\Packages\PythonSoftwareFoundation.Python.3.11_qbz5n2kfra8p0\LocalCache\local-packages\Python311\site-packages\rest_framework\serializers.py", line 1222, in build_field
    return self.build_unknown_field(field_name, model_class)
           ^^^^^^^^^^^^^^^^^^^^^^^^^^^^^^^^^^^^^^^^^^^^^^^^^
  File "C:\Users\ASHISH KUMAR\AppData\Local\Packages\PythonSoftwareFoundation.Python.3.11_qbz5n2kfra8p0\LocalCache\local-packages\Python311\site-packages\rest_framework\serializers.py", line 1340, in build_unknown_field
    raise ImproperlyConfigured(
django.core.exceptions.ImproperlyConfigured: Field name `current_streak` is not valid for model `UserProfile`.
WARNING 2025-09-09 00:58:51,862 log 25148 16620 Bad Request: /api/v1/challenges/submissions/
WARNING 2025-09-09 00:58:52,336 log 25148 16620 Unauthorized: /api/v1/challenges/submissions/
WARNING 2025-09-09 00:58:53,811 log 25148 16620 Unauthorized: /api/v1/content/lessons/
WARNING 2025-09-09 00:58:58,498 log 25148 16620 Unauthorized: /api/v1/gamification/badges/
WARNING 2025-09-09 00:59:00,798 log 25148 16620 Unauthorized: /api/v1/gamification/point-transactions/
WARNING 2025-09-09 00:59:03,386 log 25148 16620 Unauthorized: /api/v1/auth/users/
WARNING 2025-09-09 01:00:15,091 log 33952 15532 Unauthorized: /api/v1/challenges/challenges/
ERROR 2025-09-09 01:00:15,621 log 33952 15532 Internal Server Error: /api/v1/challenges/challenges/1/
Traceback (most recent call last):
  File "C:\Users\ASHISH KUMAR\AppData\Local\Packages\PythonSoftwareFoundation.Python.3.11_qbz5n2kfra8p0\LocalCache\local-packages\Python311\site-packages\django\core\handlers\exception.py", line 55, in inner
    response = get_response(request)
               ^^^^^^^^^^^^^^^^^^^^^
  File "C:\Users\ASHISH KUMAR\AppData\Local\Packages\PythonSoftwareFoundation.Python.3.11_qbz5n2kfra8p0\LocalCache\local-packages\Python311\site-packages\django\core\handlers\base.py", line 197, in _get_response
    response = wrapped_callback(request, *callback_args, **callback_kwargs)
               ^^^^^^^^^^^^^^^^^^^^^^^^^^^^^^^^^^^^^^^^^^^^^^^^^^^^^^^^^^^^
  File "C:\Users\ASHISH KUMAR\AppData\Local\Packages\PythonSoftwareFoundation.Python.3.11_qbz5n2kfra8p0\LocalCache\local-packages\Python311\site-packages\django\views\decorators\csrf.py", line 56, in wrapper_view
    return view_func(*args, **kwargs)
           ^^^^^^^^^^^^^^^^^^^^^^^^^^
  File "C:\Users\ASHISH KUMAR\AppData\Local\Packages\PythonSoftwareFoundation.Python.3.11_qbz5n2kfra8p0\LocalCache\local-packages\Python311\site-packages\rest_framework\viewsets.py", line 125, in view
    return self.dispatch(request, *args, **kwargs)
           ^^^^^^^^^^^^^^^^^^^^^^^^^^^^^^^^^^^^^^^
  File "C:\Users\ASHISH KUMAR\AppData\Local\Packages\PythonSoftwareFoundation.Python.3.11_qbz5n2kfra8p0\LocalCache\local-packages\Python311\site-packages\rest_framework\views.py", line 509, in dispatch
    response = self.handle_exception(exc)
               ^^^^^^^^^^^^^^^^^^^^^^^^^^
  File "C:\Users\ASHISH KUMAR\AppData\Local\Packages\PythonSoftwareFoundation.Python.3.11_qbz5n2kfra8p0\LocalCache\local-packages\Python311\site-packages\rest_framework\views.py", line 469, in handle_exception
    self.raise_uncaught_exception(exc)
  File "C:\Users\ASHISH KUMAR\AppData\Local\Packages\PythonSoftwareFoundation.Python.3.11_qbz5n2kfra8p0\LocalCache\local-packages\Python311\site-packages\rest_framework\views.py", line 480, in raise_uncaught_exception
    raise exc
  File "C:\Users\ASHISH KUMAR\AppData\Local\Packages\PythonSoftwareFoundation.Python.3.11_qbz5n2kfra8p0\LocalCache\local-packages\Python311\site-packages\rest_framework\views.py", line 506, in dispatch
    response = handler(request, *args, **kwargs)
               ^^^^^^^^^^^^^^^^^^^^^^^^^^^^^^^^^
  File "C:\Users\ASHISH KUMAR\AppData\Local\Packages\PythonSoftwareFoundation.Python.3.11_qbz5n2kfra8p0\LocalCache\local-packages\Python311\site-packages\rest_framework\mixins.py", line 56, in retrieve
    return Response(serializer.data)
                    ^^^^^^^^^^^^^^^
  File "C:\Users\ASHISH KUMAR\AppData\Local\Packages\PythonSoftwareFoundation.Python.3.11_qbz5n2kfra8p0\LocalCache\local-packages\Python311\site-packages\rest_framework\serializers.py", line 555, in data
    ret = super().data
          ^^^^^^^^^^^^
  File "C:\Users\ASHISH KUMAR\AppData\Local\Packages\PythonSoftwareFoundation.Python.3.11_qbz5n2kfra8p0\LocalCache\local-packages\Python311\site-packages\rest_framework\serializers.py", line 253, in data
    self._data = self.to_representation(self.instance)
                 ^^^^^^^^^^^^^^^^^^^^^^^^^^^^^^^^^^^^^
  File "C:\Users\ASHISH KUMAR\AppData\Local\Packages\PythonSoftwareFoundation.Python.3.11_qbz5n2kfra8p0\LocalCache\local-packages\Python311\site-packages\rest_framework\serializers.py", line 522, in to_representation
    ret[field.field_name] = field.to_representation(attribute)
                            ^^^^^^^^^^^^^^^^^^^^^^^^^^^^^^^^^^
  File "C:\Users\ASHISH KUMAR\AppData\Local\Packages\PythonSoftwareFoundation.Python.3.11_qbz5n2kfra8p0\LocalCache\local-packages\Python311\site-packages\rest_framework\serializers.py", line 507, in to_representation
    for field in fields:
  File "C:\Users\ASHISH KUMAR\AppData\Local\Packages\PythonSoftwareFoundation.Python.3.11_qbz5n2kfra8p0\LocalCache\local-packages\Python311\site-packages\rest_framework\serializers.py", line 368, in _readable_fields
    for field in self.fields.values():
                 ^^^^^^^^^^^
  File "C:\Users\ASHISH KUMAR\AppData\Local\Packages\PythonSoftwareFoundation.Python.3.11_qbz5n2kfra8p0\LocalCache\local-packages\Python311\site-packages\django\utils\functional.py", line 57, in __get__
    res = instance.__dict__[self.name] = self.func(instance)
                                         ^^^^^^^^^^^^^^^^^^^
  File "C:\Users\ASHISH KUMAR\AppData\Local\Packages\PythonSoftwareFoundation.Python.3.11_qbz5n2kfra8p0\LocalCache\local-packages\Python311\site-packages\rest_framework\serializers.py", line 356, in fields
    for key, value in self.get_fields().items():
                      ^^^^^^^^^^^^^^^^^
  File "C:\Users\ASHISH KUMAR\AppData\Local\Packages\PythonSoftwareFoundation.Python.3.11_qbz5n2kfra8p0\LocalCache\local-packages\Python311\site-packages\rest_framework\serializers.py", line 1076, in get_fields
    field_class, field_kwargs = self.build_field(
                                ^^^^^^^^^^^^^^^^^
  File "C:\Users\ASHISH KUMAR\AppData\Local\Packages\PythonSoftwareFoundation.Python.3.11_qbz5n2kfra8p0\LocalCache\local-packages\Python311\site-packages\rest_framework\serializers.py", line 1222, in build_field
    return self.build_unknown_field(field_name, model_class)
           ^^^^^^^^^^^^^^^^^^^^^^^^^^^^^^^^^^^^^^^^^^^^^^^^^
  File "C:\Users\ASHISH KUMAR\AppData\Local\Packages\PythonSoftwareFoundation.Python.3.11_qbz5n2kfra8p0\LocalCache\local-packages\Python311\site-packages\rest_framework\serializers.py", line 1340, in build_unknown_field
    raise ImproperlyConfigured(
django.core.exceptions.ImproperlyConfigured: Field name `current_streak` is not valid for model `UserProfile`.
ERROR 2025-09-09 01:00:16,123 log 33952 15532 Internal Server Error: /api/v1/challenges/challenges/
Traceback (most recent call last):
  File "C:\Users\ASHISH KUMAR\AppData\Local\Packages\PythonSoftwareFoundation.Python.3.11_qbz5n2kfra8p0\LocalCache\local-packages\Python311\site-packages\django\core\handlers\exception.py", line 55, in inner
    response = get_response(request)
               ^^^^^^^^^^^^^^^^^^^^^
  File "C:\Users\ASHISH KUMAR\AppData\Local\Packages\PythonSoftwareFoundation.Python.3.11_qbz5n2kfra8p0\LocalCache\local-packages\Python311\site-packages\django\core\handlers\base.py", line 197, in _get_response
    response = wrapped_callback(request, *callback_args, **callback_kwargs)
               ^^^^^^^^^^^^^^^^^^^^^^^^^^^^^^^^^^^^^^^^^^^^^^^^^^^^^^^^^^^^
  File "C:\Users\ASHISH KUMAR\AppData\Local\Packages\PythonSoftwareFoundation.Python.3.11_qbz5n2kfra8p0\LocalCache\local-packages\Python311\site-packages\django\views\decorators\csrf.py", line 56, in wrapper_view
    return view_func(*args, **kwargs)
           ^^^^^^^^^^^^^^^^^^^^^^^^^^
  File "C:\Users\ASHISH KUMAR\AppData\Local\Packages\PythonSoftwareFoundation.Python.3.11_qbz5n2kfra8p0\LocalCache\local-packages\Python311\site-packages\rest_framework\viewsets.py", line 125, in view
    return self.dispatch(request, *args, **kwargs)
           ^^^^^^^^^^^^^^^^^^^^^^^^^^^^^^^^^^^^^^^
  File "C:\Users\ASHISH KUMAR\AppData\Local\Packages\PythonSoftwareFoundation.Python.3.11_qbz5n2kfra8p0\LocalCache\local-packages\Python311\site-packages\rest_framework\views.py", line 509, in dispatch
    response = self.handle_exception(exc)
               ^^^^^^^^^^^^^^^^^^^^^^^^^^
  File "C:\Users\ASHISH KUMAR\AppData\Local\Packages\PythonSoftwareFoundation.Python.3.11_qbz5n2kfra8p0\LocalCache\local-packages\Python311\site-packages\rest_framework\views.py", line 469, in handle_exception
    self.raise_uncaught_exception(exc)
  File "C:\Users\ASHISH KUMAR\AppData\Local\Packages\PythonSoftwareFoundation.Python.3.11_qbz5n2kfra8p0\LocalCache\local-packages\Python311\site-packages\rest_framework\views.py", line 480, in raise_uncaught_exception
    raise exc
  File "C:\Users\ASHISH KUMAR\AppData\Local\Packages\PythonSoftwareFoundation.Python.3.11_qbz5n2kfra8p0\LocalCache\local-packages\Python311\site-packages\rest_framework\views.py", line 506, in dispatch
    response = handler(request, *args, **kwargs)
               ^^^^^^^^^^^^^^^^^^^^^^^^^^^^^^^^^
  File "C:\Users\ASHISH KUMAR\AppData\Local\Packages\PythonSoftwareFoundation.Python.3.11_qbz5n2kfra8p0\LocalCache\local-packages\Python311\site-packages\rest_framework\mixins.py", line 43, in list
    return self.get_paginated_response(serializer.data)
                                       ^^^^^^^^^^^^^^^
  File "C:\Users\ASHISH KUMAR\AppData\Local\Packages\PythonSoftwareFoundation.Python.3.11_qbz5n2kfra8p0\LocalCache\local-packages\Python311\site-packages\rest_framework\serializers.py", line 768, in data
    ret = super().data
          ^^^^^^^^^^^^
  File "C:\Users\ASHISH KUMAR\AppData\Local\Packages\PythonSoftwareFoundation.Python.3.11_qbz5n2kfra8p0\LocalCache\local-packages\Python311\site-packages\rest_framework\serializers.py", line 253, in data
    self._data = self.to_representation(self.instance)
                 ^^^^^^^^^^^^^^^^^^^^^^^^^^^^^^^^^^^^^
  File "C:\Users\ASHISH KUMAR\AppData\Local\Packages\PythonSoftwareFoundation.Python.3.11_qbz5n2kfra8p0\LocalCache\local-packages\Python311\site-packages\rest_framework\serializers.py", line 686, in to_representation
    return [
           ^
  File "C:\Users\ASHISH KUMAR\AppData\Local\Packages\PythonSoftwareFoundation.Python.3.11_qbz5n2kfra8p0\LocalCache\local-packages\Python311\site-packages\rest_framework\serializers.py", line 687, in <listcomp>
    self.child.to_representation(item) for item in iterable
    ^^^^^^^^^^^^^^^^^^^^^^^^^^^^^^^^^^
  File "C:\Users\ASHISH KUMAR\AppData\Local\Packages\PythonSoftwareFoundation.Python.3.11_qbz5n2kfra8p0\LocalCache\local-packages\Python311\site-packages\rest_framework\serializers.py", line 522, in to_representation
    ret[field.field_name] = field.to_representation(attribute)
                            ^^^^^^^^^^^^^^^^^^^^^^^^^^^^^^^^^^
  File "C:\Users\ASHISH KUMAR\AppData\Local\Packages\PythonSoftwareFoundation.Python.3.11_qbz5n2kfra8p0\LocalCache\local-packages\Python311\site-packages\rest_framework\serializers.py", line 507, in to_representation
    for field in fields:
  File "C:\Users\ASHISH KUMAR\AppData\Local\Packages\PythonSoftwareFoundation.Python.3.11_qbz5n2kfra8p0\LocalCache\local-packages\Python311\site-packages\rest_framework\serializers.py", line 368, in _readable_fields
    for field in self.fields.values():
                 ^^^^^^^^^^^
  File "C:\Users\ASHISH KUMAR\AppData\Local\Packages\PythonSoftwareFoundation.Python.3.11_qbz5n2kfra8p0\LocalCache\local-packages\Python311\site-packages\django\utils\functional.py", line 57, in __get__
    res = instance.__dict__[self.name] = self.func(instance)
                                         ^^^^^^^^^^^^^^^^^^^
  File "C:\Users\ASHISH KUMAR\AppData\Local\Packages\PythonSoftwareFoundation.Python.3.11_qbz5n2kfra8p0\LocalCache\local-packages\Python311\site-packages\rest_framework\serializers.py", line 356, in fields
    for key, value in self.get_fields().items():
                      ^^^^^^^^^^^^^^^^^
  File "C:\Users\ASHISH KUMAR\AppData\Local\Packages\PythonSoftwareFoundation.Python.3.11_qbz5n2kfra8p0\LocalCache\local-packages\Python311\site-packages\rest_framework\serializers.py", line 1076, in get_fields
    field_class, field_kwargs = self.build_field(
                                ^^^^^^^^^^^^^^^^^
  File "C:\Users\ASHISH KUMAR\AppData\Local\Packages\PythonSoftwareFoundation.Python.3.11_qbz5n2kfra8p0\LocalCache\local-packages\Python311\site-packages\rest_framework\serializers.py", line 1222, in build_field
    return self.build_unknown_field(field_name, model_class)
           ^^^^^^^^^^^^^^^^^^^^^^^^^^^^^^^^^^^^^^^^^^^^^^^^^
  File "C:\Users\ASHISH KUMAR\AppData\Local\Packages\PythonSoftwareFoundation.Python.3.11_qbz5n2kfra8p0\LocalCache\local-packages\Python311\site-packages\rest_framework\serializers.py", line 1340, in build_unknown_field
    raise ImproperlyConfigured(
django.core.exceptions.ImproperlyConfigured: Field name `current_streak` is not valid for model `UserProfile`.
WARNING 2025-09-09 01:00:19,793 log 33952 15532 Bad Request: /api/v1/challenges/submissions/
WARNING 2025-09-09 01:00:20,406 log 33952 15532 Unauthorized: /api/v1/challenges/submissions/
WARNING 2025-09-09 01:00:22,509 log 33952 15532 Unauthorized: /api/v1/content/lessons/
WARNING 2025-09-09 01:00:28,501 log 33952 15532 Unauthorized: /api/v1/gamification/badges/
WARNING 2025-09-09 01:00:31,834 log 33952 15532 Unauthorized: /api/v1/gamification/point-transactions/
WARNING 2025-09-09 01:00:34,883 log 33952 15532 Unauthorized: /api/v1/auth/users/
WARNING 2025-09-09 01:01:08,307 log 36076 14860 Unauthorized: /api/v1/challenges/challenges/
ERROR 2025-09-09 01:01:08,892 log 36076 14860 Internal Server Error: /api/v1/challenges/challenges/1/
Traceback (most recent call last):
  File "C:\Users\ASHISH KUMAR\AppData\Local\Packages\PythonSoftwareFoundation.Python.3.11_qbz5n2kfra8p0\LocalCache\local-packages\Python311\site-packages\django\core\handlers\exception.py", line 55, in inner
    response = get_response(request)
               ^^^^^^^^^^^^^^^^^^^^^
  File "C:\Users\ASHISH KUMAR\AppData\Local\Packages\PythonSoftwareFoundation.Python.3.11_qbz5n2kfra8p0\LocalCache\local-packages\Python311\site-packages\django\core\handlers\base.py", line 197, in _get_response
    response = wrapped_callback(request, *callback_args, **callback_kwargs)
               ^^^^^^^^^^^^^^^^^^^^^^^^^^^^^^^^^^^^^^^^^^^^^^^^^^^^^^^^^^^^
  File "C:\Users\ASHISH KUMAR\AppData\Local\Packages\PythonSoftwareFoundation.Python.3.11_qbz5n2kfra8p0\LocalCache\local-packages\Python311\site-packages\django\views\decorators\csrf.py", line 56, in wrapper_view
    return view_func(*args, **kwargs)
           ^^^^^^^^^^^^^^^^^^^^^^^^^^
  File "C:\Users\ASHISH KUMAR\AppData\Local\Packages\PythonSoftwareFoundation.Python.3.11_qbz5n2kfra8p0\LocalCache\local-packages\Python311\site-packages\rest_framework\viewsets.py", line 125, in view
    return self.dispatch(request, *args, **kwargs)
           ^^^^^^^^^^^^^^^^^^^^^^^^^^^^^^^^^^^^^^^
  File "C:\Users\ASHISH KUMAR\AppData\Local\Packages\PythonSoftwareFoundation.Python.3.11_qbz5n2kfra8p0\LocalCache\local-packages\Python311\site-packages\rest_framework\views.py", line 509, in dispatch
    response = self.handle_exception(exc)
               ^^^^^^^^^^^^^^^^^^^^^^^^^^
  File "C:\Users\ASHISH KUMAR\AppData\Local\Packages\PythonSoftwareFoundation.Python.3.11_qbz5n2kfra8p0\LocalCache\local-packages\Python311\site-packages\rest_framework\views.py", line 469, in handle_exception
    self.raise_uncaught_exception(exc)
  File "C:\Users\ASHISH KUMAR\AppData\Local\Packages\PythonSoftwareFoundation.Python.3.11_qbz5n2kfra8p0\LocalCache\local-packages\Python311\site-packages\rest_framework\views.py", line 480, in raise_uncaught_exception
    raise exc
  File "C:\Users\ASHISH KUMAR\AppData\Local\Packages\PythonSoftwareFoundation.Python.3.11_qbz5n2kfra8p0\LocalCache\local-packages\Python311\site-packages\rest_framework\views.py", line 506, in dispatch
    response = handler(request, *args, **kwargs)
               ^^^^^^^^^^^^^^^^^^^^^^^^^^^^^^^^^
  File "C:\Users\ASHISH KUMAR\AppData\Local\Packages\PythonSoftwareFoundation.Python.3.11_qbz5n2kfra8p0\LocalCache\local-packages\Python311\site-packages\rest_framework\mixins.py", line 56, in retrieve
    return Response(serializer.data)
                    ^^^^^^^^^^^^^^^
  File "C:\Users\ASHISH KUMAR\AppData\Local\Packages\PythonSoftwareFoundation.Python.3.11_qbz5n2kfra8p0\LocalCache\local-packages\Python311\site-packages\rest_framework\serializers.py", line 555, in data
    ret = super().data
          ^^^^^^^^^^^^
  File "C:\Users\ASHISH KUMAR\AppData\Local\Packages\PythonSoftwareFoundation.Python.3.11_qbz5n2kfra8p0\LocalCache\local-packages\Python311\site-packages\rest_framework\serializers.py", line 253, in data
    self._data = self.to_representation(self.instance)
                 ^^^^^^^^^^^^^^^^^^^^^^^^^^^^^^^^^^^^^
  File "C:\Users\ASHISH KUMAR\AppData\Local\Packages\PythonSoftwareFoundation.Python.3.11_qbz5n2kfra8p0\LocalCache\local-packages\Python311\site-packages\rest_framework\serializers.py", line 522, in to_representation
    ret[field.field_name] = field.to_representation(attribute)
                            ^^^^^^^^^^^^^^^^^^^^^^^^^^^^^^^^^^
  File "C:\Users\ASHISH KUMAR\AppData\Local\Packages\PythonSoftwareFoundation.Python.3.11_qbz5n2kfra8p0\LocalCache\local-packages\Python311\site-packages\rest_framework\serializers.py", line 507, in to_representation
    for field in fields:
  File "C:\Users\ASHISH KUMAR\AppData\Local\Packages\PythonSoftwareFoundation.Python.3.11_qbz5n2kfra8p0\LocalCache\local-packages\Python311\site-packages\rest_framework\serializers.py", line 368, in _readable_fields
    for field in self.fields.values():
                 ^^^^^^^^^^^
  File "C:\Users\ASHISH KUMAR\AppData\Local\Packages\PythonSoftwareFoundation.Python.3.11_qbz5n2kfra8p0\LocalCache\local-packages\Python311\site-packages\django\utils\functional.py", line 57, in __get__
    res = instance.__dict__[self.name] = self.func(instance)
                                         ^^^^^^^^^^^^^^^^^^^
  File "C:\Users\ASHISH KUMAR\AppData\Local\Packages\PythonSoftwareFoundation.Python.3.11_qbz5n2kfra8p0\LocalCache\local-packages\Python311\site-packages\rest_framework\serializers.py", line 356, in fields
    for key, value in self.get_fields().items():
                      ^^^^^^^^^^^^^^^^^
  File "C:\Users\ASHISH KUMAR\AppData\Local\Packages\PythonSoftwareFoundation.Python.3.11_qbz5n2kfra8p0\LocalCache\local-packages\Python311\site-packages\rest_framework\serializers.py", line 1076, in get_fields
    field_class, field_kwargs = self.build_field(
                                ^^^^^^^^^^^^^^^^^
  File "C:\Users\ASHISH KUMAR\AppData\Local\Packages\PythonSoftwareFoundation.Python.3.11_qbz5n2kfra8p0\LocalCache\local-packages\Python311\site-packages\rest_framework\serializers.py", line 1222, in build_field
    return self.build_unknown_field(field_name, model_class)
           ^^^^^^^^^^^^^^^^^^^^^^^^^^^^^^^^^^^^^^^^^^^^^^^^^
  File "C:\Users\ASHISH KUMAR\AppData\Local\Packages\PythonSoftwareFoundation.Python.3.11_qbz5n2kfra8p0\LocalCache\local-packages\Python311\site-packages\rest_framework\serializers.py", line 1340, in build_unknown_field
    raise ImproperlyConfigured(
django.core.exceptions.ImproperlyConfigured: Field name `current_streak` is not valid for model `UserProfile`.
ERROR 2025-09-09 01:01:09,462 log 36076 14860 Internal Server Error: /api/v1/challenges/challenges/
Traceback (most recent call last):
  File "C:\Users\ASHISH KUMAR\AppData\Local\Packages\PythonSoftwareFoundation.Python.3.11_qbz5n2kfra8p0\LocalCache\local-packages\Python311\site-packages\django\core\handlers\exception.py", line 55, in inner
    response = get_response(request)
               ^^^^^^^^^^^^^^^^^^^^^
  File "C:\Users\ASHISH KUMAR\AppData\Local\Packages\PythonSoftwareFoundation.Python.3.11_qbz5n2kfra8p0\LocalCache\local-packages\Python311\site-packages\django\core\handlers\base.py", line 197, in _get_response
    response = wrapped_callback(request, *callback_args, **callback_kwargs)
               ^^^^^^^^^^^^^^^^^^^^^^^^^^^^^^^^^^^^^^^^^^^^^^^^^^^^^^^^^^^^
  File "C:\Users\ASHISH KUMAR\AppData\Local\Packages\PythonSoftwareFoundation.Python.3.11_qbz5n2kfra8p0\LocalCache\local-packages\Python311\site-packages\django\views\decorators\csrf.py", line 56, in wrapper_view
    return view_func(*args, **kwargs)
           ^^^^^^^^^^^^^^^^^^^^^^^^^^
  File "C:\Users\ASHISH KUMAR\AppData\Local\Packages\PythonSoftwareFoundation.Python.3.11_qbz5n2kfra8p0\LocalCache\local-packages\Python311\site-packages\rest_framework\viewsets.py", line 125, in view
    return self.dispatch(request, *args, **kwargs)
           ^^^^^^^^^^^^^^^^^^^^^^^^^^^^^^^^^^^^^^^
  File "C:\Users\ASHISH KUMAR\AppData\Local\Packages\PythonSoftwareFoundation.Python.3.11_qbz5n2kfra8p0\LocalCache\local-packages\Python311\site-packages\rest_framework\views.py", line 509, in dispatch
    response = self.handle_exception(exc)
               ^^^^^^^^^^^^^^^^^^^^^^^^^^
  File "C:\Users\ASHISH KUMAR\AppData\Local\Packages\PythonSoftwareFoundation.Python.3.11_qbz5n2kfra8p0\LocalCache\local-packages\Python311\site-packages\rest_framework\views.py", line 469, in handle_exception
    self.raise_uncaught_exception(exc)
  File "C:\Users\ASHISH KUMAR\AppData\Local\Packages\PythonSoftwareFoundation.Python.3.11_qbz5n2kfra8p0\LocalCache\local-packages\Python311\site-packages\rest_framework\views.py", line 480, in raise_uncaught_exception
    raise exc
  File "C:\Users\ASHISH KUMAR\AppData\Local\Packages\PythonSoftwareFoundation.Python.3.11_qbz5n2kfra8p0\LocalCache\local-packages\Python311\site-packages\rest_framework\views.py", line 506, in dispatch
    response = handler(request, *args, **kwargs)
               ^^^^^^^^^^^^^^^^^^^^^^^^^^^^^^^^^
  File "C:\Users\ASHISH KUMAR\AppData\Local\Packages\PythonSoftwareFoundation.Python.3.11_qbz5n2kfra8p0\LocalCache\local-packages\Python311\site-packages\rest_framework\mixins.py", line 43, in list
    return self.get_paginated_response(serializer.data)
                                       ^^^^^^^^^^^^^^^
  File "C:\Users\ASHISH KUMAR\AppData\Local\Packages\PythonSoftwareFoundation.Python.3.11_qbz5n2kfra8p0\LocalCache\local-packages\Python311\site-packages\rest_framework\serializers.py", line 768, in data
    ret = super().data
          ^^^^^^^^^^^^
  File "C:\Users\ASHISH KUMAR\AppData\Local\Packages\PythonSoftwareFoundation.Python.3.11_qbz5n2kfra8p0\LocalCache\local-packages\Python311\site-packages\rest_framework\serializers.py", line 253, in data
    self._data = self.to_representation(self.instance)
                 ^^^^^^^^^^^^^^^^^^^^^^^^^^^^^^^^^^^^^
  File "C:\Users\ASHISH KUMAR\AppData\Local\Packages\PythonSoftwareFoundation.Python.3.11_qbz5n2kfra8p0\LocalCache\local-packages\Python311\site-packages\rest_framework\serializers.py", line 686, in to_representation
    return [
           ^
  File "C:\Users\ASHISH KUMAR\AppData\Local\Packages\PythonSoftwareFoundation.Python.3.11_qbz5n2kfra8p0\LocalCache\local-packages\Python311\site-packages\rest_framework\serializers.py", line 687, in <listcomp>
    self.child.to_representation(item) for item in iterable
    ^^^^^^^^^^^^^^^^^^^^^^^^^^^^^^^^^^
  File "C:\Users\ASHISH KUMAR\AppData\Local\Packages\PythonSoftwareFoundation.Python.3.11_qbz5n2kfra8p0\LocalCache\local-packages\Python311\site-packages\rest_framework\serializers.py", line 522, in to_representation
    ret[field.field_name] = field.to_representation(attribute)
                            ^^^^^^^^^^^^^^^^^^^^^^^^^^^^^^^^^^
  File "C:\Users\ASHISH KUMAR\AppData\Local\Packages\PythonSoftwareFoundation.Python.3.11_qbz5n2kfra8p0\LocalCache\local-packages\Python311\site-packages\rest_framework\serializers.py", line 507, in to_representation
    for field in fields:
  File "C:\Users\ASHISH KUMAR\AppData\Local\Packages\PythonSoftwareFoundation.Python.3.11_qbz5n2kfra8p0\LocalCache\local-packages\Python311\site-packages\rest_framework\serializers.py", line 368, in _readable_fields
    for field in self.fields.values():
                 ^^^^^^^^^^^
  File "C:\Users\ASHISH KUMAR\AppData\Local\Packages\PythonSoftwareFoundation.Python.3.11_qbz5n2kfra8p0\LocalCache\local-packages\Python311\site-packages\django\utils\functional.py", line 57, in __get__
    res = instance.__dict__[self.name] = self.func(instance)
                                         ^^^^^^^^^^^^^^^^^^^
  File "C:\Users\ASHISH KUMAR\AppData\Local\Packages\PythonSoftwareFoundation.Python.3.11_qbz5n2kfra8p0\LocalCache\local-packages\Python311\site-packages\rest_framework\serializers.py", line 356, in fields
    for key, value in self.get_fields().items():
                      ^^^^^^^^^^^^^^^^^
  File "C:\Users\ASHISH KUMAR\AppData\Local\Packages\PythonSoftwareFoundation.Python.3.11_qbz5n2kfra8p0\LocalCache\local-packages\Python311\site-packages\rest_framework\serializers.py", line 1076, in get_fields
    field_class, field_kwargs = self.build_field(
                                ^^^^^^^^^^^^^^^^^
  File "C:\Users\ASHISH KUMAR\AppData\Local\Packages\PythonSoftwareFoundation.Python.3.11_qbz5n2kfra8p0\LocalCache\local-packages\Python311\site-packages\rest_framework\serializers.py", line 1222, in build_field
    return self.build_unknown_field(field_name, model_class)
           ^^^^^^^^^^^^^^^^^^^^^^^^^^^^^^^^^^^^^^^^^^^^^^^^^
  File "C:\Users\ASHISH KUMAR\AppData\Local\Packages\PythonSoftwareFoundation.Python.3.11_qbz5n2kfra8p0\LocalCache\local-packages\Python311\site-packages\rest_framework\serializers.py", line 1340, in build_unknown_field
    raise ImproperlyConfigured(
django.core.exceptions.ImproperlyConfigured: Field name `current_streak` is not valid for model `UserProfile`.
WARNING 2025-09-09 01:01:13,147 log 36076 14860 Bad Request: /api/v1/challenges/submissions/
WARNING 2025-09-09 01:01:13,702 log 36076 14860 Unauthorized: /api/v1/challenges/submissions/
WARNING 2025-09-09 01:01:15,688 log 36076 14860 Unauthorized: /api/v1/content/lessons/
WARNING 2025-09-09 01:01:21,077 log 36076 14860 Unauthorized: /api/v1/gamification/badges/
WARNING 2025-09-09 01:01:24,373 log 36076 14860 Unauthorized: /api/v1/gamification/point-transactions/
WARNING 2025-09-09 01:01:27,318 log 36076 14860 Unauthorized: /api/v1/auth/users/
WARNING 2025-09-09 01:02:40,985 log 30268 39756 Unauthorized: /api/v1/challenges/challenges/
ERROR 2025-09-09 01:02:41,532 log 30268 39756 Internal Server Error: /api/v1/challenges/challenges/1/
Traceback (most recent call last):
  File "C:\Users\ASHISH KUMAR\AppData\Local\Packages\PythonSoftwareFoundation.Python.3.11_qbz5n2kfra8p0\LocalCache\local-packages\Python311\site-packages\django\core\handlers\exception.py", line 55, in inner
    response = get_response(request)
               ^^^^^^^^^^^^^^^^^^^^^
  File "C:\Users\ASHISH KUMAR\AppData\Local\Packages\PythonSoftwareFoundation.Python.3.11_qbz5n2kfra8p0\LocalCache\local-packages\Python311\site-packages\django\core\handlers\base.py", line 197, in _get_response
    response = wrapped_callback(request, *callback_args, **callback_kwargs)
               ^^^^^^^^^^^^^^^^^^^^^^^^^^^^^^^^^^^^^^^^^^^^^^^^^^^^^^^^^^^^
  File "C:\Users\ASHISH KUMAR\AppData\Local\Packages\PythonSoftwareFoundation.Python.3.11_qbz5n2kfra8p0\LocalCache\local-packages\Python311\site-packages\django\views\decorators\csrf.py", line 56, in wrapper_view
    return view_func(*args, **kwargs)
           ^^^^^^^^^^^^^^^^^^^^^^^^^^
  File "C:\Users\ASHISH KUMAR\AppData\Local\Packages\PythonSoftwareFoundation.Python.3.11_qbz5n2kfra8p0\LocalCache\local-packages\Python311\site-packages\rest_framework\viewsets.py", line 125, in view
    return self.dispatch(request, *args, **kwargs)
           ^^^^^^^^^^^^^^^^^^^^^^^^^^^^^^^^^^^^^^^
  File "C:\Users\ASHISH KUMAR\AppData\Local\Packages\PythonSoftwareFoundation.Python.3.11_qbz5n2kfra8p0\LocalCache\local-packages\Python311\site-packages\rest_framework\views.py", line 509, in dispatch
    response = self.handle_exception(exc)
               ^^^^^^^^^^^^^^^^^^^^^^^^^^
  File "C:\Users\ASHISH KUMAR\AppData\Local\Packages\PythonSoftwareFoundation.Python.3.11_qbz5n2kfra8p0\LocalCache\local-packages\Python311\site-packages\rest_framework\views.py", line 469, in handle_exception
    self.raise_uncaught_exception(exc)
  File "C:\Users\ASHISH KUMAR\AppData\Local\Packages\PythonSoftwareFoundation.Python.3.11_qbz5n2kfra8p0\LocalCache\local-packages\Python311\site-packages\rest_framework\views.py", line 480, in raise_uncaught_exception
    raise exc
  File "C:\Users\ASHISH KUMAR\AppData\Local\Packages\PythonSoftwareFoundation.Python.3.11_qbz5n2kfra8p0\LocalCache\local-packages\Python311\site-packages\rest_framework\views.py", line 506, in dispatch
    response = handler(request, *args, **kwargs)
               ^^^^^^^^^^^^^^^^^^^^^^^^^^^^^^^^^
  File "C:\Users\ASHISH KUMAR\AppData\Local\Packages\PythonSoftwareFoundation.Python.3.11_qbz5n2kfra8p0\LocalCache\local-packages\Python311\site-packages\rest_framework\mixins.py", line 56, in retrieve
    return Response(serializer.data)
                    ^^^^^^^^^^^^^^^
  File "C:\Users\ASHISH KUMAR\AppData\Local\Packages\PythonSoftwareFoundation.Python.3.11_qbz5n2kfra8p0\LocalCache\local-packages\Python311\site-packages\rest_framework\serializers.py", line 555, in data
    ret = super().data
          ^^^^^^^^^^^^
  File "C:\Users\ASHISH KUMAR\AppData\Local\Packages\PythonSoftwareFoundation.Python.3.11_qbz5n2kfra8p0\LocalCache\local-packages\Python311\site-packages\rest_framework\serializers.py", line 253, in data
    self._data = self.to_representation(self.instance)
                 ^^^^^^^^^^^^^^^^^^^^^^^^^^^^^^^^^^^^^
  File "C:\Users\ASHISH KUMAR\AppData\Local\Packages\PythonSoftwareFoundation.Python.3.11_qbz5n2kfra8p0\LocalCache\local-packages\Python311\site-packages\rest_framework\serializers.py", line 522, in to_representation
    ret[field.field_name] = field.to_representation(attribute)
                            ^^^^^^^^^^^^^^^^^^^^^^^^^^^^^^^^^^
  File "C:\Users\ASHISH KUMAR\AppData\Local\Packages\PythonSoftwareFoundation.Python.3.11_qbz5n2kfra8p0\LocalCache\local-packages\Python311\site-packages\rest_framework\serializers.py", line 507, in to_representation
    for field in fields:
  File "C:\Users\ASHISH KUMAR\AppData\Local\Packages\PythonSoftwareFoundation.Python.3.11_qbz5n2kfra8p0\LocalCache\local-packages\Python311\site-packages\rest_framework\serializers.py", line 368, in _readable_fields
    for field in self.fields.values():
                 ^^^^^^^^^^^
  File "C:\Users\ASHISH KUMAR\AppData\Local\Packages\PythonSoftwareFoundation.Python.3.11_qbz5n2kfra8p0\LocalCache\local-packages\Python311\site-packages\django\utils\functional.py", line 57, in __get__
    res = instance.__dict__[self.name] = self.func(instance)
                                         ^^^^^^^^^^^^^^^^^^^
  File "C:\Users\ASHISH KUMAR\AppData\Local\Packages\PythonSoftwareFoundation.Python.3.11_qbz5n2kfra8p0\LocalCache\local-packages\Python311\site-packages\rest_framework\serializers.py", line 356, in fields
    for key, value in self.get_fields().items():
                      ^^^^^^^^^^^^^^^^^
  File "C:\Users\ASHISH KUMAR\AppData\Local\Packages\PythonSoftwareFoundation.Python.3.11_qbz5n2kfra8p0\LocalCache\local-packages\Python311\site-packages\rest_framework\serializers.py", line 1076, in get_fields
    field_class, field_kwargs = self.build_field(
                                ^^^^^^^^^^^^^^^^^
  File "C:\Users\ASHISH KUMAR\AppData\Local\Packages\PythonSoftwareFoundation.Python.3.11_qbz5n2kfra8p0\LocalCache\local-packages\Python311\site-packages\rest_framework\serializers.py", line 1222, in build_field
    return self.build_unknown_field(field_name, model_class)
           ^^^^^^^^^^^^^^^^^^^^^^^^^^^^^^^^^^^^^^^^^^^^^^^^^
  File "C:\Users\ASHISH KUMAR\AppData\Local\Packages\PythonSoftwareFoundation.Python.3.11_qbz5n2kfra8p0\LocalCache\local-packages\Python311\site-packages\rest_framework\serializers.py", line 1340, in build_unknown_field
    raise ImproperlyConfigured(
django.core.exceptions.ImproperlyConfigured: Field name `current_streak` is not valid for model `UserProfile`.
ERROR 2025-09-09 01:02:42,027 log 30268 39756 Internal Server Error: /api/v1/challenges/challenges/
Traceback (most recent call last):
  File "C:\Users\ASHISH KUMAR\AppData\Local\Packages\PythonSoftwareFoundation.Python.3.11_qbz5n2kfra8p0\LocalCache\local-packages\Python311\site-packages\django\core\handlers\exception.py", line 55, in inner
    response = get_response(request)
               ^^^^^^^^^^^^^^^^^^^^^
  File "C:\Users\ASHISH KUMAR\AppData\Local\Packages\PythonSoftwareFoundation.Python.3.11_qbz5n2kfra8p0\LocalCache\local-packages\Python311\site-packages\django\core\handlers\base.py", line 197, in _get_response
    response = wrapped_callback(request, *callback_args, **callback_kwargs)
               ^^^^^^^^^^^^^^^^^^^^^^^^^^^^^^^^^^^^^^^^^^^^^^^^^^^^^^^^^^^^
  File "C:\Users\ASHISH KUMAR\AppData\Local\Packages\PythonSoftwareFoundation.Python.3.11_qbz5n2kfra8p0\LocalCache\local-packages\Python311\site-packages\django\views\decorators\csrf.py", line 56, in wrapper_view
    return view_func(*args, **kwargs)
           ^^^^^^^^^^^^^^^^^^^^^^^^^^
  File "C:\Users\ASHISH KUMAR\AppData\Local\Packages\PythonSoftwareFoundation.Python.3.11_qbz5n2kfra8p0\LocalCache\local-packages\Python311\site-packages\rest_framework\viewsets.py", line 125, in view
    return self.dispatch(request, *args, **kwargs)
           ^^^^^^^^^^^^^^^^^^^^^^^^^^^^^^^^^^^^^^^
  File "C:\Users\ASHISH KUMAR\AppData\Local\Packages\PythonSoftwareFoundation.Python.3.11_qbz5n2kfra8p0\LocalCache\local-packages\Python311\site-packages\rest_framework\views.py", line 509, in dispatch
    response = self.handle_exception(exc)
               ^^^^^^^^^^^^^^^^^^^^^^^^^^
  File "C:\Users\ASHISH KUMAR\AppData\Local\Packages\PythonSoftwareFoundation.Python.3.11_qbz5n2kfra8p0\LocalCache\local-packages\Python311\site-packages\rest_framework\views.py", line 469, in handle_exception
    self.raise_uncaught_exception(exc)
  File "C:\Users\ASHISH KUMAR\AppData\Local\Packages\PythonSoftwareFoundation.Python.3.11_qbz5n2kfra8p0\LocalCache\local-packages\Python311\site-packages\rest_framework\views.py", line 480, in raise_uncaught_exception
    raise exc
  File "C:\Users\ASHISH KUMAR\AppData\Local\Packages\PythonSoftwareFoundation.Python.3.11_qbz5n2kfra8p0\LocalCache\local-packages\Python311\site-packages\rest_framework\views.py", line 506, in dispatch
    response = handler(request, *args, **kwargs)
               ^^^^^^^^^^^^^^^^^^^^^^^^^^^^^^^^^
  File "C:\Users\ASHISH KUMAR\AppData\Local\Packages\PythonSoftwareFoundation.Python.3.11_qbz5n2kfra8p0\LocalCache\local-packages\Python311\site-packages\rest_framework\mixins.py", line 43, in list
    return self.get_paginated_response(serializer.data)
                                       ^^^^^^^^^^^^^^^
  File "C:\Users\ASHISH KUMAR\AppData\Local\Packages\PythonSoftwareFoundation.Python.3.11_qbz5n2kfra8p0\LocalCache\local-packages\Python311\site-packages\rest_framework\serializers.py", line 768, in data
    ret = super().data
          ^^^^^^^^^^^^
  File "C:\Users\ASHISH KUMAR\AppData\Local\Packages\PythonSoftwareFoundation.Python.3.11_qbz5n2kfra8p0\LocalCache\local-packages\Python311\site-packages\rest_framework\serializers.py", line 253, in data
    self._data = self.to_representation(self.instance)
                 ^^^^^^^^^^^^^^^^^^^^^^^^^^^^^^^^^^^^^
  File "C:\Users\ASHISH KUMAR\AppData\Local\Packages\PythonSoftwareFoundation.Python.3.11_qbz5n2kfra8p0\LocalCache\local-packages\Python311\site-packages\rest_framework\serializers.py", line 686, in to_representation
    return [
           ^
  File "C:\Users\ASHISH KUMAR\AppData\Local\Packages\PythonSoftwareFoundation.Python.3.11_qbz5n2kfra8p0\LocalCache\local-packages\Python311\site-packages\rest_framework\serializers.py", line 687, in <listcomp>
    self.child.to_representation(item) for item in iterable
    ^^^^^^^^^^^^^^^^^^^^^^^^^^^^^^^^^^
  File "C:\Users\ASHISH KUMAR\AppData\Local\Packages\PythonSoftwareFoundation.Python.3.11_qbz5n2kfra8p0\LocalCache\local-packages\Python311\site-packages\rest_framework\serializers.py", line 522, in to_representation
    ret[field.field_name] = field.to_representation(attribute)
                            ^^^^^^^^^^^^^^^^^^^^^^^^^^^^^^^^^^
  File "C:\Users\ASHISH KUMAR\AppData\Local\Packages\PythonSoftwareFoundation.Python.3.11_qbz5n2kfra8p0\LocalCache\local-packages\Python311\site-packages\rest_framework\serializers.py", line 507, in to_representation
    for field in fields:
  File "C:\Users\ASHISH KUMAR\AppData\Local\Packages\PythonSoftwareFoundation.Python.3.11_qbz5n2kfra8p0\LocalCache\local-packages\Python311\site-packages\rest_framework\serializers.py", line 368, in _readable_fields
    for field in self.fields.values():
                 ^^^^^^^^^^^
  File "C:\Users\ASHISH KUMAR\AppData\Local\Packages\PythonSoftwareFoundation.Python.3.11_qbz5n2kfra8p0\LocalCache\local-packages\Python311\site-packages\django\utils\functional.py", line 57, in __get__
    res = instance.__dict__[self.name] = self.func(instance)
                                         ^^^^^^^^^^^^^^^^^^^
  File "C:\Users\ASHISH KUMAR\AppData\Local\Packages\PythonSoftwareFoundation.Python.3.11_qbz5n2kfra8p0\LocalCache\local-packages\Python311\site-packages\rest_framework\serializers.py", line 356, in fields
    for key, value in self.get_fields().items():
                      ^^^^^^^^^^^^^^^^^
  File "C:\Users\ASHISH KUMAR\AppData\Local\Packages\PythonSoftwareFoundation.Python.3.11_qbz5n2kfra8p0\LocalCache\local-packages\Python311\site-packages\rest_framework\serializers.py", line 1076, in get_fields
    field_class, field_kwargs = self.build_field(
                                ^^^^^^^^^^^^^^^^^
  File "C:\Users\ASHISH KUMAR\AppData\Local\Packages\PythonSoftwareFoundation.Python.3.11_qbz5n2kfra8p0\LocalCache\local-packages\Python311\site-packages\rest_framework\serializers.py", line 1222, in build_field
    return self.build_unknown_field(field_name, model_class)
           ^^^^^^^^^^^^^^^^^^^^^^^^^^^^^^^^^^^^^^^^^^^^^^^^^
  File "C:\Users\ASHISH KUMAR\AppData\Local\Packages\PythonSoftwareFoundation.Python.3.11_qbz5n2kfra8p0\LocalCache\local-packages\Python311\site-packages\rest_framework\serializers.py", line 1340, in build_unknown_field
    raise ImproperlyConfigured(
django.core.exceptions.ImproperlyConfigured: Field name `current_streak` is not valid for model `UserProfile`.
WARNING 2025-09-09 01:02:46,069 log 30268 39756 Bad Request: /api/v1/challenges/submissions/
WARNING 2025-09-09 01:02:46,779 log 30268 39756 Unauthorized: /api/v1/challenges/submissions/
WARNING 2025-09-09 01:02:48,893 log 30268 39756 Unauthorized: /api/v1/content/lessons/
WARNING 2025-09-09 01:02:55,009 log 30268 39756 Unauthorized: /api/v1/gamification/badges/
WARNING 2025-09-09 01:02:58,479 log 30268 39756 Unauthorized: /api/v1/gamification/point-transactions/
WARNING 2025-09-09 01:03:01,681 log 30268 39756 Unauthorized: /api/v1/auth/users/
WARNING 2025-09-09 01:03:24,004 log 16412 29768 Bad Request: /api/v1/challenges/submissions/
WARNING 2025-09-09 01:04:48,952 log 23444 33236 Unauthorized: /api/v1/challenges/challenges/
ERROR 2025-09-09 01:04:49,503 log 23444 33236 Internal Server Error: /api/v1/challenges/challenges/1/
Traceback (most recent call last):
  File "C:\Users\ASHISH KUMAR\AppData\Local\Packages\PythonSoftwareFoundation.Python.3.11_qbz5n2kfra8p0\LocalCache\local-packages\Python311\site-packages\django\core\handlers\exception.py", line 55, in inner
    response = get_response(request)
               ^^^^^^^^^^^^^^^^^^^^^
  File "C:\Users\ASHISH KUMAR\AppData\Local\Packages\PythonSoftwareFoundation.Python.3.11_qbz5n2kfra8p0\LocalCache\local-packages\Python311\site-packages\django\core\handlers\base.py", line 197, in _get_response
    response = wrapped_callback(request, *callback_args, **callback_kwargs)
               ^^^^^^^^^^^^^^^^^^^^^^^^^^^^^^^^^^^^^^^^^^^^^^^^^^^^^^^^^^^^
  File "C:\Users\ASHISH KUMAR\AppData\Local\Packages\PythonSoftwareFoundation.Python.3.11_qbz5n2kfra8p0\LocalCache\local-packages\Python311\site-packages\django\views\decorators\csrf.py", line 56, in wrapper_view
    return view_func(*args, **kwargs)
           ^^^^^^^^^^^^^^^^^^^^^^^^^^
  File "C:\Users\ASHISH KUMAR\AppData\Local\Packages\PythonSoftwareFoundation.Python.3.11_qbz5n2kfra8p0\LocalCache\local-packages\Python311\site-packages\rest_framework\viewsets.py", line 125, in view
    return self.dispatch(request, *args, **kwargs)
           ^^^^^^^^^^^^^^^^^^^^^^^^^^^^^^^^^^^^^^^
  File "C:\Users\ASHISH KUMAR\AppData\Local\Packages\PythonSoftwareFoundation.Python.3.11_qbz5n2kfra8p0\LocalCache\local-packages\Python311\site-packages\rest_framework\views.py", line 509, in dispatch
    response = self.handle_exception(exc)
               ^^^^^^^^^^^^^^^^^^^^^^^^^^
  File "C:\Users\ASHISH KUMAR\AppData\Local\Packages\PythonSoftwareFoundation.Python.3.11_qbz5n2kfra8p0\LocalCache\local-packages\Python311\site-packages\rest_framework\views.py", line 469, in handle_exception
    self.raise_uncaught_exception(exc)
  File "C:\Users\ASHISH KUMAR\AppData\Local\Packages\PythonSoftwareFoundation.Python.3.11_qbz5n2kfra8p0\LocalCache\local-packages\Python311\site-packages\rest_framework\views.py", line 480, in raise_uncaught_exception
    raise exc
  File "C:\Users\ASHISH KUMAR\AppData\Local\Packages\PythonSoftwareFoundation.Python.3.11_qbz5n2kfra8p0\LocalCache\local-packages\Python311\site-packages\rest_framework\views.py", line 506, in dispatch
    response = handler(request, *args, **kwargs)
               ^^^^^^^^^^^^^^^^^^^^^^^^^^^^^^^^^
  File "C:\Users\ASHISH KUMAR\AppData\Local\Packages\PythonSoftwareFoundation.Python.3.11_qbz5n2kfra8p0\LocalCache\local-packages\Python311\site-packages\rest_framework\mixins.py", line 56, in retrieve
    return Response(serializer.data)
                    ^^^^^^^^^^^^^^^
  File "C:\Users\ASHISH KUMAR\AppData\Local\Packages\PythonSoftwareFoundation.Python.3.11_qbz5n2kfra8p0\LocalCache\local-packages\Python311\site-packages\rest_framework\serializers.py", line 555, in data
    ret = super().data
          ^^^^^^^^^^^^
  File "C:\Users\ASHISH KUMAR\AppData\Local\Packages\PythonSoftwareFoundation.Python.3.11_qbz5n2kfra8p0\LocalCache\local-packages\Python311\site-packages\rest_framework\serializers.py", line 253, in data
    self._data = self.to_representation(self.instance)
                 ^^^^^^^^^^^^^^^^^^^^^^^^^^^^^^^^^^^^^
  File "C:\Users\ASHISH KUMAR\AppData\Local\Packages\PythonSoftwareFoundation.Python.3.11_qbz5n2kfra8p0\LocalCache\local-packages\Python311\site-packages\rest_framework\serializers.py", line 522, in to_representation
    ret[field.field_name] = field.to_representation(attribute)
                            ^^^^^^^^^^^^^^^^^^^^^^^^^^^^^^^^^^
  File "C:\Users\ASHISH KUMAR\AppData\Local\Packages\PythonSoftwareFoundation.Python.3.11_qbz5n2kfra8p0\LocalCache\local-packages\Python311\site-packages\rest_framework\serializers.py", line 507, in to_representation
    for field in fields:
  File "C:\Users\ASHISH KUMAR\AppData\Local\Packages\PythonSoftwareFoundation.Python.3.11_qbz5n2kfra8p0\LocalCache\local-packages\Python311\site-packages\rest_framework\serializers.py", line 368, in _readable_fields
    for field in self.fields.values():
                 ^^^^^^^^^^^
  File "C:\Users\ASHISH KUMAR\AppData\Local\Packages\PythonSoftwareFoundation.Python.3.11_qbz5n2kfra8p0\LocalCache\local-packages\Python311\site-packages\django\utils\functional.py", line 57, in __get__
    res = instance.__dict__[self.name] = self.func(instance)
                                         ^^^^^^^^^^^^^^^^^^^
  File "C:\Users\ASHISH KUMAR\AppData\Local\Packages\PythonSoftwareFoundation.Python.3.11_qbz5n2kfra8p0\LocalCache\local-packages\Python311\site-packages\rest_framework\serializers.py", line 356, in fields
    for key, value in self.get_fields().items():
                      ^^^^^^^^^^^^^^^^^
  File "C:\Users\ASHISH KUMAR\AppData\Local\Packages\PythonSoftwareFoundation.Python.3.11_qbz5n2kfra8p0\LocalCache\local-packages\Python311\site-packages\rest_framework\serializers.py", line 1076, in get_fields
    field_class, field_kwargs = self.build_field(
                                ^^^^^^^^^^^^^^^^^
  File "C:\Users\ASHISH KUMAR\AppData\Local\Packages\PythonSoftwareFoundation.Python.3.11_qbz5n2kfra8p0\LocalCache\local-packages\Python311\site-packages\rest_framework\serializers.py", line 1222, in build_field
    return self.build_unknown_field(field_name, model_class)
           ^^^^^^^^^^^^^^^^^^^^^^^^^^^^^^^^^^^^^^^^^^^^^^^^^
  File "C:\Users\ASHISH KUMAR\AppData\Local\Packages\PythonSoftwareFoundation.Python.3.11_qbz5n2kfra8p0\LocalCache\local-packages\Python311\site-packages\rest_framework\serializers.py", line 1340, in build_unknown_field
    raise ImproperlyConfigured(
django.core.exceptions.ImproperlyConfigured: Field name `current_streak` is not valid for model `UserProfile`.
ERROR 2025-09-09 01:04:50,053 log 23444 33236 Internal Server Error: /api/v1/challenges/challenges/
Traceback (most recent call last):
  File "C:\Users\ASHISH KUMAR\AppData\Local\Packages\PythonSoftwareFoundation.Python.3.11_qbz5n2kfra8p0\LocalCache\local-packages\Python311\site-packages\django\core\handlers\exception.py", line 55, in inner
    response = get_response(request)
               ^^^^^^^^^^^^^^^^^^^^^
  File "C:\Users\ASHISH KUMAR\AppData\Local\Packages\PythonSoftwareFoundation.Python.3.11_qbz5n2kfra8p0\LocalCache\local-packages\Python311\site-packages\django\core\handlers\base.py", line 197, in _get_response
    response = wrapped_callback(request, *callback_args, **callback_kwargs)
               ^^^^^^^^^^^^^^^^^^^^^^^^^^^^^^^^^^^^^^^^^^^^^^^^^^^^^^^^^^^^
  File "C:\Users\ASHISH KUMAR\AppData\Local\Packages\PythonSoftwareFoundation.Python.3.11_qbz5n2kfra8p0\LocalCache\local-packages\Python311\site-packages\django\views\decorators\csrf.py", line 56, in wrapper_view
    return view_func(*args, **kwargs)
           ^^^^^^^^^^^^^^^^^^^^^^^^^^
  File "C:\Users\ASHISH KUMAR\AppData\Local\Packages\PythonSoftwareFoundation.Python.3.11_qbz5n2kfra8p0\LocalCache\local-packages\Python311\site-packages\rest_framework\viewsets.py", line 125, in view
    return self.dispatch(request, *args, **kwargs)
           ^^^^^^^^^^^^^^^^^^^^^^^^^^^^^^^^^^^^^^^
  File "C:\Users\ASHISH KUMAR\AppData\Local\Packages\PythonSoftwareFoundation.Python.3.11_qbz5n2kfra8p0\LocalCache\local-packages\Python311\site-packages\rest_framework\views.py", line 509, in dispatch
    response = self.handle_exception(exc)
               ^^^^^^^^^^^^^^^^^^^^^^^^^^
  File "C:\Users\ASHISH KUMAR\AppData\Local\Packages\PythonSoftwareFoundation.Python.3.11_qbz5n2kfra8p0\LocalCache\local-packages\Python311\site-packages\rest_framework\views.py", line 469, in handle_exception
    self.raise_uncaught_exception(exc)
  File "C:\Users\ASHISH KUMAR\AppData\Local\Packages\PythonSoftwareFoundation.Python.3.11_qbz5n2kfra8p0\LocalCache\local-packages\Python311\site-packages\rest_framework\views.py", line 480, in raise_uncaught_exception
    raise exc
  File "C:\Users\ASHISH KUMAR\AppData\Local\Packages\PythonSoftwareFoundation.Python.3.11_qbz5n2kfra8p0\LocalCache\local-packages\Python311\site-packages\rest_framework\views.py", line 506, in dispatch
    response = handler(request, *args, **kwargs)
               ^^^^^^^^^^^^^^^^^^^^^^^^^^^^^^^^^
  File "C:\Users\ASHISH KUMAR\AppData\Local\Packages\PythonSoftwareFoundation.Python.3.11_qbz5n2kfra8p0\LocalCache\local-packages\Python311\site-packages\rest_framework\mixins.py", line 43, in list
    return self.get_paginated_response(serializer.data)
                                       ^^^^^^^^^^^^^^^
  File "C:\Users\ASHISH KUMAR\AppData\Local\Packages\PythonSoftwareFoundation.Python.3.11_qbz5n2kfra8p0\LocalCache\local-packages\Python311\site-packages\rest_framework\serializers.py", line 768, in data
    ret = super().data
          ^^^^^^^^^^^^
  File "C:\Users\ASHISH KUMAR\AppData\Local\Packages\PythonSoftwareFoundation.Python.3.11_qbz5n2kfra8p0\LocalCache\local-packages\Python311\site-packages\rest_framework\serializers.py", line 253, in data
    self._data = self.to_representation(self.instance)
                 ^^^^^^^^^^^^^^^^^^^^^^^^^^^^^^^^^^^^^
  File "C:\Users\ASHISH KUMAR\AppData\Local\Packages\PythonSoftwareFoundation.Python.3.11_qbz5n2kfra8p0\LocalCache\local-packages\Python311\site-packages\rest_framework\serializers.py", line 686, in to_representation
    return [
           ^
  File "C:\Users\ASHISH KUMAR\AppData\Local\Packages\PythonSoftwareFoundation.Python.3.11_qbz5n2kfra8p0\LocalCache\local-packages\Python311\site-packages\rest_framework\serializers.py", line 687, in <listcomp>
    self.child.to_representation(item) for item in iterable
    ^^^^^^^^^^^^^^^^^^^^^^^^^^^^^^^^^^
  File "C:\Users\ASHISH KUMAR\AppData\Local\Packages\PythonSoftwareFoundation.Python.3.11_qbz5n2kfra8p0\LocalCache\local-packages\Python311\site-packages\rest_framework\serializers.py", line 522, in to_representation
    ret[field.field_name] = field.to_representation(attribute)
                            ^^^^^^^^^^^^^^^^^^^^^^^^^^^^^^^^^^
  File "C:\Users\ASHISH KUMAR\AppData\Local\Packages\PythonSoftwareFoundation.Python.3.11_qbz5n2kfra8p0\LocalCache\local-packages\Python311\site-packages\rest_framework\serializers.py", line 507, in to_representation
    for field in fields:
  File "C:\Users\ASHISH KUMAR\AppData\Local\Packages\PythonSoftwareFoundation.Python.3.11_qbz5n2kfra8p0\LocalCache\local-packages\Python311\site-packages\rest_framework\serializers.py", line 368, in _readable_fields
    for field in self.fields.values():
                 ^^^^^^^^^^^
  File "C:\Users\ASHISH KUMAR\AppData\Local\Packages\PythonSoftwareFoundation.Python.3.11_qbz5n2kfra8p0\LocalCache\local-packages\Python311\site-packages\django\utils\functional.py", line 57, in __get__
    res = instance.__dict__[self.name] = self.func(instance)
                                         ^^^^^^^^^^^^^^^^^^^
  File "C:\Users\ASHISH KUMAR\AppData\Local\Packages\PythonSoftwareFoundation.Python.3.11_qbz5n2kfra8p0\LocalCache\local-packages\Python311\site-packages\rest_framework\serializers.py", line 356, in fields
    for key, value in self.get_fields().items():
                      ^^^^^^^^^^^^^^^^^
  File "C:\Users\ASHISH KUMAR\AppData\Local\Packages\PythonSoftwareFoundation.Python.3.11_qbz5n2kfra8p0\LocalCache\local-packages\Python311\site-packages\rest_framework\serializers.py", line 1076, in get_fields
    field_class, field_kwargs = self.build_field(
                                ^^^^^^^^^^^^^^^^^
  File "C:\Users\ASHISH KUMAR\AppData\Local\Packages\PythonSoftwareFoundation.Python.3.11_qbz5n2kfra8p0\LocalCache\local-packages\Python311\site-packages\rest_framework\serializers.py", line 1222, in build_field
    return self.build_unknown_field(field_name, model_class)
           ^^^^^^^^^^^^^^^^^^^^^^^^^^^^^^^^^^^^^^^^^^^^^^^^^
  File "C:\Users\ASHISH KUMAR\AppData\Local\Packages\PythonSoftwareFoundation.Python.3.11_qbz5n2kfra8p0\LocalCache\local-packages\Python311\site-packages\rest_framework\serializers.py", line 1340, in build_unknown_field
    raise ImproperlyConfigured(
django.core.exceptions.ImproperlyConfigured: Field name `current_streak` is not valid for model `UserProfile`.
WARNING 2025-09-09 01:04:54,644 log 23444 33236 Unauthorized: /api/v1/challenges/submissions/
WARNING 2025-09-09 01:04:56,786 log 23444 33236 Unauthorized: /api/v1/content/lessons/
WARNING 2025-09-09 01:05:02,807 log 23444 33236 Unauthorized: /api/v1/gamification/badges/
WARNING 2025-09-09 01:05:06,206 log 23444 33236 Unauthorized: /api/v1/gamification/point-transactions/
WARNING 2025-09-09 01:05:09,311 log 23444 33236 Unauthorized: /api/v1/auth/users/
WARNING 2025-09-09 01:05:56,667 log 40332 32040 Unauthorized: /api/v1/challenges/challenges/
ERROR 2025-09-09 01:05:57,167 log 40332 32040 Internal Server Error: /api/v1/challenges/challenges/1/
Traceback (most recent call last):
  File "C:\Users\ASHISH KUMAR\AppData\Local\Packages\PythonSoftwareFoundation.Python.3.11_qbz5n2kfra8p0\LocalCache\local-packages\Python311\site-packages\django\core\handlers\exception.py", line 55, in inner
    response = get_response(request)
               ^^^^^^^^^^^^^^^^^^^^^
  File "C:\Users\ASHISH KUMAR\AppData\Local\Packages\PythonSoftwareFoundation.Python.3.11_qbz5n2kfra8p0\LocalCache\local-packages\Python311\site-packages\django\core\handlers\base.py", line 197, in _get_response
    response = wrapped_callback(request, *callback_args, **callback_kwargs)
               ^^^^^^^^^^^^^^^^^^^^^^^^^^^^^^^^^^^^^^^^^^^^^^^^^^^^^^^^^^^^
  File "C:\Users\ASHISH KUMAR\AppData\Local\Packages\PythonSoftwareFoundation.Python.3.11_qbz5n2kfra8p0\LocalCache\local-packages\Python311\site-packages\django\views\decorators\csrf.py", line 56, in wrapper_view
    return view_func(*args, **kwargs)
           ^^^^^^^^^^^^^^^^^^^^^^^^^^
  File "C:\Users\ASHISH KUMAR\AppData\Local\Packages\PythonSoftwareFoundation.Python.3.11_qbz5n2kfra8p0\LocalCache\local-packages\Python311\site-packages\rest_framework\viewsets.py", line 125, in view
    return self.dispatch(request, *args, **kwargs)
           ^^^^^^^^^^^^^^^^^^^^^^^^^^^^^^^^^^^^^^^
  File "C:\Users\ASHISH KUMAR\AppData\Local\Packages\PythonSoftwareFoundation.Python.3.11_qbz5n2kfra8p0\LocalCache\local-packages\Python311\site-packages\rest_framework\views.py", line 509, in dispatch
    response = self.handle_exception(exc)
               ^^^^^^^^^^^^^^^^^^^^^^^^^^
  File "C:\Users\ASHISH KUMAR\AppData\Local\Packages\PythonSoftwareFoundation.Python.3.11_qbz5n2kfra8p0\LocalCache\local-packages\Python311\site-packages\rest_framework\views.py", line 469, in handle_exception
    self.raise_uncaught_exception(exc)
  File "C:\Users\ASHISH KUMAR\AppData\Local\Packages\PythonSoftwareFoundation.Python.3.11_qbz5n2kfra8p0\LocalCache\local-packages\Python311\site-packages\rest_framework\views.py", line 480, in raise_uncaught_exception
    raise exc
  File "C:\Users\ASHISH KUMAR\AppData\Local\Packages\PythonSoftwareFoundation.Python.3.11_qbz5n2kfra8p0\LocalCache\local-packages\Python311\site-packages\rest_framework\views.py", line 506, in dispatch
    response = handler(request, *args, **kwargs)
               ^^^^^^^^^^^^^^^^^^^^^^^^^^^^^^^^^
  File "C:\Users\ASHISH KUMAR\AppData\Local\Packages\PythonSoftwareFoundation.Python.3.11_qbz5n2kfra8p0\LocalCache\local-packages\Python311\site-packages\rest_framework\mixins.py", line 56, in retrieve
    return Response(serializer.data)
                    ^^^^^^^^^^^^^^^
  File "C:\Users\ASHISH KUMAR\AppData\Local\Packages\PythonSoftwareFoundation.Python.3.11_qbz5n2kfra8p0\LocalCache\local-packages\Python311\site-packages\rest_framework\serializers.py", line 555, in data
    ret = super().data
          ^^^^^^^^^^^^
  File "C:\Users\ASHISH KUMAR\AppData\Local\Packages\PythonSoftwareFoundation.Python.3.11_qbz5n2kfra8p0\LocalCache\local-packages\Python311\site-packages\rest_framework\serializers.py", line 253, in data
    self._data = self.to_representation(self.instance)
                 ^^^^^^^^^^^^^^^^^^^^^^^^^^^^^^^^^^^^^
  File "C:\Users\ASHISH KUMAR\AppData\Local\Packages\PythonSoftwareFoundation.Python.3.11_qbz5n2kfra8p0\LocalCache\local-packages\Python311\site-packages\rest_framework\serializers.py", line 522, in to_representation
    ret[field.field_name] = field.to_representation(attribute)
                            ^^^^^^^^^^^^^^^^^^^^^^^^^^^^^^^^^^
  File "C:\Users\ASHISH KUMAR\AppData\Local\Packages\PythonSoftwareFoundation.Python.3.11_qbz5n2kfra8p0\LocalCache\local-packages\Python311\site-packages\rest_framework\serializers.py", line 507, in to_representation
    for field in fields:
  File "C:\Users\ASHISH KUMAR\AppData\Local\Packages\PythonSoftwareFoundation.Python.3.11_qbz5n2kfra8p0\LocalCache\local-packages\Python311\site-packages\rest_framework\serializers.py", line 368, in _readable_fields
    for field in self.fields.values():
                 ^^^^^^^^^^^
  File "C:\Users\ASHISH KUMAR\AppData\Local\Packages\PythonSoftwareFoundation.Python.3.11_qbz5n2kfra8p0\LocalCache\local-packages\Python311\site-packages\django\utils\functional.py", line 57, in __get__
    res = instance.__dict__[self.name] = self.func(instance)
                                         ^^^^^^^^^^^^^^^^^^^
  File "C:\Users\ASHISH KUMAR\AppData\Local\Packages\PythonSoftwareFoundation.Python.3.11_qbz5n2kfra8p0\LocalCache\local-packages\Python311\site-packages\rest_framework\serializers.py", line 356, in fields
    for key, value in self.get_fields().items():
                      ^^^^^^^^^^^^^^^^^
  File "C:\Users\ASHISH KUMAR\AppData\Local\Packages\PythonSoftwareFoundation.Python.3.11_qbz5n2kfra8p0\LocalCache\local-packages\Python311\site-packages\rest_framework\serializers.py", line 1076, in get_fields
    field_class, field_kwargs = self.build_field(
                                ^^^^^^^^^^^^^^^^^
  File "C:\Users\ASHISH KUMAR\AppData\Local\Packages\PythonSoftwareFoundation.Python.3.11_qbz5n2kfra8p0\LocalCache\local-packages\Python311\site-packages\rest_framework\serializers.py", line 1222, in build_field
    return self.build_unknown_field(field_name, model_class)
           ^^^^^^^^^^^^^^^^^^^^^^^^^^^^^^^^^^^^^^^^^^^^^^^^^
  File "C:\Users\ASHISH KUMAR\AppData\Local\Packages\PythonSoftwareFoundation.Python.3.11_qbz5n2kfra8p0\LocalCache\local-packages\Python311\site-packages\rest_framework\serializers.py", line 1340, in build_unknown_field
    raise ImproperlyConfigured(
django.core.exceptions.ImproperlyConfigured: Field name `current_streak` is not valid for model `UserProfile`.
ERROR 2025-09-09 01:05:57,674 log 40332 32040 Internal Server Error: /api/v1/challenges/challenges/
Traceback (most recent call last):
  File "C:\Users\ASHISH KUMAR\AppData\Local\Packages\PythonSoftwareFoundation.Python.3.11_qbz5n2kfra8p0\LocalCache\local-packages\Python311\site-packages\django\core\handlers\exception.py", line 55, in inner
    response = get_response(request)
               ^^^^^^^^^^^^^^^^^^^^^
  File "C:\Users\ASHISH KUMAR\AppData\Local\Packages\PythonSoftwareFoundation.Python.3.11_qbz5n2kfra8p0\LocalCache\local-packages\Python311\site-packages\django\core\handlers\base.py", line 197, in _get_response
    response = wrapped_callback(request, *callback_args, **callback_kwargs)
               ^^^^^^^^^^^^^^^^^^^^^^^^^^^^^^^^^^^^^^^^^^^^^^^^^^^^^^^^^^^^
  File "C:\Users\ASHISH KUMAR\AppData\Local\Packages\PythonSoftwareFoundation.Python.3.11_qbz5n2kfra8p0\LocalCache\local-packages\Python311\site-packages\django\views\decorators\csrf.py", line 56, in wrapper_view
    return view_func(*args, **kwargs)
           ^^^^^^^^^^^^^^^^^^^^^^^^^^
  File "C:\Users\ASHISH KUMAR\AppData\Local\Packages\PythonSoftwareFoundation.Python.3.11_qbz5n2kfra8p0\LocalCache\local-packages\Python311\site-packages\rest_framework\viewsets.py", line 125, in view
    return self.dispatch(request, *args, **kwargs)
           ^^^^^^^^^^^^^^^^^^^^^^^^^^^^^^^^^^^^^^^
  File "C:\Users\ASHISH KUMAR\AppData\Local\Packages\PythonSoftwareFoundation.Python.3.11_qbz5n2kfra8p0\LocalCache\local-packages\Python311\site-packages\rest_framework\views.py", line 509, in dispatch
    response = self.handle_exception(exc)
               ^^^^^^^^^^^^^^^^^^^^^^^^^^
  File "C:\Users\ASHISH KUMAR\AppData\Local\Packages\PythonSoftwareFoundation.Python.3.11_qbz5n2kfra8p0\LocalCache\local-packages\Python311\site-packages\rest_framework\views.py", line 469, in handle_exception
    self.raise_uncaught_exception(exc)
  File "C:\Users\ASHISH KUMAR\AppData\Local\Packages\PythonSoftwareFoundation.Python.3.11_qbz5n2kfra8p0\LocalCache\local-packages\Python311\site-packages\rest_framework\views.py", line 480, in raise_uncaught_exception
    raise exc
  File "C:\Users\ASHISH KUMAR\AppData\Local\Packages\PythonSoftwareFoundation.Python.3.11_qbz5n2kfra8p0\LocalCache\local-packages\Python311\site-packages\rest_framework\views.py", line 506, in dispatch
    response = handler(request, *args, **kwargs)
               ^^^^^^^^^^^^^^^^^^^^^^^^^^^^^^^^^
  File "C:\Users\ASHISH KUMAR\AppData\Local\Packages\PythonSoftwareFoundation.Python.3.11_qbz5n2kfra8p0\LocalCache\local-packages\Python311\site-packages\rest_framework\mixins.py", line 43, in list
    return self.get_paginated_response(serializer.data)
                                       ^^^^^^^^^^^^^^^
  File "C:\Users\ASHISH KUMAR\AppData\Local\Packages\PythonSoftwareFoundation.Python.3.11_qbz5n2kfra8p0\LocalCache\local-packages\Python311\site-packages\rest_framework\serializers.py", line 768, in data
    ret = super().data
          ^^^^^^^^^^^^
  File "C:\Users\ASHISH KUMAR\AppData\Local\Packages\PythonSoftwareFoundation.Python.3.11_qbz5n2kfra8p0\LocalCache\local-packages\Python311\site-packages\rest_framework\serializers.py", line 253, in data
    self._data = self.to_representation(self.instance)
                 ^^^^^^^^^^^^^^^^^^^^^^^^^^^^^^^^^^^^^
  File "C:\Users\ASHISH KUMAR\AppData\Local\Packages\PythonSoftwareFoundation.Python.3.11_qbz5n2kfra8p0\LocalCache\local-packages\Python311\site-packages\rest_framework\serializers.py", line 686, in to_representation
    return [
           ^
  File "C:\Users\ASHISH KUMAR\AppData\Local\Packages\PythonSoftwareFoundation.Python.3.11_qbz5n2kfra8p0\LocalCache\local-packages\Python311\site-packages\rest_framework\serializers.py", line 687, in <listcomp>
    self.child.to_representation(item) for item in iterable
    ^^^^^^^^^^^^^^^^^^^^^^^^^^^^^^^^^^
  File "C:\Users\ASHISH KUMAR\AppData\Local\Packages\PythonSoftwareFoundation.Python.3.11_qbz5n2kfra8p0\LocalCache\local-packages\Python311\site-packages\rest_framework\serializers.py", line 522, in to_representation
    ret[field.field_name] = field.to_representation(attribute)
                            ^^^^^^^^^^^^^^^^^^^^^^^^^^^^^^^^^^
  File "C:\Users\ASHISH KUMAR\AppData\Local\Packages\PythonSoftwareFoundation.Python.3.11_qbz5n2kfra8p0\LocalCache\local-packages\Python311\site-packages\rest_framework\serializers.py", line 507, in to_representation
    for field in fields:
  File "C:\Users\ASHISH KUMAR\AppData\Local\Packages\PythonSoftwareFoundation.Python.3.11_qbz5n2kfra8p0\LocalCache\local-packages\Python311\site-packages\rest_framework\serializers.py", line 368, in _readable_fields
    for field in self.fields.values():
                 ^^^^^^^^^^^
  File "C:\Users\ASHISH KUMAR\AppData\Local\Packages\PythonSoftwareFoundation.Python.3.11_qbz5n2kfra8p0\LocalCache\local-packages\Python311\site-packages\django\utils\functional.py", line 57, in __get__
    res = instance.__dict__[self.name] = self.func(instance)
                                         ^^^^^^^^^^^^^^^^^^^
  File "C:\Users\ASHISH KUMAR\AppData\Local\Packages\PythonSoftwareFoundation.Python.3.11_qbz5n2kfra8p0\LocalCache\local-packages\Python311\site-packages\rest_framework\serializers.py", line 356, in fields
    for key, value in self.get_fields().items():
                      ^^^^^^^^^^^^^^^^^
  File "C:\Users\ASHISH KUMAR\AppData\Local\Packages\PythonSoftwareFoundation.Python.3.11_qbz5n2kfra8p0\LocalCache\local-packages\Python311\site-packages\rest_framework\serializers.py", line 1076, in get_fields
    field_class, field_kwargs = self.build_field(
                                ^^^^^^^^^^^^^^^^^
  File "C:\Users\ASHISH KUMAR\AppData\Local\Packages\PythonSoftwareFoundation.Python.3.11_qbz5n2kfra8p0\LocalCache\local-packages\Python311\site-packages\rest_framework\serializers.py", line 1222, in build_field
    return self.build_unknown_field(field_name, model_class)
           ^^^^^^^^^^^^^^^^^^^^^^^^^^^^^^^^^^^^^^^^^^^^^^^^^
  File "C:\Users\ASHISH KUMAR\AppData\Local\Packages\PythonSoftwareFoundation.Python.3.11_qbz5n2kfra8p0\LocalCache\local-packages\Python311\site-packages\rest_framework\serializers.py", line 1340, in build_unknown_field
    raise ImproperlyConfigured(
django.core.exceptions.ImproperlyConfigured: Field name `current_streak` is not valid for model `UserProfile`.
WARNING 2025-09-09 01:06:01,374 log 40332 32040 Unauthorized: /api/v1/challenges/submissions/
WARNING 2025-09-09 01:06:03,066 log 40332 32040 Unauthorized: /api/v1/content/lessons/
WARNING 2025-09-09 01:06:07,770 log 40332 32040 Unauthorized: /api/v1/gamification/badges/
WARNING 2025-09-09 01:06:10,548 log 40332 32040 Unauthorized: /api/v1/gamification/point-transactions/
WARNING 2025-09-09 01:06:13,020 log 40332 32040 Unauthorized: /api/v1/auth/users/
WARNING 2025-09-09 01:07:54,818 log 24344 32772 Unauthorized: /api/v1/challenges/challenges/
ERROR 2025-09-09 01:07:55,569 log 24344 32772 Internal Server Error: /api/v1/challenges/challenges/1/
Traceback (most recent call last):
  File "C:\Users\ASHISH KUMAR\AppData\Local\Packages\PythonSoftwareFoundation.Python.3.11_qbz5n2kfra8p0\LocalCache\local-packages\Python311\site-packages\django\core\handlers\exception.py", line 55, in inner
    response = get_response(request)
               ^^^^^^^^^^^^^^^^^^^^^
  File "C:\Users\ASHISH KUMAR\AppData\Local\Packages\PythonSoftwareFoundation.Python.3.11_qbz5n2kfra8p0\LocalCache\local-packages\Python311\site-packages\django\core\handlers\base.py", line 197, in _get_response
    response = wrapped_callback(request, *callback_args, **callback_kwargs)
               ^^^^^^^^^^^^^^^^^^^^^^^^^^^^^^^^^^^^^^^^^^^^^^^^^^^^^^^^^^^^
  File "C:\Users\ASHISH KUMAR\AppData\Local\Packages\PythonSoftwareFoundation.Python.3.11_qbz5n2kfra8p0\LocalCache\local-packages\Python311\site-packages\django\views\decorators\csrf.py", line 56, in wrapper_view
    return view_func(*args, **kwargs)
           ^^^^^^^^^^^^^^^^^^^^^^^^^^
  File "C:\Users\ASHISH KUMAR\AppData\Local\Packages\PythonSoftwareFoundation.Python.3.11_qbz5n2kfra8p0\LocalCache\local-packages\Python311\site-packages\rest_framework\viewsets.py", line 125, in view
    return self.dispatch(request, *args, **kwargs)
           ^^^^^^^^^^^^^^^^^^^^^^^^^^^^^^^^^^^^^^^
  File "C:\Users\ASHISH KUMAR\AppData\Local\Packages\PythonSoftwareFoundation.Python.3.11_qbz5n2kfra8p0\LocalCache\local-packages\Python311\site-packages\rest_framework\views.py", line 509, in dispatch
    response = self.handle_exception(exc)
               ^^^^^^^^^^^^^^^^^^^^^^^^^^
  File "C:\Users\ASHISH KUMAR\AppData\Local\Packages\PythonSoftwareFoundation.Python.3.11_qbz5n2kfra8p0\LocalCache\local-packages\Python311\site-packages\rest_framework\views.py", line 469, in handle_exception
    self.raise_uncaught_exception(exc)
  File "C:\Users\ASHISH KUMAR\AppData\Local\Packages\PythonSoftwareFoundation.Python.3.11_qbz5n2kfra8p0\LocalCache\local-packages\Python311\site-packages\rest_framework\views.py", line 480, in raise_uncaught_exception
    raise exc
  File "C:\Users\ASHISH KUMAR\AppData\Local\Packages\PythonSoftwareFoundation.Python.3.11_qbz5n2kfra8p0\LocalCache\local-packages\Python311\site-packages\rest_framework\views.py", line 506, in dispatch
    response = handler(request, *args, **kwargs)
               ^^^^^^^^^^^^^^^^^^^^^^^^^^^^^^^^^
  File "C:\Users\ASHISH KUMAR\AppData\Local\Packages\PythonSoftwareFoundation.Python.3.11_qbz5n2kfra8p0\LocalCache\local-packages\Python311\site-packages\rest_framework\mixins.py", line 56, in retrieve
    return Response(serializer.data)
                    ^^^^^^^^^^^^^^^
  File "C:\Users\ASHISH KUMAR\AppData\Local\Packages\PythonSoftwareFoundation.Python.3.11_qbz5n2kfra8p0\LocalCache\local-packages\Python311\site-packages\rest_framework\serializers.py", line 555, in data
    ret = super().data
          ^^^^^^^^^^^^
  File "C:\Users\ASHISH KUMAR\AppData\Local\Packages\PythonSoftwareFoundation.Python.3.11_qbz5n2kfra8p0\LocalCache\local-packages\Python311\site-packages\rest_framework\serializers.py", line 253, in data
    self._data = self.to_representation(self.instance)
                 ^^^^^^^^^^^^^^^^^^^^^^^^^^^^^^^^^^^^^
  File "C:\Users\ASHISH KUMAR\AppData\Local\Packages\PythonSoftwareFoundation.Python.3.11_qbz5n2kfra8p0\LocalCache\local-packages\Python311\site-packages\rest_framework\serializers.py", line 522, in to_representation
    ret[field.field_name] = field.to_representation(attribute)
                            ^^^^^^^^^^^^^^^^^^^^^^^^^^^^^^^^^^
  File "C:\Users\ASHISH KUMAR\AppData\Local\Packages\PythonSoftwareFoundation.Python.3.11_qbz5n2kfra8p0\LocalCache\local-packages\Python311\site-packages\rest_framework\serializers.py", line 507, in to_representation
    for field in fields:
  File "C:\Users\ASHISH KUMAR\AppData\Local\Packages\PythonSoftwareFoundation.Python.3.11_qbz5n2kfra8p0\LocalCache\local-packages\Python311\site-packages\rest_framework\serializers.py", line 368, in _readable_fields
    for field in self.fields.values():
                 ^^^^^^^^^^^
  File "C:\Users\ASHISH KUMAR\AppData\Local\Packages\PythonSoftwareFoundation.Python.3.11_qbz5n2kfra8p0\LocalCache\local-packages\Python311\site-packages\django\utils\functional.py", line 57, in __get__
    res = instance.__dict__[self.name] = self.func(instance)
                                         ^^^^^^^^^^^^^^^^^^^
  File "C:\Users\ASHISH KUMAR\AppData\Local\Packages\PythonSoftwareFoundation.Python.3.11_qbz5n2kfra8p0\LocalCache\local-packages\Python311\site-packages\rest_framework\serializers.py", line 356, in fields
    for key, value in self.get_fields().items():
                      ^^^^^^^^^^^^^^^^^
  File "C:\Users\ASHISH KUMAR\AppData\Local\Packages\PythonSoftwareFoundation.Python.3.11_qbz5n2kfra8p0\LocalCache\local-packages\Python311\site-packages\rest_framework\serializers.py", line 1076, in get_fields
    field_class, field_kwargs = self.build_field(
                                ^^^^^^^^^^^^^^^^^
  File "C:\Users\ASHISH KUMAR\AppData\Local\Packages\PythonSoftwareFoundation.Python.3.11_qbz5n2kfra8p0\LocalCache\local-packages\Python311\site-packages\rest_framework\serializers.py", line 1222, in build_field
    return self.build_unknown_field(field_name, model_class)
           ^^^^^^^^^^^^^^^^^^^^^^^^^^^^^^^^^^^^^^^^^^^^^^^^^
  File "C:\Users\ASHISH KUMAR\AppData\Local\Packages\PythonSoftwareFoundation.Python.3.11_qbz5n2kfra8p0\LocalCache\local-packages\Python311\site-packages\rest_framework\serializers.py", line 1340, in build_unknown_field
    raise ImproperlyConfigured(
django.core.exceptions.ImproperlyConfigured: Field name `location` is not valid for model `UserProfile`.
ERROR 2025-09-09 01:07:56,370 log 24344 32772 Internal Server Error: /api/v1/challenges/challenges/
Traceback (most recent call last):
  File "C:\Users\ASHISH KUMAR\AppData\Local\Packages\PythonSoftwareFoundation.Python.3.11_qbz5n2kfra8p0\LocalCache\local-packages\Python311\site-packages\django\core\handlers\exception.py", line 55, in inner
    response = get_response(request)
               ^^^^^^^^^^^^^^^^^^^^^
  File "C:\Users\ASHISH KUMAR\AppData\Local\Packages\PythonSoftwareFoundation.Python.3.11_qbz5n2kfra8p0\LocalCache\local-packages\Python311\site-packages\django\core\handlers\base.py", line 197, in _get_response
    response = wrapped_callback(request, *callback_args, **callback_kwargs)
               ^^^^^^^^^^^^^^^^^^^^^^^^^^^^^^^^^^^^^^^^^^^^^^^^^^^^^^^^^^^^
  File "C:\Users\ASHISH KUMAR\AppData\Local\Packages\PythonSoftwareFoundation.Python.3.11_qbz5n2kfra8p0\LocalCache\local-packages\Python311\site-packages\django\views\decorators\csrf.py", line 56, in wrapper_view
    return view_func(*args, **kwargs)
           ^^^^^^^^^^^^^^^^^^^^^^^^^^
  File "C:\Users\ASHISH KUMAR\AppData\Local\Packages\PythonSoftwareFoundation.Python.3.11_qbz5n2kfra8p0\LocalCache\local-packages\Python311\site-packages\rest_framework\viewsets.py", line 125, in view
    return self.dispatch(request, *args, **kwargs)
           ^^^^^^^^^^^^^^^^^^^^^^^^^^^^^^^^^^^^^^^
  File "C:\Users\ASHISH KUMAR\AppData\Local\Packages\PythonSoftwareFoundation.Python.3.11_qbz5n2kfra8p0\LocalCache\local-packages\Python311\site-packages\rest_framework\views.py", line 509, in dispatch
    response = self.handle_exception(exc)
               ^^^^^^^^^^^^^^^^^^^^^^^^^^
  File "C:\Users\ASHISH KUMAR\AppData\Local\Packages\PythonSoftwareFoundation.Python.3.11_qbz5n2kfra8p0\LocalCache\local-packages\Python311\site-packages\rest_framework\views.py", line 469, in handle_exception
    self.raise_uncaught_exception(exc)
  File "C:\Users\ASHISH KUMAR\AppData\Local\Packages\PythonSoftwareFoundation.Python.3.11_qbz5n2kfra8p0\LocalCache\local-packages\Python311\site-packages\rest_framework\views.py", line 480, in raise_uncaught_exception
    raise exc
  File "C:\Users\ASHISH KUMAR\AppData\Local\Packages\PythonSoftwareFoundation.Python.3.11_qbz5n2kfra8p0\LocalCache\local-packages\Python311\site-packages\rest_framework\views.py", line 506, in dispatch
    response = handler(request, *args, **kwargs)
               ^^^^^^^^^^^^^^^^^^^^^^^^^^^^^^^^^
  File "C:\Users\ASHISH KUMAR\AppData\Local\Packages\PythonSoftwareFoundation.Python.3.11_qbz5n2kfra8p0\LocalCache\local-packages\Python311\site-packages\rest_framework\mixins.py", line 43, in list
    return self.get_paginated_response(serializer.data)
                                       ^^^^^^^^^^^^^^^
  File "C:\Users\ASHISH KUMAR\AppData\Local\Packages\PythonSoftwareFoundation.Python.3.11_qbz5n2kfra8p0\LocalCache\local-packages\Python311\site-packages\rest_framework\serializers.py", line 768, in data
    ret = super().data
          ^^^^^^^^^^^^
  File "C:\Users\ASHISH KUMAR\AppData\Local\Packages\PythonSoftwareFoundation.Python.3.11_qbz5n2kfra8p0\LocalCache\local-packages\Python311\site-packages\rest_framework\serializers.py", line 253, in data
    self._data = self.to_representation(self.instance)
                 ^^^^^^^^^^^^^^^^^^^^^^^^^^^^^^^^^^^^^
  File "C:\Users\ASHISH KUMAR\AppData\Local\Packages\PythonSoftwareFoundation.Python.3.11_qbz5n2kfra8p0\LocalCache\local-packages\Python311\site-packages\rest_framework\serializers.py", line 686, in to_representation
    return [
           ^
  File "C:\Users\ASHISH KUMAR\AppData\Local\Packages\PythonSoftwareFoundation.Python.3.11_qbz5n2kfra8p0\LocalCache\local-packages\Python311\site-packages\rest_framework\serializers.py", line 687, in <listcomp>
    self.child.to_representation(item) for item in iterable
    ^^^^^^^^^^^^^^^^^^^^^^^^^^^^^^^^^^
  File "C:\Users\ASHISH KUMAR\AppData\Local\Packages\PythonSoftwareFoundation.Python.3.11_qbz5n2kfra8p0\LocalCache\local-packages\Python311\site-packages\rest_framework\serializers.py", line 522, in to_representation
    ret[field.field_name] = field.to_representation(attribute)
                            ^^^^^^^^^^^^^^^^^^^^^^^^^^^^^^^^^^
  File "C:\Users\ASHISH KUMAR\AppData\Local\Packages\PythonSoftwareFoundation.Python.3.11_qbz5n2kfra8p0\LocalCache\local-packages\Python311\site-packages\rest_framework\serializers.py", line 507, in to_representation
    for field in fields:
  File "C:\Users\ASHISH KUMAR\AppData\Local\Packages\PythonSoftwareFoundation.Python.3.11_qbz5n2kfra8p0\LocalCache\local-packages\Python311\site-packages\rest_framework\serializers.py", line 368, in _readable_fields
    for field in self.fields.values():
                 ^^^^^^^^^^^
  File "C:\Users\ASHISH KUMAR\AppData\Local\Packages\PythonSoftwareFoundation.Python.3.11_qbz5n2kfra8p0\LocalCache\local-packages\Python311\site-packages\django\utils\functional.py", line 57, in __get__
    res = instance.__dict__[self.name] = self.func(instance)
                                         ^^^^^^^^^^^^^^^^^^^
  File "C:\Users\ASHISH KUMAR\AppData\Local\Packages\PythonSoftwareFoundation.Python.3.11_qbz5n2kfra8p0\LocalCache\local-packages\Python311\site-packages\rest_framework\serializers.py", line 356, in fields
    for key, value in self.get_fields().items():
                      ^^^^^^^^^^^^^^^^^
  File "C:\Users\ASHISH KUMAR\AppData\Local\Packages\PythonSoftwareFoundation.Python.3.11_qbz5n2kfra8p0\LocalCache\local-packages\Python311\site-packages\rest_framework\serializers.py", line 1076, in get_fields
    field_class, field_kwargs = self.build_field(
                                ^^^^^^^^^^^^^^^^^
  File "C:\Users\ASHISH KUMAR\AppData\Local\Packages\PythonSoftwareFoundation.Python.3.11_qbz5n2kfra8p0\LocalCache\local-packages\Python311\site-packages\rest_framework\serializers.py", line 1222, in build_field
    return self.build_unknown_field(field_name, model_class)
           ^^^^^^^^^^^^^^^^^^^^^^^^^^^^^^^^^^^^^^^^^^^^^^^^^
  File "C:\Users\ASHISH KUMAR\AppData\Local\Packages\PythonSoftwareFoundation.Python.3.11_qbz5n2kfra8p0\LocalCache\local-packages\Python311\site-packages\rest_framework\serializers.py", line 1340, in build_unknown_field
    raise ImproperlyConfigured(
django.core.exceptions.ImproperlyConfigured: Field name `location` is not valid for model `UserProfile`.
WARNING 2025-09-09 01:08:00,992 log 24344 32772 Unauthorized: /api/v1/challenges/submissions/
WARNING 2025-09-09 01:08:02,776 log 24344 32772 Unauthorized: /api/v1/content/lessons/
WARNING 2025-09-09 01:08:10,189 log 24344 32772 Unauthorized: /api/v1/gamification/badges/
WARNING 2025-09-09 01:08:15,362 log 24344 32772 Unauthorized: /api/v1/gamification/point-transactions/
WARNING 2025-09-09 01:08:18,654 log 24344 32772 Unauthorized: /api/v1/auth/users/
WARNING 2025-09-09 01:09:01,677 log 24212 2464 Unauthorized: /api/v1/challenges/challenges/
ERROR 2025-09-09 01:09:02,277 log 24212 2464 Internal Server Error: /api/v1/challenges/challenges/1/
Traceback (most recent call last):
  File "C:\Users\ASHISH KUMAR\AppData\Local\Packages\PythonSoftwareFoundation.Python.3.11_qbz5n2kfra8p0\LocalCache\local-packages\Python311\site-packages\django\core\handlers\exception.py", line 55, in inner
    response = get_response(request)
               ^^^^^^^^^^^^^^^^^^^^^
  File "C:\Users\ASHISH KUMAR\AppData\Local\Packages\PythonSoftwareFoundation.Python.3.11_qbz5n2kfra8p0\LocalCache\local-packages\Python311\site-packages\django\core\handlers\base.py", line 197, in _get_response
    response = wrapped_callback(request, *callback_args, **callback_kwargs)
               ^^^^^^^^^^^^^^^^^^^^^^^^^^^^^^^^^^^^^^^^^^^^^^^^^^^^^^^^^^^^
  File "C:\Users\ASHISH KUMAR\AppData\Local\Packages\PythonSoftwareFoundation.Python.3.11_qbz5n2kfra8p0\LocalCache\local-packages\Python311\site-packages\django\views\decorators\csrf.py", line 56, in wrapper_view
    return view_func(*args, **kwargs)
           ^^^^^^^^^^^^^^^^^^^^^^^^^^
  File "C:\Users\ASHISH KUMAR\AppData\Local\Packages\PythonSoftwareFoundation.Python.3.11_qbz5n2kfra8p0\LocalCache\local-packages\Python311\site-packages\rest_framework\viewsets.py", line 125, in view
    return self.dispatch(request, *args, **kwargs)
           ^^^^^^^^^^^^^^^^^^^^^^^^^^^^^^^^^^^^^^^
  File "C:\Users\ASHISH KUMAR\AppData\Local\Packages\PythonSoftwareFoundation.Python.3.11_qbz5n2kfra8p0\LocalCache\local-packages\Python311\site-packages\rest_framework\views.py", line 509, in dispatch
    response = self.handle_exception(exc)
               ^^^^^^^^^^^^^^^^^^^^^^^^^^
  File "C:\Users\ASHISH KUMAR\AppData\Local\Packages\PythonSoftwareFoundation.Python.3.11_qbz5n2kfra8p0\LocalCache\local-packages\Python311\site-packages\rest_framework\views.py", line 469, in handle_exception
    self.raise_uncaught_exception(exc)
  File "C:\Users\ASHISH KUMAR\AppData\Local\Packages\PythonSoftwareFoundation.Python.3.11_qbz5n2kfra8p0\LocalCache\local-packages\Python311\site-packages\rest_framework\views.py", line 480, in raise_uncaught_exception
    raise exc
  File "C:\Users\ASHISH KUMAR\AppData\Local\Packages\PythonSoftwareFoundation.Python.3.11_qbz5n2kfra8p0\LocalCache\local-packages\Python311\site-packages\rest_framework\views.py", line 506, in dispatch
    response = handler(request, *args, **kwargs)
               ^^^^^^^^^^^^^^^^^^^^^^^^^^^^^^^^^
  File "C:\Users\ASHISH KUMAR\AppData\Local\Packages\PythonSoftwareFoundation.Python.3.11_qbz5n2kfra8p0\LocalCache\local-packages\Python311\site-packages\rest_framework\mixins.py", line 56, in retrieve
    return Response(serializer.data)
                    ^^^^^^^^^^^^^^^
  File "C:\Users\ASHISH KUMAR\AppData\Local\Packages\PythonSoftwareFoundation.Python.3.11_qbz5n2kfra8p0\LocalCache\local-packages\Python311\site-packages\rest_framework\serializers.py", line 555, in data
    ret = super().data
          ^^^^^^^^^^^^
  File "C:\Users\ASHISH KUMAR\AppData\Local\Packages\PythonSoftwareFoundation.Python.3.11_qbz5n2kfra8p0\LocalCache\local-packages\Python311\site-packages\rest_framework\serializers.py", line 253, in data
    self._data = self.to_representation(self.instance)
                 ^^^^^^^^^^^^^^^^^^^^^^^^^^^^^^^^^^^^^
  File "C:\Users\ASHISH KUMAR\AppData\Local\Packages\PythonSoftwareFoundation.Python.3.11_qbz5n2kfra8p0\LocalCache\local-packages\Python311\site-packages\rest_framework\serializers.py", line 522, in to_representation
    ret[field.field_name] = field.to_representation(attribute)
                            ^^^^^^^^^^^^^^^^^^^^^^^^^^^^^^^^^^
  File "C:\Users\ASHISH KUMAR\AppData\Local\Packages\PythonSoftwareFoundation.Python.3.11_qbz5n2kfra8p0\LocalCache\local-packages\Python311\site-packages\rest_framework\serializers.py", line 507, in to_representation
    for field in fields:
  File "C:\Users\ASHISH KUMAR\AppData\Local\Packages\PythonSoftwareFoundation.Python.3.11_qbz5n2kfra8p0\LocalCache\local-packages\Python311\site-packages\rest_framework\serializers.py", line 368, in _readable_fields
    for field in self.fields.values():
                 ^^^^^^^^^^^
  File "C:\Users\ASHISH KUMAR\AppData\Local\Packages\PythonSoftwareFoundation.Python.3.11_qbz5n2kfra8p0\LocalCache\local-packages\Python311\site-packages\django\utils\functional.py", line 57, in __get__
    res = instance.__dict__[self.name] = self.func(instance)
                                         ^^^^^^^^^^^^^^^^^^^
  File "C:\Users\ASHISH KUMAR\AppData\Local\Packages\PythonSoftwareFoundation.Python.3.11_qbz5n2kfra8p0\LocalCache\local-packages\Python311\site-packages\rest_framework\serializers.py", line 356, in fields
    for key, value in self.get_fields().items():
                      ^^^^^^^^^^^^^^^^^
  File "C:\Users\ASHISH KUMAR\AppData\Local\Packages\PythonSoftwareFoundation.Python.3.11_qbz5n2kfra8p0\LocalCache\local-packages\Python311\site-packages\rest_framework\serializers.py", line 1076, in get_fields
    field_class, field_kwargs = self.build_field(
                                ^^^^^^^^^^^^^^^^^
  File "C:\Users\ASHISH KUMAR\AppData\Local\Packages\PythonSoftwareFoundation.Python.3.11_qbz5n2kfra8p0\LocalCache\local-packages\Python311\site-packages\rest_framework\serializers.py", line 1222, in build_field
    return self.build_unknown_field(field_name, model_class)
           ^^^^^^^^^^^^^^^^^^^^^^^^^^^^^^^^^^^^^^^^^^^^^^^^^
  File "C:\Users\ASHISH KUMAR\AppData\Local\Packages\PythonSoftwareFoundation.Python.3.11_qbz5n2kfra8p0\LocalCache\local-packages\Python311\site-packages\rest_framework\serializers.py", line 1340, in build_unknown_field
    raise ImproperlyConfigured(
django.core.exceptions.ImproperlyConfigured: Field name `date_joined` is not valid for model `UserProfile`.
ERROR 2025-09-09 01:09:02,792 log 24212 2464 Internal Server Error: /api/v1/challenges/challenges/
Traceback (most recent call last):
  File "C:\Users\ASHISH KUMAR\AppData\Local\Packages\PythonSoftwareFoundation.Python.3.11_qbz5n2kfra8p0\LocalCache\local-packages\Python311\site-packages\django\core\handlers\exception.py", line 55, in inner
    response = get_response(request)
               ^^^^^^^^^^^^^^^^^^^^^
  File "C:\Users\ASHISH KUMAR\AppData\Local\Packages\PythonSoftwareFoundation.Python.3.11_qbz5n2kfra8p0\LocalCache\local-packages\Python311\site-packages\django\core\handlers\base.py", line 197, in _get_response
    response = wrapped_callback(request, *callback_args, **callback_kwargs)
               ^^^^^^^^^^^^^^^^^^^^^^^^^^^^^^^^^^^^^^^^^^^^^^^^^^^^^^^^^^^^
  File "C:\Users\ASHISH KUMAR\AppData\Local\Packages\PythonSoftwareFoundation.Python.3.11_qbz5n2kfra8p0\LocalCache\local-packages\Python311\site-packages\django\views\decorators\csrf.py", line 56, in wrapper_view
    return view_func(*args, **kwargs)
           ^^^^^^^^^^^^^^^^^^^^^^^^^^
  File "C:\Users\ASHISH KUMAR\AppData\Local\Packages\PythonSoftwareFoundation.Python.3.11_qbz5n2kfra8p0\LocalCache\local-packages\Python311\site-packages\rest_framework\viewsets.py", line 125, in view
    return self.dispatch(request, *args, **kwargs)
           ^^^^^^^^^^^^^^^^^^^^^^^^^^^^^^^^^^^^^^^
  File "C:\Users\ASHISH KUMAR\AppData\Local\Packages\PythonSoftwareFoundation.Python.3.11_qbz5n2kfra8p0\LocalCache\local-packages\Python311\site-packages\rest_framework\views.py", line 509, in dispatch
    response = self.handle_exception(exc)
               ^^^^^^^^^^^^^^^^^^^^^^^^^^
  File "C:\Users\ASHISH KUMAR\AppData\Local\Packages\PythonSoftwareFoundation.Python.3.11_qbz5n2kfra8p0\LocalCache\local-packages\Python311\site-packages\rest_framework\views.py", line 469, in handle_exception
    self.raise_uncaught_exception(exc)
  File "C:\Users\ASHISH KUMAR\AppData\Local\Packages\PythonSoftwareFoundation.Python.3.11_qbz5n2kfra8p0\LocalCache\local-packages\Python311\site-packages\rest_framework\views.py", line 480, in raise_uncaught_exception
    raise exc
  File "C:\Users\ASHISH KUMAR\AppData\Local\Packages\PythonSoftwareFoundation.Python.3.11_qbz5n2kfra8p0\LocalCache\local-packages\Python311\site-packages\rest_framework\views.py", line 506, in dispatch
    response = handler(request, *args, **kwargs)
               ^^^^^^^^^^^^^^^^^^^^^^^^^^^^^^^^^
  File "C:\Users\ASHISH KUMAR\AppData\Local\Packages\PythonSoftwareFoundation.Python.3.11_qbz5n2kfra8p0\LocalCache\local-packages\Python311\site-packages\rest_framework\mixins.py", line 43, in list
    return self.get_paginated_response(serializer.data)
                                       ^^^^^^^^^^^^^^^
  File "C:\Users\ASHISH KUMAR\AppData\Local\Packages\PythonSoftwareFoundation.Python.3.11_qbz5n2kfra8p0\LocalCache\local-packages\Python311\site-packages\rest_framework\serializers.py", line 768, in data
    ret = super().data
          ^^^^^^^^^^^^
  File "C:\Users\ASHISH KUMAR\AppData\Local\Packages\PythonSoftwareFoundation.Python.3.11_qbz5n2kfra8p0\LocalCache\local-packages\Python311\site-packages\rest_framework\serializers.py", line 253, in data
    self._data = self.to_representation(self.instance)
                 ^^^^^^^^^^^^^^^^^^^^^^^^^^^^^^^^^^^^^
  File "C:\Users\ASHISH KUMAR\AppData\Local\Packages\PythonSoftwareFoundation.Python.3.11_qbz5n2kfra8p0\LocalCache\local-packages\Python311\site-packages\rest_framework\serializers.py", line 686, in to_representation
    return [
           ^
  File "C:\Users\ASHISH KUMAR\AppData\Local\Packages\PythonSoftwareFoundation.Python.3.11_qbz5n2kfra8p0\LocalCache\local-packages\Python311\site-packages\rest_framework\serializers.py", line 687, in <listcomp>
    self.child.to_representation(item) for item in iterable
    ^^^^^^^^^^^^^^^^^^^^^^^^^^^^^^^^^^
  File "C:\Users\ASHISH KUMAR\AppData\Local\Packages\PythonSoftwareFoundation.Python.3.11_qbz5n2kfra8p0\LocalCache\local-packages\Python311\site-packages\rest_framework\serializers.py", line 522, in to_representation
    ret[field.field_name] = field.to_representation(attribute)
                            ^^^^^^^^^^^^^^^^^^^^^^^^^^^^^^^^^^
  File "C:\Users\ASHISH KUMAR\AppData\Local\Packages\PythonSoftwareFoundation.Python.3.11_qbz5n2kfra8p0\LocalCache\local-packages\Python311\site-packages\rest_framework\serializers.py", line 507, in to_representation
    for field in fields:
  File "C:\Users\ASHISH KUMAR\AppData\Local\Packages\PythonSoftwareFoundation.Python.3.11_qbz5n2kfra8p0\LocalCache\local-packages\Python311\site-packages\rest_framework\serializers.py", line 368, in _readable_fields
    for field in self.fields.values():
                 ^^^^^^^^^^^
  File "C:\Users\ASHISH KUMAR\AppData\Local\Packages\PythonSoftwareFoundation.Python.3.11_qbz5n2kfra8p0\LocalCache\local-packages\Python311\site-packages\django\utils\functional.py", line 57, in __get__
    res = instance.__dict__[self.name] = self.func(instance)
                                         ^^^^^^^^^^^^^^^^^^^
  File "C:\Users\ASHISH KUMAR\AppData\Local\Packages\PythonSoftwareFoundation.Python.3.11_qbz5n2kfra8p0\LocalCache\local-packages\Python311\site-packages\rest_framework\serializers.py", line 356, in fields
    for key, value in self.get_fields().items():
                      ^^^^^^^^^^^^^^^^^
  File "C:\Users\ASHISH KUMAR\AppData\Local\Packages\PythonSoftwareFoundation.Python.3.11_qbz5n2kfra8p0\LocalCache\local-packages\Python311\site-packages\rest_framework\serializers.py", line 1076, in get_fields
    field_class, field_kwargs = self.build_field(
                                ^^^^^^^^^^^^^^^^^
  File "C:\Users\ASHISH KUMAR\AppData\Local\Packages\PythonSoftwareFoundation.Python.3.11_qbz5n2kfra8p0\LocalCache\local-packages\Python311\site-packages\rest_framework\serializers.py", line 1222, in build_field
    return self.build_unknown_field(field_name, model_class)
           ^^^^^^^^^^^^^^^^^^^^^^^^^^^^^^^^^^^^^^^^^^^^^^^^^
  File "C:\Users\ASHISH KUMAR\AppData\Local\Packages\PythonSoftwareFoundation.Python.3.11_qbz5n2kfra8p0\LocalCache\local-packages\Python311\site-packages\rest_framework\serializers.py", line 1340, in build_unknown_field
    raise ImproperlyConfigured(
django.core.exceptions.ImproperlyConfigured: Field name `date_joined` is not valid for model `UserProfile`.
WARNING 2025-09-09 01:09:07,404 log 24212 2464 Unauthorized: /api/v1/challenges/submissions/
WARNING 2025-09-09 01:09:08,857 log 24212 2464 Unauthorized: /api/v1/content/lessons/
WARNING 2025-09-09 01:09:13,625 log 24212 2464 Unauthorized: /api/v1/gamification/badges/
WARNING 2025-09-09 01:09:16,540 log 24212 2464 Unauthorized: /api/v1/gamification/point-transactions/
WARNING 2025-09-09 01:09:18,653 log 24212 2464 Unauthorized: /api/v1/auth/users/
WARNING 2025-09-09 01:09:39,157 log 36268 32264 Unauthorized: /api/v1/challenges/challenges/
ERROR 2025-09-09 01:09:39,950 log 36268 32264 Internal Server Error: /api/v1/challenges/challenges/1/
Traceback (most recent call last):
  File "C:\Users\ASHISH KUMAR\AppData\Local\Packages\PythonSoftwareFoundation.Python.3.11_qbz5n2kfra8p0\LocalCache\local-packages\Python311\site-packages\django\core\handlers\exception.py", line 55, in inner
    response = get_response(request)
               ^^^^^^^^^^^^^^^^^^^^^
  File "C:\Users\ASHISH KUMAR\AppData\Local\Packages\PythonSoftwareFoundation.Python.3.11_qbz5n2kfra8p0\LocalCache\local-packages\Python311\site-packages\django\core\handlers\base.py", line 197, in _get_response
    response = wrapped_callback(request, *callback_args, **callback_kwargs)
               ^^^^^^^^^^^^^^^^^^^^^^^^^^^^^^^^^^^^^^^^^^^^^^^^^^^^^^^^^^^^
  File "C:\Users\ASHISH KUMAR\AppData\Local\Packages\PythonSoftwareFoundation.Python.3.11_qbz5n2kfra8p0\LocalCache\local-packages\Python311\site-packages\django\views\decorators\csrf.py", line 56, in wrapper_view
    return view_func(*args, **kwargs)
           ^^^^^^^^^^^^^^^^^^^^^^^^^^
  File "C:\Users\ASHISH KUMAR\AppData\Local\Packages\PythonSoftwareFoundation.Python.3.11_qbz5n2kfra8p0\LocalCache\local-packages\Python311\site-packages\rest_framework\viewsets.py", line 125, in view
    return self.dispatch(request, *args, **kwargs)
           ^^^^^^^^^^^^^^^^^^^^^^^^^^^^^^^^^^^^^^^
  File "C:\Users\ASHISH KUMAR\AppData\Local\Packages\PythonSoftwareFoundation.Python.3.11_qbz5n2kfra8p0\LocalCache\local-packages\Python311\site-packages\rest_framework\views.py", line 509, in dispatch
    response = self.handle_exception(exc)
               ^^^^^^^^^^^^^^^^^^^^^^^^^^
  File "C:\Users\ASHISH KUMAR\AppData\Local\Packages\PythonSoftwareFoundation.Python.3.11_qbz5n2kfra8p0\LocalCache\local-packages\Python311\site-packages\rest_framework\views.py", line 469, in handle_exception
    self.raise_uncaught_exception(exc)
  File "C:\Users\ASHISH KUMAR\AppData\Local\Packages\PythonSoftwareFoundation.Python.3.11_qbz5n2kfra8p0\LocalCache\local-packages\Python311\site-packages\rest_framework\views.py", line 480, in raise_uncaught_exception
    raise exc
  File "C:\Users\ASHISH KUMAR\AppData\Local\Packages\PythonSoftwareFoundation.Python.3.11_qbz5n2kfra8p0\LocalCache\local-packages\Python311\site-packages\rest_framework\views.py", line 506, in dispatch
    response = handler(request, *args, **kwargs)
               ^^^^^^^^^^^^^^^^^^^^^^^^^^^^^^^^^
  File "C:\Users\ASHISH KUMAR\AppData\Local\Packages\PythonSoftwareFoundation.Python.3.11_qbz5n2kfra8p0\LocalCache\local-packages\Python311\site-packages\rest_framework\mixins.py", line 56, in retrieve
    return Response(serializer.data)
                    ^^^^^^^^^^^^^^^
  File "C:\Users\ASHISH KUMAR\AppData\Local\Packages\PythonSoftwareFoundation.Python.3.11_qbz5n2kfra8p0\LocalCache\local-packages\Python311\site-packages\rest_framework\serializers.py", line 555, in data
    ret = super().data
          ^^^^^^^^^^^^
  File "C:\Users\ASHISH KUMAR\AppData\Local\Packages\PythonSoftwareFoundation.Python.3.11_qbz5n2kfra8p0\LocalCache\local-packages\Python311\site-packages\rest_framework\serializers.py", line 253, in data
    self._data = self.to_representation(self.instance)
                 ^^^^^^^^^^^^^^^^^^^^^^^^^^^^^^^^^^^^^
  File "C:\Users\ASHISH KUMAR\AppData\Local\Packages\PythonSoftwareFoundation.Python.3.11_qbz5n2kfra8p0\LocalCache\local-packages\Python311\site-packages\rest_framework\serializers.py", line 522, in to_representation
    ret[field.field_name] = field.to_representation(attribute)
                            ^^^^^^^^^^^^^^^^^^^^^^^^^^^^^^^^^^
  File "C:\Users\ASHISH KUMAR\AppData\Local\Packages\PythonSoftwareFoundation.Python.3.11_qbz5n2kfra8p0\LocalCache\local-packages\Python311\site-packages\rest_framework\serializers.py", line 522, in to_representation
    ret[field.field_name] = field.to_representation(attribute)
                            ^^^^^^^^^^^^^^^^^^^^^^^^^^^^^^^^^^
  File "C:\Users\ASHISH KUMAR\AppData\Local\Packages\PythonSoftwareFoundation.Python.3.11_qbz5n2kfra8p0\LocalCache\local-packages\Python311\site-packages\rest_framework\fields.py", line 1838, in to_representation
    return method(value)
           ^^^^^^^^^^^^^
  File "C:\Users\ASHISH KUMAR\OneDrive\Documents\Desktop\KJSCE\kj stuff\trae\backend\apps\users\serializers.py", line 238, in get_avatar_url
    if obj.avatar:
       ^^^^^^^^^^
AttributeError: 'User' object has no attribute 'avatar'
ERROR 2025-09-09 01:09:40,773 log 36268 32264 Internal Server Error: /api/v1/challenges/challenges/
Traceback (most recent call last):
  File "C:\Users\ASHISH KUMAR\AppData\Local\Packages\PythonSoftwareFoundation.Python.3.11_qbz5n2kfra8p0\LocalCache\local-packages\Python311\site-packages\django\core\handlers\exception.py", line 55, in inner
    response = get_response(request)
               ^^^^^^^^^^^^^^^^^^^^^
  File "C:\Users\ASHISH KUMAR\AppData\Local\Packages\PythonSoftwareFoundation.Python.3.11_qbz5n2kfra8p0\LocalCache\local-packages\Python311\site-packages\django\core\handlers\base.py", line 197, in _get_response
    response = wrapped_callback(request, *callback_args, **callback_kwargs)
               ^^^^^^^^^^^^^^^^^^^^^^^^^^^^^^^^^^^^^^^^^^^^^^^^^^^^^^^^^^^^
  File "C:\Users\ASHISH KUMAR\AppData\Local\Packages\PythonSoftwareFoundation.Python.3.11_qbz5n2kfra8p0\LocalCache\local-packages\Python311\site-packages\django\views\decorators\csrf.py", line 56, in wrapper_view
    return view_func(*args, **kwargs)
           ^^^^^^^^^^^^^^^^^^^^^^^^^^
  File "C:\Users\ASHISH KUMAR\AppData\Local\Packages\PythonSoftwareFoundation.Python.3.11_qbz5n2kfra8p0\LocalCache\local-packages\Python311\site-packages\rest_framework\viewsets.py", line 125, in view
    return self.dispatch(request, *args, **kwargs)
           ^^^^^^^^^^^^^^^^^^^^^^^^^^^^^^^^^^^^^^^
  File "C:\Users\ASHISH KUMAR\AppData\Local\Packages\PythonSoftwareFoundation.Python.3.11_qbz5n2kfra8p0\LocalCache\local-packages\Python311\site-packages\rest_framework\views.py", line 509, in dispatch
    response = self.handle_exception(exc)
               ^^^^^^^^^^^^^^^^^^^^^^^^^^
  File "C:\Users\ASHISH KUMAR\AppData\Local\Packages\PythonSoftwareFoundation.Python.3.11_qbz5n2kfra8p0\LocalCache\local-packages\Python311\site-packages\rest_framework\views.py", line 469, in handle_exception
    self.raise_uncaught_exception(exc)
  File "C:\Users\ASHISH KUMAR\AppData\Local\Packages\PythonSoftwareFoundation.Python.3.11_qbz5n2kfra8p0\LocalCache\local-packages\Python311\site-packages\rest_framework\views.py", line 480, in raise_uncaught_exception
    raise exc
  File "C:\Users\ASHISH KUMAR\AppData\Local\Packages\PythonSoftwareFoundation.Python.3.11_qbz5n2kfra8p0\LocalCache\local-packages\Python311\site-packages\rest_framework\views.py", line 506, in dispatch
    response = handler(request, *args, **kwargs)
               ^^^^^^^^^^^^^^^^^^^^^^^^^^^^^^^^^
  File "C:\Users\ASHISH KUMAR\AppData\Local\Packages\PythonSoftwareFoundation.Python.3.11_qbz5n2kfra8p0\LocalCache\local-packages\Python311\site-packages\rest_framework\mixins.py", line 43, in list
    return self.get_paginated_response(serializer.data)
                                       ^^^^^^^^^^^^^^^
  File "C:\Users\ASHISH KUMAR\AppData\Local\Packages\PythonSoftwareFoundation.Python.3.11_qbz5n2kfra8p0\LocalCache\local-packages\Python311\site-packages\rest_framework\serializers.py", line 768, in data
    ret = super().data
          ^^^^^^^^^^^^
  File "C:\Users\ASHISH KUMAR\AppData\Local\Packages\PythonSoftwareFoundation.Python.3.11_qbz5n2kfra8p0\LocalCache\local-packages\Python311\site-packages\rest_framework\serializers.py", line 253, in data
    self._data = self.to_representation(self.instance)
                 ^^^^^^^^^^^^^^^^^^^^^^^^^^^^^^^^^^^^^
  File "C:\Users\ASHISH KUMAR\AppData\Local\Packages\PythonSoftwareFoundation.Python.3.11_qbz5n2kfra8p0\LocalCache\local-packages\Python311\site-packages\rest_framework\serializers.py", line 686, in to_representation
    return [
           ^
  File "C:\Users\ASHISH KUMAR\AppData\Local\Packages\PythonSoftwareFoundation.Python.3.11_qbz5n2kfra8p0\LocalCache\local-packages\Python311\site-packages\rest_framework\serializers.py", line 687, in <listcomp>
    self.child.to_representation(item) for item in iterable
    ^^^^^^^^^^^^^^^^^^^^^^^^^^^^^^^^^^
  File "C:\Users\ASHISH KUMAR\AppData\Local\Packages\PythonSoftwareFoundation.Python.3.11_qbz5n2kfra8p0\LocalCache\local-packages\Python311\site-packages\rest_framework\serializers.py", line 522, in to_representation
    ret[field.field_name] = field.to_representation(attribute)
                            ^^^^^^^^^^^^^^^^^^^^^^^^^^^^^^^^^^
  File "C:\Users\ASHISH KUMAR\AppData\Local\Packages\PythonSoftwareFoundation.Python.3.11_qbz5n2kfra8p0\LocalCache\local-packages\Python311\site-packages\rest_framework\serializers.py", line 522, in to_representation
    ret[field.field_name] = field.to_representation(attribute)
                            ^^^^^^^^^^^^^^^^^^^^^^^^^^^^^^^^^^
  File "C:\Users\ASHISH KUMAR\AppData\Local\Packages\PythonSoftwareFoundation.Python.3.11_qbz5n2kfra8p0\LocalCache\local-packages\Python311\site-packages\rest_framework\fields.py", line 1838, in to_representation
    return method(value)
           ^^^^^^^^^^^^^
  File "C:\Users\ASHISH KUMAR\OneDrive\Documents\Desktop\KJSCE\kj stuff\trae\backend\apps\users\serializers.py", line 238, in get_avatar_url
    if obj.avatar:
       ^^^^^^^^^^
AttributeError: 'User' object has no attribute 'avatar'
WARNING 2025-09-09 01:09:45,857 log 36268 32264 Unauthorized: /api/v1/challenges/submissions/
WARNING 2025-09-09 01:09:47,614 log 36268 32264 Unauthorized: /api/v1/content/lessons/
WARNING 2025-09-09 01:09:53,280 log 36268 32264 Unauthorized: /api/v1/gamification/badges/
WARNING 2025-09-09 01:09:57,040 log 36268 32264 Unauthorized: /api/v1/gamification/point-transactions/
WARNING 2025-09-09 01:10:00,037 log 36268 32264 Unauthorized: /api/v1/auth/users/
WARNING 2025-09-09 01:10:35,399 log 25112 3648 Unauthorized: /api/v1/challenges/challenges/
ERROR 2025-09-09 01:10:35,977 log 25112 3648 Internal Server Error: /api/v1/challenges/challenges/1/
Traceback (most recent call last):
  File "C:\Users\ASHISH KUMAR\AppData\Local\Packages\PythonSoftwareFoundation.Python.3.11_qbz5n2kfra8p0\LocalCache\local-packages\Python311\site-packages\django\core\handlers\exception.py", line 55, in inner
    response = get_response(request)
               ^^^^^^^^^^^^^^^^^^^^^
  File "C:\Users\ASHISH KUMAR\AppData\Local\Packages\PythonSoftwareFoundation.Python.3.11_qbz5n2kfra8p0\LocalCache\local-packages\Python311\site-packages\django\core\handlers\base.py", line 197, in _get_response
    response = wrapped_callback(request, *callback_args, **callback_kwargs)
               ^^^^^^^^^^^^^^^^^^^^^^^^^^^^^^^^^^^^^^^^^^^^^^^^^^^^^^^^^^^^
  File "C:\Users\ASHISH KUMAR\AppData\Local\Packages\PythonSoftwareFoundation.Python.3.11_qbz5n2kfra8p0\LocalCache\local-packages\Python311\site-packages\django\views\decorators\csrf.py", line 56, in wrapper_view
    return view_func(*args, **kwargs)
           ^^^^^^^^^^^^^^^^^^^^^^^^^^
  File "C:\Users\ASHISH KUMAR\AppData\Local\Packages\PythonSoftwareFoundation.Python.3.11_qbz5n2kfra8p0\LocalCache\local-packages\Python311\site-packages\rest_framework\viewsets.py", line 125, in view
    return self.dispatch(request, *args, **kwargs)
           ^^^^^^^^^^^^^^^^^^^^^^^^^^^^^^^^^^^^^^^
  File "C:\Users\ASHISH KUMAR\AppData\Local\Packages\PythonSoftwareFoundation.Python.3.11_qbz5n2kfra8p0\LocalCache\local-packages\Python311\site-packages\rest_framework\views.py", line 509, in dispatch
    response = self.handle_exception(exc)
               ^^^^^^^^^^^^^^^^^^^^^^^^^^
  File "C:\Users\ASHISH KUMAR\AppData\Local\Packages\PythonSoftwareFoundation.Python.3.11_qbz5n2kfra8p0\LocalCache\local-packages\Python311\site-packages\rest_framework\views.py", line 469, in handle_exception
    self.raise_uncaught_exception(exc)
  File "C:\Users\ASHISH KUMAR\AppData\Local\Packages\PythonSoftwareFoundation.Python.3.11_qbz5n2kfra8p0\LocalCache\local-packages\Python311\site-packages\rest_framework\views.py", line 480, in raise_uncaught_exception
    raise exc
  File "C:\Users\ASHISH KUMAR\AppData\Local\Packages\PythonSoftwareFoundation.Python.3.11_qbz5n2kfra8p0\LocalCache\local-packages\Python311\site-packages\rest_framework\views.py", line 506, in dispatch
    response = handler(request, *args, **kwargs)
               ^^^^^^^^^^^^^^^^^^^^^^^^^^^^^^^^^
  File "C:\Users\ASHISH KUMAR\AppData\Local\Packages\PythonSoftwareFoundation.Python.3.11_qbz5n2kfra8p0\LocalCache\local-packages\Python311\site-packages\rest_framework\mixins.py", line 56, in retrieve
    return Response(serializer.data)
                    ^^^^^^^^^^^^^^^
  File "C:\Users\ASHISH KUMAR\AppData\Local\Packages\PythonSoftwareFoundation.Python.3.11_qbz5n2kfra8p0\LocalCache\local-packages\Python311\site-packages\rest_framework\serializers.py", line 555, in data
    ret = super().data
          ^^^^^^^^^^^^
  File "C:\Users\ASHISH KUMAR\AppData\Local\Packages\PythonSoftwareFoundation.Python.3.11_qbz5n2kfra8p0\LocalCache\local-packages\Python311\site-packages\rest_framework\serializers.py", line 253, in data
    self._data = self.to_representation(self.instance)
                 ^^^^^^^^^^^^^^^^^^^^^^^^^^^^^^^^^^^^^
  File "C:\Users\ASHISH KUMAR\AppData\Local\Packages\PythonSoftwareFoundation.Python.3.11_qbz5n2kfra8p0\LocalCache\local-packages\Python311\site-packages\rest_framework\serializers.py", line 522, in to_representation
    ret[field.field_name] = field.to_representation(attribute)
                            ^^^^^^^^^^^^^^^^^^^^^^^^^^^^^^^^^^
  File "C:\Users\ASHISH KUMAR\AppData\Local\Packages\PythonSoftwareFoundation.Python.3.11_qbz5n2kfra8p0\LocalCache\local-packages\Python311\site-packages\rest_framework\serializers.py", line 522, in to_representation
    ret[field.field_name] = field.to_representation(attribute)
                            ^^^^^^^^^^^^^^^^^^^^^^^^^^^^^^^^^^
  File "C:\Users\ASHISH KUMAR\AppData\Local\Packages\PythonSoftwareFoundation.Python.3.11_qbz5n2kfra8p0\LocalCache\local-packages\Python311\site-packages\rest_framework\fields.py", line 1838, in to_representation
    return method(value)
           ^^^^^^^^^^^^^
  File "C:\Users\ASHISH KUMAR\OneDrive\Documents\Desktop\KJSCE\kj stuff\trae\backend\apps\users\serializers.py", line 238, in get_avatar_url
    if obj.avatar:
       ^^^^^^^^^^
AttributeError: 'User' object has no attribute 'avatar'
ERROR 2025-09-09 01:10:36,667 log 25112 3648 Internal Server Error: /api/v1/challenges/challenges/
Traceback (most recent call last):
  File "C:\Users\ASHISH KUMAR\AppData\Local\Packages\PythonSoftwareFoundation.Python.3.11_qbz5n2kfra8p0\LocalCache\local-packages\Python311\site-packages\django\core\handlers\exception.py", line 55, in inner
    response = get_response(request)
               ^^^^^^^^^^^^^^^^^^^^^
  File "C:\Users\ASHISH KUMAR\AppData\Local\Packages\PythonSoftwareFoundation.Python.3.11_qbz5n2kfra8p0\LocalCache\local-packages\Python311\site-packages\django\core\handlers\base.py", line 197, in _get_response
    response = wrapped_callback(request, *callback_args, **callback_kwargs)
               ^^^^^^^^^^^^^^^^^^^^^^^^^^^^^^^^^^^^^^^^^^^^^^^^^^^^^^^^^^^^
  File "C:\Users\ASHISH KUMAR\AppData\Local\Packages\PythonSoftwareFoundation.Python.3.11_qbz5n2kfra8p0\LocalCache\local-packages\Python311\site-packages\django\views\decorators\csrf.py", line 56, in wrapper_view
    return view_func(*args, **kwargs)
           ^^^^^^^^^^^^^^^^^^^^^^^^^^
  File "C:\Users\ASHISH KUMAR\AppData\Local\Packages\PythonSoftwareFoundation.Python.3.11_qbz5n2kfra8p0\LocalCache\local-packages\Python311\site-packages\rest_framework\viewsets.py", line 125, in view
    return self.dispatch(request, *args, **kwargs)
           ^^^^^^^^^^^^^^^^^^^^^^^^^^^^^^^^^^^^^^^
  File "C:\Users\ASHISH KUMAR\AppData\Local\Packages\PythonSoftwareFoundation.Python.3.11_qbz5n2kfra8p0\LocalCache\local-packages\Python311\site-packages\rest_framework\views.py", line 509, in dispatch
    response = self.handle_exception(exc)
               ^^^^^^^^^^^^^^^^^^^^^^^^^^
  File "C:\Users\ASHISH KUMAR\AppData\Local\Packages\PythonSoftwareFoundation.Python.3.11_qbz5n2kfra8p0\LocalCache\local-packages\Python311\site-packages\rest_framework\views.py", line 469, in handle_exception
    self.raise_uncaught_exception(exc)
  File "C:\Users\ASHISH KUMAR\AppData\Local\Packages\PythonSoftwareFoundation.Python.3.11_qbz5n2kfra8p0\LocalCache\local-packages\Python311\site-packages\rest_framework\views.py", line 480, in raise_uncaught_exception
    raise exc
  File "C:\Users\ASHISH KUMAR\AppData\Local\Packages\PythonSoftwareFoundation.Python.3.11_qbz5n2kfra8p0\LocalCache\local-packages\Python311\site-packages\rest_framework\views.py", line 506, in dispatch
    response = handler(request, *args, **kwargs)
               ^^^^^^^^^^^^^^^^^^^^^^^^^^^^^^^^^
  File "C:\Users\ASHISH KUMAR\AppData\Local\Packages\PythonSoftwareFoundation.Python.3.11_qbz5n2kfra8p0\LocalCache\local-packages\Python311\site-packages\rest_framework\mixins.py", line 43, in list
    return self.get_paginated_response(serializer.data)
                                       ^^^^^^^^^^^^^^^
  File "C:\Users\ASHISH KUMAR\AppData\Local\Packages\PythonSoftwareFoundation.Python.3.11_qbz5n2kfra8p0\LocalCache\local-packages\Python311\site-packages\rest_framework\serializers.py", line 768, in data
    ret = super().data
          ^^^^^^^^^^^^
  File "C:\Users\ASHISH KUMAR\AppData\Local\Packages\PythonSoftwareFoundation.Python.3.11_qbz5n2kfra8p0\LocalCache\local-packages\Python311\site-packages\rest_framework\serializers.py", line 253, in data
    self._data = self.to_representation(self.instance)
                 ^^^^^^^^^^^^^^^^^^^^^^^^^^^^^^^^^^^^^
  File "C:\Users\ASHISH KUMAR\AppData\Local\Packages\PythonSoftwareFoundation.Python.3.11_qbz5n2kfra8p0\LocalCache\local-packages\Python311\site-packages\rest_framework\serializers.py", line 686, in to_representation
    return [
           ^
  File "C:\Users\ASHISH KUMAR\AppData\Local\Packages\PythonSoftwareFoundation.Python.3.11_qbz5n2kfra8p0\LocalCache\local-packages\Python311\site-packages\rest_framework\serializers.py", line 687, in <listcomp>
    self.child.to_representation(item) for item in iterable
    ^^^^^^^^^^^^^^^^^^^^^^^^^^^^^^^^^^
  File "C:\Users\ASHISH KUMAR\AppData\Local\Packages\PythonSoftwareFoundation.Python.3.11_qbz5n2kfra8p0\LocalCache\local-packages\Python311\site-packages\rest_framework\serializers.py", line 522, in to_representation
    ret[field.field_name] = field.to_representation(attribute)
                            ^^^^^^^^^^^^^^^^^^^^^^^^^^^^^^^^^^
  File "C:\Users\ASHISH KUMAR\AppData\Local\Packages\PythonSoftwareFoundation.Python.3.11_qbz5n2kfra8p0\LocalCache\local-packages\Python311\site-packages\rest_framework\serializers.py", line 522, in to_representation
    ret[field.field_name] = field.to_representation(attribute)
                            ^^^^^^^^^^^^^^^^^^^^^^^^^^^^^^^^^^
  File "C:\Users\ASHISH KUMAR\AppData\Local\Packages\PythonSoftwareFoundation.Python.3.11_qbz5n2kfra8p0\LocalCache\local-packages\Python311\site-packages\rest_framework\fields.py", line 1838, in to_representation
    return method(value)
           ^^^^^^^^^^^^^
  File "C:\Users\ASHISH KUMAR\OneDrive\Documents\Desktop\KJSCE\kj stuff\trae\backend\apps\users\serializers.py", line 238, in get_avatar_url
    if obj.avatar:
       ^^^^^^^^^^
AttributeError: 'User' object has no attribute 'avatar'
WARNING 2025-09-09 01:10:42,138 log 25112 3648 Unauthorized: /api/v1/challenges/submissions/
WARNING 2025-09-09 01:10:44,065 log 25112 3648 Unauthorized: /api/v1/content/lessons/
WARNING 2025-09-09 01:10:48,974 log 25112 3648 Unauthorized: /api/v1/gamification/badges/
WARNING 2025-09-09 01:10:53,021 log 25112 3648 Unauthorized: /api/v1/gamification/point-transactions/
WARNING 2025-09-09 01:10:56,411 log 25112 3648 Unauthorized: /api/v1/auth/users/
WARNING 2025-09-09 01:12:29,085 log 40888 19140 Unauthorized: /api/v1/challenges/challenges/
WARNING 2025-09-09 01:12:34,756 log 40888 19140 Unauthorized: /api/v1/challenges/submissions/
WARNING 2025-09-09 01:12:36,537 log 40888 19140 Unauthorized: /api/v1/content/lessons/
WARNING 2025-09-09 01:12:41,449 log 40888 19140 Unauthorized: /api/v1/gamification/badges/
WARNING 2025-09-09 01:12:44,118 log 40888 19140 Unauthorized: /api/v1/gamification/point-transactions/
WARNING 2025-09-09 01:12:46,885 log 40888 19140 Unauthorized: /api/v1/auth/users/
INFO 2025-09-09 02:06:16,028 autoreload 40120 16328 Watching for file changes with StatReloader
WARNING 2025-09-09 02:06:23,846 log 40120 16148 Not Found: /
WARNING 2025-09-09 02:06:23,846 basehttp 40120 16148 "GET /?ide_webview_request_time=1757363783296 HTTP/1.1" 404 3194
WARNING 2025-09-09 02:06:23,961 log 40120 16148 Not Found: /@vite/client
WARNING 2025-09-09 02:06:23,962 basehttp 40120 16148 "GET /@vite/client HTTP/1.1" 404 3209
INFO 2025-09-09 02:14:42,338 basehttp 40120 26920 "OPTIONS /api/v1/auth/register/ HTTP/1.1" 200 0
WARNING 2025-09-09 02:14:42,410 log 40120 26920 Not Found: /api/v1/auth/register/
WARNING 2025-09-09 02:14:42,415 basehttp 40120 26920 "POST /api/v1/auth/register/ HTTP/1.1" 404 12158
INFO 2025-09-09 02:14:55,178 basehttp 40120 39500 "OPTIONS /api/v1/auth/login/ HTTP/1.1" 200 0
WARNING 2025-09-09 02:14:55,198 log 40120 39500 Not Found: /api/v1/auth/login/
WARNING 2025-09-09 02:14:55,198 basehttp 40120 39500 "POST /api/v1/auth/login/ HTTP/1.1" 404 12149
WARNING 2025-09-09 02:16:40,317 log 40120 34068 Not Found: /api/v1/auth/login/
WARNING 2025-09-09 02:16:40,323 basehttp 40120 34068 "POST /api/v1/auth/login/ HTTP/1.1" 404 12149
INFO 2025-09-09 02:17:02,239 basehttp 40120 6656 "OPTIONS /api/v1/users/ HTTP/1.1" 200 0
WARNING 2025-09-09 02:17:02,281 log 40120 6656 Not Found: /api/v1/users/
WARNING 2025-09-09 02:17:02,281 basehttp 40120 6656 "POST /api/v1/users/ HTTP/1.1" 404 3213
INFO 2025-09-09 02:20:06,094 autoreload 30368 22044 Watching for file changes with StatReloader
WARNING 2025-09-09 02:20:12,954 log 30368 38688 Not Found: /
WARNING 2025-09-09 02:20:12,954 basehttp 30368 38688 "GET /?ide_webview_request_time=1757363783296 HTTP/1.1" 404 3194
WARNING 2025-09-09 02:20:13,038 log 30368 38688 Not Found: /@vite/client
WARNING 2025-09-09 02:20:13,038 basehttp 30368 38688 "GET /@vite/client HTTP/1.1" 404 3209
INFO 2025-09-09 02:21:25,827 autoreload 30368 22044 C:\Users\ASHISH KUMAR\OneDrive\Documents\Desktop\KJSCE\kj stuff\trae\backend\apps\users\urls.py changed, reloading.
INFO 2025-09-09 02:21:27,981 autoreload 38768 27016 Watching for file changes with StatReloader
INFO 2025-09-09 02:21:34,361 autoreload 38768 27016 C:\Users\ASHISH KUMAR\OneDrive\Documents\Desktop\KJSCE\kj stuff\trae\backend\config\urls.py changed, reloading.
INFO 2025-09-09 02:21:35,647 autoreload 12804 26124 Watching for file changes with StatReloader
INFO 2025-09-09 02:21:40,826 autoreload 12804 26124 C:\Users\ASHISH KUMAR\OneDrive\Documents\Desktop\KJSCE\kj stuff\trae\backend\apps\users\urls.py changed, reloading.
INFO 2025-09-09 02:21:42,542 autoreload 40308 36492 Watching for file changes with StatReloader
WARNING 2025-09-09 02:22:11,447 log 40308 30892 Bad Request: /api/v1/users/
WARNING 2025-09-09 02:22:11,449 basehttp 40308 30892 "POST /api/v1/users/ HTTP/1.1" 400 48
INFO 2025-09-09 02:23:09,689 basehttp 40308 30892 "POST /api/v1/users/ HTTP/1.1" 201 84
ERROR 2025-09-09 02:23:17,289 log 40308 30892 Internal Server Error: /api/v1/auth/login/
Traceback (most recent call last):
  File "C:\Users\ASHISH KUMAR\AppData\Local\Packages\PythonSoftwareFoundation.Python.3.11_qbz5n2kfra8p0\LocalCache\local-packages\Python311\site-packages\django\db\backends\utils.py", line 89, in _execute
    return self.cursor.execute(sql, params)
           ^^^^^^^^^^^^^^^^^^^^^^^^^^^^^^^^
  File "C:\Users\ASHISH KUMAR\AppData\Local\Packages\PythonSoftwareFoundation.Python.3.11_qbz5n2kfra8p0\LocalCache\local-packages\Python311\site-packages\django\db\backends\sqlite3\base.py", line 328, in execute
    return super().execute(query, params)
           ^^^^^^^^^^^^^^^^^^^^^^^^^^^^^^
sqlite3.OperationalError: no such table: gamification_point_transaction

The above exception was the direct cause of the following exception:

Traceback (most recent call last):
  File "C:\Users\ASHISH KUMAR\AppData\Local\Packages\PythonSoftwareFoundation.Python.3.11_qbz5n2kfra8p0\LocalCache\local-packages\Python311\site-packages\django\core\handlers\exception.py", line 55, in inner
    response = get_response(request)
               ^^^^^^^^^^^^^^^^^^^^^
  File "C:\Users\ASHISH KUMAR\AppData\Local\Packages\PythonSoftwareFoundation.Python.3.11_qbz5n2kfra8p0\LocalCache\local-packages\Python311\site-packages\django\core\handlers\base.py", line 197, in _get_response
    response = wrapped_callback(request, *callback_args, **callback_kwargs)
               ^^^^^^^^^^^^^^^^^^^^^^^^^^^^^^^^^^^^^^^^^^^^^^^^^^^^^^^^^^^^
  File "C:\Users\ASHISH KUMAR\AppData\Local\Packages\PythonSoftwareFoundation.Python.3.11_qbz5n2kfra8p0\LocalCache\local-packages\Python311\site-packages\django\views\decorators\csrf.py", line 56, in wrapper_view
    return view_func(*args, **kwargs)
           ^^^^^^^^^^^^^^^^^^^^^^^^^^
  File "C:\Users\ASHISH KUMAR\AppData\Local\Packages\PythonSoftwareFoundation.Python.3.11_qbz5n2kfra8p0\LocalCache\local-packages\Python311\site-packages\django\views\generic\base.py", line 104, in view
    return self.dispatch(request, *args, **kwargs)
           ^^^^^^^^^^^^^^^^^^^^^^^^^^^^^^^^^^^^^^^
  File "C:\Users\ASHISH KUMAR\AppData\Local\Packages\PythonSoftwareFoundation.Python.3.11_qbz5n2kfra8p0\LocalCache\local-packages\Python311\site-packages\rest_framework\views.py", line 509, in dispatch
    response = self.handle_exception(exc)
               ^^^^^^^^^^^^^^^^^^^^^^^^^^
  File "C:\Users\ASHISH KUMAR\AppData\Local\Packages\PythonSoftwareFoundation.Python.3.11_qbz5n2kfra8p0\LocalCache\local-packages\Python311\site-packages\rest_framework\views.py", line 469, in handle_exception
    self.raise_uncaught_exception(exc)
  File "C:\Users\ASHISH KUMAR\AppData\Local\Packages\PythonSoftwareFoundation.Python.3.11_qbz5n2kfra8p0\LocalCache\local-packages\Python311\site-packages\rest_framework\views.py", line 480, in raise_uncaught_exception
    raise exc
  File "C:\Users\ASHISH KUMAR\AppData\Local\Packages\PythonSoftwareFoundation.Python.3.11_qbz5n2kfra8p0\LocalCache\local-packages\Python311\site-packages\rest_framework\views.py", line 506, in dispatch
    response = handler(request, *args, **kwargs)
               ^^^^^^^^^^^^^^^^^^^^^^^^^^^^^^^^^
  File "C:\Users\ASHISH KUMAR\AppData\Local\Packages\PythonSoftwareFoundation.Python.3.11_qbz5n2kfra8p0\LocalCache\local-packages\Python311\site-packages\rest_framework_simplejwt\views.py", line 44, in post
    serializer.is_valid(raise_exception=True)
  File "C:\Users\ASHISH KUMAR\AppData\Local\Packages\PythonSoftwareFoundation.Python.3.11_qbz5n2kfra8p0\LocalCache\local-packages\Python311\site-packages\rest_framework\serializers.py", line 227, in is_valid
    self._validated_data = self.run_validation(self.initial_data)
                           ^^^^^^^^^^^^^^^^^^^^^^^^^^^^^^^^^^^^^^
  File "C:\Users\ASHISH KUMAR\AppData\Local\Packages\PythonSoftwareFoundation.Python.3.11_qbz5n2kfra8p0\LocalCache\local-packages\Python311\site-packages\rest_framework\serializers.py", line 429, in run_validation
    value = self.validate(value)
            ^^^^^^^^^^^^^^^^^^^^
  File "C:\Users\ASHISH KUMAR\OneDrive\Documents\Desktop\KJSCE\kj stuff\trae\backend\apps\users\serializers.py", line 23, in validate
    data = super().validate(attrs)
           ^^^^^^^^^^^^^^^^^^^^^^^
  File "C:\Users\ASHISH KUMAR\AppData\Local\Packages\PythonSoftwareFoundation.Python.3.11_qbz5n2kfra8p0\LocalCache\local-packages\Python311\site-packages\rest_framework_simplejwt\serializers.py", line 81, in validate
    update_last_login(None, self.user)
  File "C:\Users\ASHISH KUMAR\AppData\Local\Packages\PythonSoftwareFoundation.Python.3.11_qbz5n2kfra8p0\LocalCache\local-packages\Python311\site-packages\django\contrib\auth\models.py", line 23, in update_last_login
    user.save(update_fields=["last_login"])
  File "C:\Users\ASHISH KUMAR\AppData\Local\Packages\PythonSoftwareFoundation.Python.3.11_qbz5n2kfra8p0\LocalCache\local-packages\Python311\site-packages\django\contrib\auth\base_user.py", line 76, in save
    super().save(*args, **kwargs)
  File "C:\Users\ASHISH KUMAR\AppData\Local\Packages\PythonSoftwareFoundation.Python.3.11_qbz5n2kfra8p0\LocalCache\local-packages\Python311\site-packages\django\db\models\base.py", line 814, in save
    self.save_base(
  File "C:\Users\ASHISH KUMAR\AppData\Local\Packages\PythonSoftwareFoundation.Python.3.11_qbz5n2kfra8p0\LocalCache\local-packages\Python311\site-packages\django\db\models\base.py", line 892, in save_base
    post_save.send(
  File "C:\Users\ASHISH KUMAR\AppData\Local\Packages\PythonSoftwareFoundation.Python.3.11_qbz5n2kfra8p0\LocalCache\local-packages\Python311\site-packages\django\dispatch\dispatcher.py", line 176, in send
    return [
           ^
  File "C:\Users\ASHISH KUMAR\AppData\Local\Packages\PythonSoftwareFoundation.Python.3.11_qbz5n2kfra8p0\LocalCache\local-packages\Python311\site-packages\django\dispatch\dispatcher.py", line 177, in <listcomp>
    (receiver, receiver(signal=self, sender=sender, **named))
               ^^^^^^^^^^^^^^^^^^^^^^^^^^^^^^^^^^^^^^^^^^^^^
  File "C:\Users\ASHISH KUMAR\OneDrive\Documents\Desktop\KJSCE\kj stuff\trae\backend\apps\gamification\signals.py", line 347, in create_daily_login_points
    ).exists()
      ^^^^^^^^
  File "C:\Users\ASHISH KUMAR\AppData\Local\Packages\PythonSoftwareFoundation.Python.3.11_qbz5n2kfra8p0\LocalCache\local-packages\Python311\site-packages\django\db\models\query.py", line 1241, in exists
    return self.query.has_results(using=self.db)
           ^^^^^^^^^^^^^^^^^^^^^^^^^^^^^^^^^^^^^
  File "C:\Users\ASHISH KUMAR\AppData\Local\Packages\PythonSoftwareFoundation.Python.3.11_qbz5n2kfra8p0\LocalCache\local-packages\Python311\site-packages\django\db\models\sql\query.py", line 598, in has_results
    return compiler.has_results()
           ^^^^^^^^^^^^^^^^^^^^^^
  File "C:\Users\ASHISH KUMAR\AppData\Local\Packages\PythonSoftwareFoundation.Python.3.11_qbz5n2kfra8p0\LocalCache\local-packages\Python311\site-packages\django\db\models\sql\compiler.py", line 1530, in has_results
    return bool(self.execute_sql(SINGLE))
                ^^^^^^^^^^^^^^^^^^^^^^^^
  File "C:\Users\ASHISH KUMAR\AppData\Local\Packages\PythonSoftwareFoundation.Python.3.11_qbz5n2kfra8p0\LocalCache\local-packages\Python311\site-packages\django\db\models\sql\compiler.py", line 1562, in execute_sql
    cursor.execute(sql, params)
  File "C:\Users\ASHISH KUMAR\AppData\Local\Packages\PythonSoftwareFoundation.Python.3.11_qbz5n2kfra8p0\LocalCache\local-packages\Python311\site-packages\django\db\backends\utils.py", line 102, in execute
    return super().execute(sql, params)
           ^^^^^^^^^^^^^^^^^^^^^^^^^^^^
  File "C:\Users\ASHISH KUMAR\AppData\Local\Packages\PythonSoftwareFoundation.Python.3.11_qbz5n2kfra8p0\LocalCache\local-packages\Python311\site-packages\django\db\backends\utils.py", line 67, in execute
    return self._execute_with_wrappers(
           ^^^^^^^^^^^^^^^^^^^^^^^^^^^^
  File "C:\Users\ASHISH KUMAR\AppData\Local\Packages\PythonSoftwareFoundation.Python.3.11_qbz5n2kfra8p0\LocalCache\local-packages\Python311\site-packages\django\db\backends\utils.py", line 80, in _execute_with_wrappers
    return executor(sql, params, many, context)
           ^^^^^^^^^^^^^^^^^^^^^^^^^^^^^^^^^^^^
  File "C:\Users\ASHISH KUMAR\AppData\Local\Packages\PythonSoftwareFoundation.Python.3.11_qbz5n2kfra8p0\LocalCache\local-packages\Python311\site-packages\django\db\backends\utils.py", line 84, in _execute
    with self.db.wrap_database_errors:
  File "C:\Users\ASHISH KUMAR\AppData\Local\Packages\PythonSoftwareFoundation.Python.3.11_qbz5n2kfra8p0\LocalCache\local-packages\Python311\site-packages\django\db\utils.py", line 91, in __exit__
    raise dj_exc_value.with_traceback(traceback) from exc_value
  File "C:\Users\ASHISH KUMAR\AppData\Local\Packages\PythonSoftwareFoundation.Python.3.11_qbz5n2kfra8p0\LocalCache\local-packages\Python311\site-packages\django\db\backends\utils.py", line 89, in _execute
    return self.cursor.execute(sql, params)
           ^^^^^^^^^^^^^^^^^^^^^^^^^^^^^^^^
  File "C:\Users\ASHISH KUMAR\AppData\Local\Packages\PythonSoftwareFoundation.Python.3.11_qbz5n2kfra8p0\LocalCache\local-packages\Python311\site-packages\django\db\backends\sqlite3\base.py", line 328, in execute
    return super().execute(query, params)
           ^^^^^^^^^^^^^^^^^^^^^^^^^^^^^^
django.db.utils.OperationalError: no such table: gamification_point_transaction
ERROR 2025-09-09 02:23:17,297 basehttp 40308 30892 "POST /api/v1/auth/login/ HTTP/1.1" 500 221472
INFO 2025-09-09 02:23:17,307 basehttp 40308 30892 - Broken pipe from ('127.0.0.1', 58335)
INFO 2025-09-09 02:24:07,265 basehttp 40308 33916 "POST /api/v1/auth/login/ HTTP/1.1" 200 790
INFO 2025-09-09 02:25:03,980 basehttp 40308 40100 "POST /api/v1/users/ HTTP/1.1" 201 94
WARNING 2025-09-09 02:26:58,738 log 40308 1308 Not Found: /api/v1/lessons/
WARNING 2025-09-09 02:26:58,746 basehttp 40308 1308 "GET /api/v1/lessons/?page=1 HTTP/1.1" 404 11976
WARNING 2025-09-09 02:26:59,782 log 40308 1308 Not Found: /api/v1/lessons/
WARNING 2025-09-09 02:26:59,782 basehttp 40308 1308 "GET /api/v1/lessons/?page=1 HTTP/1.1" 404 11976
WARNING 2025-09-09 02:27:00,446 log 40308 28764 Not Found: /api/v1/lessons/
WARNING 2025-09-09 02:27:00,454 basehttp 40308 28764 "GET /api/v1/lessons/?page=1 HTTP/1.1" 404 11976
WARNING 2025-09-09 02:27:01,796 log 40308 1308 Not Found: /api/v1/lessons/
WARNING 2025-09-09 02:27:01,799 basehttp 40308 1308 "GET /api/v1/lessons/?page=1 HTTP/1.1" 404 11976
WARNING 2025-09-09 02:27:06,163 log 40308 34872 Not Found: /api/v1/lessons/
WARNING 2025-09-09 02:27:06,163 basehttp 40308 34872 "GET /api/v1/lessons/?page=1 HTTP/1.1" 404 11976
WARNING 2025-09-09 02:27:09,642 log 40308 28392 Not Found: /api/v1/lessons/
WARNING 2025-09-09 02:27:09,642 basehttp 40308 28392 "GET /api/v1/lessons/?page=1 HTTP/1.1" 404 11976
WARNING 2025-09-09 02:27:09,995 log 40308 21400 Not Found: /api/v1/lessons/
WARNING 2025-09-09 02:27:09,996 basehttp 40308 21400 "GET /api/v1/lessons/?page=1 HTTP/1.1" 404 11976
WARNING 2025-09-09 02:27:10,662 log 40308 28392 Not Found: /api/v1/lessons/
WARNING 2025-09-09 02:27:10,662 basehttp 40308 28392 "GET /api/v1/lessons/?page=1 HTTP/1.1" 404 11976
WARNING 2025-09-09 02:27:12,680 log 40308 28392 Not Found: /api/v1/lessons/
WARNING 2025-09-09 02:27:12,680 basehttp 40308 28392 "GET /api/v1/lessons/?page=1 HTTP/1.1" 404 11976
WARNING 2025-09-09 02:27:16,700 log 40308 28392 Not Found: /api/v1/lessons/
WARNING 2025-09-09 02:27:16,701 basehttp 40308 28392 "GET /api/v1/lessons/?page=1 HTTP/1.1" 404 11976
WARNING 2025-09-09 02:27:20,642 log 40308 14736 Not Found: /api/v1/lessons/
WARNING 2025-09-09 02:27:20,645 basehttp 40308 14736 "GET /api/v1/lessons/?page=1 HTTP/1.1" 404 11976
WARNING 2025-09-09 02:27:21,132 log 40308 23228 Not Found: /api/v1/lessons/
WARNING 2025-09-09 02:27:21,133 basehttp 40308 23228 "GET /api/v1/lessons/?page=1 HTTP/1.1" 404 11976
WARNING 2025-09-09 02:27:21,665 log 40308 14736 Not Found: /api/v1/lessons/
WARNING 2025-09-09 02:27:21,667 basehttp 40308 14736 "GET /api/v1/lessons/?page=1 HTTP/1.1" 404 11976
WARNING 2025-09-09 02:27:23,684 log 40308 14736 Not Found: /api/v1/lessons/
WARNING 2025-09-09 02:27:23,684 basehttp 40308 14736 "GET /api/v1/lessons/?page=1 HTTP/1.1" 404 11976
WARNING 2025-09-09 02:27:27,700 log 40308 14736 Not Found: /api/v1/lessons/
WARNING 2025-09-09 02:27:27,700 basehttp 40308 14736 "GET /api/v1/lessons/?page=1 HTTP/1.1" 404 11976
WARNING 2025-09-09 02:27:32,334 log 40308 18824 Not Found: /api/v1/lessons/
WARNING 2025-09-09 02:27:32,335 basehttp 40308 18824 "GET /api/v1/lessons/?page=1 HTTP/1.1" 404 11976
WARNING 2025-09-09 02:27:32,899 log 40308 11500 Not Found: /api/v1/lessons/
WARNING 2025-09-09 02:27:32,900 basehttp 40308 11500 "GET /api/v1/lessons/?page=1 HTTP/1.1" 404 11976
WARNING 2025-09-09 02:27:33,351 log 40308 18824 Not Found: /api/v1/lessons/
WARNING 2025-09-09 02:27:33,352 basehttp 40308 18824 "GET /api/v1/lessons/?page=1 HTTP/1.1" 404 11976
WARNING 2025-09-09 02:27:35,366 log 40308 18824 Not Found: /api/v1/lessons/
WARNING 2025-09-09 02:27:35,366 basehttp 40308 18824 "GET /api/v1/lessons/?page=1 HTTP/1.1" 404 11976
WARNING 2025-09-09 02:27:39,939 log 40308 31212 Not Found: /api/v1/lessons/
WARNING 2025-09-09 02:27:39,942 basehttp 40308 31212 "GET /api/v1/lessons/?page=1 HTTP/1.1" 404 11976
WARNING 2025-09-09 02:27:40,957 log 40308 2920 Not Found: /api/v1/lessons/
WARNING 2025-09-09 02:27:40,964 basehttp 40308 2920 "GET /api/v1/lessons/?page=1 HTTP/1.1" 404 11976
WARNING 2025-09-09 02:27:41,005 log 40308 31212 Not Found: /api/v1/lessons/
WARNING 2025-09-09 02:27:41,006 basehttp 40308 31212 "GET /api/v1/lessons/?page=1 HTTP/1.1" 404 11976
WARNING 2025-09-09 02:27:43,014 log 40308 31212 Not Found: /api/v1/lessons/
WARNING 2025-09-09 02:27:43,014 basehttp 40308 31212 "GET /api/v1/lessons/?page=1 HTTP/1.1" 404 11976
WARNING 2025-09-09 02:27:47,039 log 40308 31212 Not Found: /api/v1/lessons/
WARNING 2025-09-09 02:27:47,039 basehttp 40308 31212 "GET /api/v1/lessons/?page=1 HTTP/1.1" 404 11976
WARNING 2025-09-09 02:27:56,658 log 40308 38188 Not Found: /api/v1/lessons/
WARNING 2025-09-09 02:27:56,659 basehttp 40308 38188 "GET /api/v1/lessons/?page=1 HTTP/1.1" 404 11976
WARNING 2025-09-09 02:28:16,474 log 40308 25000 Not Found: /api/v1/lessons/
WARNING 2025-09-09 02:28:16,476 basehttp 40308 25000 "GET /api/v1/lessons/?page=1 HTTP/1.1" 404 11976
WARNING 2025-09-09 02:28:17,491 log 40308 25000 Not Found: /api/v1/lessons/
WARNING 2025-09-09 02:28:17,491 basehttp 40308 25000 "GET /api/v1/lessons/?page=1 HTTP/1.1" 404 11976
WARNING 2025-09-09 02:28:19,814 log 40308 34380 Not Found: /api/v1/lessons/
WARNING 2025-09-09 02:28:19,814 basehttp 40308 34380 "GET /api/v1/lessons/?page=1 HTTP/1.1" 404 11976
WARNING 2025-09-09 02:28:23,826 log 40308 34380 Not Found: /api/v1/lessons/
WARNING 2025-09-09 02:28:23,827 basehttp 40308 34380 "GET /api/v1/lessons/?page=1 HTTP/1.1" 404 11976
WARNING 2025-09-09 02:28:30,413 log 40308 31004 Not Found: /api/v1/lessons/
WARNING 2025-09-09 02:28:30,414 basehttp 40308 31004 "GET /api/v1/lessons/?page=1 HTTP/1.1" 404 11976
WARNING 2025-09-09 02:28:31,424 log 40308 31004 Not Found: /api/v1/lessons/
WARNING 2025-09-09 02:28:31,424 basehttp 40308 31004 "GET /api/v1/lessons/?page=1 HTTP/1.1" 404 11976
WARNING 2025-09-09 02:28:33,443 log 40308 31004 Not Found: /api/v1/lessons/
WARNING 2025-09-09 02:28:33,443 basehttp 40308 31004 "GET /api/v1/lessons/?page=1 HTTP/1.1" 404 11976
WARNING 2025-09-09 02:28:37,457 log 40308 31004 Not Found: /api/v1/lessons/
WARNING 2025-09-09 02:28:37,458 basehttp 40308 31004 "GET /api/v1/lessons/?page=1 HTTP/1.1" 404 11976
WARNING 2025-09-09 02:28:41,112 log 40308 21740 Not Found: /api/v1/lessons/
WARNING 2025-09-09 02:28:41,113 basehttp 40308 21740 "GET /api/v1/lessons/?page=1 HTTP/1.1" 404 11976
WARNING 2025-09-09 02:28:42,132 log 40308 21740 Not Found: /api/v1/lessons/
WARNING 2025-09-09 02:28:42,132 basehttp 40308 21740 "GET /api/v1/lessons/?page=1 HTTP/1.1" 404 11976
WARNING 2025-09-09 02:28:44,147 log 40308 21740 Not Found: /api/v1/lessons/
WARNING 2025-09-09 02:28:44,147 basehttp 40308 21740 "GET /api/v1/lessons/?page=1 HTTP/1.1" 404 11976
WARNING 2025-09-09 02:28:44,551 log 40308 27532 Not Found: /api/v1/lessons/
WARNING 2025-09-09 02:28:44,551 basehttp 40308 27532 "GET /api/v1/lessons/?page=1 HTTP/1.1" 404 11976
WARNING 2025-09-09 02:28:46,571 log 40308 27532 Not Found: /api/v1/lessons/
WARNING 2025-09-09 02:28:46,571 basehttp 40308 27532 "GET /api/v1/lessons/?page=1 HTTP/1.1" 404 11976
WARNING 2025-09-09 02:28:48,163 log 40308 21740 Not Found: /api/v1/lessons/
WARNING 2025-09-09 02:28:48,163 basehttp 40308 21740 "GET /api/v1/lessons/?page=1 HTTP/1.1" 404 11976
WARNING 2025-09-09 02:28:50,593 log 40308 27532 Not Found: /api/v1/lessons/
WARNING 2025-09-09 02:28:50,593 basehttp 40308 27532 "GET /api/v1/lessons/?page=1 HTTP/1.1" 404 11976
WARNING 2025-09-09 02:30:57,905 log 40308 13656 Not Found: /api/v1/lessons/
WARNING 2025-09-09 02:30:57,918 basehttp 40308 13656 "GET /api/v1/lessons/?page=1 HTTP/1.1" 404 11976
WARNING 2025-09-09 02:30:58,961 log 40308 13656 Not Found: /api/v1/lessons/
WARNING 2025-09-09 02:30:58,961 basehttp 40308 13656 "GET /api/v1/lessons/?page=1 HTTP/1.1" 404 11976
WARNING 2025-09-09 02:31:01,282 log 40308 27596 Not Found: /api/v1/lessons/
WARNING 2025-09-09 02:31:01,284 basehttp 40308 27596 "GET /api/v1/lessons/?page=1 HTTP/1.1" 404 11976
WARNING 2025-09-09 02:31:05,608 log 40308 29372 Not Found: /api/v1/lessons/
WARNING 2025-09-09 02:31:05,608 basehttp 40308 29372 "GET /api/v1/lessons/?page=1 HTTP/1.1" 404 11976
WARNING 2025-09-09 02:33:51,008 log 40308 40652 Not Found: /api/v1/lessons/
WARNING 2025-09-09 02:33:51,026 basehttp 40308 40652 "GET /api/v1/lessons/?page=1 HTTP/1.1" 404 11976
WARNING 2025-09-09 02:33:52,054 log 40308 40652 Not Found: /api/v1/lessons/
WARNING 2025-09-09 02:33:52,056 basehttp 40308 40652 "GET /api/v1/lessons/?page=1 HTTP/1.1" 404 11976
WARNING 2025-09-09 02:33:54,076 log 40308 40652 Not Found: /api/v1/lessons/
WARNING 2025-09-09 02:33:54,076 basehttp 40308 40652 "GET /api/v1/lessons/?page=1 HTTP/1.1" 404 11976
WARNING 2025-09-09 02:36:18,151 log 40308 39164 Not Found: /api/v1/lessons/
WARNING 2025-09-09 02:36:18,156 basehttp 40308 39164 "GET /api/v1/lessons/?page=1 HTTP/1.1" 404 11976
INFO 2025-09-09 02:41:13,725 autoreload 40308 36492 C:\Users\ASHISH KUMAR\OneDrive\Documents\Desktop\KJSCE\kj stuff\trae\backend\apps\challenges\models.py changed, reloading.
INFO 2025-09-09 02:41:15,894 autoreload 12740 36588 Watching for file changes with StatReloader
INFO 2025-09-09 03:04:13,360 autoreload 19216 32644 Watching for file changes with StatReloader
WARNING 2025-09-09 03:04:19,659 log 19216 9324 Not Found: /
WARNING 2025-09-09 03:04:19,659 basehttp 19216 9324 "GET /?ide_webview_request_time=1757363783296 HTTP/1.1" 404 3189
WARNING 2025-09-09 03:04:19,833 log 19216 9324 Not Found: /@vite/client
WARNING 2025-09-09 03:04:19,833 basehttp 19216 9324 "GET /@vite/client HTTP/1.1" 404 3204
WARNING 2025-09-09 03:04:24,708 log 19216 38972 Not Found: /api/v1/lessons/
WARNING 2025-09-09 03:04:24,708 basehttp 19216 38972 "GET /api/v1/lessons/?page=1 HTTP/1.1" 404 11976
WARNING 2025-09-09 03:04:25,773 log 19216 38972 Not Found: /api/v1/lessons/
WARNING 2025-09-09 03:04:25,773 basehttp 19216 38972 "GET /api/v1/lessons/?page=1 HTTP/1.1" 404 11976
WARNING 2025-09-09 03:04:27,805 log 19216 38972 Not Found: /api/v1/lessons/
WARNING 2025-09-09 03:04:27,806 basehttp 19216 38972 "GET /api/v1/lessons/?page=1 HTTP/1.1" 404 11976
WARNING 2025-09-09 03:04:32,130 log 19216 14492 Not Found: /api/v1/lessons/
WARNING 2025-09-09 03:04:32,130 basehttp 19216 14492 "GET /api/v1/lessons/?page=1 HTTP/1.1" 404 11976
WARNING 2025-09-09 03:29:50,572 log 19216 39796 Not Found: /api/v1/lessons/
WARNING 2025-09-09 03:29:50,582 basehttp 19216 39796 "GET /api/v1/lessons/?page=1 HTTP/1.1" 404 11976
WARNING 2025-09-09 03:29:51,612 log 19216 39796 Not Found: /api/v1/lessons/
WARNING 2025-09-09 03:29:51,612 basehttp 19216 39796 "GET /api/v1/lessons/?page=1 HTTP/1.1" 404 11976
WARNING 2025-09-09 03:29:53,627 log 19216 39796 Not Found: /api/v1/lessons/
WARNING 2025-09-09 03:29:53,627 basehttp 19216 39796 "GET /api/v1/lessons/?page=1 HTTP/1.1" 404 11976
WARNING 2025-09-09 03:29:57,973 log 19216 39840 Not Found: /api/v1/lessons/
WARNING 2025-09-09 03:29:57,973 basehttp 19216 39840 "GET /api/v1/lessons/?page=1 HTTP/1.1" 404 11976
INFO 2025-09-09 10:02:38,524 autoreload 39720 30444 Watching for file changes with StatReloader
WARNING 2025-09-09 10:02:47,714 log 39720 40000 Not Found: /
WARNING 2025-09-09 10:02:47,715 basehttp 39720 40000 "GET /?ide_webview_request_time=1757363783296 HTTP/1.1" 404 3189
WARNING 2025-09-09 10:02:47,894 log 39720 40000 Not Found: /@vite/client
WARNING 2025-09-09 10:02:47,894 basehttp 39720 40000 "GET /@vite/client HTTP/1.1" 404 3204
INFO 2025-09-09 10:03:30,936 basehttp 39720 28220 "GET /api/v1/content/lessons/ HTTP/1.1" 200 3877
WARNING 2025-09-09 10:43:25,628 log 39720 12132 Not Found: /
WARNING 2025-09-09 10:43:25,644 basehttp 39720 12132 "GET / HTTP/1.1" 404 3150
WARNING 2025-09-09 10:43:25,976 log 39720 12132 Not Found: /favicon.ico
WARNING 2025-09-09 10:43:25,977 basehttp 39720 12132 "GET /favicon.ico HTTP/1.1" 404 3201
WARNING 2025-09-09 11:02:28,551 log 39720 41124 Not Found: /
WARNING 2025-09-09 11:02:28,561 basehttp 39720 41124 "GET / HTTP/1.1" 404 3150
INFO 2025-09-09 11:03:02,004 basehttp 39720 3780 "OPTIONS /api/v1/auth/login/ HTTP/1.1" 200 0
INFO 2025-09-09 11:03:02,721 basehttp 39720 3780 "POST /api/v1/auth/login/ HTTP/1.1" 200 826
WARNING 2025-09-09 11:03:23,643 log 39720 39852 Not Found: /
WARNING 2025-09-09 11:03:23,644 basehttp 39720 39852 "GET / HTTP/1.1" 404 3150
INFO 2025-09-09 11:31:44,340 autoreload 6504 8948 Watching for file changes with StatReloader
WARNING 2025-09-09 11:31:47,647 log 6504 16744 Not Found: /
WARNING 2025-09-09 11:31:47,647 basehttp 6504 16744 "GET / HTTP/1.1" 404 3150
WARNING 2025-09-09 11:31:47,777 log 6504 16744 Not Found: /favicon.ico
WARNING 2025-09-09 11:31:47,778 basehttp 6504 16744 "GET /favicon.ico HTTP/1.1" 404 3201
WARNING 2025-09-09 11:33:42,313 log 6504 15256 Not Found: /
WARNING 2025-09-09 11:33:42,314 basehttp 6504 15256 "GET / HTTP/1.1" 404 3150
WARNING 2025-09-09 11:34:54,852 log 6504 5884 Not Found: /
WARNING 2025-09-09 11:34:54,852 basehttp 6504 5884 "GET / HTTP/1.1" 404 3150
INFO 2025-09-09 11:35:08,384 autoreload 14376 23116 Watching for file changes with StatReloader
WARNING 2025-09-09 11:35:10,563 log 14376 7460 Not Found: /
WARNING 2025-09-09 11:35:10,566 basehttp 14376 7460 "GET / HTTP/1.1" 404 3150
INFO 2025-09-09 11:36:23,362 autoreload 14376 23116 C:\Users\aswin\Documents\Sih_website\EcoLearn\backend\config\urls.py changed, reloading.
INFO 2025-09-09 11:36:25,040 autoreload 5180 18712 Watching for file changes with StatReloader
INFO 2025-09-09 11:36:33,871 basehttp 5180 9532 "GET / HTTP/1.1" 200 328
INFO 2025-09-09 11:40:31,487 basehttp 5180 21216 "OPTIONS /api/v1/auth/register/ HTTP/1.1" 200 0
WARNING 2025-09-09 11:40:31,549 log 5180 21216 Not Found: /api/v1/auth/register/
WARNING 2025-09-09 11:40:31,550 basehttp 5180 21216 "POST /api/v1/auth/register/ HTTP/1.1" 404 12105
INFO 2025-09-09 11:43:59,892 autoreload 21456 20128 Watching for file changes with StatReloader
INFO 2025-09-09 11:44:35,265 basehttp 5180 21240 "GET /?id=ce9d2735-9444-4dd9-80ac-161075ec7c72&vscodeBrowserReqId=1757398474927 HTTP/1.1" 200 328
INFO 2025-09-09 11:44:44,379 basehttp 5180 17548 "GET /api/docs/?id=ce9d2735-9444-4dd9-80ac-161075ec7c72&vscodeBrowserReqId=1757398483814 HTTP/1.1" 200 4478
WARNING 2025-09-09 11:44:59,333 log 5180 19296 Not Found: /api/v1/auth/register/
WARNING 2025-09-09 11:44:59,334 basehttp 5180 19296 "POST /api/v1/auth/register/ HTTP/1.1" 404 12105
INFO 2025-09-09 11:45:02,155 autoreload 21456 20128 C:\Users\aswin\Documents\Sih_website\EcoLearn\backend\config\urls.py changed, reloading.
INFO 2025-09-09 11:45:02,443 autoreload 5180 18712 C:\Users\aswin\Documents\Sih_website\EcoLearn\backend\config\urls.py changed, reloading.
INFO 2025-09-09 11:45:03,938 autoreload 17548 14356 Watching for file changes with StatReloader
INFO 2025-09-09 11:45:04,326 autoreload 22760 12580 Watching for file changes with StatReloader
INFO 2025-09-09 11:46:00,798 basehttp 22824 20004 "OPTIONS /api/v1/auth/register/ HTTP/1.1" 200 0
WARNING 2025-09-09 11:46:08,113 log 22824 19324 Not Found: /health/
WARNING 2025-09-09 11:46:08,114 basehttp 22824 19324 "GET /health/?id=ce9d2735-9444-4dd9-80ac-161075ec7c72&vscodeBrowserReqId=1757398567740 HTTP/1.1" 404 3383
INFO 2025-09-09 12:08:35,259 autoreload 23352 6672 Watching for file changes with StatReloader
INFO 2025-09-09 12:09:11,190 autoreload 1976 13392 Watching for file changes with StatReloader
INFO 2025-09-09 12:09:13,289 basehttp 1976 21348 "GET / HTTP/1.1" 200 328
WARNING 2025-09-09 12:11:46,761 log 1976 17228 Not Found: /api/v1/auth/register/
WARNING 2025-09-09 12:11:46,761 basehttp 1976 17228 "POST /api/v1/auth/register/ HTTP/1.1" 404 12233
INFO 2025-09-09 12:13:10,568 autoreload 1976 13392 C:\Users\aswin\Documents\Sih_website\EcoLearn\backend\apps\users\urls.py changed, reloading.
INFO 2025-09-09 12:13:12,656 autoreload 9604 21896 Watching for file changes with StatReloader
INFO 2025-09-09 12:13:28,793 autoreload 9604 21896 C:\Users\aswin\Documents\Sih_website\EcoLearn\backend\apps\users\views.py changed, reloading.
INFO 2025-09-09 12:13:30,423 autoreload 20736 21424 Watching for file changes with StatReloader
WARNING 2025-09-09 12:14:05,795 log 20736 4712 Bad Request: /api/v1/auth/register/
WARNING 2025-09-09 12:14:05,800 basehttp 20736 4712 "POST /api/v1/auth/register/ HTTP/1.1" 400 53
WARNING 2025-09-09 12:14:30,369 log 20736 21244 Bad Request: /api/v1/auth/register/
WARNING 2025-09-09 12:14:30,371 basehttp 20736 21244 "POST /api/v1/auth/register/ HTTP/1.1" 400 53
INFO 2025-09-09 12:16:00,402 autoreload 20736 21424 C:\Users\aswin\Documents\Sih_website\EcoLearn\backend\apps\users\views.py changed, reloading.
INFO 2025-09-09 12:16:02,039 autoreload 18800 19188 Watching for file changes with StatReloader
INFO 2025-09-09 12:18:13,727 autoreload 18800 19188 C:\Users\aswin\Documents\Sih_website\EcoLearn\backend\apps\users\views.py changed, reloading.
INFO 2025-09-09 12:18:15,374 autoreload 20860 6296 Watching for file changes with StatReloader
INFO 2025-09-09 12:19:47,717 basehttp 20860 13516 "POST /api/v1/auth/register/ HTTP/1.1" 201 640
