WARNING 2025-09-09 00:33:46,395 log 34388 1228 Unauthorized: /api/v1/auth/users/
WARNING 2025-09-09 00:33:46,637 log 34388 1228 Bad Request: /api/v1/auth/users/
WARNING 2025-09-09 00:34:35,108 log 23120 30212 Unauthorized: /api/v1/auth/users/
WARNING 2025-09-09 00:34:35,346 log 23120 30212 Bad Request: /api/v1/auth/users/
WARNING 2025-09-09 00:35:39,687 log 832 34972 Unauthorized: /api/v1/auth/users/
WARNING 2025-09-09 00:36:57,248 log 33476 8528 Unauthorized: /api/v1/auth/users/
WARNING 2025-09-09 00:38:40,046 log 35400 38376 Unauthorized: /api/v1/auth/users/
WARNING 2025-09-09 00:40:20,742 log 14860 33068 Unauthorized: /api/v1/gamification/badges/
WARNING 2025-09-09 00:40:21,175 log 14860 33068 Unauthorized: /api/v1/gamification/badges/
WARNING 2025-09-09 00:40:22,911 log 14860 33068 Unauthorized: /api/v1/gamification/point-transactions/
WARNING 2025-09-09 00:40:24,891 log 14860 33068 Unauthorized: /api/v1/auth/users/
WARNING 2025-09-09 00:41:54,981 log 25664 11128 Unauthorized: /api/v1/gamification/badges/
WARNING 2025-09-09 00:41:55,442 log 25664 11128 Unauthorized: /api/v1/gamification/badges/
WARNING 2025-09-09 00:41:55,890 log 25664 11128 Unauthorized: /api/v1/gamification/leaderboards/
WARNING 2025-09-09 00:41:56,321 log 25664 11128 Unauthorized: /api/v1/gamification/leaderboards/
WARNING 2025-09-09 00:41:57,194 log 25664 11128 Unauthorized: /api/v1/gamification/point-transactions/
WARNING 2025-09-09 00:41:59,225 log 25664 11128 Unauthorized: /api/v1/auth/users/
WARNING 2025-09-09 00:42:34,000 log 39836 30388 Unauthorized: /api/v1/gamification/badges/
WARNING 2025-09-09 00:42:34,606 log 39836 30388 Unauthorized: /api/v1/gamification/badges/
WARNING 2025-09-09 00:42:35,207 log 39836 30388 Unauthorized: /api/v1/gamification/leaderboards/
WARNING 2025-09-09 00:42:35,796 log 39836 30388 Unauthorized: /api/v1/gamification/leaderboards/
WARNING 2025-09-09 00:42:36,902 log 39836 30388 Unauthorized: /api/v1/gamification/point-transactions/
WARNING 2025-09-09 00:42:39,544 log 39836 30388 Unauthorized: /api/v1/auth/users/
WARNING 2025-09-09 00:43:35,117 log 34460 2700 Unauthorized: /api/v1/gamification/badges/
WARNING 2025-09-09 00:43:35,749 log 34460 2700 Unauthorized: /api/v1/gamification/badges/
WARNING 2025-09-09 00:43:38,170 log 34460 2700 Unauthorized: /api/v1/gamification/point-transactions/
WARNING 2025-09-09 00:43:41,011 log 34460 2700 Unauthorized: /api/v1/auth/users/
WARNING 2025-09-09 00:44:29,856 log 39952 25124 Unauthorized: /api/v1/gamification/badges/
WARNING 2025-09-09 00:44:32,153 log 39952 25124 Unauthorized: /api/v1/gamification/point-transactions/
WARNING 2025-09-09 00:44:34,193 log 39952 25124 Unauthorized: /api/v1/auth/users/
WARNING 2025-09-09 00:45:52,323 log 39424 19352 Unauthorized: /api/v1/gamification/badges/
WARNING 2025-09-09 00:45:55,461 log 39424 19352 Unauthorized: /api/v1/gamification/point-transactions/
WARNING 2025-09-09 00:45:58,195 log 39424 19352 Unauthorized: /api/v1/auth/users/
WARNING 2025-09-09 00:46:41,524 log 9728 18560 Unauthorized: /api/v1/gamification/badges/
WARNING 2025-09-09 00:46:44,219 log 9728 18560 Unauthorized: /api/v1/gamification/point-transactions/
WARNING 2025-09-09 00:46:47,255 log 9728 18560 Unauthorized: /api/v1/auth/users/
WARNING 2025-09-09 00:48:24,846 log 21124 22576 Not Found: /api/v1/content/quizzes/1/
WARNING 2025-09-09 00:48:26,838 log 21124 22576 Unauthorized: /api/v1/gamification/badges/
WARNING 2025-09-09 00:48:29,643 log 21124 22576 Unauthorized: /api/v1/gamification/point-transactions/
WARNING 2025-09-09 00:50:09,169 log 36568 960 Unauthorized: /api/v1/gamification/badges/
WARNING 2025-09-09 00:50:12,173 log 36568 960 Unauthorized: /api/v1/gamification/point-transactions/
WARNING 2025-09-09 00:50:14,973 log 36568 960 Unauthorized: /api/v1/auth/users/
WARNING 2025-09-09 00:51:29,042 log 19056 24588 Not Found: /api/v1/content/quizzes/1/
WARNING 2025-09-09 00:51:30,805 log 19056 24588 Unauthorized: /api/v1/gamification/badges/
WARNING 2025-09-09 00:51:33,367 log 19056 24588 Unauthorized: /api/v1/gamification/point-transactions/
WARNING 2025-09-09 00:51:35,692 log 19056 24588 Unauthorized: /api/v1/auth/users/
WARNING 2025-09-09 00:52:35,561 log 40952 32632 Unauthorized: /api/v1/content/lessons/
WARNING 2025-09-09 00:52:36,253 log 40952 32632 Not Found: /api/v1/content/lessons/1/
WARNING 2025-09-09 00:52:38,984 log 40952 32632 Not Found: /api/v1/content/quizzes/1/
WARNING 2025-09-09 00:52:41,270 log 40952 32632 Unauthorized: /api/v1/gamification/badges/
WARNING 2025-09-09 00:52:44,157 log 40952 32632 Unauthorized: /api/v1/gamification/point-transactions/
WARNING 2025-09-09 00:52:46,180 log 40952 32632 Unauthorized: /api/v1/auth/users/
WARNING 2025-09-09 00:53:47,473 log 28120 28692 Unauthorized: /api/v1/content/lessons/
WARNING 2025-09-09 00:53:52,366 log 28120 28692 Unauthorized: /api/v1/gamification/badges/
WARNING 2025-09-09 00:53:55,944 log 28120 28692 Unauthorized: /api/v1/gamification/point-transactions/
WARNING 2025-09-09 00:53:59,096 log 28120 28692 Unauthorized: /api/v1/auth/users/
WARNING 2025-09-09 00:54:31,557 log 19840 39712 Unauthorized: /api/v1/content/lessons/
WARNING 2025-09-09 00:54:36,183 log 19840 39712 Unauthorized: /api/v1/gamification/badges/
WARNING 2025-09-09 00:54:40,281 log 19840 39712 Unauthorized: /api/v1/gamification/point-transactions/
WARNING 2025-09-09 00:54:45,301 log 19840 39712 Unauthorized: /api/v1/auth/users/
WARNING 2025-09-09 00:56:06,069 log 26156 32480 Forbidden: /api/v1/challenges/challenges/
WARNING 2025-09-09 00:56:06,551 log 26156 32480 Unauthorized: /api/v1/challenges/challenges/
WARNING 2025-09-09 00:56:07,028 log 26156 32480 Not Found: /api/v1/challenges/challenges/1/
WARNING 2025-09-09 00:56:10,663 log 26156 32480 Bad Request: /api/v1/challenges/submissions/
WARNING 2025-09-09 00:56:11,163 log 26156 32480 Unauthorized: /api/v1/challenges/submissions/
WARNING 2025-09-09 00:56:12,690 log 26156 32480 Unauthorized: /api/v1/content/lessons/
WARNING 2025-09-09 00:56:18,202 log 26156 32480 Unauthorized: /api/v1/gamification/badges/
WARNING 2025-09-09 00:56:21,530 log 26156 32480 Unauthorized: /api/v1/gamification/point-transactions/
WARNING 2025-09-09 00:56:24,457 log 26156 32480 Unauthorized: /api/v1/auth/users/
WARNING 2025-09-09 00:57:32,995 log 5512 29044 Forbidden: /api/v1/challenges/challenges/
WARNING 2025-09-09 00:57:33,491 log 5512 29044 Unauthorized: /api/v1/challenges/challenges/
WARNING 2025-09-09 00:57:34,005 log 5512 29044 Not Found: /api/v1/challenges/challenges/1/
WARNING 2025-09-09 00:57:38,603 log 5512 29044 Bad Request: /api/v1/challenges/submissions/
WARNING 2025-09-09 00:57:39,375 log 5512 29044 Unauthorized: /api/v1/challenges/submissions/
WARNING 2025-09-09 00:57:41,463 log 5512 29044 Unauthorized: /api/v1/content/lessons/
WARNING 2025-09-09 00:57:47,785 log 5512 29044 Unauthorized: /api/v1/gamification/badges/
WARNING 2025-09-09 00:57:51,536 log 5512 29044 Unauthorized: /api/v1/gamification/point-transactions/
WARNING 2025-09-09 00:57:54,645 log 5512 29044 Unauthorized: /api/v1/auth/users/
WARNING 2025-09-09 00:58:47,197 log 25148 16620 Forbidden: /api/v1/challenges/challenges/
WARNING 2025-09-09 00:58:47,691 log 25148 16620 Unauthorized: /api/v1/challenges/challenges/
ERROR 2025-09-09 00:58:48,244 log 25148 16620 Internal Server Error: /api/v1/challenges/challenges/1/
Traceback (most recent call last):
  File "C:\Users\ASHISH KUMAR\AppData\Local\Packages\PythonSoftwareFoundation.Python.3.11_qbz5n2kfra8p0\LocalCache\local-packages\Python311\site-packages\django\core\handlers\exception.py", line 55, in inner
    response = get_response(request)
               ^^^^^^^^^^^^^^^^^^^^^
  File "C:\Users\ASHISH KUMAR\AppData\Local\Packages\PythonSoftwareFoundation.Python.3.11_qbz5n2kfra8p0\LocalCache\local-packages\Python311\site-packages\django\core\handlers\base.py", line 197, in _get_response
    response = wrapped_callback(request, *callback_args, **callback_kwargs)
               ^^^^^^^^^^^^^^^^^^^^^^^^^^^^^^^^^^^^^^^^^^^^^^^^^^^^^^^^^^^^
  File "C:\Users\ASHISH KUMAR\AppData\Local\Packages\PythonSoftwareFoundation.Python.3.11_qbz5n2kfra8p0\LocalCache\local-packages\Python311\site-packages\django\views\decorators\csrf.py", line 56, in wrapper_view
    return view_func(*args, **kwargs)
           ^^^^^^^^^^^^^^^^^^^^^^^^^^
  File "C:\Users\ASHISH KUMAR\AppData\Local\Packages\PythonSoftwareFoundation.Python.3.11_qbz5n2kfra8p0\LocalCache\local-packages\Python311\site-packages\rest_framework\viewsets.py", line 125, in view
    return self.dispatch(request, *args, **kwargs)
           ^^^^^^^^^^^^^^^^^^^^^^^^^^^^^^^^^^^^^^^
  File "C:\Users\ASHISH KUMAR\AppData\Local\Packages\PythonSoftwareFoundation.Python.3.11_qbz5n2kfra8p0\LocalCache\local-packages\Python311\site-packages\rest_framework\views.py", line 509, in dispatch
    response = self.handle_exception(exc)
               ^^^^^^^^^^^^^^^^^^^^^^^^^^
  File "C:\Users\ASHISH KUMAR\AppData\Local\Packages\PythonSoftwareFoundation.Python.3.11_qbz5n2kfra8p0\LocalCache\local-packages\Python311\site-packages\rest_framework\views.py", line 469, in handle_exception
    self.raise_uncaught_exception(exc)
  File "C:\Users\ASHISH KUMAR\AppData\Local\Packages\PythonSoftwareFoundation.Python.3.11_qbz5n2kfra8p0\LocalCache\local-packages\Python311\site-packages\rest_framework\views.py", line 480, in raise_uncaught_exception
    raise exc
  File "C:\Users\ASHISH KUMAR\AppData\Local\Packages\PythonSoftwareFoundation.Python.3.11_qbz5n2kfra8p0\LocalCache\local-packages\Python311\site-packages\rest_framework\views.py", line 506, in dispatch
    response = handler(request, *args, **kwargs)
               ^^^^^^^^^^^^^^^^^^^^^^^^^^^^^^^^^
  File "C:\Users\ASHISH KUMAR\AppData\Local\Packages\PythonSoftwareFoundation.Python.3.11_qbz5n2kfra8p0\LocalCache\local-packages\Python311\site-packages\rest_framework\mixins.py", line 56, in retrieve
    return Response(serializer.data)
                    ^^^^^^^^^^^^^^^
  File "C:\Users\ASHISH KUMAR\AppData\Local\Packages\PythonSoftwareFoundation.Python.3.11_qbz5n2kfra8p0\LocalCache\local-packages\Python311\site-packages\rest_framework\serializers.py", line 555, in data
    ret = super().data
          ^^^^^^^^^^^^
  File "C:\Users\ASHISH KUMAR\AppData\Local\Packages\PythonSoftwareFoundation.Python.3.11_qbz5n2kfra8p0\LocalCache\local-packages\Python311\site-packages\rest_framework\serializers.py", line 253, in data
    self._data = self.to_representation(self.instance)
                 ^^^^^^^^^^^^^^^^^^^^^^^^^^^^^^^^^^^^^
  File "C:\Users\ASHISH KUMAR\AppData\Local\Packages\PythonSoftwareFoundation.Python.3.11_qbz5n2kfra8p0\LocalCache\local-packages\Python311\site-packages\rest_framework\serializers.py", line 522, in to_representation
    ret[field.field_name] = field.to_representation(attribute)
                            ^^^^^^^^^^^^^^^^^^^^^^^^^^^^^^^^^^
  File "C:\Users\ASHISH KUMAR\AppData\Local\Packages\PythonSoftwareFoundation.Python.3.11_qbz5n2kfra8p0\LocalCache\local-packages\Python311\site-packages\rest_framework\serializers.py", line 507, in to_representation
    for field in fields:
  File "C:\Users\ASHISH KUMAR\AppData\Local\Packages\PythonSoftwareFoundation.Python.3.11_qbz5n2kfra8p0\LocalCache\local-packages\Python311\site-packages\rest_framework\serializers.py", line 368, in _readable_fields
    for field in self.fields.values():
                 ^^^^^^^^^^^
  File "C:\Users\ASHISH KUMAR\AppData\Local\Packages\PythonSoftwareFoundation.Python.3.11_qbz5n2kfra8p0\LocalCache\local-packages\Python311\site-packages\django\utils\functional.py", line 57, in __get__
    res = instance.__dict__[self.name] = self.func(instance)
                                         ^^^^^^^^^^^^^^^^^^^
  File "C:\Users\ASHISH KUMAR\AppData\Local\Packages\PythonSoftwareFoundation.Python.3.11_qbz5n2kfra8p0\LocalCache\local-packages\Python311\site-packages\rest_framework\serializers.py", line 356, in fields
    for key, value in self.get_fields().items():
                      ^^^^^^^^^^^^^^^^^
  File "C:\Users\ASHISH KUMAR\AppData\Local\Packages\PythonSoftwareFoundation.Python.3.11_qbz5n2kfra8p0\LocalCache\local-packages\Python311\site-packages\rest_framework\serializers.py", line 1076, in get_fields
    field_class, field_kwargs = self.build_field(
                                ^^^^^^^^^^^^^^^^^
  File "C:\Users\ASHISH KUMAR\AppData\Local\Packages\PythonSoftwareFoundation.Python.3.11_qbz5n2kfra8p0\LocalCache\local-packages\Python311\site-packages\rest_framework\serializers.py", line 1222, in build_field
    return self.build_unknown_field(field_name, model_class)
           ^^^^^^^^^^^^^^^^^^^^^^^^^^^^^^^^^^^^^^^^^^^^^^^^^
  File "C:\Users\ASHISH KUMAR\AppData\Local\Packages\PythonSoftwareFoundation.Python.3.11_qbz5n2kfra8p0\LocalCache\local-packages\Python311\site-packages\rest_framework\serializers.py", line 1340, in build_unknown_field
    raise ImproperlyConfigured(
django.core.exceptions.ImproperlyConfigured: Field name `current_streak` is not valid for model `UserProfile`.
ERROR 2025-09-09 00:58:48,771 log 25148 16620 Internal Server Error: /api/v1/challenges/challenges/
Traceback (most recent call last):
  File "C:\Users\ASHISH KUMAR\AppData\Local\Packages\PythonSoftwareFoundation.Python.3.11_qbz5n2kfra8p0\LocalCache\local-packages\Python311\site-packages\django\core\handlers\exception.py", line 55, in inner
    response = get_response(request)
               ^^^^^^^^^^^^^^^^^^^^^
  File "C:\Users\ASHISH KUMAR\AppData\Local\Packages\PythonSoftwareFoundation.Python.3.11_qbz5n2kfra8p0\LocalCache\local-packages\Python311\site-packages\django\core\handlers\base.py", line 197, in _get_response
    response = wrapped_callback(request, *callback_args, **callback_kwargs)
               ^^^^^^^^^^^^^^^^^^^^^^^^^^^^^^^^^^^^^^^^^^^^^^^^^^^^^^^^^^^^
  File "C:\Users\ASHISH KUMAR\AppData\Local\Packages\PythonSoftwareFoundation.Python.3.11_qbz5n2kfra8p0\LocalCache\local-packages\Python311\site-packages\django\views\decorators\csrf.py", line 56, in wrapper_view
    return view_func(*args, **kwargs)
           ^^^^^^^^^^^^^^^^^^^^^^^^^^
  File "C:\Users\ASHISH KUMAR\AppData\Local\Packages\PythonSoftwareFoundation.Python.3.11_qbz5n2kfra8p0\LocalCache\local-packages\Python311\site-packages\rest_framework\viewsets.py", line 125, in view
    return self.dispatch(request, *args, **kwargs)
           ^^^^^^^^^^^^^^^^^^^^^^^^^^^^^^^^^^^^^^^
  File "C:\Users\ASHISH KUMAR\AppData\Local\Packages\PythonSoftwareFoundation.Python.3.11_qbz5n2kfra8p0\LocalCache\local-packages\Python311\site-packages\rest_framework\views.py", line 509, in dispatch
    response = self.handle_exception(exc)
               ^^^^^^^^^^^^^^^^^^^^^^^^^^
  File "C:\Users\ASHISH KUMAR\AppData\Local\Packages\PythonSoftwareFoundation.Python.3.11_qbz5n2kfra8p0\LocalCache\local-packages\Python311\site-packages\rest_framework\views.py", line 469, in handle_exception
    self.raise_uncaught_exception(exc)
  File "C:\Users\ASHISH KUMAR\AppData\Local\Packages\PythonSoftwareFoundation.Python.3.11_qbz5n2kfra8p0\LocalCache\local-packages\Python311\site-packages\rest_framework\views.py", line 480, in raise_uncaught_exception
    raise exc
  File "C:\Users\ASHISH KUMAR\AppData\Local\Packages\PythonSoftwareFoundation.Python.3.11_qbz5n2kfra8p0\LocalCache\local-packages\Python311\site-packages\rest_framework\views.py", line 506, in dispatch
    response = handler(request, *args, **kwargs)
               ^^^^^^^^^^^^^^^^^^^^^^^^^^^^^^^^^
  File "C:\Users\ASHISH KUMAR\AppData\Local\Packages\PythonSoftwareFoundation.Python.3.11_qbz5n2kfra8p0\LocalCache\local-packages\Python311\site-packages\rest_framework\mixins.py", line 43, in list
    return self.get_paginated_response(serializer.data)
                                       ^^^^^^^^^^^^^^^
  File "C:\Users\ASHISH KUMAR\AppData\Local\Packages\PythonSoftwareFoundation.Python.3.11_qbz5n2kfra8p0\LocalCache\local-packages\Python311\site-packages\rest_framework\serializers.py", line 768, in data
    ret = super().data
          ^^^^^^^^^^^^
  File "C:\Users\ASHISH KUMAR\AppData\Local\Packages\PythonSoftwareFoundation.Python.3.11_qbz5n2kfra8p0\LocalCache\local-packages\Python311\site-packages\rest_framework\serializers.py", line 253, in data
    self._data = self.to_representation(self.instance)
                 ^^^^^^^^^^^^^^^^^^^^^^^^^^^^^^^^^^^^^
  File "C:\Users\ASHISH KUMAR\AppData\Local\Packages\PythonSoftwareFoundation.Python.3.11_qbz5n2kfra8p0\LocalCache\local-packages\Python311\site-packages\rest_framework\serializers.py", line 686, in to_representation
    return [
           ^
  File "C:\Users\ASHISH KUMAR\AppData\Local\Packages\PythonSoftwareFoundation.Python.3.11_qbz5n2kfra8p0\LocalCache\local-packages\Python311\site-packages\rest_framework\serializers.py", line 687, in <listcomp>
    self.child.to_representation(item) for item in iterable
    ^^^^^^^^^^^^^^^^^^^^^^^^^^^^^^^^^^
  File "C:\Users\ASHISH KUMAR\AppData\Local\Packages\PythonSoftwareFoundation.Python.3.11_qbz5n2kfra8p0\LocalCache\local-packages\Python311\site-packages\rest_framework\serializers.py", line 522, in to_representation
    ret[field.field_name] = field.to_representation(attribute)
                            ^^^^^^^^^^^^^^^^^^^^^^^^^^^^^^^^^^
  File "C:\Users\ASHISH KUMAR\AppData\Local\Packages\PythonSoftwareFoundation.Python.3.11_qbz5n2kfra8p0\LocalCache\local-packages\Python311\site-packages\rest_framework\serializers.py", line 507, in to_representation
    for field in fields:
  File "C:\Users\ASHISH KUMAR\AppData\Local\Packages\PythonSoftwareFoundation.Python.3.11_qbz5n2kfra8p0\LocalCache\local-packages\Python311\site-packages\rest_framework\serializers.py", line 368, in _readable_fields
    for field in self.fields.values():
                 ^^^^^^^^^^^
  File "C:\Users\ASHISH KUMAR\AppData\Local\Packages\PythonSoftwareFoundation.Python.3.11_qbz5n2kfra8p0\LocalCache\local-packages\Python311\site-packages\django\utils\functional.py", line 57, in __get__
    res = instance.__dict__[self.name] = self.func(instance)
                                         ^^^^^^^^^^^^^^^^^^^
  File "C:\Users\ASHISH KUMAR\AppData\Local\Packages\PythonSoftwareFoundation.Python.3.11_qbz5n2kfra8p0\LocalCache\local-packages\Python311\site-packages\rest_framework\serializers.py", line 356, in fields
    for key, value in self.get_fields().items():
                      ^^^^^^^^^^^^^^^^^
  File "C:\Users\ASHISH KUMAR\AppData\Local\Packages\PythonSoftwareFoundation.Python.3.11_qbz5n2kfra8p0\LocalCache\local-packages\Python311\site-packages\rest_framework\serializers.py", line 1076, in get_fields
    field_class, field_kwargs = self.build_field(
                                ^^^^^^^^^^^^^^^^^
  File "C:\Users\ASHISH KUMAR\AppData\Local\Packages\PythonSoftwareFoundation.Python.3.11_qbz5n2kfra8p0\LocalCache\local-packages\Python311\site-packages\rest_framework\serializers.py", line 1222, in build_field
    return self.build_unknown_field(field_name, model_class)
           ^^^^^^^^^^^^^^^^^^^^^^^^^^^^^^^^^^^^^^^^^^^^^^^^^
  File "C:\Users\ASHISH KUMAR\AppData\Local\Packages\PythonSoftwareFoundation.Python.3.11_qbz5n2kfra8p0\LocalCache\local-packages\Python311\site-packages\rest_framework\serializers.py", line 1340, in build_unknown_field
    raise ImproperlyConfigured(
django.core.exceptions.ImproperlyConfigured: Field name `current_streak` is not valid for model `UserProfile`.
WARNING 2025-09-09 00:58:51,862 log 25148 16620 Bad Request: /api/v1/challenges/submissions/
WARNING 2025-09-09 00:58:52,336 log 25148 16620 Unauthorized: /api/v1/challenges/submissions/
WARNING 2025-09-09 00:58:53,811 log 25148 16620 Unauthorized: /api/v1/content/lessons/
WARNING 2025-09-09 00:58:58,498 log 25148 16620 Unauthorized: /api/v1/gamification/badges/
WARNING 2025-09-09 00:59:00,798 log 25148 16620 Unauthorized: /api/v1/gamification/point-transactions/
WARNING 2025-09-09 00:59:03,386 log 25148 16620 Unauthorized: /api/v1/auth/users/
WARNING 2025-09-09 01:00:15,091 log 33952 15532 Unauthorized: /api/v1/challenges/challenges/
ERROR 2025-09-09 01:00:15,621 log 33952 15532 Internal Server Error: /api/v1/challenges/challenges/1/
Traceback (most recent call last):
  File "C:\Users\ASHISH KUMAR\AppData\Local\Packages\PythonSoftwareFoundation.Python.3.11_qbz5n2kfra8p0\LocalCache\local-packages\Python311\site-packages\django\core\handlers\exception.py", line 55, in inner
    response = get_response(request)
               ^^^^^^^^^^^^^^^^^^^^^
  File "C:\Users\ASHISH KUMAR\AppData\Local\Packages\PythonSoftwareFoundation.Python.3.11_qbz5n2kfra8p0\LocalCache\local-packages\Python311\site-packages\django\core\handlers\base.py", line 197, in _get_response
    response = wrapped_callback(request, *callback_args, **callback_kwargs)
               ^^^^^^^^^^^^^^^^^^^^^^^^^^^^^^^^^^^^^^^^^^^^^^^^^^^^^^^^^^^^
  File "C:\Users\ASHISH KUMAR\AppData\Local\Packages\PythonSoftwareFoundation.Python.3.11_qbz5n2kfra8p0\LocalCache\local-packages\Python311\site-packages\django\views\decorators\csrf.py", line 56, in wrapper_view
    return view_func(*args, **kwargs)
           ^^^^^^^^^^^^^^^^^^^^^^^^^^
  File "C:\Users\ASHISH KUMAR\AppData\Local\Packages\PythonSoftwareFoundation.Python.3.11_qbz5n2kfra8p0\LocalCache\local-packages\Python311\site-packages\rest_framework\viewsets.py", line 125, in view
    return self.dispatch(request, *args, **kwargs)
           ^^^^^^^^^^^^^^^^^^^^^^^^^^^^^^^^^^^^^^^
  File "C:\Users\ASHISH KUMAR\AppData\Local\Packages\PythonSoftwareFoundation.Python.3.11_qbz5n2kfra8p0\LocalCache\local-packages\Python311\site-packages\rest_framework\views.py", line 509, in dispatch
    response = self.handle_exception(exc)
               ^^^^^^^^^^^^^^^^^^^^^^^^^^
  File "C:\Users\ASHISH KUMAR\AppData\Local\Packages\PythonSoftwareFoundation.Python.3.11_qbz5n2kfra8p0\LocalCache\local-packages\Python311\site-packages\rest_framework\views.py", line 469, in handle_exception
    self.raise_uncaught_exception(exc)
  File "C:\Users\ASHISH KUMAR\AppData\Local\Packages\PythonSoftwareFoundation.Python.3.11_qbz5n2kfra8p0\LocalCache\local-packages\Python311\site-packages\rest_framework\views.py", line 480, in raise_uncaught_exception
    raise exc
  File "C:\Users\ASHISH KUMAR\AppData\Local\Packages\PythonSoftwareFoundation.Python.3.11_qbz5n2kfra8p0\LocalCache\local-packages\Python311\site-packages\rest_framework\views.py", line 506, in dispatch
    response = handler(request, *args, **kwargs)
               ^^^^^^^^^^^^^^^^^^^^^^^^^^^^^^^^^
  File "C:\Users\ASHISH KUMAR\AppData\Local\Packages\PythonSoftwareFoundation.Python.3.11_qbz5n2kfra8p0\LocalCache\local-packages\Python311\site-packages\rest_framework\mixins.py", line 56, in retrieve
    return Response(serializer.data)
                    ^^^^^^^^^^^^^^^
  File "C:\Users\ASHISH KUMAR\AppData\Local\Packages\PythonSoftwareFoundation.Python.3.11_qbz5n2kfra8p0\LocalCache\local-packages\Python311\site-packages\rest_framework\serializers.py", line 555, in data
    ret = super().data
          ^^^^^^^^^^^^
  File "C:\Users\ASHISH KUMAR\AppData\Local\Packages\PythonSoftwareFoundation.Python.3.11_qbz5n2kfra8p0\LocalCache\local-packages\Python311\site-packages\rest_framework\serializers.py", line 253, in data
    self._data = self.to_representation(self.instance)
                 ^^^^^^^^^^^^^^^^^^^^^^^^^^^^^^^^^^^^^
  File "C:\Users\ASHISH KUMAR\AppData\Local\Packages\PythonSoftwareFoundation.Python.3.11_qbz5n2kfra8p0\LocalCache\local-packages\Python311\site-packages\rest_framework\serializers.py", line 522, in to_representation
    ret[field.field_name] = field.to_representation(attribute)
                            ^^^^^^^^^^^^^^^^^^^^^^^^^^^^^^^^^^
  File "C:\Users\ASHISH KUMAR\AppData\Local\Packages\PythonSoftwareFoundation.Python.3.11_qbz5n2kfra8p0\LocalCache\local-packages\Python311\site-packages\rest_framework\serializers.py", line 507, in to_representation
    for field in fields:
  File "C:\Users\ASHISH KUMAR\AppData\Local\Packages\PythonSoftwareFoundation.Python.3.11_qbz5n2kfra8p0\LocalCache\local-packages\Python311\site-packages\rest_framework\serializers.py", line 368, in _readable_fields
    for field in self.fields.values():
                 ^^^^^^^^^^^
  File "C:\Users\ASHISH KUMAR\AppData\Local\Packages\PythonSoftwareFoundation.Python.3.11_qbz5n2kfra8p0\LocalCache\local-packages\Python311\site-packages\django\utils\functional.py", line 57, in __get__
    res = instance.__dict__[self.name] = self.func(instance)
                                         ^^^^^^^^^^^^^^^^^^^
  File "C:\Users\ASHISH KUMAR\AppData\Local\Packages\PythonSoftwareFoundation.Python.3.11_qbz5n2kfra8p0\LocalCache\local-packages\Python311\site-packages\rest_framework\serializers.py", line 356, in fields
    for key, value in self.get_fields().items():
                      ^^^^^^^^^^^^^^^^^
  File "C:\Users\ASHISH KUMAR\AppData\Local\Packages\PythonSoftwareFoundation.Python.3.11_qbz5n2kfra8p0\LocalCache\local-packages\Python311\site-packages\rest_framework\serializers.py", line 1076, in get_fields
    field_class, field_kwargs = self.build_field(
                                ^^^^^^^^^^^^^^^^^
  File "C:\Users\ASHISH KUMAR\AppData\Local\Packages\PythonSoftwareFoundation.Python.3.11_qbz5n2kfra8p0\LocalCache\local-packages\Python311\site-packages\rest_framework\serializers.py", line 1222, in build_field
    return self.build_unknown_field(field_name, model_class)
           ^^^^^^^^^^^^^^^^^^^^^^^^^^^^^^^^^^^^^^^^^^^^^^^^^
  File "C:\Users\ASHISH KUMAR\AppData\Local\Packages\PythonSoftwareFoundation.Python.3.11_qbz5n2kfra8p0\LocalCache\local-packages\Python311\site-packages\rest_framework\serializers.py", line 1340, in build_unknown_field
    raise ImproperlyConfigured(
django.core.exceptions.ImproperlyConfigured: Field name `current_streak` is not valid for model `UserProfile`.
ERROR 2025-09-09 01:00:16,123 log 33952 15532 Internal Server Error: /api/v1/challenges/challenges/
Traceback (most recent call last):
  File "C:\Users\ASHISH KUMAR\AppData\Local\Packages\PythonSoftwareFoundation.Python.3.11_qbz5n2kfra8p0\LocalCache\local-packages\Python311\site-packages\django\core\handlers\exception.py", line 55, in inner
    response = get_response(request)
               ^^^^^^^^^^^^^^^^^^^^^
  File "C:\Users\ASHISH KUMAR\AppData\Local\Packages\PythonSoftwareFoundation.Python.3.11_qbz5n2kfra8p0\LocalCache\local-packages\Python311\site-packages\django\core\handlers\base.py", line 197, in _get_response
    response = wrapped_callback(request, *callback_args, **callback_kwargs)
               ^^^^^^^^^^^^^^^^^^^^^^^^^^^^^^^^^^^^^^^^^^^^^^^^^^^^^^^^^^^^
  File "C:\Users\ASHISH KUMAR\AppData\Local\Packages\PythonSoftwareFoundation.Python.3.11_qbz5n2kfra8p0\LocalCache\local-packages\Python311\site-packages\django\views\decorators\csrf.py", line 56, in wrapper_view
    return view_func(*args, **kwargs)
           ^^^^^^^^^^^^^^^^^^^^^^^^^^
  File "C:\Users\ASHISH KUMAR\AppData\Local\Packages\PythonSoftwareFoundation.Python.3.11_qbz5n2kfra8p0\LocalCache\local-packages\Python311\site-packages\rest_framework\viewsets.py", line 125, in view
    return self.dispatch(request, *args, **kwargs)
           ^^^^^^^^^^^^^^^^^^^^^^^^^^^^^^^^^^^^^^^
  File "C:\Users\ASHISH KUMAR\AppData\Local\Packages\PythonSoftwareFoundation.Python.3.11_qbz5n2kfra8p0\LocalCache\local-packages\Python311\site-packages\rest_framework\views.py", line 509, in dispatch
    response = self.handle_exception(exc)
               ^^^^^^^^^^^^^^^^^^^^^^^^^^
  File "C:\Users\ASHISH KUMAR\AppData\Local\Packages\PythonSoftwareFoundation.Python.3.11_qbz5n2kfra8p0\LocalCache\local-packages\Python311\site-packages\rest_framework\views.py", line 469, in handle_exception
    self.raise_uncaught_exception(exc)
  File "C:\Users\ASHISH KUMAR\AppData\Local\Packages\PythonSoftwareFoundation.Python.3.11_qbz5n2kfra8p0\LocalCache\local-packages\Python311\site-packages\rest_framework\views.py", line 480, in raise_uncaught_exception
    raise exc
  File "C:\Users\ASHISH KUMAR\AppData\Local\Packages\PythonSoftwareFoundation.Python.3.11_qbz5n2kfra8p0\LocalCache\local-packages\Python311\site-packages\rest_framework\views.py", line 506, in dispatch
    response = handler(request, *args, **kwargs)
               ^^^^^^^^^^^^^^^^^^^^^^^^^^^^^^^^^
  File "C:\Users\ASHISH KUMAR\AppData\Local\Packages\PythonSoftwareFoundation.Python.3.11_qbz5n2kfra8p0\LocalCache\local-packages\Python311\site-packages\rest_framework\mixins.py", line 43, in list
    return self.get_paginated_response(serializer.data)
                                       ^^^^^^^^^^^^^^^
  File "C:\Users\ASHISH KUMAR\AppData\Local\Packages\PythonSoftwareFoundation.Python.3.11_qbz5n2kfra8p0\LocalCache\local-packages\Python311\site-packages\rest_framework\serializers.py", line 768, in data
    ret = super().data
          ^^^^^^^^^^^^
  File "C:\Users\ASHISH KUMAR\AppData\Local\Packages\PythonSoftwareFoundation.Python.3.11_qbz5n2kfra8p0\LocalCache\local-packages\Python311\site-packages\rest_framework\serializers.py", line 253, in data
    self._data = self.to_representation(self.instance)
                 ^^^^^^^^^^^^^^^^^^^^^^^^^^^^^^^^^^^^^
  File "C:\Users\ASHISH KUMAR\AppData\Local\Packages\PythonSoftwareFoundation.Python.3.11_qbz5n2kfra8p0\LocalCache\local-packages\Python311\site-packages\rest_framework\serializers.py", line 686, in to_representation
    return [
           ^
  File "C:\Users\ASHISH KUMAR\AppData\Local\Packages\PythonSoftwareFoundation.Python.3.11_qbz5n2kfra8p0\LocalCache\local-packages\Python311\site-packages\rest_framework\serializers.py", line 687, in <listcomp>
    self.child.to_representation(item) for item in iterable
    ^^^^^^^^^^^^^^^^^^^^^^^^^^^^^^^^^^
  File "C:\Users\ASHISH KUMAR\AppData\Local\Packages\PythonSoftwareFoundation.Python.3.11_qbz5n2kfra8p0\LocalCache\local-packages\Python311\site-packages\rest_framework\serializers.py", line 522, in to_representation
    ret[field.field_name] = field.to_representation(attribute)
                            ^^^^^^^^^^^^^^^^^^^^^^^^^^^^^^^^^^
  File "C:\Users\ASHISH KUMAR\AppData\Local\Packages\PythonSoftwareFoundation.Python.3.11_qbz5n2kfra8p0\LocalCache\local-packages\Python311\site-packages\rest_framework\serializers.py", line 507, in to_representation
    for field in fields:
  File "C:\Users\ASHISH KUMAR\AppData\Local\Packages\PythonSoftwareFoundation.Python.3.11_qbz5n2kfra8p0\LocalCache\local-packages\Python311\site-packages\rest_framework\serializers.py", line 368, in _readable_fields
    for field in self.fields.values():
                 ^^^^^^^^^^^
  File "C:\Users\ASHISH KUMAR\AppData\Local\Packages\PythonSoftwareFoundation.Python.3.11_qbz5n2kfra8p0\LocalCache\local-packages\Python311\site-packages\django\utils\functional.py", line 57, in __get__
    res = instance.__dict__[self.name] = self.func(instance)
                                         ^^^^^^^^^^^^^^^^^^^
  File "C:\Users\ASHISH KUMAR\AppData\Local\Packages\PythonSoftwareFoundation.Python.3.11_qbz5n2kfra8p0\LocalCache\local-packages\Python311\site-packages\rest_framework\serializers.py", line 356, in fields
    for key, value in self.get_fields().items():
                      ^^^^^^^^^^^^^^^^^
  File "C:\Users\ASHISH KUMAR\AppData\Local\Packages\PythonSoftwareFoundation.Python.3.11_qbz5n2kfra8p0\LocalCache\local-packages\Python311\site-packages\rest_framework\serializers.py", line 1076, in get_fields
    field_class, field_kwargs = self.build_field(
                                ^^^^^^^^^^^^^^^^^
  File "C:\Users\ASHISH KUMAR\AppData\Local\Packages\PythonSoftwareFoundation.Python.3.11_qbz5n2kfra8p0\LocalCache\local-packages\Python311\site-packages\rest_framework\serializers.py", line 1222, in build_field
    return self.build_unknown_field(field_name, model_class)
           ^^^^^^^^^^^^^^^^^^^^^^^^^^^^^^^^^^^^^^^^^^^^^^^^^
  File "C:\Users\ASHISH KUMAR\AppData\Local\Packages\PythonSoftwareFoundation.Python.3.11_qbz5n2kfra8p0\LocalCache\local-packages\Python311\site-packages\rest_framework\serializers.py", line 1340, in build_unknown_field
    raise ImproperlyConfigured(
django.core.exceptions.ImproperlyConfigured: Field name `current_streak` is not valid for model `UserProfile`.
WARNING 2025-09-09 01:00:19,793 log 33952 15532 Bad Request: /api/v1/challenges/submissions/
WARNING 2025-09-09 01:00:20,406 log 33952 15532 Unauthorized: /api/v1/challenges/submissions/
WARNING 2025-09-09 01:00:22,509 log 33952 15532 Unauthorized: /api/v1/content/lessons/
WARNING 2025-09-09 01:00:28,501 log 33952 15532 Unauthorized: /api/v1/gamification/badges/
WARNING 2025-09-09 01:00:31,834 log 33952 15532 Unauthorized: /api/v1/gamification/point-transactions/
WARNING 2025-09-09 01:00:34,883 log 33952 15532 Unauthorized: /api/v1/auth/users/
WARNING 2025-09-09 01:01:08,307 log 36076 14860 Unauthorized: /api/v1/challenges/challenges/
ERROR 2025-09-09 01:01:08,892 log 36076 14860 Internal Server Error: /api/v1/challenges/challenges/1/
Traceback (most recent call last):
  File "C:\Users\ASHISH KUMAR\AppData\Local\Packages\PythonSoftwareFoundation.Python.3.11_qbz5n2kfra8p0\LocalCache\local-packages\Python311\site-packages\django\core\handlers\exception.py", line 55, in inner
    response = get_response(request)
               ^^^^^^^^^^^^^^^^^^^^^
  File "C:\Users\ASHISH KUMAR\AppData\Local\Packages\PythonSoftwareFoundation.Python.3.11_qbz5n2kfra8p0\LocalCache\local-packages\Python311\site-packages\django\core\handlers\base.py", line 197, in _get_response
    response = wrapped_callback(request, *callback_args, **callback_kwargs)
               ^^^^^^^^^^^^^^^^^^^^^^^^^^^^^^^^^^^^^^^^^^^^^^^^^^^^^^^^^^^^
  File "C:\Users\ASHISH KUMAR\AppData\Local\Packages\PythonSoftwareFoundation.Python.3.11_qbz5n2kfra8p0\LocalCache\local-packages\Python311\site-packages\django\views\decorators\csrf.py", line 56, in wrapper_view
    return view_func(*args, **kwargs)
           ^^^^^^^^^^^^^^^^^^^^^^^^^^
  File "C:\Users\ASHISH KUMAR\AppData\Local\Packages\PythonSoftwareFoundation.Python.3.11_qbz5n2kfra8p0\LocalCache\local-packages\Python311\site-packages\rest_framework\viewsets.py", line 125, in view
    return self.dispatch(request, *args, **kwargs)
           ^^^^^^^^^^^^^^^^^^^^^^^^^^^^^^^^^^^^^^^
  File "C:\Users\ASHISH KUMAR\AppData\Local\Packages\PythonSoftwareFoundation.Python.3.11_qbz5n2kfra8p0\LocalCache\local-packages\Python311\site-packages\rest_framework\views.py", line 509, in dispatch
    response = self.handle_exception(exc)
               ^^^^^^^^^^^^^^^^^^^^^^^^^^
  File "C:\Users\ASHISH KUMAR\AppData\Local\Packages\PythonSoftwareFoundation.Python.3.11_qbz5n2kfra8p0\LocalCache\local-packages\Python311\site-packages\rest_framework\views.py", line 469, in handle_exception
    self.raise_uncaught_exception(exc)
  File "C:\Users\ASHISH KUMAR\AppData\Local\Packages\PythonSoftwareFoundation.Python.3.11_qbz5n2kfra8p0\LocalCache\local-packages\Python311\site-packages\rest_framework\views.py", line 480, in raise_uncaught_exception
    raise exc
  File "C:\Users\ASHISH KUMAR\AppData\Local\Packages\PythonSoftwareFoundation.Python.3.11_qbz5n2kfra8p0\LocalCache\local-packages\Python311\site-packages\rest_framework\views.py", line 506, in dispatch
    response = handler(request, *args, **kwargs)
               ^^^^^^^^^^^^^^^^^^^^^^^^^^^^^^^^^
  File "C:\Users\ASHISH KUMAR\AppData\Local\Packages\PythonSoftwareFoundation.Python.3.11_qbz5n2kfra8p0\LocalCache\local-packages\Python311\site-packages\rest_framework\mixins.py", line 56, in retrieve
    return Response(serializer.data)
                    ^^^^^^^^^^^^^^^
  File "C:\Users\ASHISH KUMAR\AppData\Local\Packages\PythonSoftwareFoundation.Python.3.11_qbz5n2kfra8p0\LocalCache\local-packages\Python311\site-packages\rest_framework\serializers.py", line 555, in data
    ret = super().data
          ^^^^^^^^^^^^
  File "C:\Users\ASHISH KUMAR\AppData\Local\Packages\PythonSoftwareFoundation.Python.3.11_qbz5n2kfra8p0\LocalCache\local-packages\Python311\site-packages\rest_framework\serializers.py", line 253, in data
    self._data = self.to_representation(self.instance)
                 ^^^^^^^^^^^^^^^^^^^^^^^^^^^^^^^^^^^^^
  File "C:\Users\ASHISH KUMAR\AppData\Local\Packages\PythonSoftwareFoundation.Python.3.11_qbz5n2kfra8p0\LocalCache\local-packages\Python311\site-packages\rest_framework\serializers.py", line 522, in to_representation
    ret[field.field_name] = field.to_representation(attribute)
                            ^^^^^^^^^^^^^^^^^^^^^^^^^^^^^^^^^^
  File "C:\Users\ASHISH KUMAR\AppData\Local\Packages\PythonSoftwareFoundation.Python.3.11_qbz5n2kfra8p0\LocalCache\local-packages\Python311\site-packages\rest_framework\serializers.py", line 507, in to_representation
    for field in fields:
  File "C:\Users\ASHISH KUMAR\AppData\Local\Packages\PythonSoftwareFoundation.Python.3.11_qbz5n2kfra8p0\LocalCache\local-packages\Python311\site-packages\rest_framework\serializers.py", line 368, in _readable_fields
    for field in self.fields.values():
                 ^^^^^^^^^^^
  File "C:\Users\ASHISH KUMAR\AppData\Local\Packages\PythonSoftwareFoundation.Python.3.11_qbz5n2kfra8p0\LocalCache\local-packages\Python311\site-packages\django\utils\functional.py", line 57, in __get__
    res = instance.__dict__[self.name] = self.func(instance)
                                         ^^^^^^^^^^^^^^^^^^^
  File "C:\Users\ASHISH KUMAR\AppData\Local\Packages\PythonSoftwareFoundation.Python.3.11_qbz5n2kfra8p0\LocalCache\local-packages\Python311\site-packages\rest_framework\serializers.py", line 356, in fields
    for key, value in self.get_fields().items():
                      ^^^^^^^^^^^^^^^^^
  File "C:\Users\ASHISH KUMAR\AppData\Local\Packages\PythonSoftwareFoundation.Python.3.11_qbz5n2kfra8p0\LocalCache\local-packages\Python311\site-packages\rest_framework\serializers.py", line 1076, in get_fields
    field_class, field_kwargs = self.build_field(
                                ^^^^^^^^^^^^^^^^^
  File "C:\Users\ASHISH KUMAR\AppData\Local\Packages\PythonSoftwareFoundation.Python.3.11_qbz5n2kfra8p0\LocalCache\local-packages\Python311\site-packages\rest_framework\serializers.py", line 1222, in build_field
    return self.build_unknown_field(field_name, model_class)
           ^^^^^^^^^^^^^^^^^^^^^^^^^^^^^^^^^^^^^^^^^^^^^^^^^
  File "C:\Users\ASHISH KUMAR\AppData\Local\Packages\PythonSoftwareFoundation.Python.3.11_qbz5n2kfra8p0\LocalCache\local-packages\Python311\site-packages\rest_framework\serializers.py", line 1340, in build_unknown_field
    raise ImproperlyConfigured(
django.core.exceptions.ImproperlyConfigured: Field name `current_streak` is not valid for model `UserProfile`.
ERROR 2025-09-09 01:01:09,462 log 36076 14860 Internal Server Error: /api/v1/challenges/challenges/
Traceback (most recent call last):
  File "C:\Users\ASHISH KUMAR\AppData\Local\Packages\PythonSoftwareFoundation.Python.3.11_qbz5n2kfra8p0\LocalCache\local-packages\Python311\site-packages\django\core\handlers\exception.py", line 55, in inner
    response = get_response(request)
               ^^^^^^^^^^^^^^^^^^^^^
  File "C:\Users\ASHISH KUMAR\AppData\Local\Packages\PythonSoftwareFoundation.Python.3.11_qbz5n2kfra8p0\LocalCache\local-packages\Python311\site-packages\django\core\handlers\base.py", line 197, in _get_response
    response = wrapped_callback(request, *callback_args, **callback_kwargs)
               ^^^^^^^^^^^^^^^^^^^^^^^^^^^^^^^^^^^^^^^^^^^^^^^^^^^^^^^^^^^^
  File "C:\Users\ASHISH KUMAR\AppData\Local\Packages\PythonSoftwareFoundation.Python.3.11_qbz5n2kfra8p0\LocalCache\local-packages\Python311\site-packages\django\views\decorators\csrf.py", line 56, in wrapper_view
    return view_func(*args, **kwargs)
           ^^^^^^^^^^^^^^^^^^^^^^^^^^
  File "C:\Users\ASHISH KUMAR\AppData\Local\Packages\PythonSoftwareFoundation.Python.3.11_qbz5n2kfra8p0\LocalCache\local-packages\Python311\site-packages\rest_framework\viewsets.py", line 125, in view
    return self.dispatch(request, *args, **kwargs)
           ^^^^^^^^^^^^^^^^^^^^^^^^^^^^^^^^^^^^^^^
  File "C:\Users\ASHISH KUMAR\AppData\Local\Packages\PythonSoftwareFoundation.Python.3.11_qbz5n2kfra8p0\LocalCache\local-packages\Python311\site-packages\rest_framework\views.py", line 509, in dispatch
    response = self.handle_exception(exc)
               ^^^^^^^^^^^^^^^^^^^^^^^^^^
  File "C:\Users\ASHISH KUMAR\AppData\Local\Packages\PythonSoftwareFoundation.Python.3.11_qbz5n2kfra8p0\LocalCache\local-packages\Python311\site-packages\rest_framework\views.py", line 469, in handle_exception
    self.raise_uncaught_exception(exc)
  File "C:\Users\ASHISH KUMAR\AppData\Local\Packages\PythonSoftwareFoundation.Python.3.11_qbz5n2kfra8p0\LocalCache\local-packages\Python311\site-packages\rest_framework\views.py", line 480, in raise_uncaught_exception
    raise exc
  File "C:\Users\ASHISH KUMAR\AppData\Local\Packages\PythonSoftwareFoundation.Python.3.11_qbz5n2kfra8p0\LocalCache\local-packages\Python311\site-packages\rest_framework\views.py", line 506, in dispatch
    response = handler(request, *args, **kwargs)
               ^^^^^^^^^^^^^^^^^^^^^^^^^^^^^^^^^
  File "C:\Users\ASHISH KUMAR\AppData\Local\Packages\PythonSoftwareFoundation.Python.3.11_qbz5n2kfra8p0\LocalCache\local-packages\Python311\site-packages\rest_framework\mixins.py", line 43, in list
    return self.get_paginated_response(serializer.data)
                                       ^^^^^^^^^^^^^^^
  File "C:\Users\ASHISH KUMAR\AppData\Local\Packages\PythonSoftwareFoundation.Python.3.11_qbz5n2kfra8p0\LocalCache\local-packages\Python311\site-packages\rest_framework\serializers.py", line 768, in data
    ret = super().data
          ^^^^^^^^^^^^
  File "C:\Users\ASHISH KUMAR\AppData\Local\Packages\PythonSoftwareFoundation.Python.3.11_qbz5n2kfra8p0\LocalCache\local-packages\Python311\site-packages\rest_framework\serializers.py", line 253, in data
    self._data = self.to_representation(self.instance)
                 ^^^^^^^^^^^^^^^^^^^^^^^^^^^^^^^^^^^^^
  File "C:\Users\ASHISH KUMAR\AppData\Local\Packages\PythonSoftwareFoundation.Python.3.11_qbz5n2kfra8p0\LocalCache\local-packages\Python311\site-packages\rest_framework\serializers.py", line 686, in to_representation
    return [
           ^
  File "C:\Users\ASHISH KUMAR\AppData\Local\Packages\PythonSoftwareFoundation.Python.3.11_qbz5n2kfra8p0\LocalCache\local-packages\Python311\site-packages\rest_framework\serializers.py", line 687, in <listcomp>
    self.child.to_representation(item) for item in iterable
    ^^^^^^^^^^^^^^^^^^^^^^^^^^^^^^^^^^
  File "C:\Users\ASHISH KUMAR\AppData\Local\Packages\PythonSoftwareFoundation.Python.3.11_qbz5n2kfra8p0\LocalCache\local-packages\Python311\site-packages\rest_framework\serializers.py", line 522, in to_representation
    ret[field.field_name] = field.to_representation(attribute)
                            ^^^^^^^^^^^^^^^^^^^^^^^^^^^^^^^^^^
  File "C:\Users\ASHISH KUMAR\AppData\Local\Packages\PythonSoftwareFoundation.Python.3.11_qbz5n2kfra8p0\LocalCache\local-packages\Python311\site-packages\rest_framework\serializers.py", line 507, in to_representation
    for field in fields:
  File "C:\Users\ASHISH KUMAR\AppData\Local\Packages\PythonSoftwareFoundation.Python.3.11_qbz5n2kfra8p0\LocalCache\local-packages\Python311\site-packages\rest_framework\serializers.py", line 368, in _readable_fields
    for field in self.fields.values():
                 ^^^^^^^^^^^
  File "C:\Users\ASHISH KUMAR\AppData\Local\Packages\PythonSoftwareFoundation.Python.3.11_qbz5n2kfra8p0\LocalCache\local-packages\Python311\site-packages\django\utils\functional.py", line 57, in __get__
    res = instance.__dict__[self.name] = self.func(instance)
                                         ^^^^^^^^^^^^^^^^^^^
  File "C:\Users\ASHISH KUMAR\AppData\Local\Packages\PythonSoftwareFoundation.Python.3.11_qbz5n2kfra8p0\LocalCache\local-packages\Python311\site-packages\rest_framework\serializers.py", line 356, in fields
    for key, value in self.get_fields().items():
                      ^^^^^^^^^^^^^^^^^
  File "C:\Users\ASHISH KUMAR\AppData\Local\Packages\PythonSoftwareFoundation.Python.3.11_qbz5n2kfra8p0\LocalCache\local-packages\Python311\site-packages\rest_framework\serializers.py", line 1076, in get_fields
    field_class, field_kwargs = self.build_field(
                                ^^^^^^^^^^^^^^^^^
  File "C:\Users\ASHISH KUMAR\AppData\Local\Packages\PythonSoftwareFoundation.Python.3.11_qbz5n2kfra8p0\LocalCache\local-packages\Python311\site-packages\rest_framework\serializers.py", line 1222, in build_field
    return self.build_unknown_field(field_name, model_class)
           ^^^^^^^^^^^^^^^^^^^^^^^^^^^^^^^^^^^^^^^^^^^^^^^^^
  File "C:\Users\ASHISH KUMAR\AppData\Local\Packages\PythonSoftwareFoundation.Python.3.11_qbz5n2kfra8p0\LocalCache\local-packages\Python311\site-packages\rest_framework\serializers.py", line 1340, in build_unknown_field
    raise ImproperlyConfigured(
django.core.exceptions.ImproperlyConfigured: Field name `current_streak` is not valid for model `UserProfile`.
WARNING 2025-09-09 01:01:13,147 log 36076 14860 Bad Request: /api/v1/challenges/submissions/
WARNING 2025-09-09 01:01:13,702 log 36076 14860 Unauthorized: /api/v1/challenges/submissions/
WARNING 2025-09-09 01:01:15,688 log 36076 14860 Unauthorized: /api/v1/content/lessons/
WARNING 2025-09-09 01:01:21,077 log 36076 14860 Unauthorized: /api/v1/gamification/badges/
WARNING 2025-09-09 01:01:24,373 log 36076 14860 Unauthorized: /api/v1/gamification/point-transactions/
WARNING 2025-09-09 01:01:27,318 log 36076 14860 Unauthorized: /api/v1/auth/users/
WARNING 2025-09-09 01:02:40,985 log 30268 39756 Unauthorized: /api/v1/challenges/challenges/
ERROR 2025-09-09 01:02:41,532 log 30268 39756 Internal Server Error: /api/v1/challenges/challenges/1/
Traceback (most recent call last):
  File "C:\Users\ASHISH KUMAR\AppData\Local\Packages\PythonSoftwareFoundation.Python.3.11_qbz5n2kfra8p0\LocalCache\local-packages\Python311\site-packages\django\core\handlers\exception.py", line 55, in inner
    response = get_response(request)
               ^^^^^^^^^^^^^^^^^^^^^
  File "C:\Users\ASHISH KUMAR\AppData\Local\Packages\PythonSoftwareFoundation.Python.3.11_qbz5n2kfra8p0\LocalCache\local-packages\Python311\site-packages\django\core\handlers\base.py", line 197, in _get_response
    response = wrapped_callback(request, *callback_args, **callback_kwargs)
               ^^^^^^^^^^^^^^^^^^^^^^^^^^^^^^^^^^^^^^^^^^^^^^^^^^^^^^^^^^^^
  File "C:\Users\ASHISH KUMAR\AppData\Local\Packages\PythonSoftwareFoundation.Python.3.11_qbz5n2kfra8p0\LocalCache\local-packages\Python311\site-packages\django\views\decorators\csrf.py", line 56, in wrapper_view
    return view_func(*args, **kwargs)
           ^^^^^^^^^^^^^^^^^^^^^^^^^^
  File "C:\Users\ASHISH KUMAR\AppData\Local\Packages\PythonSoftwareFoundation.Python.3.11_qbz5n2kfra8p0\LocalCache\local-packages\Python311\site-packages\rest_framework\viewsets.py", line 125, in view
    return self.dispatch(request, *args, **kwargs)
           ^^^^^^^^^^^^^^^^^^^^^^^^^^^^^^^^^^^^^^^
  File "C:\Users\ASHISH KUMAR\AppData\Local\Packages\PythonSoftwareFoundation.Python.3.11_qbz5n2kfra8p0\LocalCache\local-packages\Python311\site-packages\rest_framework\views.py", line 509, in dispatch
    response = self.handle_exception(exc)
               ^^^^^^^^^^^^^^^^^^^^^^^^^^
  File "C:\Users\ASHISH KUMAR\AppData\Local\Packages\PythonSoftwareFoundation.Python.3.11_qbz5n2kfra8p0\LocalCache\local-packages\Python311\site-packages\rest_framework\views.py", line 469, in handle_exception
    self.raise_uncaught_exception(exc)
  File "C:\Users\ASHISH KUMAR\AppData\Local\Packages\PythonSoftwareFoundation.Python.3.11_qbz5n2kfra8p0\LocalCache\local-packages\Python311\site-packages\rest_framework\views.py", line 480, in raise_uncaught_exception
    raise exc
  File "C:\Users\ASHISH KUMAR\AppData\Local\Packages\PythonSoftwareFoundation.Python.3.11_qbz5n2kfra8p0\LocalCache\local-packages\Python311\site-packages\rest_framework\views.py", line 506, in dispatch
    response = handler(request, *args, **kwargs)
               ^^^^^^^^^^^^^^^^^^^^^^^^^^^^^^^^^
  File "C:\Users\ASHISH KUMAR\AppData\Local\Packages\PythonSoftwareFoundation.Python.3.11_qbz5n2kfra8p0\LocalCache\local-packages\Python311\site-packages\rest_framework\mixins.py", line 56, in retrieve
    return Response(serializer.data)
                    ^^^^^^^^^^^^^^^
  File "C:\Users\ASHISH KUMAR\AppData\Local\Packages\PythonSoftwareFoundation.Python.3.11_qbz5n2kfra8p0\LocalCache\local-packages\Python311\site-packages\rest_framework\serializers.py", line 555, in data
    ret = super().data
          ^^^^^^^^^^^^
  File "C:\Users\ASHISH KUMAR\AppData\Local\Packages\PythonSoftwareFoundation.Python.3.11_qbz5n2kfra8p0\LocalCache\local-packages\Python311\site-packages\rest_framework\serializers.py", line 253, in data
    self._data = self.to_representation(self.instance)
                 ^^^^^^^^^^^^^^^^^^^^^^^^^^^^^^^^^^^^^
  File "C:\Users\ASHISH KUMAR\AppData\Local\Packages\PythonSoftwareFoundation.Python.3.11_qbz5n2kfra8p0\LocalCache\local-packages\Python311\site-packages\rest_framework\serializers.py", line 522, in to_representation
    ret[field.field_name] = field.to_representation(attribute)
                            ^^^^^^^^^^^^^^^^^^^^^^^^^^^^^^^^^^
  File "C:\Users\ASHISH KUMAR\AppData\Local\Packages\PythonSoftwareFoundation.Python.3.11_qbz5n2kfra8p0\LocalCache\local-packages\Python311\site-packages\rest_framework\serializers.py", line 507, in to_representation
    for field in fields:
  File "C:\Users\ASHISH KUMAR\AppData\Local\Packages\PythonSoftwareFoundation.Python.3.11_qbz5n2kfra8p0\LocalCache\local-packages\Python311\site-packages\rest_framework\serializers.py", line 368, in _readable_fields
    for field in self.fields.values():
                 ^^^^^^^^^^^
  File "C:\Users\ASHISH KUMAR\AppData\Local\Packages\PythonSoftwareFoundation.Python.3.11_qbz5n2kfra8p0\LocalCache\local-packages\Python311\site-packages\django\utils\functional.py", line 57, in __get__
    res = instance.__dict__[self.name] = self.func(instance)
                                         ^^^^^^^^^^^^^^^^^^^
  File "C:\Users\ASHISH KUMAR\AppData\Local\Packages\PythonSoftwareFoundation.Python.3.11_qbz5n2kfra8p0\LocalCache\local-packages\Python311\site-packages\rest_framework\serializers.py", line 356, in fields
    for key, value in self.get_fields().items():
                      ^^^^^^^^^^^^^^^^^
  File "C:\Users\ASHISH KUMAR\AppData\Local\Packages\PythonSoftwareFoundation.Python.3.11_qbz5n2kfra8p0\LocalCache\local-packages\Python311\site-packages\rest_framework\serializers.py", line 1076, in get_fields
    field_class, field_kwargs = self.build_field(
                                ^^^^^^^^^^^^^^^^^
  File "C:\Users\ASHISH KUMAR\AppData\Local\Packages\PythonSoftwareFoundation.Python.3.11_qbz5n2kfra8p0\LocalCache\local-packages\Python311\site-packages\rest_framework\serializers.py", line 1222, in build_field
    return self.build_unknown_field(field_name, model_class)
           ^^^^^^^^^^^^^^^^^^^^^^^^^^^^^^^^^^^^^^^^^^^^^^^^^
  File "C:\Users\ASHISH KUMAR\AppData\Local\Packages\PythonSoftwareFoundation.Python.3.11_qbz5n2kfra8p0\LocalCache\local-packages\Python311\site-packages\rest_framework\serializers.py", line 1340, in build_unknown_field
    raise ImproperlyConfigured(
django.core.exceptions.ImproperlyConfigured: Field name `current_streak` is not valid for model `UserProfile`.
ERROR 2025-09-09 01:02:42,027 log 30268 39756 Internal Server Error: /api/v1/challenges/challenges/
Traceback (most recent call last):
  File "C:\Users\ASHISH KUMAR\AppData\Local\Packages\PythonSoftwareFoundation.Python.3.11_qbz5n2kfra8p0\LocalCache\local-packages\Python311\site-packages\django\core\handlers\exception.py", line 55, in inner
    response = get_response(request)
               ^^^^^^^^^^^^^^^^^^^^^
  File "C:\Users\ASHISH KUMAR\AppData\Local\Packages\PythonSoftwareFoundation.Python.3.11_qbz5n2kfra8p0\LocalCache\local-packages\Python311\site-packages\django\core\handlers\base.py", line 197, in _get_response
    response = wrapped_callback(request, *callback_args, **callback_kwargs)
               ^^^^^^^^^^^^^^^^^^^^^^^^^^^^^^^^^^^^^^^^^^^^^^^^^^^^^^^^^^^^
  File "C:\Users\ASHISH KUMAR\AppData\Local\Packages\PythonSoftwareFoundation.Python.3.11_qbz5n2kfra8p0\LocalCache\local-packages\Python311\site-packages\django\views\decorators\csrf.py", line 56, in wrapper_view
    return view_func(*args, **kwargs)
           ^^^^^^^^^^^^^^^^^^^^^^^^^^
  File "C:\Users\ASHISH KUMAR\AppData\Local\Packages\PythonSoftwareFoundation.Python.3.11_qbz5n2kfra8p0\LocalCache\local-packages\Python311\site-packages\rest_framework\viewsets.py", line 125, in view
    return self.dispatch(request, *args, **kwargs)
           ^^^^^^^^^^^^^^^^^^^^^^^^^^^^^^^^^^^^^^^
  File "C:\Users\ASHISH KUMAR\AppData\Local\Packages\PythonSoftwareFoundation.Python.3.11_qbz5n2kfra8p0\LocalCache\local-packages\Python311\site-packages\rest_framework\views.py", line 509, in dispatch
    response = self.handle_exception(exc)
               ^^^^^^^^^^^^^^^^^^^^^^^^^^
  File "C:\Users\ASHISH KUMAR\AppData\Local\Packages\PythonSoftwareFoundation.Python.3.11_qbz5n2kfra8p0\LocalCache\local-packages\Python311\site-packages\rest_framework\views.py", line 469, in handle_exception
    self.raise_uncaught_exception(exc)
  File "C:\Users\ASHISH KUMAR\AppData\Local\Packages\PythonSoftwareFoundation.Python.3.11_qbz5n2kfra8p0\LocalCache\local-packages\Python311\site-packages\rest_framework\views.py", line 480, in raise_uncaught_exception
    raise exc
  File "C:\Users\ASHISH KUMAR\AppData\Local\Packages\PythonSoftwareFoundation.Python.3.11_qbz5n2kfra8p0\LocalCache\local-packages\Python311\site-packages\rest_framework\views.py", line 506, in dispatch
    response = handler(request, *args, **kwargs)
               ^^^^^^^^^^^^^^^^^^^^^^^^^^^^^^^^^
  File "C:\Users\ASHISH KUMAR\AppData\Local\Packages\PythonSoftwareFoundation.Python.3.11_qbz5n2kfra8p0\LocalCache\local-packages\Python311\site-packages\rest_framework\mixins.py", line 43, in list
    return self.get_paginated_response(serializer.data)
                                       ^^^^^^^^^^^^^^^
  File "C:\Users\ASHISH KUMAR\AppData\Local\Packages\PythonSoftwareFoundation.Python.3.11_qbz5n2kfra8p0\LocalCache\local-packages\Python311\site-packages\rest_framework\serializers.py", line 768, in data
    ret = super().data
          ^^^^^^^^^^^^
  File "C:\Users\ASHISH KUMAR\AppData\Local\Packages\PythonSoftwareFoundation.Python.3.11_qbz5n2kfra8p0\LocalCache\local-packages\Python311\site-packages\rest_framework\serializers.py", line 253, in data
    self._data = self.to_representation(self.instance)
                 ^^^^^^^^^^^^^^^^^^^^^^^^^^^^^^^^^^^^^
  File "C:\Users\ASHISH KUMAR\AppData\Local\Packages\PythonSoftwareFoundation.Python.3.11_qbz5n2kfra8p0\LocalCache\local-packages\Python311\site-packages\rest_framework\serializers.py", line 686, in to_representation
    return [
           ^
  File "C:\Users\ASHISH KUMAR\AppData\Local\Packages\PythonSoftwareFoundation.Python.3.11_qbz5n2kfra8p0\LocalCache\local-packages\Python311\site-packages\rest_framework\serializers.py", line 687, in <listcomp>
    self.child.to_representation(item) for item in iterable
    ^^^^^^^^^^^^^^^^^^^^^^^^^^^^^^^^^^
  File "C:\Users\ASHISH KUMAR\AppData\Local\Packages\PythonSoftwareFoundation.Python.3.11_qbz5n2kfra8p0\LocalCache\local-packages\Python311\site-packages\rest_framework\serializers.py", line 522, in to_representation
    ret[field.field_name] = field.to_representation(attribute)
                            ^^^^^^^^^^^^^^^^^^^^^^^^^^^^^^^^^^
  File "C:\Users\ASHISH KUMAR\AppData\Local\Packages\PythonSoftwareFoundation.Python.3.11_qbz5n2kfra8p0\LocalCache\local-packages\Python311\site-packages\rest_framework\serializers.py", line 507, in to_representation
    for field in fields:
  File "C:\Users\ASHISH KUMAR\AppData\Local\Packages\PythonSoftwareFoundation.Python.3.11_qbz5n2kfra8p0\LocalCache\local-packages\Python311\site-packages\rest_framework\serializers.py", line 368, in _readable_fields
    for field in self.fields.values():
                 ^^^^^^^^^^^
  File "C:\Users\ASHISH KUMAR\AppData\Local\Packages\PythonSoftwareFoundation.Python.3.11_qbz5n2kfra8p0\LocalCache\local-packages\Python311\site-packages\django\utils\functional.py", line 57, in __get__
    res = instance.__dict__[self.name] = self.func(instance)
                                         ^^^^^^^^^^^^^^^^^^^
  File "C:\Users\ASHISH KUMAR\AppData\Local\Packages\PythonSoftwareFoundation.Python.3.11_qbz5n2kfra8p0\LocalCache\local-packages\Python311\site-packages\rest_framework\serializers.py", line 356, in fields
    for key, value in self.get_fields().items():
                      ^^^^^^^^^^^^^^^^^
  File "C:\Users\ASHISH KUMAR\AppData\Local\Packages\PythonSoftwareFoundation.Python.3.11_qbz5n2kfra8p0\LocalCache\local-packages\Python311\site-packages\rest_framework\serializers.py", line 1076, in get_fields
    field_class, field_kwargs = self.build_field(
                                ^^^^^^^^^^^^^^^^^
  File "C:\Users\ASHISH KUMAR\AppData\Local\Packages\PythonSoftwareFoundation.Python.3.11_qbz5n2kfra8p0\LocalCache\local-packages\Python311\site-packages\rest_framework\serializers.py", line 1222, in build_field
    return self.build_unknown_field(field_name, model_class)
           ^^^^^^^^^^^^^^^^^^^^^^^^^^^^^^^^^^^^^^^^^^^^^^^^^
  File "C:\Users\ASHISH KUMAR\AppData\Local\Packages\PythonSoftwareFoundation.Python.3.11_qbz5n2kfra8p0\LocalCache\local-packages\Python311\site-packages\rest_framework\serializers.py", line 1340, in build_unknown_field
    raise ImproperlyConfigured(
django.core.exceptions.ImproperlyConfigured: Field name `current_streak` is not valid for model `UserProfile`.
WARNING 2025-09-09 01:02:46,069 log 30268 39756 Bad Request: /api/v1/challenges/submissions/
WARNING 2025-09-09 01:02:46,779 log 30268 39756 Unauthorized: /api/v1/challenges/submissions/
WARNING 2025-09-09 01:02:48,893 log 30268 39756 Unauthorized: /api/v1/content/lessons/
WARNING 2025-09-09 01:02:55,009 log 30268 39756 Unauthorized: /api/v1/gamification/badges/
WARNING 2025-09-09 01:02:58,479 log 30268 39756 Unauthorized: /api/v1/gamification/point-transactions/
WARNING 2025-09-09 01:03:01,681 log 30268 39756 Unauthorized: /api/v1/auth/users/
WARNING 2025-09-09 01:03:24,004 log 16412 29768 Bad Request: /api/v1/challenges/submissions/
WARNING 2025-09-09 01:04:48,952 log 23444 33236 Unauthorized: /api/v1/challenges/challenges/
ERROR 2025-09-09 01:04:49,503 log 23444 33236 Internal Server Error: /api/v1/challenges/challenges/1/
Traceback (most recent call last):
  File "C:\Users\ASHISH KUMAR\AppData\Local\Packages\PythonSoftwareFoundation.Python.3.11_qbz5n2kfra8p0\LocalCache\local-packages\Python311\site-packages\django\core\handlers\exception.py", line 55, in inner
    response = get_response(request)
               ^^^^^^^^^^^^^^^^^^^^^
  File "C:\Users\ASHISH KUMAR\AppData\Local\Packages\PythonSoftwareFoundation.Python.3.11_qbz5n2kfra8p0\LocalCache\local-packages\Python311\site-packages\django\core\handlers\base.py", line 197, in _get_response
    response = wrapped_callback(request, *callback_args, **callback_kwargs)
               ^^^^^^^^^^^^^^^^^^^^^^^^^^^^^^^^^^^^^^^^^^^^^^^^^^^^^^^^^^^^
  File "C:\Users\ASHISH KUMAR\AppData\Local\Packages\PythonSoftwareFoundation.Python.3.11_qbz5n2kfra8p0\LocalCache\local-packages\Python311\site-packages\django\views\decorators\csrf.py", line 56, in wrapper_view
    return view_func(*args, **kwargs)
           ^^^^^^^^^^^^^^^^^^^^^^^^^^
  File "C:\Users\ASHISH KUMAR\AppData\Local\Packages\PythonSoftwareFoundation.Python.3.11_qbz5n2kfra8p0\LocalCache\local-packages\Python311\site-packages\rest_framework\viewsets.py", line 125, in view
    return self.dispatch(request, *args, **kwargs)
           ^^^^^^^^^^^^^^^^^^^^^^^^^^^^^^^^^^^^^^^
  File "C:\Users\ASHISH KUMAR\AppData\Local\Packages\PythonSoftwareFoundation.Python.3.11_qbz5n2kfra8p0\LocalCache\local-packages\Python311\site-packages\rest_framework\views.py", line 509, in dispatch
    response = self.handle_exception(exc)
               ^^^^^^^^^^^^^^^^^^^^^^^^^^
  File "C:\Users\ASHISH KUMAR\AppData\Local\Packages\PythonSoftwareFoundation.Python.3.11_qbz5n2kfra8p0\LocalCache\local-packages\Python311\site-packages\rest_framework\views.py", line 469, in handle_exception
    self.raise_uncaught_exception(exc)
  File "C:\Users\ASHISH KUMAR\AppData\Local\Packages\PythonSoftwareFoundation.Python.3.11_qbz5n2kfra8p0\LocalCache\local-packages\Python311\site-packages\rest_framework\views.py", line 480, in raise_uncaught_exception
    raise exc
  File "C:\Users\ASHISH KUMAR\AppData\Local\Packages\PythonSoftwareFoundation.Python.3.11_qbz5n2kfra8p0\LocalCache\local-packages\Python311\site-packages\rest_framework\views.py", line 506, in dispatch
    response = handler(request, *args, **kwargs)
               ^^^^^^^^^^^^^^^^^^^^^^^^^^^^^^^^^
  File "C:\Users\ASHISH KUMAR\AppData\Local\Packages\PythonSoftwareFoundation.Python.3.11_qbz5n2kfra8p0\LocalCache\local-packages\Python311\site-packages\rest_framework\mixins.py", line 56, in retrieve
    return Response(serializer.data)
                    ^^^^^^^^^^^^^^^
  File "C:\Users\ASHISH KUMAR\AppData\Local\Packages\PythonSoftwareFoundation.Python.3.11_qbz5n2kfra8p0\LocalCache\local-packages\Python311\site-packages\rest_framework\serializers.py", line 555, in data
    ret = super().data
          ^^^^^^^^^^^^
  File "C:\Users\ASHISH KUMAR\AppData\Local\Packages\PythonSoftwareFoundation.Python.3.11_qbz5n2kfra8p0\LocalCache\local-packages\Python311\site-packages\rest_framework\serializers.py", line 253, in data
    self._data = self.to_representation(self.instance)
                 ^^^^^^^^^^^^^^^^^^^^^^^^^^^^^^^^^^^^^
  File "C:\Users\ASHISH KUMAR\AppData\Local\Packages\PythonSoftwareFoundation.Python.3.11_qbz5n2kfra8p0\LocalCache\local-packages\Python311\site-packages\rest_framework\serializers.py", line 522, in to_representation
    ret[field.field_name] = field.to_representation(attribute)
                            ^^^^^^^^^^^^^^^^^^^^^^^^^^^^^^^^^^
  File "C:\Users\ASHISH KUMAR\AppData\Local\Packages\PythonSoftwareFoundation.Python.3.11_qbz5n2kfra8p0\LocalCache\local-packages\Python311\site-packages\rest_framework\serializers.py", line 507, in to_representation
    for field in fields:
  File "C:\Users\ASHISH KUMAR\AppData\Local\Packages\PythonSoftwareFoundation.Python.3.11_qbz5n2kfra8p0\LocalCache\local-packages\Python311\site-packages\rest_framework\serializers.py", line 368, in _readable_fields
    for field in self.fields.values():
                 ^^^^^^^^^^^
  File "C:\Users\ASHISH KUMAR\AppData\Local\Packages\PythonSoftwareFoundation.Python.3.11_qbz5n2kfra8p0\LocalCache\local-packages\Python311\site-packages\django\utils\functional.py", line 57, in __get__
    res = instance.__dict__[self.name] = self.func(instance)
                                         ^^^^^^^^^^^^^^^^^^^
  File "C:\Users\ASHISH KUMAR\AppData\Local\Packages\PythonSoftwareFoundation.Python.3.11_qbz5n2kfra8p0\LocalCache\local-packages\Python311\site-packages\rest_framework\serializers.py", line 356, in fields
    for key, value in self.get_fields().items():
                      ^^^^^^^^^^^^^^^^^
  File "C:\Users\ASHISH KUMAR\AppData\Local\Packages\PythonSoftwareFoundation.Python.3.11_qbz5n2kfra8p0\LocalCache\local-packages\Python311\site-packages\rest_framework\serializers.py", line 1076, in get_fields
    field_class, field_kwargs = self.build_field(
                                ^^^^^^^^^^^^^^^^^
  File "C:\Users\ASHISH KUMAR\AppData\Local\Packages\PythonSoftwareFoundation.Python.3.11_qbz5n2kfra8p0\LocalCache\local-packages\Python311\site-packages\rest_framework\serializers.py", line 1222, in build_field
    return self.build_unknown_field(field_name, model_class)
           ^^^^^^^^^^^^^^^^^^^^^^^^^^^^^^^^^^^^^^^^^^^^^^^^^
  File "C:\Users\ASHISH KUMAR\AppData\Local\Packages\PythonSoftwareFoundation.Python.3.11_qbz5n2kfra8p0\LocalCache\local-packages\Python311\site-packages\rest_framework\serializers.py", line 1340, in build_unknown_field
    raise ImproperlyConfigured(
django.core.exceptions.ImproperlyConfigured: Field name `current_streak` is not valid for model `UserProfile`.
ERROR 2025-09-09 01:04:50,053 log 23444 33236 Internal Server Error: /api/v1/challenges/challenges/
Traceback (most recent call last):
  File "C:\Users\ASHISH KUMAR\AppData\Local\Packages\PythonSoftwareFoundation.Python.3.11_qbz5n2kfra8p0\LocalCache\local-packages\Python311\site-packages\django\core\handlers\exception.py", line 55, in inner
    response = get_response(request)
               ^^^^^^^^^^^^^^^^^^^^^
  File "C:\Users\ASHISH KUMAR\AppData\Local\Packages\PythonSoftwareFoundation.Python.3.11_qbz5n2kfra8p0\LocalCache\local-packages\Python311\site-packages\django\core\handlers\base.py", line 197, in _get_response
    response = wrapped_callback(request, *callback_args, **callback_kwargs)
               ^^^^^^^^^^^^^^^^^^^^^^^^^^^^^^^^^^^^^^^^^^^^^^^^^^^^^^^^^^^^
  File "C:\Users\ASHISH KUMAR\AppData\Local\Packages\PythonSoftwareFoundation.Python.3.11_qbz5n2kfra8p0\LocalCache\local-packages\Python311\site-packages\django\views\decorators\csrf.py", line 56, in wrapper_view
    return view_func(*args, **kwargs)
           ^^^^^^^^^^^^^^^^^^^^^^^^^^
  File "C:\Users\ASHISH KUMAR\AppData\Local\Packages\PythonSoftwareFoundation.Python.3.11_qbz5n2kfra8p0\LocalCache\local-packages\Python311\site-packages\rest_framework\viewsets.py", line 125, in view
    return self.dispatch(request, *args, **kwargs)
           ^^^^^^^^^^^^^^^^^^^^^^^^^^^^^^^^^^^^^^^
  File "C:\Users\ASHISH KUMAR\AppData\Local\Packages\PythonSoftwareFoundation.Python.3.11_qbz5n2kfra8p0\LocalCache\local-packages\Python311\site-packages\rest_framework\views.py", line 509, in dispatch
    response = self.handle_exception(exc)
               ^^^^^^^^^^^^^^^^^^^^^^^^^^
  File "C:\Users\ASHISH KUMAR\AppData\Local\Packages\PythonSoftwareFoundation.Python.3.11_qbz5n2kfra8p0\LocalCache\local-packages\Python311\site-packages\rest_framework\views.py", line 469, in handle_exception
    self.raise_uncaught_exception(exc)
  File "C:\Users\ASHISH KUMAR\AppData\Local\Packages\PythonSoftwareFoundation.Python.3.11_qbz5n2kfra8p0\LocalCache\local-packages\Python311\site-packages\rest_framework\views.py", line 480, in raise_uncaught_exception
    raise exc
  File "C:\Users\ASHISH KUMAR\AppData\Local\Packages\PythonSoftwareFoundation.Python.3.11_qbz5n2kfra8p0\LocalCache\local-packages\Python311\site-packages\rest_framework\views.py", line 506, in dispatch
    response = handler(request, *args, **kwargs)
               ^^^^^^^^^^^^^^^^^^^^^^^^^^^^^^^^^
  File "C:\Users\ASHISH KUMAR\AppData\Local\Packages\PythonSoftwareFoundation.Python.3.11_qbz5n2kfra8p0\LocalCache\local-packages\Python311\site-packages\rest_framework\mixins.py", line 43, in list
    return self.get_paginated_response(serializer.data)
                                       ^^^^^^^^^^^^^^^
  File "C:\Users\ASHISH KUMAR\AppData\Local\Packages\PythonSoftwareFoundation.Python.3.11_qbz5n2kfra8p0\LocalCache\local-packages\Python311\site-packages\rest_framework\serializers.py", line 768, in data
    ret = super().data
          ^^^^^^^^^^^^
  File "C:\Users\ASHISH KUMAR\AppData\Local\Packages\PythonSoftwareFoundation.Python.3.11_qbz5n2kfra8p0\LocalCache\local-packages\Python311\site-packages\rest_framework\serializers.py", line 253, in data
    self._data = self.to_representation(self.instance)
                 ^^^^^^^^^^^^^^^^^^^^^^^^^^^^^^^^^^^^^
  File "C:\Users\ASHISH KUMAR\AppData\Local\Packages\PythonSoftwareFoundation.Python.3.11_qbz5n2kfra8p0\LocalCache\local-packages\Python311\site-packages\rest_framework\serializers.py", line 686, in to_representation
    return [
           ^
  File "C:\Users\ASHISH KUMAR\AppData\Local\Packages\PythonSoftwareFoundation.Python.3.11_qbz5n2kfra8p0\LocalCache\local-packages\Python311\site-packages\rest_framework\serializers.py", line 687, in <listcomp>
    self.child.to_representation(item) for item in iterable
    ^^^^^^^^^^^^^^^^^^^^^^^^^^^^^^^^^^
  File "C:\Users\ASHISH KUMAR\AppData\Local\Packages\PythonSoftwareFoundation.Python.3.11_qbz5n2kfra8p0\LocalCache\local-packages\Python311\site-packages\rest_framework\serializers.py", line 522, in to_representation
    ret[field.field_name] = field.to_representation(attribute)
                            ^^^^^^^^^^^^^^^^^^^^^^^^^^^^^^^^^^
  File "C:\Users\ASHISH KUMAR\AppData\Local\Packages\PythonSoftwareFoundation.Python.3.11_qbz5n2kfra8p0\LocalCache\local-packages\Python311\site-packages\rest_framework\serializers.py", line 507, in to_representation
    for field in fields:
  File "C:\Users\ASHISH KUMAR\AppData\Local\Packages\PythonSoftwareFoundation.Python.3.11_qbz5n2kfra8p0\LocalCache\local-packages\Python311\site-packages\rest_framework\serializers.py", line 368, in _readable_fields
    for field in self.fields.values():
                 ^^^^^^^^^^^
  File "C:\Users\ASHISH KUMAR\AppData\Local\Packages\PythonSoftwareFoundation.Python.3.11_qbz5n2kfra8p0\LocalCache\local-packages\Python311\site-packages\django\utils\functional.py", line 57, in __get__
    res = instance.__dict__[self.name] = self.func(instance)
                                         ^^^^^^^^^^^^^^^^^^^
  File "C:\Users\ASHISH KUMAR\AppData\Local\Packages\PythonSoftwareFoundation.Python.3.11_qbz5n2kfra8p0\LocalCache\local-packages\Python311\site-packages\rest_framework\serializers.py", line 356, in fields
    for key, value in self.get_fields().items():
                      ^^^^^^^^^^^^^^^^^
  File "C:\Users\ASHISH KUMAR\AppData\Local\Packages\PythonSoftwareFoundation.Python.3.11_qbz5n2kfra8p0\LocalCache\local-packages\Python311\site-packages\rest_framework\serializers.py", line 1076, in get_fields
    field_class, field_kwargs = self.build_field(
                                ^^^^^^^^^^^^^^^^^
  File "C:\Users\ASHISH KUMAR\AppData\Local\Packages\PythonSoftwareFoundation.Python.3.11_qbz5n2kfra8p0\LocalCache\local-packages\Python311\site-packages\rest_framework\serializers.py", line 1222, in build_field
    return self.build_unknown_field(field_name, model_class)
           ^^^^^^^^^^^^^^^^^^^^^^^^^^^^^^^^^^^^^^^^^^^^^^^^^
  File "C:\Users\ASHISH KUMAR\AppData\Local\Packages\PythonSoftwareFoundation.Python.3.11_qbz5n2kfra8p0\LocalCache\local-packages\Python311\site-packages\rest_framework\serializers.py", line 1340, in build_unknown_field
    raise ImproperlyConfigured(
django.core.exceptions.ImproperlyConfigured: Field name `current_streak` is not valid for model `UserProfile`.
WARNING 2025-09-09 01:04:54,644 log 23444 33236 Unauthorized: /api/v1/challenges/submissions/
WARNING 2025-09-09 01:04:56,786 log 23444 33236 Unauthorized: /api/v1/content/lessons/
WARNING 2025-09-09 01:05:02,807 log 23444 33236 Unauthorized: /api/v1/gamification/badges/
WARNING 2025-09-09 01:05:06,206 log 23444 33236 Unauthorized: /api/v1/gamification/point-transactions/
WARNING 2025-09-09 01:05:09,311 log 23444 33236 Unauthorized: /api/v1/auth/users/
WARNING 2025-09-09 01:05:56,667 log 40332 32040 Unauthorized: /api/v1/challenges/challenges/
ERROR 2025-09-09 01:05:57,167 log 40332 32040 Internal Server Error: /api/v1/challenges/challenges/1/
Traceback (most recent call last):
  File "C:\Users\ASHISH KUMAR\AppData\Local\Packages\PythonSoftwareFoundation.Python.3.11_qbz5n2kfra8p0\LocalCache\local-packages\Python311\site-packages\django\core\handlers\exception.py", line 55, in inner
    response = get_response(request)
               ^^^^^^^^^^^^^^^^^^^^^
  File "C:\Users\ASHISH KUMAR\AppData\Local\Packages\PythonSoftwareFoundation.Python.3.11_qbz5n2kfra8p0\LocalCache\local-packages\Python311\site-packages\django\core\handlers\base.py", line 197, in _get_response
    response = wrapped_callback(request, *callback_args, **callback_kwargs)
               ^^^^^^^^^^^^^^^^^^^^^^^^^^^^^^^^^^^^^^^^^^^^^^^^^^^^^^^^^^^^
  File "C:\Users\ASHISH KUMAR\AppData\Local\Packages\PythonSoftwareFoundation.Python.3.11_qbz5n2kfra8p0\LocalCache\local-packages\Python311\site-packages\django\views\decorators\csrf.py", line 56, in wrapper_view
    return view_func(*args, **kwargs)
           ^^^^^^^^^^^^^^^^^^^^^^^^^^
  File "C:\Users\ASHISH KUMAR\AppData\Local\Packages\PythonSoftwareFoundation.Python.3.11_qbz5n2kfra8p0\LocalCache\local-packages\Python311\site-packages\rest_framework\viewsets.py", line 125, in view
    return self.dispatch(request, *args, **kwargs)
           ^^^^^^^^^^^^^^^^^^^^^^^^^^^^^^^^^^^^^^^
  File "C:\Users\ASHISH KUMAR\AppData\Local\Packages\PythonSoftwareFoundation.Python.3.11_qbz5n2kfra8p0\LocalCache\local-packages\Python311\site-packages\rest_framework\views.py", line 509, in dispatch
    response = self.handle_exception(exc)
               ^^^^^^^^^^^^^^^^^^^^^^^^^^
  File "C:\Users\ASHISH KUMAR\AppData\Local\Packages\PythonSoftwareFoundation.Python.3.11_qbz5n2kfra8p0\LocalCache\local-packages\Python311\site-packages\rest_framework\views.py", line 469, in handle_exception
    self.raise_uncaught_exception(exc)
  File "C:\Users\ASHISH KUMAR\AppData\Local\Packages\PythonSoftwareFoundation.Python.3.11_qbz5n2kfra8p0\LocalCache\local-packages\Python311\site-packages\rest_framework\views.py", line 480, in raise_uncaught_exception
    raise exc
  File "C:\Users\ASHISH KUMAR\AppData\Local\Packages\PythonSoftwareFoundation.Python.3.11_qbz5n2kfra8p0\LocalCache\local-packages\Python311\site-packages\rest_framework\views.py", line 506, in dispatch
    response = handler(request, *args, **kwargs)
               ^^^^^^^^^^^^^^^^^^^^^^^^^^^^^^^^^
  File "C:\Users\ASHISH KUMAR\AppData\Local\Packages\PythonSoftwareFoundation.Python.3.11_qbz5n2kfra8p0\LocalCache\local-packages\Python311\site-packages\rest_framework\mixins.py", line 56, in retrieve
    return Response(serializer.data)
                    ^^^^^^^^^^^^^^^
  File "C:\Users\ASHISH KUMAR\AppData\Local\Packages\PythonSoftwareFoundation.Python.3.11_qbz5n2kfra8p0\LocalCache\local-packages\Python311\site-packages\rest_framework\serializers.py", line 555, in data
    ret = super().data
          ^^^^^^^^^^^^
  File "C:\Users\ASHISH KUMAR\AppData\Local\Packages\PythonSoftwareFoundation.Python.3.11_qbz5n2kfra8p0\LocalCache\local-packages\Python311\site-packages\rest_framework\serializers.py", line 253, in data
    self._data = self.to_representation(self.instance)
                 ^^^^^^^^^^^^^^^^^^^^^^^^^^^^^^^^^^^^^
  File "C:\Users\ASHISH KUMAR\AppData\Local\Packages\PythonSoftwareFoundation.Python.3.11_qbz5n2kfra8p0\LocalCache\local-packages\Python311\site-packages\rest_framework\serializers.py", line 522, in to_representation
    ret[field.field_name] = field.to_representation(attribute)
                            ^^^^^^^^^^^^^^^^^^^^^^^^^^^^^^^^^^
  File "C:\Users\ASHISH KUMAR\AppData\Local\Packages\PythonSoftwareFoundation.Python.3.11_qbz5n2kfra8p0\LocalCache\local-packages\Python311\site-packages\rest_framework\serializers.py", line 507, in to_representation
    for field in fields:
  File "C:\Users\ASHISH KUMAR\AppData\Local\Packages\PythonSoftwareFoundation.Python.3.11_qbz5n2kfra8p0\LocalCache\local-packages\Python311\site-packages\rest_framework\serializers.py", line 368, in _readable_fields
    for field in self.fields.values():
                 ^^^^^^^^^^^
  File "C:\Users\ASHISH KUMAR\AppData\Local\Packages\PythonSoftwareFoundation.Python.3.11_qbz5n2kfra8p0\LocalCache\local-packages\Python311\site-packages\django\utils\functional.py", line 57, in __get__
    res = instance.__dict__[self.name] = self.func(instance)
                                         ^^^^^^^^^^^^^^^^^^^
  File "C:\Users\ASHISH KUMAR\AppData\Local\Packages\PythonSoftwareFoundation.Python.3.11_qbz5n2kfra8p0\LocalCache\local-packages\Python311\site-packages\rest_framework\serializers.py", line 356, in fields
    for key, value in self.get_fields().items():
                      ^^^^^^^^^^^^^^^^^
  File "C:\Users\ASHISH KUMAR\AppData\Local\Packages\PythonSoftwareFoundation.Python.3.11_qbz5n2kfra8p0\LocalCache\local-packages\Python311\site-packages\rest_framework\serializers.py", line 1076, in get_fields
    field_class, field_kwargs = self.build_field(
                                ^^^^^^^^^^^^^^^^^
  File "C:\Users\ASHISH KUMAR\AppData\Local\Packages\PythonSoftwareFoundation.Python.3.11_qbz5n2kfra8p0\LocalCache\local-packages\Python311\site-packages\rest_framework\serializers.py", line 1222, in build_field
    return self.build_unknown_field(field_name, model_class)
           ^^^^^^^^^^^^^^^^^^^^^^^^^^^^^^^^^^^^^^^^^^^^^^^^^
  File "C:\Users\ASHISH KUMAR\AppData\Local\Packages\PythonSoftwareFoundation.Python.3.11_qbz5n2kfra8p0\LocalCache\local-packages\Python311\site-packages\rest_framework\serializers.py", line 1340, in build_unknown_field
    raise ImproperlyConfigured(
django.core.exceptions.ImproperlyConfigured: Field name `current_streak` is not valid for model `UserProfile`.
ERROR 2025-09-09 01:05:57,674 log 40332 32040 Internal Server Error: /api/v1/challenges/challenges/
Traceback (most recent call last):
  File "C:\Users\ASHISH KUMAR\AppData\Local\Packages\PythonSoftwareFoundation.Python.3.11_qbz5n2kfra8p0\LocalCache\local-packages\Python311\site-packages\django\core\handlers\exception.py", line 55, in inner
    response = get_response(request)
               ^^^^^^^^^^^^^^^^^^^^^
  File "C:\Users\ASHISH KUMAR\AppData\Local\Packages\PythonSoftwareFoundation.Python.3.11_qbz5n2kfra8p0\LocalCache\local-packages\Python311\site-packages\django\core\handlers\base.py", line 197, in _get_response
    response = wrapped_callback(request, *callback_args, **callback_kwargs)
               ^^^^^^^^^^^^^^^^^^^^^^^^^^^^^^^^^^^^^^^^^^^^^^^^^^^^^^^^^^^^
  File "C:\Users\ASHISH KUMAR\AppData\Local\Packages\PythonSoftwareFoundation.Python.3.11_qbz5n2kfra8p0\LocalCache\local-packages\Python311\site-packages\django\views\decorators\csrf.py", line 56, in wrapper_view
    return view_func(*args, **kwargs)
           ^^^^^^^^^^^^^^^^^^^^^^^^^^
  File "C:\Users\ASHISH KUMAR\AppData\Local\Packages\PythonSoftwareFoundation.Python.3.11_qbz5n2kfra8p0\LocalCache\local-packages\Python311\site-packages\rest_framework\viewsets.py", line 125, in view
    return self.dispatch(request, *args, **kwargs)
           ^^^^^^^^^^^^^^^^^^^^^^^^^^^^^^^^^^^^^^^
  File "C:\Users\ASHISH KUMAR\AppData\Local\Packages\PythonSoftwareFoundation.Python.3.11_qbz5n2kfra8p0\LocalCache\local-packages\Python311\site-packages\rest_framework\views.py", line 509, in dispatch
    response = self.handle_exception(exc)
               ^^^^^^^^^^^^^^^^^^^^^^^^^^
  File "C:\Users\ASHISH KUMAR\AppData\Local\Packages\PythonSoftwareFoundation.Python.3.11_qbz5n2kfra8p0\LocalCache\local-packages\Python311\site-packages\rest_framework\views.py", line 469, in handle_exception
    self.raise_uncaught_exception(exc)
  File "C:\Users\ASHISH KUMAR\AppData\Local\Packages\PythonSoftwareFoundation.Python.3.11_qbz5n2kfra8p0\LocalCache\local-packages\Python311\site-packages\rest_framework\views.py", line 480, in raise_uncaught_exception
    raise exc
  File "C:\Users\ASHISH KUMAR\AppData\Local\Packages\PythonSoftwareFoundation.Python.3.11_qbz5n2kfra8p0\LocalCache\local-packages\Python311\site-packages\rest_framework\views.py", line 506, in dispatch
    response = handler(request, *args, **kwargs)
               ^^^^^^^^^^^^^^^^^^^^^^^^^^^^^^^^^
  File "C:\Users\ASHISH KUMAR\AppData\Local\Packages\PythonSoftwareFoundation.Python.3.11_qbz5n2kfra8p0\LocalCache\local-packages\Python311\site-packages\rest_framework\mixins.py", line 43, in list
    return self.get_paginated_response(serializer.data)
                                       ^^^^^^^^^^^^^^^
  File "C:\Users\ASHISH KUMAR\AppData\Local\Packages\PythonSoftwareFoundation.Python.3.11_qbz5n2kfra8p0\LocalCache\local-packages\Python311\site-packages\rest_framework\serializers.py", line 768, in data
    ret = super().data
          ^^^^^^^^^^^^
  File "C:\Users\ASHISH KUMAR\AppData\Local\Packages\PythonSoftwareFoundation.Python.3.11_qbz5n2kfra8p0\LocalCache\local-packages\Python311\site-packages\rest_framework\serializers.py", line 253, in data
    self._data = self.to_representation(self.instance)
                 ^^^^^^^^^^^^^^^^^^^^^^^^^^^^^^^^^^^^^
  File "C:\Users\ASHISH KUMAR\AppData\Local\Packages\PythonSoftwareFoundation.Python.3.11_qbz5n2kfra8p0\LocalCache\local-packages\Python311\site-packages\rest_framework\serializers.py", line 686, in to_representation
    return [
           ^
  File "C:\Users\ASHISH KUMAR\AppData\Local\Packages\PythonSoftwareFoundation.Python.3.11_qbz5n2kfra8p0\LocalCache\local-packages\Python311\site-packages\rest_framework\serializers.py", line 687, in <listcomp>
    self.child.to_representation(item) for item in iterable
    ^^^^^^^^^^^^^^^^^^^^^^^^^^^^^^^^^^
  File "C:\Users\ASHISH KUMAR\AppData\Local\Packages\PythonSoftwareFoundation.Python.3.11_qbz5n2kfra8p0\LocalCache\local-packages\Python311\site-packages\rest_framework\serializers.py", line 522, in to_representation
    ret[field.field_name] = field.to_representation(attribute)
                            ^^^^^^^^^^^^^^^^^^^^^^^^^^^^^^^^^^
  File "C:\Users\ASHISH KUMAR\AppData\Local\Packages\PythonSoftwareFoundation.Python.3.11_qbz5n2kfra8p0\LocalCache\local-packages\Python311\site-packages\rest_framework\serializers.py", line 507, in to_representation
    for field in fields:
  File "C:\Users\ASHISH KUMAR\AppData\Local\Packages\PythonSoftwareFoundation.Python.3.11_qbz5n2kfra8p0\LocalCache\local-packages\Python311\site-packages\rest_framework\serializers.py", line 368, in _readable_fields
    for field in self.fields.values():
                 ^^^^^^^^^^^
  File "C:\Users\ASHISH KUMAR\AppData\Local\Packages\PythonSoftwareFoundation.Python.3.11_qbz5n2kfra8p0\LocalCache\local-packages\Python311\site-packages\django\utils\functional.py", line 57, in __get__
    res = instance.__dict__[self.name] = self.func(instance)
                                         ^^^^^^^^^^^^^^^^^^^
  File "C:\Users\ASHISH KUMAR\AppData\Local\Packages\PythonSoftwareFoundation.Python.3.11_qbz5n2kfra8p0\LocalCache\local-packages\Python311\site-packages\rest_framework\serializers.py", line 356, in fields
    for key, value in self.get_fields().items():
                      ^^^^^^^^^^^^^^^^^
  File "C:\Users\ASHISH KUMAR\AppData\Local\Packages\PythonSoftwareFoundation.Python.3.11_qbz5n2kfra8p0\LocalCache\local-packages\Python311\site-packages\rest_framework\serializers.py", line 1076, in get_fields
    field_class, field_kwargs = self.build_field(
                                ^^^^^^^^^^^^^^^^^
  File "C:\Users\ASHISH KUMAR\AppData\Local\Packages\PythonSoftwareFoundation.Python.3.11_qbz5n2kfra8p0\LocalCache\local-packages\Python311\site-packages\rest_framework\serializers.py", line 1222, in build_field
    return self.build_unknown_field(field_name, model_class)
           ^^^^^^^^^^^^^^^^^^^^^^^^^^^^^^^^^^^^^^^^^^^^^^^^^
  File "C:\Users\ASHISH KUMAR\AppData\Local\Packages\PythonSoftwareFoundation.Python.3.11_qbz5n2kfra8p0\LocalCache\local-packages\Python311\site-packages\rest_framework\serializers.py", line 1340, in build_unknown_field
    raise ImproperlyConfigured(
django.core.exceptions.ImproperlyConfigured: Field name `current_streak` is not valid for model `UserProfile`.
WARNING 2025-09-09 01:06:01,374 log 40332 32040 Unauthorized: /api/v1/challenges/submissions/
WARNING 2025-09-09 01:06:03,066 log 40332 32040 Unauthorized: /api/v1/content/lessons/
WARNING 2025-09-09 01:06:07,770 log 40332 32040 Unauthorized: /api/v1/gamification/badges/
WARNING 2025-09-09 01:06:10,548 log 40332 32040 Unauthorized: /api/v1/gamification/point-transactions/
WARNING 2025-09-09 01:06:13,020 log 40332 32040 Unauthorized: /api/v1/auth/users/
WARNING 2025-09-09 01:07:54,818 log 24344 32772 Unauthorized: /api/v1/challenges/challenges/
ERROR 2025-09-09 01:07:55,569 log 24344 32772 Internal Server Error: /api/v1/challenges/challenges/1/
Traceback (most recent call last):
  File "C:\Users\ASHISH KUMAR\AppData\Local\Packages\PythonSoftwareFoundation.Python.3.11_qbz5n2kfra8p0\LocalCache\local-packages\Python311\site-packages\django\core\handlers\exception.py", line 55, in inner
    response = get_response(request)
               ^^^^^^^^^^^^^^^^^^^^^
  File "C:\Users\ASHISH KUMAR\AppData\Local\Packages\PythonSoftwareFoundation.Python.3.11_qbz5n2kfra8p0\LocalCache\local-packages\Python311\site-packages\django\core\handlers\base.py", line 197, in _get_response
    response = wrapped_callback(request, *callback_args, **callback_kwargs)
               ^^^^^^^^^^^^^^^^^^^^^^^^^^^^^^^^^^^^^^^^^^^^^^^^^^^^^^^^^^^^
  File "C:\Users\ASHISH KUMAR\AppData\Local\Packages\PythonSoftwareFoundation.Python.3.11_qbz5n2kfra8p0\LocalCache\local-packages\Python311\site-packages\django\views\decorators\csrf.py", line 56, in wrapper_view
    return view_func(*args, **kwargs)
           ^^^^^^^^^^^^^^^^^^^^^^^^^^
  File "C:\Users\ASHISH KUMAR\AppData\Local\Packages\PythonSoftwareFoundation.Python.3.11_qbz5n2kfra8p0\LocalCache\local-packages\Python311\site-packages\rest_framework\viewsets.py", line 125, in view
    return self.dispatch(request, *args, **kwargs)
           ^^^^^^^^^^^^^^^^^^^^^^^^^^^^^^^^^^^^^^^
  File "C:\Users\ASHISH KUMAR\AppData\Local\Packages\PythonSoftwareFoundation.Python.3.11_qbz5n2kfra8p0\LocalCache\local-packages\Python311\site-packages\rest_framework\views.py", line 509, in dispatch
    response = self.handle_exception(exc)
               ^^^^^^^^^^^^^^^^^^^^^^^^^^
  File "C:\Users\ASHISH KUMAR\AppData\Local\Packages\PythonSoftwareFoundation.Python.3.11_qbz5n2kfra8p0\LocalCache\local-packages\Python311\site-packages\rest_framework\views.py", line 469, in handle_exception
    self.raise_uncaught_exception(exc)
  File "C:\Users\ASHISH KUMAR\AppData\Local\Packages\PythonSoftwareFoundation.Python.3.11_qbz5n2kfra8p0\LocalCache\local-packages\Python311\site-packages\rest_framework\views.py", line 480, in raise_uncaught_exception
    raise exc
  File "C:\Users\ASHISH KUMAR\AppData\Local\Packages\PythonSoftwareFoundation.Python.3.11_qbz5n2kfra8p0\LocalCache\local-packages\Python311\site-packages\rest_framework\views.py", line 506, in dispatch
    response = handler(request, *args, **kwargs)
               ^^^^^^^^^^^^^^^^^^^^^^^^^^^^^^^^^
  File "C:\Users\ASHISH KUMAR\AppData\Local\Packages\PythonSoftwareFoundation.Python.3.11_qbz5n2kfra8p0\LocalCache\local-packages\Python311\site-packages\rest_framework\mixins.py", line 56, in retrieve
    return Response(serializer.data)
                    ^^^^^^^^^^^^^^^
  File "C:\Users\ASHISH KUMAR\AppData\Local\Packages\PythonSoftwareFoundation.Python.3.11_qbz5n2kfra8p0\LocalCache\local-packages\Python311\site-packages\rest_framework\serializers.py", line 555, in data
    ret = super().data
          ^^^^^^^^^^^^
  File "C:\Users\ASHISH KUMAR\AppData\Local\Packages\PythonSoftwareFoundation.Python.3.11_qbz5n2kfra8p0\LocalCache\local-packages\Python311\site-packages\rest_framework\serializers.py", line 253, in data
    self._data = self.to_representation(self.instance)
                 ^^^^^^^^^^^^^^^^^^^^^^^^^^^^^^^^^^^^^
  File "C:\Users\ASHISH KUMAR\AppData\Local\Packages\PythonSoftwareFoundation.Python.3.11_qbz5n2kfra8p0\LocalCache\local-packages\Python311\site-packages\rest_framework\serializers.py", line 522, in to_representation
    ret[field.field_name] = field.to_representation(attribute)
                            ^^^^^^^^^^^^^^^^^^^^^^^^^^^^^^^^^^
  File "C:\Users\ASHISH KUMAR\AppData\Local\Packages\PythonSoftwareFoundation.Python.3.11_qbz5n2kfra8p0\LocalCache\local-packages\Python311\site-packages\rest_framework\serializers.py", line 507, in to_representation
    for field in fields:
  File "C:\Users\ASHISH KUMAR\AppData\Local\Packages\PythonSoftwareFoundation.Python.3.11_qbz5n2kfra8p0\LocalCache\local-packages\Python311\site-packages\rest_framework\serializers.py", line 368, in _readable_fields
    for field in self.fields.values():
                 ^^^^^^^^^^^
  File "C:\Users\ASHISH KUMAR\AppData\Local\Packages\PythonSoftwareFoundation.Python.3.11_qbz5n2kfra8p0\LocalCache\local-packages\Python311\site-packages\django\utils\functional.py", line 57, in __get__
    res = instance.__dict__[self.name] = self.func(instance)
                                         ^^^^^^^^^^^^^^^^^^^
  File "C:\Users\ASHISH KUMAR\AppData\Local\Packages\PythonSoftwareFoundation.Python.3.11_qbz5n2kfra8p0\LocalCache\local-packages\Python311\site-packages\rest_framework\serializers.py", line 356, in fields
    for key, value in self.get_fields().items():
                      ^^^^^^^^^^^^^^^^^
  File "C:\Users\ASHISH KUMAR\AppData\Local\Packages\PythonSoftwareFoundation.Python.3.11_qbz5n2kfra8p0\LocalCache\local-packages\Python311\site-packages\rest_framework\serializers.py", line 1076, in get_fields
    field_class, field_kwargs = self.build_field(
                                ^^^^^^^^^^^^^^^^^
  File "C:\Users\ASHISH KUMAR\AppData\Local\Packages\PythonSoftwareFoundation.Python.3.11_qbz5n2kfra8p0\LocalCache\local-packages\Python311\site-packages\rest_framework\serializers.py", line 1222, in build_field
    return self.build_unknown_field(field_name, model_class)
           ^^^^^^^^^^^^^^^^^^^^^^^^^^^^^^^^^^^^^^^^^^^^^^^^^
  File "C:\Users\ASHISH KUMAR\AppData\Local\Packages\PythonSoftwareFoundation.Python.3.11_qbz5n2kfra8p0\LocalCache\local-packages\Python311\site-packages\rest_framework\serializers.py", line 1340, in build_unknown_field
    raise ImproperlyConfigured(
django.core.exceptions.ImproperlyConfigured: Field name `location` is not valid for model `UserProfile`.
ERROR 2025-09-09 01:07:56,370 log 24344 32772 Internal Server Error: /api/v1/challenges/challenges/
Traceback (most recent call last):
  File "C:\Users\ASHISH KUMAR\AppData\Local\Packages\PythonSoftwareFoundation.Python.3.11_qbz5n2kfra8p0\LocalCache\local-packages\Python311\site-packages\django\core\handlers\exception.py", line 55, in inner
    response = get_response(request)
               ^^^^^^^^^^^^^^^^^^^^^
  File "C:\Users\ASHISH KUMAR\AppData\Local\Packages\PythonSoftwareFoundation.Python.3.11_qbz5n2kfra8p0\LocalCache\local-packages\Python311\site-packages\django\core\handlers\base.py", line 197, in _get_response
    response = wrapped_callback(request, *callback_args, **callback_kwargs)
               ^^^^^^^^^^^^^^^^^^^^^^^^^^^^^^^^^^^^^^^^^^^^^^^^^^^^^^^^^^^^
  File "C:\Users\ASHISH KUMAR\AppData\Local\Packages\PythonSoftwareFoundation.Python.3.11_qbz5n2kfra8p0\LocalCache\local-packages\Python311\site-packages\django\views\decorators\csrf.py", line 56, in wrapper_view
    return view_func(*args, **kwargs)
           ^^^^^^^^^^^^^^^^^^^^^^^^^^
  File "C:\Users\ASHISH KUMAR\AppData\Local\Packages\PythonSoftwareFoundation.Python.3.11_qbz5n2kfra8p0\LocalCache\local-packages\Python311\site-packages\rest_framework\viewsets.py", line 125, in view
    return self.dispatch(request, *args, **kwargs)
           ^^^^^^^^^^^^^^^^^^^^^^^^^^^^^^^^^^^^^^^
  File "C:\Users\ASHISH KUMAR\AppData\Local\Packages\PythonSoftwareFoundation.Python.3.11_qbz5n2kfra8p0\LocalCache\local-packages\Python311\site-packages\rest_framework\views.py", line 509, in dispatch
    response = self.handle_exception(exc)
               ^^^^^^^^^^^^^^^^^^^^^^^^^^
  File "C:\Users\ASHISH KUMAR\AppData\Local\Packages\PythonSoftwareFoundation.Python.3.11_qbz5n2kfra8p0\LocalCache\local-packages\Python311\site-packages\rest_framework\views.py", line 469, in handle_exception
    self.raise_uncaught_exception(exc)
  File "C:\Users\ASHISH KUMAR\AppData\Local\Packages\PythonSoftwareFoundation.Python.3.11_qbz5n2kfra8p0\LocalCache\local-packages\Python311\site-packages\rest_framework\views.py", line 480, in raise_uncaught_exception
    raise exc
  File "C:\Users\ASHISH KUMAR\AppData\Local\Packages\PythonSoftwareFoundation.Python.3.11_qbz5n2kfra8p0\LocalCache\local-packages\Python311\site-packages\rest_framework\views.py", line 506, in dispatch
    response = handler(request, *args, **kwargs)
               ^^^^^^^^^^^^^^^^^^^^^^^^^^^^^^^^^
  File "C:\Users\ASHISH KUMAR\AppData\Local\Packages\PythonSoftwareFoundation.Python.3.11_qbz5n2kfra8p0\LocalCache\local-packages\Python311\site-packages\rest_framework\mixins.py", line 43, in list
    return self.get_paginated_response(serializer.data)
                                       ^^^^^^^^^^^^^^^
  File "C:\Users\ASHISH KUMAR\AppData\Local\Packages\PythonSoftwareFoundation.Python.3.11_qbz5n2kfra8p0\LocalCache\local-packages\Python311\site-packages\rest_framework\serializers.py", line 768, in data
    ret = super().data
          ^^^^^^^^^^^^
  File "C:\Users\ASHISH KUMAR\AppData\Local\Packages\PythonSoftwareFoundation.Python.3.11_qbz5n2kfra8p0\LocalCache\local-packages\Python311\site-packages\rest_framework\serializers.py", line 253, in data
    self._data = self.to_representation(self.instance)
                 ^^^^^^^^^^^^^^^^^^^^^^^^^^^^^^^^^^^^^
  File "C:\Users\ASHISH KUMAR\AppData\Local\Packages\PythonSoftwareFoundation.Python.3.11_qbz5n2kfra8p0\LocalCache\local-packages\Python311\site-packages\rest_framework\serializers.py", line 686, in to_representation
    return [
           ^
  File "C:\Users\ASHISH KUMAR\AppData\Local\Packages\PythonSoftwareFoundation.Python.3.11_qbz5n2kfra8p0\LocalCache\local-packages\Python311\site-packages\rest_framework\serializers.py", line 687, in <listcomp>
    self.child.to_representation(item) for item in iterable
    ^^^^^^^^^^^^^^^^^^^^^^^^^^^^^^^^^^
  File "C:\Users\ASHISH KUMAR\AppData\Local\Packages\PythonSoftwareFoundation.Python.3.11_qbz5n2kfra8p0\LocalCache\local-packages\Python311\site-packages\rest_framework\serializers.py", line 522, in to_representation
    ret[field.field_name] = field.to_representation(attribute)
                            ^^^^^^^^^^^^^^^^^^^^^^^^^^^^^^^^^^
  File "C:\Users\ASHISH KUMAR\AppData\Local\Packages\PythonSoftwareFoundation.Python.3.11_qbz5n2kfra8p0\LocalCache\local-packages\Python311\site-packages\rest_framework\serializers.py", line 507, in to_representation
    for field in fields:
  File "C:\Users\ASHISH KUMAR\AppData\Local\Packages\PythonSoftwareFoundation.Python.3.11_qbz5n2kfra8p0\LocalCache\local-packages\Python311\site-packages\rest_framework\serializers.py", line 368, in _readable_fields
    for field in self.fields.values():
                 ^^^^^^^^^^^
  File "C:\Users\ASHISH KUMAR\AppData\Local\Packages\PythonSoftwareFoundation.Python.3.11_qbz5n2kfra8p0\LocalCache\local-packages\Python311\site-packages\django\utils\functional.py", line 57, in __get__
    res = instance.__dict__[self.name] = self.func(instance)
                                         ^^^^^^^^^^^^^^^^^^^
  File "C:\Users\ASHISH KUMAR\AppData\Local\Packages\PythonSoftwareFoundation.Python.3.11_qbz5n2kfra8p0\LocalCache\local-packages\Python311\site-packages\rest_framework\serializers.py", line 356, in fields
    for key, value in self.get_fields().items():
                      ^^^^^^^^^^^^^^^^^
  File "C:\Users\ASHISH KUMAR\AppData\Local\Packages\PythonSoftwareFoundation.Python.3.11_qbz5n2kfra8p0\LocalCache\local-packages\Python311\site-packages\rest_framework\serializers.py", line 1076, in get_fields
    field_class, field_kwargs = self.build_field(
                                ^^^^^^^^^^^^^^^^^
  File "C:\Users\ASHISH KUMAR\AppData\Local\Packages\PythonSoftwareFoundation.Python.3.11_qbz5n2kfra8p0\LocalCache\local-packages\Python311\site-packages\rest_framework\serializers.py", line 1222, in build_field
    return self.build_unknown_field(field_name, model_class)
           ^^^^^^^^^^^^^^^^^^^^^^^^^^^^^^^^^^^^^^^^^^^^^^^^^
  File "C:\Users\ASHISH KUMAR\AppData\Local\Packages\PythonSoftwareFoundation.Python.3.11_qbz5n2kfra8p0\LocalCache\local-packages\Python311\site-packages\rest_framework\serializers.py", line 1340, in build_unknown_field
    raise ImproperlyConfigured(
django.core.exceptions.ImproperlyConfigured: Field name `location` is not valid for model `UserProfile`.
WARNING 2025-09-09 01:08:00,992 log 24344 32772 Unauthorized: /api/v1/challenges/submissions/
WARNING 2025-09-09 01:08:02,776 log 24344 32772 Unauthorized: /api/v1/content/lessons/
WARNING 2025-09-09 01:08:10,189 log 24344 32772 Unauthorized: /api/v1/gamification/badges/
WARNING 2025-09-09 01:08:15,362 log 24344 32772 Unauthorized: /api/v1/gamification/point-transactions/
WARNING 2025-09-09 01:08:18,654 log 24344 32772 Unauthorized: /api/v1/auth/users/
WARNING 2025-09-09 01:09:01,677 log 24212 2464 Unauthorized: /api/v1/challenges/challenges/
ERROR 2025-09-09 01:09:02,277 log 24212 2464 Internal Server Error: /api/v1/challenges/challenges/1/
Traceback (most recent call last):
  File "C:\Users\ASHISH KUMAR\AppData\Local\Packages\PythonSoftwareFoundation.Python.3.11_qbz5n2kfra8p0\LocalCache\local-packages\Python311\site-packages\django\core\handlers\exception.py", line 55, in inner
    response = get_response(request)
               ^^^^^^^^^^^^^^^^^^^^^
  File "C:\Users\ASHISH KUMAR\AppData\Local\Packages\PythonSoftwareFoundation.Python.3.11_qbz5n2kfra8p0\LocalCache\local-packages\Python311\site-packages\django\core\handlers\base.py", line 197, in _get_response
    response = wrapped_callback(request, *callback_args, **callback_kwargs)
               ^^^^^^^^^^^^^^^^^^^^^^^^^^^^^^^^^^^^^^^^^^^^^^^^^^^^^^^^^^^^
  File "C:\Users\ASHISH KUMAR\AppData\Local\Packages\PythonSoftwareFoundation.Python.3.11_qbz5n2kfra8p0\LocalCache\local-packages\Python311\site-packages\django\views\decorators\csrf.py", line 56, in wrapper_view
    return view_func(*args, **kwargs)
           ^^^^^^^^^^^^^^^^^^^^^^^^^^
  File "C:\Users\ASHISH KUMAR\AppData\Local\Packages\PythonSoftwareFoundation.Python.3.11_qbz5n2kfra8p0\LocalCache\local-packages\Python311\site-packages\rest_framework\viewsets.py", line 125, in view
    return self.dispatch(request, *args, **kwargs)
           ^^^^^^^^^^^^^^^^^^^^^^^^^^^^^^^^^^^^^^^
  File "C:\Users\ASHISH KUMAR\AppData\Local\Packages\PythonSoftwareFoundation.Python.3.11_qbz5n2kfra8p0\LocalCache\local-packages\Python311\site-packages\rest_framework\views.py", line 509, in dispatch
    response = self.handle_exception(exc)
               ^^^^^^^^^^^^^^^^^^^^^^^^^^
  File "C:\Users\ASHISH KUMAR\AppData\Local\Packages\PythonSoftwareFoundation.Python.3.11_qbz5n2kfra8p0\LocalCache\local-packages\Python311\site-packages\rest_framework\views.py", line 469, in handle_exception
    self.raise_uncaught_exception(exc)
  File "C:\Users\ASHISH KUMAR\AppData\Local\Packages\PythonSoftwareFoundation.Python.3.11_qbz5n2kfra8p0\LocalCache\local-packages\Python311\site-packages\rest_framework\views.py", line 480, in raise_uncaught_exception
    raise exc
  File "C:\Users\ASHISH KUMAR\AppData\Local\Packages\PythonSoftwareFoundation.Python.3.11_qbz5n2kfra8p0\LocalCache\local-packages\Python311\site-packages\rest_framework\views.py", line 506, in dispatch
    response = handler(request, *args, **kwargs)
               ^^^^^^^^^^^^^^^^^^^^^^^^^^^^^^^^^
  File "C:\Users\ASHISH KUMAR\AppData\Local\Packages\PythonSoftwareFoundation.Python.3.11_qbz5n2kfra8p0\LocalCache\local-packages\Python311\site-packages\rest_framework\mixins.py", line 56, in retrieve
    return Response(serializer.data)
                    ^^^^^^^^^^^^^^^
  File "C:\Users\ASHISH KUMAR\AppData\Local\Packages\PythonSoftwareFoundation.Python.3.11_qbz5n2kfra8p0\LocalCache\local-packages\Python311\site-packages\rest_framework\serializers.py", line 555, in data
    ret = super().data
          ^^^^^^^^^^^^
  File "C:\Users\ASHISH KUMAR\AppData\Local\Packages\PythonSoftwareFoundation.Python.3.11_qbz5n2kfra8p0\LocalCache\local-packages\Python311\site-packages\rest_framework\serializers.py", line 253, in data
    self._data = self.to_representation(self.instance)
                 ^^^^^^^^^^^^^^^^^^^^^^^^^^^^^^^^^^^^^
  File "C:\Users\ASHISH KUMAR\AppData\Local\Packages\PythonSoftwareFoundation.Python.3.11_qbz5n2kfra8p0\LocalCache\local-packages\Python311\site-packages\rest_framework\serializers.py", line 522, in to_representation
    ret[field.field_name] = field.to_representation(attribute)
                            ^^^^^^^^^^^^^^^^^^^^^^^^^^^^^^^^^^
  File "C:\Users\ASHISH KUMAR\AppData\Local\Packages\PythonSoftwareFoundation.Python.3.11_qbz5n2kfra8p0\LocalCache\local-packages\Python311\site-packages\rest_framework\serializers.py", line 507, in to_representation
    for field in fields:
  File "C:\Users\ASHISH KUMAR\AppData\Local\Packages\PythonSoftwareFoundation.Python.3.11_qbz5n2kfra8p0\LocalCache\local-packages\Python311\site-packages\rest_framework\serializers.py", line 368, in _readable_fields
    for field in self.fields.values():
                 ^^^^^^^^^^^
  File "C:\Users\ASHISH KUMAR\AppData\Local\Packages\PythonSoftwareFoundation.Python.3.11_qbz5n2kfra8p0\LocalCache\local-packages\Python311\site-packages\django\utils\functional.py", line 57, in __get__
    res = instance.__dict__[self.name] = self.func(instance)
                                         ^^^^^^^^^^^^^^^^^^^
  File "C:\Users\ASHISH KUMAR\AppData\Local\Packages\PythonSoftwareFoundation.Python.3.11_qbz5n2kfra8p0\LocalCache\local-packages\Python311\site-packages\rest_framework\serializers.py", line 356, in fields
    for key, value in self.get_fields().items():
                      ^^^^^^^^^^^^^^^^^
  File "C:\Users\ASHISH KUMAR\AppData\Local\Packages\PythonSoftwareFoundation.Python.3.11_qbz5n2kfra8p0\LocalCache\local-packages\Python311\site-packages\rest_framework\serializers.py", line 1076, in get_fields
    field_class, field_kwargs = self.build_field(
                                ^^^^^^^^^^^^^^^^^
  File "C:\Users\ASHISH KUMAR\AppData\Local\Packages\PythonSoftwareFoundation.Python.3.11_qbz5n2kfra8p0\LocalCache\local-packages\Python311\site-packages\rest_framework\serializers.py", line 1222, in build_field
    return self.build_unknown_field(field_name, model_class)
           ^^^^^^^^^^^^^^^^^^^^^^^^^^^^^^^^^^^^^^^^^^^^^^^^^
  File "C:\Users\ASHISH KUMAR\AppData\Local\Packages\PythonSoftwareFoundation.Python.3.11_qbz5n2kfra8p0\LocalCache\local-packages\Python311\site-packages\rest_framework\serializers.py", line 1340, in build_unknown_field
    raise ImproperlyConfigured(
django.core.exceptions.ImproperlyConfigured: Field name `date_joined` is not valid for model `UserProfile`.
ERROR 2025-09-09 01:09:02,792 log 24212 2464 Internal Server Error: /api/v1/challenges/challenges/
Traceback (most recent call last):
  File "C:\Users\ASHISH KUMAR\AppData\Local\Packages\PythonSoftwareFoundation.Python.3.11_qbz5n2kfra8p0\LocalCache\local-packages\Python311\site-packages\django\core\handlers\exception.py", line 55, in inner
    response = get_response(request)
               ^^^^^^^^^^^^^^^^^^^^^
  File "C:\Users\ASHISH KUMAR\AppData\Local\Packages\PythonSoftwareFoundation.Python.3.11_qbz5n2kfra8p0\LocalCache\local-packages\Python311\site-packages\django\core\handlers\base.py", line 197, in _get_response
    response = wrapped_callback(request, *callback_args, **callback_kwargs)
               ^^^^^^^^^^^^^^^^^^^^^^^^^^^^^^^^^^^^^^^^^^^^^^^^^^^^^^^^^^^^
  File "C:\Users\ASHISH KUMAR\AppData\Local\Packages\PythonSoftwareFoundation.Python.3.11_qbz5n2kfra8p0\LocalCache\local-packages\Python311\site-packages\django\views\decorators\csrf.py", line 56, in wrapper_view
    return view_func(*args, **kwargs)
           ^^^^^^^^^^^^^^^^^^^^^^^^^^
  File "C:\Users\ASHISH KUMAR\AppData\Local\Packages\PythonSoftwareFoundation.Python.3.11_qbz5n2kfra8p0\LocalCache\local-packages\Python311\site-packages\rest_framework\viewsets.py", line 125, in view
    return self.dispatch(request, *args, **kwargs)
           ^^^^^^^^^^^^^^^^^^^^^^^^^^^^^^^^^^^^^^^
  File "C:\Users\ASHISH KUMAR\AppData\Local\Packages\PythonSoftwareFoundation.Python.3.11_qbz5n2kfra8p0\LocalCache\local-packages\Python311\site-packages\rest_framework\views.py", line 509, in dispatch
    response = self.handle_exception(exc)
               ^^^^^^^^^^^^^^^^^^^^^^^^^^
  File "C:\Users\ASHISH KUMAR\AppData\Local\Packages\PythonSoftwareFoundation.Python.3.11_qbz5n2kfra8p0\LocalCache\local-packages\Python311\site-packages\rest_framework\views.py", line 469, in handle_exception
    self.raise_uncaught_exception(exc)
  File "C:\Users\ASHISH KUMAR\AppData\Local\Packages\PythonSoftwareFoundation.Python.3.11_qbz5n2kfra8p0\LocalCache\local-packages\Python311\site-packages\rest_framework\views.py", line 480, in raise_uncaught_exception
    raise exc
  File "C:\Users\ASHISH KUMAR\AppData\Local\Packages\PythonSoftwareFoundation.Python.3.11_qbz5n2kfra8p0\LocalCache\local-packages\Python311\site-packages\rest_framework\views.py", line 506, in dispatch
    response = handler(request, *args, **kwargs)
               ^^^^^^^^^^^^^^^^^^^^^^^^^^^^^^^^^
  File "C:\Users\ASHISH KUMAR\AppData\Local\Packages\PythonSoftwareFoundation.Python.3.11_qbz5n2kfra8p0\LocalCache\local-packages\Python311\site-packages\rest_framework\mixins.py", line 43, in list
    return self.get_paginated_response(serializer.data)
                                       ^^^^^^^^^^^^^^^
  File "C:\Users\ASHISH KUMAR\AppData\Local\Packages\PythonSoftwareFoundation.Python.3.11_qbz5n2kfra8p0\LocalCache\local-packages\Python311\site-packages\rest_framework\serializers.py", line 768, in data
    ret = super().data
          ^^^^^^^^^^^^
  File "C:\Users\ASHISH KUMAR\AppData\Local\Packages\PythonSoftwareFoundation.Python.3.11_qbz5n2kfra8p0\LocalCache\local-packages\Python311\site-packages\rest_framework\serializers.py", line 253, in data
    self._data = self.to_representation(self.instance)
                 ^^^^^^^^^^^^^^^^^^^^^^^^^^^^^^^^^^^^^
  File "C:\Users\ASHISH KUMAR\AppData\Local\Packages\PythonSoftwareFoundation.Python.3.11_qbz5n2kfra8p0\LocalCache\local-packages\Python311\site-packages\rest_framework\serializers.py", line 686, in to_representation
    return [
           ^
  File "C:\Users\ASHISH KUMAR\AppData\Local\Packages\PythonSoftwareFoundation.Python.3.11_qbz5n2kfra8p0\LocalCache\local-packages\Python311\site-packages\rest_framework\serializers.py", line 687, in <listcomp>
    self.child.to_representation(item) for item in iterable
    ^^^^^^^^^^^^^^^^^^^^^^^^^^^^^^^^^^
  File "C:\Users\ASHISH KUMAR\AppData\Local\Packages\PythonSoftwareFoundation.Python.3.11_qbz5n2kfra8p0\LocalCache\local-packages\Python311\site-packages\rest_framework\serializers.py", line 522, in to_representation
    ret[field.field_name] = field.to_representation(attribute)
                            ^^^^^^^^^^^^^^^^^^^^^^^^^^^^^^^^^^
  File "C:\Users\ASHISH KUMAR\AppData\Local\Packages\PythonSoftwareFoundation.Python.3.11_qbz5n2kfra8p0\LocalCache\local-packages\Python311\site-packages\rest_framework\serializers.py", line 507, in to_representation
    for field in fields:
  File "C:\Users\ASHISH KUMAR\AppData\Local\Packages\PythonSoftwareFoundation.Python.3.11_qbz5n2kfra8p0\LocalCache\local-packages\Python311\site-packages\rest_framework\serializers.py", line 368, in _readable_fields
    for field in self.fields.values():
                 ^^^^^^^^^^^
  File "C:\Users\ASHISH KUMAR\AppData\Local\Packages\PythonSoftwareFoundation.Python.3.11_qbz5n2kfra8p0\LocalCache\local-packages\Python311\site-packages\django\utils\functional.py", line 57, in __get__
    res = instance.__dict__[self.name] = self.func(instance)
                                         ^^^^^^^^^^^^^^^^^^^
  File "C:\Users\ASHISH KUMAR\AppData\Local\Packages\PythonSoftwareFoundation.Python.3.11_qbz5n2kfra8p0\LocalCache\local-packages\Python311\site-packages\rest_framework\serializers.py", line 356, in fields
    for key, value in self.get_fields().items():
                      ^^^^^^^^^^^^^^^^^
  File "C:\Users\ASHISH KUMAR\AppData\Local\Packages\PythonSoftwareFoundation.Python.3.11_qbz5n2kfra8p0\LocalCache\local-packages\Python311\site-packages\rest_framework\serializers.py", line 1076, in get_fields
    field_class, field_kwargs = self.build_field(
                                ^^^^^^^^^^^^^^^^^
  File "C:\Users\ASHISH KUMAR\AppData\Local\Packages\PythonSoftwareFoundation.Python.3.11_qbz5n2kfra8p0\LocalCache\local-packages\Python311\site-packages\rest_framework\serializers.py", line 1222, in build_field
    return self.build_unknown_field(field_name, model_class)
           ^^^^^^^^^^^^^^^^^^^^^^^^^^^^^^^^^^^^^^^^^^^^^^^^^
  File "C:\Users\ASHISH KUMAR\AppData\Local\Packages\PythonSoftwareFoundation.Python.3.11_qbz5n2kfra8p0\LocalCache\local-packages\Python311\site-packages\rest_framework\serializers.py", line 1340, in build_unknown_field
    raise ImproperlyConfigured(
django.core.exceptions.ImproperlyConfigured: Field name `date_joined` is not valid for model `UserProfile`.
WARNING 2025-09-09 01:09:07,404 log 24212 2464 Unauthorized: /api/v1/challenges/submissions/
WARNING 2025-09-09 01:09:08,857 log 24212 2464 Unauthorized: /api/v1/content/lessons/
WARNING 2025-09-09 01:09:13,625 log 24212 2464 Unauthorized: /api/v1/gamification/badges/
WARNING 2025-09-09 01:09:16,540 log 24212 2464 Unauthorized: /api/v1/gamification/point-transactions/
WARNING 2025-09-09 01:09:18,653 log 24212 2464 Unauthorized: /api/v1/auth/users/
WARNING 2025-09-09 01:09:39,157 log 36268 32264 Unauthorized: /api/v1/challenges/challenges/
ERROR 2025-09-09 01:09:39,950 log 36268 32264 Internal Server Error: /api/v1/challenges/challenges/1/
Traceback (most recent call last):
  File "C:\Users\ASHISH KUMAR\AppData\Local\Packages\PythonSoftwareFoundation.Python.3.11_qbz5n2kfra8p0\LocalCache\local-packages\Python311\site-packages\django\core\handlers\exception.py", line 55, in inner
    response = get_response(request)
               ^^^^^^^^^^^^^^^^^^^^^
  File "C:\Users\ASHISH KUMAR\AppData\Local\Packages\PythonSoftwareFoundation.Python.3.11_qbz5n2kfra8p0\LocalCache\local-packages\Python311\site-packages\django\core\handlers\base.py", line 197, in _get_response
    response = wrapped_callback(request, *callback_args, **callback_kwargs)
               ^^^^^^^^^^^^^^^^^^^^^^^^^^^^^^^^^^^^^^^^^^^^^^^^^^^^^^^^^^^^
  File "C:\Users\ASHISH KUMAR\AppData\Local\Packages\PythonSoftwareFoundation.Python.3.11_qbz5n2kfra8p0\LocalCache\local-packages\Python311\site-packages\django\views\decorators\csrf.py", line 56, in wrapper_view
    return view_func(*args, **kwargs)
           ^^^^^^^^^^^^^^^^^^^^^^^^^^
  File "C:\Users\ASHISH KUMAR\AppData\Local\Packages\PythonSoftwareFoundation.Python.3.11_qbz5n2kfra8p0\LocalCache\local-packages\Python311\site-packages\rest_framework\viewsets.py", line 125, in view
    return self.dispatch(request, *args, **kwargs)
           ^^^^^^^^^^^^^^^^^^^^^^^^^^^^^^^^^^^^^^^
  File "C:\Users\ASHISH KUMAR\AppData\Local\Packages\PythonSoftwareFoundation.Python.3.11_qbz5n2kfra8p0\LocalCache\local-packages\Python311\site-packages\rest_framework\views.py", line 509, in dispatch
    response = self.handle_exception(exc)
               ^^^^^^^^^^^^^^^^^^^^^^^^^^
  File "C:\Users\ASHISH KUMAR\AppData\Local\Packages\PythonSoftwareFoundation.Python.3.11_qbz5n2kfra8p0\LocalCache\local-packages\Python311\site-packages\rest_framework\views.py", line 469, in handle_exception
    self.raise_uncaught_exception(exc)
  File "C:\Users\ASHISH KUMAR\AppData\Local\Packages\PythonSoftwareFoundation.Python.3.11_qbz5n2kfra8p0\LocalCache\local-packages\Python311\site-packages\rest_framework\views.py", line 480, in raise_uncaught_exception
    raise exc
  File "C:\Users\ASHISH KUMAR\AppData\Local\Packages\PythonSoftwareFoundation.Python.3.11_qbz5n2kfra8p0\LocalCache\local-packages\Python311\site-packages\rest_framework\views.py", line 506, in dispatch
    response = handler(request, *args, **kwargs)
               ^^^^^^^^^^^^^^^^^^^^^^^^^^^^^^^^^
  File "C:\Users\ASHISH KUMAR\AppData\Local\Packages\PythonSoftwareFoundation.Python.3.11_qbz5n2kfra8p0\LocalCache\local-packages\Python311\site-packages\rest_framework\mixins.py", line 56, in retrieve
    return Response(serializer.data)
                    ^^^^^^^^^^^^^^^
  File "C:\Users\ASHISH KUMAR\AppData\Local\Packages\PythonSoftwareFoundation.Python.3.11_qbz5n2kfra8p0\LocalCache\local-packages\Python311\site-packages\rest_framework\serializers.py", line 555, in data
    ret = super().data
          ^^^^^^^^^^^^
  File "C:\Users\ASHISH KUMAR\AppData\Local\Packages\PythonSoftwareFoundation.Python.3.11_qbz5n2kfra8p0\LocalCache\local-packages\Python311\site-packages\rest_framework\serializers.py", line 253, in data
    self._data = self.to_representation(self.instance)
                 ^^^^^^^^^^^^^^^^^^^^^^^^^^^^^^^^^^^^^
  File "C:\Users\ASHISH KUMAR\AppData\Local\Packages\PythonSoftwareFoundation.Python.3.11_qbz5n2kfra8p0\LocalCache\local-packages\Python311\site-packages\rest_framework\serializers.py", line 522, in to_representation
    ret[field.field_name] = field.to_representation(attribute)
                            ^^^^^^^^^^^^^^^^^^^^^^^^^^^^^^^^^^
  File "C:\Users\ASHISH KUMAR\AppData\Local\Packages\PythonSoftwareFoundation.Python.3.11_qbz5n2kfra8p0\LocalCache\local-packages\Python311\site-packages\rest_framework\serializers.py", line 522, in to_representation
    ret[field.field_name] = field.to_representation(attribute)
                            ^^^^^^^^^^^^^^^^^^^^^^^^^^^^^^^^^^
  File "C:\Users\ASHISH KUMAR\AppData\Local\Packages\PythonSoftwareFoundation.Python.3.11_qbz5n2kfra8p0\LocalCache\local-packages\Python311\site-packages\rest_framework\fields.py", line 1838, in to_representation
    return method(value)
           ^^^^^^^^^^^^^
  File "C:\Users\ASHISH KUMAR\OneDrive\Documents\Desktop\KJSCE\kj stuff\trae\backend\apps\users\serializers.py", line 238, in get_avatar_url
    if obj.avatar:
       ^^^^^^^^^^
AttributeError: 'User' object has no attribute 'avatar'
ERROR 2025-09-09 01:09:40,773 log 36268 32264 Internal Server Error: /api/v1/challenges/challenges/
Traceback (most recent call last):
  File "C:\Users\ASHISH KUMAR\AppData\Local\Packages\PythonSoftwareFoundation.Python.3.11_qbz5n2kfra8p0\LocalCache\local-packages\Python311\site-packages\django\core\handlers\exception.py", line 55, in inner
    response = get_response(request)
               ^^^^^^^^^^^^^^^^^^^^^
  File "C:\Users\ASHISH KUMAR\AppData\Local\Packages\PythonSoftwareFoundation.Python.3.11_qbz5n2kfra8p0\LocalCache\local-packages\Python311\site-packages\django\core\handlers\base.py", line 197, in _get_response
    response = wrapped_callback(request, *callback_args, **callback_kwargs)
               ^^^^^^^^^^^^^^^^^^^^^^^^^^^^^^^^^^^^^^^^^^^^^^^^^^^^^^^^^^^^
  File "C:\Users\ASHISH KUMAR\AppData\Local\Packages\PythonSoftwareFoundation.Python.3.11_qbz5n2kfra8p0\LocalCache\local-packages\Python311\site-packages\django\views\decorators\csrf.py", line 56, in wrapper_view
    return view_func(*args, **kwargs)
           ^^^^^^^^^^^^^^^^^^^^^^^^^^
  File "C:\Users\ASHISH KUMAR\AppData\Local\Packages\PythonSoftwareFoundation.Python.3.11_qbz5n2kfra8p0\LocalCache\local-packages\Python311\site-packages\rest_framework\viewsets.py", line 125, in view
    return self.dispatch(request, *args, **kwargs)
           ^^^^^^^^^^^^^^^^^^^^^^^^^^^^^^^^^^^^^^^
  File "C:\Users\ASHISH KUMAR\AppData\Local\Packages\PythonSoftwareFoundation.Python.3.11_qbz5n2kfra8p0\LocalCache\local-packages\Python311\site-packages\rest_framework\views.py", line 509, in dispatch
    response = self.handle_exception(exc)
               ^^^^^^^^^^^^^^^^^^^^^^^^^^
  File "C:\Users\ASHISH KUMAR\AppData\Local\Packages\PythonSoftwareFoundation.Python.3.11_qbz5n2kfra8p0\LocalCache\local-packages\Python311\site-packages\rest_framework\views.py", line 469, in handle_exception
    self.raise_uncaught_exception(exc)
  File "C:\Users\ASHISH KUMAR\AppData\Local\Packages\PythonSoftwareFoundation.Python.3.11_qbz5n2kfra8p0\LocalCache\local-packages\Python311\site-packages\rest_framework\views.py", line 480, in raise_uncaught_exception
    raise exc
  File "C:\Users\ASHISH KUMAR\AppData\Local\Packages\PythonSoftwareFoundation.Python.3.11_qbz5n2kfra8p0\LocalCache\local-packages\Python311\site-packages\rest_framework\views.py", line 506, in dispatch
    response = handler(request, *args, **kwargs)
               ^^^^^^^^^^^^^^^^^^^^^^^^^^^^^^^^^
  File "C:\Users\ASHISH KUMAR\AppData\Local\Packages\PythonSoftwareFoundation.Python.3.11_qbz5n2kfra8p0\LocalCache\local-packages\Python311\site-packages\rest_framework\mixins.py", line 43, in list
    return self.get_paginated_response(serializer.data)
                                       ^^^^^^^^^^^^^^^
  File "C:\Users\ASHISH KUMAR\AppData\Local\Packages\PythonSoftwareFoundation.Python.3.11_qbz5n2kfra8p0\LocalCache\local-packages\Python311\site-packages\rest_framework\serializers.py", line 768, in data
    ret = super().data
          ^^^^^^^^^^^^
  File "C:\Users\ASHISH KUMAR\AppData\Local\Packages\PythonSoftwareFoundation.Python.3.11_qbz5n2kfra8p0\LocalCache\local-packages\Python311\site-packages\rest_framework\serializers.py", line 253, in data
    self._data = self.to_representation(self.instance)
                 ^^^^^^^^^^^^^^^^^^^^^^^^^^^^^^^^^^^^^
  File "C:\Users\ASHISH KUMAR\AppData\Local\Packages\PythonSoftwareFoundation.Python.3.11_qbz5n2kfra8p0\LocalCache\local-packages\Python311\site-packages\rest_framework\serializers.py", line 686, in to_representation
    return [
           ^
  File "C:\Users\ASHISH KUMAR\AppData\Local\Packages\PythonSoftwareFoundation.Python.3.11_qbz5n2kfra8p0\LocalCache\local-packages\Python311\site-packages\rest_framework\serializers.py", line 687, in <listcomp>
    self.child.to_representation(item) for item in iterable
    ^^^^^^^^^^^^^^^^^^^^^^^^^^^^^^^^^^
  File "C:\Users\ASHISH KUMAR\AppData\Local\Packages\PythonSoftwareFoundation.Python.3.11_qbz5n2kfra8p0\LocalCache\local-packages\Python311\site-packages\rest_framework\serializers.py", line 522, in to_representation
    ret[field.field_name] = field.to_representation(attribute)
                            ^^^^^^^^^^^^^^^^^^^^^^^^^^^^^^^^^^
  File "C:\Users\ASHISH KUMAR\AppData\Local\Packages\PythonSoftwareFoundation.Python.3.11_qbz5n2kfra8p0\LocalCache\local-packages\Python311\site-packages\rest_framework\serializers.py", line 522, in to_representation
    ret[field.field_name] = field.to_representation(attribute)
                            ^^^^^^^^^^^^^^^^^^^^^^^^^^^^^^^^^^
  File "C:\Users\ASHISH KUMAR\AppData\Local\Packages\PythonSoftwareFoundation.Python.3.11_qbz5n2kfra8p0\LocalCache\local-packages\Python311\site-packages\rest_framework\fields.py", line 1838, in to_representation
    return method(value)
           ^^^^^^^^^^^^^
  File "C:\Users\ASHISH KUMAR\OneDrive\Documents\Desktop\KJSCE\kj stuff\trae\backend\apps\users\serializers.py", line 238, in get_avatar_url
    if obj.avatar:
       ^^^^^^^^^^
AttributeError: 'User' object has no attribute 'avatar'
WARNING 2025-09-09 01:09:45,857 log 36268 32264 Unauthorized: /api/v1/challenges/submissions/
WARNING 2025-09-09 01:09:47,614 log 36268 32264 Unauthorized: /api/v1/content/lessons/
WARNING 2025-09-09 01:09:53,280 log 36268 32264 Unauthorized: /api/v1/gamification/badges/
WARNING 2025-09-09 01:09:57,040 log 36268 32264 Unauthorized: /api/v1/gamification/point-transactions/
WARNING 2025-09-09 01:10:00,037 log 36268 32264 Unauthorized: /api/v1/auth/users/
WARNING 2025-09-09 01:10:35,399 log 25112 3648 Unauthorized: /api/v1/challenges/challenges/
ERROR 2025-09-09 01:10:35,977 log 25112 3648 Internal Server Error: /api/v1/challenges/challenges/1/
Traceback (most recent call last):
  File "C:\Users\ASHISH KUMAR\AppData\Local\Packages\PythonSoftwareFoundation.Python.3.11_qbz5n2kfra8p0\LocalCache\local-packages\Python311\site-packages\django\core\handlers\exception.py", line 55, in inner
    response = get_response(request)
               ^^^^^^^^^^^^^^^^^^^^^
  File "C:\Users\ASHISH KUMAR\AppData\Local\Packages\PythonSoftwareFoundation.Python.3.11_qbz5n2kfra8p0\LocalCache\local-packages\Python311\site-packages\django\core\handlers\base.py", line 197, in _get_response
    response = wrapped_callback(request, *callback_args, **callback_kwargs)
               ^^^^^^^^^^^^^^^^^^^^^^^^^^^^^^^^^^^^^^^^^^^^^^^^^^^^^^^^^^^^
  File "C:\Users\ASHISH KUMAR\AppData\Local\Packages\PythonSoftwareFoundation.Python.3.11_qbz5n2kfra8p0\LocalCache\local-packages\Python311\site-packages\django\views\decorators\csrf.py", line 56, in wrapper_view
    return view_func(*args, **kwargs)
           ^^^^^^^^^^^^^^^^^^^^^^^^^^
  File "C:\Users\ASHISH KUMAR\AppData\Local\Packages\PythonSoftwareFoundation.Python.3.11_qbz5n2kfra8p0\LocalCache\local-packages\Python311\site-packages\rest_framework\viewsets.py", line 125, in view
    return self.dispatch(request, *args, **kwargs)
           ^^^^^^^^^^^^^^^^^^^^^^^^^^^^^^^^^^^^^^^
  File "C:\Users\ASHISH KUMAR\AppData\Local\Packages\PythonSoftwareFoundation.Python.3.11_qbz5n2kfra8p0\LocalCache\local-packages\Python311\site-packages\rest_framework\views.py", line 509, in dispatch
    response = self.handle_exception(exc)
               ^^^^^^^^^^^^^^^^^^^^^^^^^^
  File "C:\Users\ASHISH KUMAR\AppData\Local\Packages\PythonSoftwareFoundation.Python.3.11_qbz5n2kfra8p0\LocalCache\local-packages\Python311\site-packages\rest_framework\views.py", line 469, in handle_exception
    self.raise_uncaught_exception(exc)
  File "C:\Users\ASHISH KUMAR\AppData\Local\Packages\PythonSoftwareFoundation.Python.3.11_qbz5n2kfra8p0\LocalCache\local-packages\Python311\site-packages\rest_framework\views.py", line 480, in raise_uncaught_exception
    raise exc
  File "C:\Users\ASHISH KUMAR\AppData\Local\Packages\PythonSoftwareFoundation.Python.3.11_qbz5n2kfra8p0\LocalCache\local-packages\Python311\site-packages\rest_framework\views.py", line 506, in dispatch
    response = handler(request, *args, **kwargs)
               ^^^^^^^^^^^^^^^^^^^^^^^^^^^^^^^^^
  File "C:\Users\ASHISH KUMAR\AppData\Local\Packages\PythonSoftwareFoundation.Python.3.11_qbz5n2kfra8p0\LocalCache\local-packages\Python311\site-packages\rest_framework\mixins.py", line 56, in retrieve
    return Response(serializer.data)
                    ^^^^^^^^^^^^^^^
  File "C:\Users\ASHISH KUMAR\AppData\Local\Packages\PythonSoftwareFoundation.Python.3.11_qbz5n2kfra8p0\LocalCache\local-packages\Python311\site-packages\rest_framework\serializers.py", line 555, in data
    ret = super().data
          ^^^^^^^^^^^^
  File "C:\Users\ASHISH KUMAR\AppData\Local\Packages\PythonSoftwareFoundation.Python.3.11_qbz5n2kfra8p0\LocalCache\local-packages\Python311\site-packages\rest_framework\serializers.py", line 253, in data
    self._data = self.to_representation(self.instance)
                 ^^^^^^^^^^^^^^^^^^^^^^^^^^^^^^^^^^^^^
  File "C:\Users\ASHISH KUMAR\AppData\Local\Packages\PythonSoftwareFoundation.Python.3.11_qbz5n2kfra8p0\LocalCache\local-packages\Python311\site-packages\rest_framework\serializers.py", line 522, in to_representation
    ret[field.field_name] = field.to_representation(attribute)
                            ^^^^^^^^^^^^^^^^^^^^^^^^^^^^^^^^^^
  File "C:\Users\ASHISH KUMAR\AppData\Local\Packages\PythonSoftwareFoundation.Python.3.11_qbz5n2kfra8p0\LocalCache\local-packages\Python311\site-packages\rest_framework\serializers.py", line 522, in to_representation
    ret[field.field_name] = field.to_representation(attribute)
                            ^^^^^^^^^^^^^^^^^^^^^^^^^^^^^^^^^^
  File "C:\Users\ASHISH KUMAR\AppData\Local\Packages\PythonSoftwareFoundation.Python.3.11_qbz5n2kfra8p0\LocalCache\local-packages\Python311\site-packages\rest_framework\fields.py", line 1838, in to_representation
    return method(value)
           ^^^^^^^^^^^^^
  File "C:\Users\ASHISH KUMAR\OneDrive\Documents\Desktop\KJSCE\kj stuff\trae\backend\apps\users\serializers.py", line 238, in get_avatar_url
    if obj.avatar:
       ^^^^^^^^^^
AttributeError: 'User' object has no attribute 'avatar'
ERROR 2025-09-09 01:10:36,667 log 25112 3648 Internal Server Error: /api/v1/challenges/challenges/
Traceback (most recent call last):
  File "C:\Users\ASHISH KUMAR\AppData\Local\Packages\PythonSoftwareFoundation.Python.3.11_qbz5n2kfra8p0\LocalCache\local-packages\Python311\site-packages\django\core\handlers\exception.py", line 55, in inner
    response = get_response(request)
               ^^^^^^^^^^^^^^^^^^^^^
  File "C:\Users\ASHISH KUMAR\AppData\Local\Packages\PythonSoftwareFoundation.Python.3.11_qbz5n2kfra8p0\LocalCache\local-packages\Python311\site-packages\django\core\handlers\base.py", line 197, in _get_response
    response = wrapped_callback(request, *callback_args, **callback_kwargs)
               ^^^^^^^^^^^^^^^^^^^^^^^^^^^^^^^^^^^^^^^^^^^^^^^^^^^^^^^^^^^^
  File "C:\Users\ASHISH KUMAR\AppData\Local\Packages\PythonSoftwareFoundation.Python.3.11_qbz5n2kfra8p0\LocalCache\local-packages\Python311\site-packages\django\views\decorators\csrf.py", line 56, in wrapper_view
    return view_func(*args, **kwargs)
           ^^^^^^^^^^^^^^^^^^^^^^^^^^
  File "C:\Users\ASHISH KUMAR\AppData\Local\Packages\PythonSoftwareFoundation.Python.3.11_qbz5n2kfra8p0\LocalCache\local-packages\Python311\site-packages\rest_framework\viewsets.py", line 125, in view
    return self.dispatch(request, *args, **kwargs)
           ^^^^^^^^^^^^^^^^^^^^^^^^^^^^^^^^^^^^^^^
  File "C:\Users\ASHISH KUMAR\AppData\Local\Packages\PythonSoftwareFoundation.Python.3.11_qbz5n2kfra8p0\LocalCache\local-packages\Python311\site-packages\rest_framework\views.py", line 509, in dispatch
    response = self.handle_exception(exc)
               ^^^^^^^^^^^^^^^^^^^^^^^^^^
  File "C:\Users\ASHISH KUMAR\AppData\Local\Packages\PythonSoftwareFoundation.Python.3.11_qbz5n2kfra8p0\LocalCache\local-packages\Python311\site-packages\rest_framework\views.py", line 469, in handle_exception
    self.raise_uncaught_exception(exc)
  File "C:\Users\ASHISH KUMAR\AppData\Local\Packages\PythonSoftwareFoundation.Python.3.11_qbz5n2kfra8p0\LocalCache\local-packages\Python311\site-packages\rest_framework\views.py", line 480, in raise_uncaught_exception
    raise exc
  File "C:\Users\ASHISH KUMAR\AppData\Local\Packages\PythonSoftwareFoundation.Python.3.11_qbz5n2kfra8p0\LocalCache\local-packages\Python311\site-packages\rest_framework\views.py", line 506, in dispatch
    response = handler(request, *args, **kwargs)
               ^^^^^^^^^^^^^^^^^^^^^^^^^^^^^^^^^
  File "C:\Users\ASHISH KUMAR\AppData\Local\Packages\PythonSoftwareFoundation.Python.3.11_qbz5n2kfra8p0\LocalCache\local-packages\Python311\site-packages\rest_framework\mixins.py", line 43, in list
    return self.get_paginated_response(serializer.data)
                                       ^^^^^^^^^^^^^^^
  File "C:\Users\ASHISH KUMAR\AppData\Local\Packages\PythonSoftwareFoundation.Python.3.11_qbz5n2kfra8p0\LocalCache\local-packages\Python311\site-packages\rest_framework\serializers.py", line 768, in data
    ret = super().data
          ^^^^^^^^^^^^
  File "C:\Users\ASHISH KUMAR\AppData\Local\Packages\PythonSoftwareFoundation.Python.3.11_qbz5n2kfra8p0\LocalCache\local-packages\Python311\site-packages\rest_framework\serializers.py", line 253, in data
    self._data = self.to_representation(self.instance)
                 ^^^^^^^^^^^^^^^^^^^^^^^^^^^^^^^^^^^^^
  File "C:\Users\ASHISH KUMAR\AppData\Local\Packages\PythonSoftwareFoundation.Python.3.11_qbz5n2kfra8p0\LocalCache\local-packages\Python311\site-packages\rest_framework\serializers.py", line 686, in to_representation
    return [
           ^
  File "C:\Users\ASHISH KUMAR\AppData\Local\Packages\PythonSoftwareFoundation.Python.3.11_qbz5n2kfra8p0\LocalCache\local-packages\Python311\site-packages\rest_framework\serializers.py", line 687, in <listcomp>
    self.child.to_representation(item) for item in iterable
    ^^^^^^^^^^^^^^^^^^^^^^^^^^^^^^^^^^
  File "C:\Users\ASHISH KUMAR\AppData\Local\Packages\PythonSoftwareFoundation.Python.3.11_qbz5n2kfra8p0\LocalCache\local-packages\Python311\site-packages\rest_framework\serializers.py", line 522, in to_representation
    ret[field.field_name] = field.to_representation(attribute)
                            ^^^^^^^^^^^^^^^^^^^^^^^^^^^^^^^^^^
  File "C:\Users\ASHISH KUMAR\AppData\Local\Packages\PythonSoftwareFoundation.Python.3.11_qbz5n2kfra8p0\LocalCache\local-packages\Python311\site-packages\rest_framework\serializers.py", line 522, in to_representation
    ret[field.field_name] = field.to_representation(attribute)
                            ^^^^^^^^^^^^^^^^^^^^^^^^^^^^^^^^^^
  File "C:\Users\ASHISH KUMAR\AppData\Local\Packages\PythonSoftwareFoundation.Python.3.11_qbz5n2kfra8p0\LocalCache\local-packages\Python311\site-packages\rest_framework\fields.py", line 1838, in to_representation
    return method(value)
           ^^^^^^^^^^^^^
  File "C:\Users\ASHISH KUMAR\OneDrive\Documents\Desktop\KJSCE\kj stuff\trae\backend\apps\users\serializers.py", line 238, in get_avatar_url
    if obj.avatar:
       ^^^^^^^^^^
AttributeError: 'User' object has no attribute 'avatar'
WARNING 2025-09-09 01:10:42,138 log 25112 3648 Unauthorized: /api/v1/challenges/submissions/
WARNING 2025-09-09 01:10:44,065 log 25112 3648 Unauthorized: /api/v1/content/lessons/
WARNING 2025-09-09 01:10:48,974 log 25112 3648 Unauthorized: /api/v1/gamification/badges/
WARNING 2025-09-09 01:10:53,021 log 25112 3648 Unauthorized: /api/v1/gamification/point-transactions/
WARNING 2025-09-09 01:10:56,411 log 25112 3648 Unauthorized: /api/v1/auth/users/
WARNING 2025-09-09 01:12:29,085 log 40888 19140 Unauthorized: /api/v1/challenges/challenges/
WARNING 2025-09-09 01:12:34,756 log 40888 19140 Unauthorized: /api/v1/challenges/submissions/
WARNING 2025-09-09 01:12:36,537 log 40888 19140 Unauthorized: /api/v1/content/lessons/
WARNING 2025-09-09 01:12:41,449 log 40888 19140 Unauthorized: /api/v1/gamification/badges/
WARNING 2025-09-09 01:12:44,118 log 40888 19140 Unauthorized: /api/v1/gamification/point-transactions/
WARNING 2025-09-09 01:12:46,885 log 40888 19140 Unauthorized: /api/v1/auth/users/
INFO 2025-09-09 02:06:16,028 autoreload 40120 16328 Watching for file changes with StatReloader
WARNING 2025-09-09 02:06:23,846 log 40120 16148 Not Found: /
WARNING 2025-09-09 02:06:23,846 basehttp 40120 16148 "GET /?ide_webview_request_time=1757363783296 HTTP/1.1" 404 3194
WARNING 2025-09-09 02:06:23,961 log 40120 16148 Not Found: /@vite/client
WARNING 2025-09-09 02:06:23,962 basehttp 40120 16148 "GET /@vite/client HTTP/1.1" 404 3209
INFO 2025-09-09 02:14:42,338 basehttp 40120 26920 "OPTIONS /api/v1/auth/register/ HTTP/1.1" 200 0
WARNING 2025-09-09 02:14:42,410 log 40120 26920 Not Found: /api/v1/auth/register/
WARNING 2025-09-09 02:14:42,415 basehttp 40120 26920 "POST /api/v1/auth/register/ HTTP/1.1" 404 12158
INFO 2025-09-09 02:14:55,178 basehttp 40120 39500 "OPTIONS /api/v1/auth/login/ HTTP/1.1" 200 0
WARNING 2025-09-09 02:14:55,198 log 40120 39500 Not Found: /api/v1/auth/login/
WARNING 2025-09-09 02:14:55,198 basehttp 40120 39500 "POST /api/v1/auth/login/ HTTP/1.1" 404 12149
WARNING 2025-09-09 02:16:40,317 log 40120 34068 Not Found: /api/v1/auth/login/
WARNING 2025-09-09 02:16:40,323 basehttp 40120 34068 "POST /api/v1/auth/login/ HTTP/1.1" 404 12149
INFO 2025-09-09 02:17:02,239 basehttp 40120 6656 "OPTIONS /api/v1/users/ HTTP/1.1" 200 0
WARNING 2025-09-09 02:17:02,281 log 40120 6656 Not Found: /api/v1/users/
WARNING 2025-09-09 02:17:02,281 basehttp 40120 6656 "POST /api/v1/users/ HTTP/1.1" 404 3213
INFO 2025-09-09 02:20:06,094 autoreload 30368 22044 Watching for file changes with StatReloader
WARNING 2025-09-09 02:20:12,954 log 30368 38688 Not Found: /
WARNING 2025-09-09 02:20:12,954 basehttp 30368 38688 "GET /?ide_webview_request_time=1757363783296 HTTP/1.1" 404 3194
WARNING 2025-09-09 02:20:13,038 log 30368 38688 Not Found: /@vite/client
WARNING 2025-09-09 02:20:13,038 basehttp 30368 38688 "GET /@vite/client HTTP/1.1" 404 3209
INFO 2025-09-09 02:21:25,827 autoreload 30368 22044 C:\Users\ASHISH KUMAR\OneDrive\Documents\Desktop\KJSCE\kj stuff\trae\backend\apps\users\urls.py changed, reloading.
INFO 2025-09-09 02:21:27,981 autoreload 38768 27016 Watching for file changes with StatReloader
INFO 2025-09-09 02:21:34,361 autoreload 38768 27016 C:\Users\ASHISH KUMAR\OneDrive\Documents\Desktop\KJSCE\kj stuff\trae\backend\config\urls.py changed, reloading.
INFO 2025-09-09 02:21:35,647 autoreload 12804 26124 Watching for file changes with StatReloader
INFO 2025-09-09 02:21:40,826 autoreload 12804 26124 C:\Users\ASHISH KUMAR\OneDrive\Documents\Desktop\KJSCE\kj stuff\trae\backend\apps\users\urls.py changed, reloading.
INFO 2025-09-09 02:21:42,542 autoreload 40308 36492 Watching for file changes with StatReloader
WARNING 2025-09-09 02:22:11,447 log 40308 30892 Bad Request: /api/v1/users/
WARNING 2025-09-09 02:22:11,449 basehttp 40308 30892 "POST /api/v1/users/ HTTP/1.1" 400 48
INFO 2025-09-09 02:23:09,689 basehttp 40308 30892 "POST /api/v1/users/ HTTP/1.1" 201 84
ERROR 2025-09-09 02:23:17,289 log 40308 30892 Internal Server Error: /api/v1/auth/login/
Traceback (most recent call last):
  File "C:\Users\ASHISH KUMAR\AppData\Local\Packages\PythonSoftwareFoundation.Python.3.11_qbz5n2kfra8p0\LocalCache\local-packages\Python311\site-packages\django\db\backends\utils.py", line 89, in _execute
    return self.cursor.execute(sql, params)
           ^^^^^^^^^^^^^^^^^^^^^^^^^^^^^^^^
  File "C:\Users\ASHISH KUMAR\AppData\Local\Packages\PythonSoftwareFoundation.Python.3.11_qbz5n2kfra8p0\LocalCache\local-packages\Python311\site-packages\django\db\backends\sqlite3\base.py", line 328, in execute
    return super().execute(query, params)
           ^^^^^^^^^^^^^^^^^^^^^^^^^^^^^^
sqlite3.OperationalError: no such table: gamification_point_transaction

The above exception was the direct cause of the following exception:

Traceback (most recent call last):
  File "C:\Users\ASHISH KUMAR\AppData\Local\Packages\PythonSoftwareFoundation.Python.3.11_qbz5n2kfra8p0\LocalCache\local-packages\Python311\site-packages\django\core\handlers\exception.py", line 55, in inner
    response = get_response(request)
               ^^^^^^^^^^^^^^^^^^^^^
  File "C:\Users\ASHISH KUMAR\AppData\Local\Packages\PythonSoftwareFoundation.Python.3.11_qbz5n2kfra8p0\LocalCache\local-packages\Python311\site-packages\django\core\handlers\base.py", line 197, in _get_response
    response = wrapped_callback(request, *callback_args, **callback_kwargs)
               ^^^^^^^^^^^^^^^^^^^^^^^^^^^^^^^^^^^^^^^^^^^^^^^^^^^^^^^^^^^^
  File "C:\Users\ASHISH KUMAR\AppData\Local\Packages\PythonSoftwareFoundation.Python.3.11_qbz5n2kfra8p0\LocalCache\local-packages\Python311\site-packages\django\views\decorators\csrf.py", line 56, in wrapper_view
    return view_func(*args, **kwargs)
           ^^^^^^^^^^^^^^^^^^^^^^^^^^
  File "C:\Users\ASHISH KUMAR\AppData\Local\Packages\PythonSoftwareFoundation.Python.3.11_qbz5n2kfra8p0\LocalCache\local-packages\Python311\site-packages\django\views\generic\base.py", line 104, in view
    return self.dispatch(request, *args, **kwargs)
           ^^^^^^^^^^^^^^^^^^^^^^^^^^^^^^^^^^^^^^^
  File "C:\Users\ASHISH KUMAR\AppData\Local\Packages\PythonSoftwareFoundation.Python.3.11_qbz5n2kfra8p0\LocalCache\local-packages\Python311\site-packages\rest_framework\views.py", line 509, in dispatch
    response = self.handle_exception(exc)
               ^^^^^^^^^^^^^^^^^^^^^^^^^^
  File "C:\Users\ASHISH KUMAR\AppData\Local\Packages\PythonSoftwareFoundation.Python.3.11_qbz5n2kfra8p0\LocalCache\local-packages\Python311\site-packages\rest_framework\views.py", line 469, in handle_exception
    self.raise_uncaught_exception(exc)
  File "C:\Users\ASHISH KUMAR\AppData\Local\Packages\PythonSoftwareFoundation.Python.3.11_qbz5n2kfra8p0\LocalCache\local-packages\Python311\site-packages\rest_framework\views.py", line 480, in raise_uncaught_exception
    raise exc
  File "C:\Users\ASHISH KUMAR\AppData\Local\Packages\PythonSoftwareFoundation.Python.3.11_qbz5n2kfra8p0\LocalCache\local-packages\Python311\site-packages\rest_framework\views.py", line 506, in dispatch
    response = handler(request, *args, **kwargs)
               ^^^^^^^^^^^^^^^^^^^^^^^^^^^^^^^^^
  File "C:\Users\ASHISH KUMAR\AppData\Local\Packages\PythonSoftwareFoundation.Python.3.11_qbz5n2kfra8p0\LocalCache\local-packages\Python311\site-packages\rest_framework_simplejwt\views.py", line 44, in post
    serializer.is_valid(raise_exception=True)
  File "C:\Users\ASHISH KUMAR\AppData\Local\Packages\PythonSoftwareFoundation.Python.3.11_qbz5n2kfra8p0\LocalCache\local-packages\Python311\site-packages\rest_framework\serializers.py", line 227, in is_valid
    self._validated_data = self.run_validation(self.initial_data)
                           ^^^^^^^^^^^^^^^^^^^^^^^^^^^^^^^^^^^^^^
  File "C:\Users\ASHISH KUMAR\AppData\Local\Packages\PythonSoftwareFoundation.Python.3.11_qbz5n2kfra8p0\LocalCache\local-packages\Python311\site-packages\rest_framework\serializers.py", line 429, in run_validation
    value = self.validate(value)
            ^^^^^^^^^^^^^^^^^^^^
  File "C:\Users\ASHISH KUMAR\OneDrive\Documents\Desktop\KJSCE\kj stuff\trae\backend\apps\users\serializers.py", line 23, in validate
    data = super().validate(attrs)
           ^^^^^^^^^^^^^^^^^^^^^^^
  File "C:\Users\ASHISH KUMAR\AppData\Local\Packages\PythonSoftwareFoundation.Python.3.11_qbz5n2kfra8p0\LocalCache\local-packages\Python311\site-packages\rest_framework_simplejwt\serializers.py", line 81, in validate
    update_last_login(None, self.user)
  File "C:\Users\ASHISH KUMAR\AppData\Local\Packages\PythonSoftwareFoundation.Python.3.11_qbz5n2kfra8p0\LocalCache\local-packages\Python311\site-packages\django\contrib\auth\models.py", line 23, in update_last_login
    user.save(update_fields=["last_login"])
  File "C:\Users\ASHISH KUMAR\AppData\Local\Packages\PythonSoftwareFoundation.Python.3.11_qbz5n2kfra8p0\LocalCache\local-packages\Python311\site-packages\django\contrib\auth\base_user.py", line 76, in save
    super().save(*args, **kwargs)
  File "C:\Users\ASHISH KUMAR\AppData\Local\Packages\PythonSoftwareFoundation.Python.3.11_qbz5n2kfra8p0\LocalCache\local-packages\Python311\site-packages\django\db\models\base.py", line 814, in save
    self.save_base(
  File "C:\Users\ASHISH KUMAR\AppData\Local\Packages\PythonSoftwareFoundation.Python.3.11_qbz5n2kfra8p0\LocalCache\local-packages\Python311\site-packages\django\db\models\base.py", line 892, in save_base
    post_save.send(
  File "C:\Users\ASHISH KUMAR\AppData\Local\Packages\PythonSoftwareFoundation.Python.3.11_qbz5n2kfra8p0\LocalCache\local-packages\Python311\site-packages\django\dispatch\dispatcher.py", line 176, in send
    return [
           ^
  File "C:\Users\ASHISH KUMAR\AppData\Local\Packages\PythonSoftwareFoundation.Python.3.11_qbz5n2kfra8p0\LocalCache\local-packages\Python311\site-packages\django\dispatch\dispatcher.py", line 177, in <listcomp>
    (receiver, receiver(signal=self, sender=sender, **named))
               ^^^^^^^^^^^^^^^^^^^^^^^^^^^^^^^^^^^^^^^^^^^^^
  File "C:\Users\ASHISH KUMAR\OneDrive\Documents\Desktop\KJSCE\kj stuff\trae\backend\apps\gamification\signals.py", line 347, in create_daily_login_points
    ).exists()
      ^^^^^^^^
  File "C:\Users\ASHISH KUMAR\AppData\Local\Packages\PythonSoftwareFoundation.Python.3.11_qbz5n2kfra8p0\LocalCache\local-packages\Python311\site-packages\django\db\models\query.py", line 1241, in exists
    return self.query.has_results(using=self.db)
           ^^^^^^^^^^^^^^^^^^^^^^^^^^^^^^^^^^^^^
  File "C:\Users\ASHISH KUMAR\AppData\Local\Packages\PythonSoftwareFoundation.Python.3.11_qbz5n2kfra8p0\LocalCache\local-packages\Python311\site-packages\django\db\models\sql\query.py", line 598, in has_results
    return compiler.has_results()
           ^^^^^^^^^^^^^^^^^^^^^^
  File "C:\Users\ASHISH KUMAR\AppData\Local\Packages\PythonSoftwareFoundation.Python.3.11_qbz5n2kfra8p0\LocalCache\local-packages\Python311\site-packages\django\db\models\sql\compiler.py", line 1530, in has_results
    return bool(self.execute_sql(SINGLE))
                ^^^^^^^^^^^^^^^^^^^^^^^^
  File "C:\Users\ASHISH KUMAR\AppData\Local\Packages\PythonSoftwareFoundation.Python.3.11_qbz5n2kfra8p0\LocalCache\local-packages\Python311\site-packages\django\db\models\sql\compiler.py", line 1562, in execute_sql
    cursor.execute(sql, params)
  File "C:\Users\ASHISH KUMAR\AppData\Local\Packages\PythonSoftwareFoundation.Python.3.11_qbz5n2kfra8p0\LocalCache\local-packages\Python311\site-packages\django\db\backends\utils.py", line 102, in execute
    return super().execute(sql, params)
           ^^^^^^^^^^^^^^^^^^^^^^^^^^^^
  File "C:\Users\ASHISH KUMAR\AppData\Local\Packages\PythonSoftwareFoundation.Python.3.11_qbz5n2kfra8p0\LocalCache\local-packages\Python311\site-packages\django\db\backends\utils.py", line 67, in execute
    return self._execute_with_wrappers(
           ^^^^^^^^^^^^^^^^^^^^^^^^^^^^
  File "C:\Users\ASHISH KUMAR\AppData\Local\Packages\PythonSoftwareFoundation.Python.3.11_qbz5n2kfra8p0\LocalCache\local-packages\Python311\site-packages\django\db\backends\utils.py", line 80, in _execute_with_wrappers
    return executor(sql, params, many, context)
           ^^^^^^^^^^^^^^^^^^^^^^^^^^^^^^^^^^^^
  File "C:\Users\ASHISH KUMAR\AppData\Local\Packages\PythonSoftwareFoundation.Python.3.11_qbz5n2kfra8p0\LocalCache\local-packages\Python311\site-packages\django\db\backends\utils.py", line 84, in _execute
    with self.db.wrap_database_errors:
  File "C:\Users\ASHISH KUMAR\AppData\Local\Packages\PythonSoftwareFoundation.Python.3.11_qbz5n2kfra8p0\LocalCache\local-packages\Python311\site-packages\django\db\utils.py", line 91, in __exit__
    raise dj_exc_value.with_traceback(traceback) from exc_value
  File "C:\Users\ASHISH KUMAR\AppData\Local\Packages\PythonSoftwareFoundation.Python.3.11_qbz5n2kfra8p0\LocalCache\local-packages\Python311\site-packages\django\db\backends\utils.py", line 89, in _execute
    return self.cursor.execute(sql, params)
           ^^^^^^^^^^^^^^^^^^^^^^^^^^^^^^^^
  File "C:\Users\ASHISH KUMAR\AppData\Local\Packages\PythonSoftwareFoundation.Python.3.11_qbz5n2kfra8p0\LocalCache\local-packages\Python311\site-packages\django\db\backends\sqlite3\base.py", line 328, in execute
    return super().execute(query, params)
           ^^^^^^^^^^^^^^^^^^^^^^^^^^^^^^
django.db.utils.OperationalError: no such table: gamification_point_transaction
ERROR 2025-09-09 02:23:17,297 basehttp 40308 30892 "POST /api/v1/auth/login/ HTTP/1.1" 500 221472
INFO 2025-09-09 02:23:17,307 basehttp 40308 30892 - Broken pipe from ('127.0.0.1', 58335)
INFO 2025-09-09 02:24:07,265 basehttp 40308 33916 "POST /api/v1/auth/login/ HTTP/1.1" 200 790
INFO 2025-09-09 02:25:03,980 basehttp 40308 40100 "POST /api/v1/users/ HTTP/1.1" 201 94
WARNING 2025-09-09 02:26:58,738 log 40308 1308 Not Found: /api/v1/lessons/
WARNING 2025-09-09 02:26:58,746 basehttp 40308 1308 "GET /api/v1/lessons/?page=1 HTTP/1.1" 404 11976
WARNING 2025-09-09 02:26:59,782 log 40308 1308 Not Found: /api/v1/lessons/
WARNING 2025-09-09 02:26:59,782 basehttp 40308 1308 "GET /api/v1/lessons/?page=1 HTTP/1.1" 404 11976
WARNING 2025-09-09 02:27:00,446 log 40308 28764 Not Found: /api/v1/lessons/
WARNING 2025-09-09 02:27:00,454 basehttp 40308 28764 "GET /api/v1/lessons/?page=1 HTTP/1.1" 404 11976
WARNING 2025-09-09 02:27:01,796 log 40308 1308 Not Found: /api/v1/lessons/
WARNING 2025-09-09 02:27:01,799 basehttp 40308 1308 "GET /api/v1/lessons/?page=1 HTTP/1.1" 404 11976
WARNING 2025-09-09 02:27:06,163 log 40308 34872 Not Found: /api/v1/lessons/
WARNING 2025-09-09 02:27:06,163 basehttp 40308 34872 "GET /api/v1/lessons/?page=1 HTTP/1.1" 404 11976
WARNING 2025-09-09 02:27:09,642 log 40308 28392 Not Found: /api/v1/lessons/
WARNING 2025-09-09 02:27:09,642 basehttp 40308 28392 "GET /api/v1/lessons/?page=1 HTTP/1.1" 404 11976
WARNING 2025-09-09 02:27:09,995 log 40308 21400 Not Found: /api/v1/lessons/
WARNING 2025-09-09 02:27:09,996 basehttp 40308 21400 "GET /api/v1/lessons/?page=1 HTTP/1.1" 404 11976
WARNING 2025-09-09 02:27:10,662 log 40308 28392 Not Found: /api/v1/lessons/
WARNING 2025-09-09 02:27:10,662 basehttp 40308 28392 "GET /api/v1/lessons/?page=1 HTTP/1.1" 404 11976
WARNING 2025-09-09 02:27:12,680 log 40308 28392 Not Found: /api/v1/lessons/
WARNING 2025-09-09 02:27:12,680 basehttp 40308 28392 "GET /api/v1/lessons/?page=1 HTTP/1.1" 404 11976
WARNING 2025-09-09 02:27:16,700 log 40308 28392 Not Found: /api/v1/lessons/
WARNING 2025-09-09 02:27:16,701 basehttp 40308 28392 "GET /api/v1/lessons/?page=1 HTTP/1.1" 404 11976
WARNING 2025-09-09 02:27:20,642 log 40308 14736 Not Found: /api/v1/lessons/
WARNING 2025-09-09 02:27:20,645 basehttp 40308 14736 "GET /api/v1/lessons/?page=1 HTTP/1.1" 404 11976
WARNING 2025-09-09 02:27:21,132 log 40308 23228 Not Found: /api/v1/lessons/
WARNING 2025-09-09 02:27:21,133 basehttp 40308 23228 "GET /api/v1/lessons/?page=1 HTTP/1.1" 404 11976
WARNING 2025-09-09 02:27:21,665 log 40308 14736 Not Found: /api/v1/lessons/
WARNING 2025-09-09 02:27:21,667 basehttp 40308 14736 "GET /api/v1/lessons/?page=1 HTTP/1.1" 404 11976
WARNING 2025-09-09 02:27:23,684 log 40308 14736 Not Found: /api/v1/lessons/
WARNING 2025-09-09 02:27:23,684 basehttp 40308 14736 "GET /api/v1/lessons/?page=1 HTTP/1.1" 404 11976
WARNING 2025-09-09 02:27:27,700 log 40308 14736 Not Found: /api/v1/lessons/
WARNING 2025-09-09 02:27:27,700 basehttp 40308 14736 "GET /api/v1/lessons/?page=1 HTTP/1.1" 404 11976
WARNING 2025-09-09 02:27:32,334 log 40308 18824 Not Found: /api/v1/lessons/
WARNING 2025-09-09 02:27:32,335 basehttp 40308 18824 "GET /api/v1/lessons/?page=1 HTTP/1.1" 404 11976
WARNING 2025-09-09 02:27:32,899 log 40308 11500 Not Found: /api/v1/lessons/
WARNING 2025-09-09 02:27:32,900 basehttp 40308 11500 "GET /api/v1/lessons/?page=1 HTTP/1.1" 404 11976
WARNING 2025-09-09 02:27:33,351 log 40308 18824 Not Found: /api/v1/lessons/
WARNING 2025-09-09 02:27:33,352 basehttp 40308 18824 "GET /api/v1/lessons/?page=1 HTTP/1.1" 404 11976
WARNING 2025-09-09 02:27:35,366 log 40308 18824 Not Found: /api/v1/lessons/
WARNING 2025-09-09 02:27:35,366 basehttp 40308 18824 "GET /api/v1/lessons/?page=1 HTTP/1.1" 404 11976
WARNING 2025-09-09 02:27:39,939 log 40308 31212 Not Found: /api/v1/lessons/
WARNING 2025-09-09 02:27:39,942 basehttp 40308 31212 "GET /api/v1/lessons/?page=1 HTTP/1.1" 404 11976
WARNING 2025-09-09 02:27:40,957 log 40308 2920 Not Found: /api/v1/lessons/
WARNING 2025-09-09 02:27:40,964 basehttp 40308 2920 "GET /api/v1/lessons/?page=1 HTTP/1.1" 404 11976
WARNING 2025-09-09 02:27:41,005 log 40308 31212 Not Found: /api/v1/lessons/
WARNING 2025-09-09 02:27:41,006 basehttp 40308 31212 "GET /api/v1/lessons/?page=1 HTTP/1.1" 404 11976
WARNING 2025-09-09 02:27:43,014 log 40308 31212 Not Found: /api/v1/lessons/
WARNING 2025-09-09 02:27:43,014 basehttp 40308 31212 "GET /api/v1/lessons/?page=1 HTTP/1.1" 404 11976
WARNING 2025-09-09 02:27:47,039 log 40308 31212 Not Found: /api/v1/lessons/
WARNING 2025-09-09 02:27:47,039 basehttp 40308 31212 "GET /api/v1/lessons/?page=1 HTTP/1.1" 404 11976
WARNING 2025-09-09 02:27:56,658 log 40308 38188 Not Found: /api/v1/lessons/
WARNING 2025-09-09 02:27:56,659 basehttp 40308 38188 "GET /api/v1/lessons/?page=1 HTTP/1.1" 404 11976
WARNING 2025-09-09 02:28:16,474 log 40308 25000 Not Found: /api/v1/lessons/
WARNING 2025-09-09 02:28:16,476 basehttp 40308 25000 "GET /api/v1/lessons/?page=1 HTTP/1.1" 404 11976
WARNING 2025-09-09 02:28:17,491 log 40308 25000 Not Found: /api/v1/lessons/
WARNING 2025-09-09 02:28:17,491 basehttp 40308 25000 "GET /api/v1/lessons/?page=1 HTTP/1.1" 404 11976
WARNING 2025-09-09 02:28:19,814 log 40308 34380 Not Found: /api/v1/lessons/
WARNING 2025-09-09 02:28:19,814 basehttp 40308 34380 "GET /api/v1/lessons/?page=1 HTTP/1.1" 404 11976
WARNING 2025-09-09 02:28:23,826 log 40308 34380 Not Found: /api/v1/lessons/
WARNING 2025-09-09 02:28:23,827 basehttp 40308 34380 "GET /api/v1/lessons/?page=1 HTTP/1.1" 404 11976
WARNING 2025-09-09 02:28:30,413 log 40308 31004 Not Found: /api/v1/lessons/
WARNING 2025-09-09 02:28:30,414 basehttp 40308 31004 "GET /api/v1/lessons/?page=1 HTTP/1.1" 404 11976
WARNING 2025-09-09 02:28:31,424 log 40308 31004 Not Found: /api/v1/lessons/
WARNING 2025-09-09 02:28:31,424 basehttp 40308 31004 "GET /api/v1/lessons/?page=1 HTTP/1.1" 404 11976
WARNING 2025-09-09 02:28:33,443 log 40308 31004 Not Found: /api/v1/lessons/
WARNING 2025-09-09 02:28:33,443 basehttp 40308 31004 "GET /api/v1/lessons/?page=1 HTTP/1.1" 404 11976
WARNING 2025-09-09 02:28:37,457 log 40308 31004 Not Found: /api/v1/lessons/
WARNING 2025-09-09 02:28:37,458 basehttp 40308 31004 "GET /api/v1/lessons/?page=1 HTTP/1.1" 404 11976
WARNING 2025-09-09 02:28:41,112 log 40308 21740 Not Found: /api/v1/lessons/
WARNING 2025-09-09 02:28:41,113 basehttp 40308 21740 "GET /api/v1/lessons/?page=1 HTTP/1.1" 404 11976
WARNING 2025-09-09 02:28:42,132 log 40308 21740 Not Found: /api/v1/lessons/
WARNING 2025-09-09 02:28:42,132 basehttp 40308 21740 "GET /api/v1/lessons/?page=1 HTTP/1.1" 404 11976
WARNING 2025-09-09 02:28:44,147 log 40308 21740 Not Found: /api/v1/lessons/
WARNING 2025-09-09 02:28:44,147 basehttp 40308 21740 "GET /api/v1/lessons/?page=1 HTTP/1.1" 404 11976
WARNING 2025-09-09 02:28:44,551 log 40308 27532 Not Found: /api/v1/lessons/
WARNING 2025-09-09 02:28:44,551 basehttp 40308 27532 "GET /api/v1/lessons/?page=1 HTTP/1.1" 404 11976
WARNING 2025-09-09 02:28:46,571 log 40308 27532 Not Found: /api/v1/lessons/
WARNING 2025-09-09 02:28:46,571 basehttp 40308 27532 "GET /api/v1/lessons/?page=1 HTTP/1.1" 404 11976
WARNING 2025-09-09 02:28:48,163 log 40308 21740 Not Found: /api/v1/lessons/
WARNING 2025-09-09 02:28:48,163 basehttp 40308 21740 "GET /api/v1/lessons/?page=1 HTTP/1.1" 404 11976
WARNING 2025-09-09 02:28:50,593 log 40308 27532 Not Found: /api/v1/lessons/
WARNING 2025-09-09 02:28:50,593 basehttp 40308 27532 "GET /api/v1/lessons/?page=1 HTTP/1.1" 404 11976
WARNING 2025-09-09 02:30:57,905 log 40308 13656 Not Found: /api/v1/lessons/
WARNING 2025-09-09 02:30:57,918 basehttp 40308 13656 "GET /api/v1/lessons/?page=1 HTTP/1.1" 404 11976
WARNING 2025-09-09 02:30:58,961 log 40308 13656 Not Found: /api/v1/lessons/
WARNING 2025-09-09 02:30:58,961 basehttp 40308 13656 "GET /api/v1/lessons/?page=1 HTTP/1.1" 404 11976
WARNING 2025-09-09 02:31:01,282 log 40308 27596 Not Found: /api/v1/lessons/
WARNING 2025-09-09 02:31:01,284 basehttp 40308 27596 "GET /api/v1/lessons/?page=1 HTTP/1.1" 404 11976
WARNING 2025-09-09 02:31:05,608 log 40308 29372 Not Found: /api/v1/lessons/
WARNING 2025-09-09 02:31:05,608 basehttp 40308 29372 "GET /api/v1/lessons/?page=1 HTTP/1.1" 404 11976
WARNING 2025-09-09 02:33:51,008 log 40308 40652 Not Found: /api/v1/lessons/
WARNING 2025-09-09 02:33:51,026 basehttp 40308 40652 "GET /api/v1/lessons/?page=1 HTTP/1.1" 404 11976
WARNING 2025-09-09 02:33:52,054 log 40308 40652 Not Found: /api/v1/lessons/
WARNING 2025-09-09 02:33:52,056 basehttp 40308 40652 "GET /api/v1/lessons/?page=1 HTTP/1.1" 404 11976
WARNING 2025-09-09 02:33:54,076 log 40308 40652 Not Found: /api/v1/lessons/
WARNING 2025-09-09 02:33:54,076 basehttp 40308 40652 "GET /api/v1/lessons/?page=1 HTTP/1.1" 404 11976
WARNING 2025-09-09 02:36:18,151 log 40308 39164 Not Found: /api/v1/lessons/
WARNING 2025-09-09 02:36:18,156 basehttp 40308 39164 "GET /api/v1/lessons/?page=1 HTTP/1.1" 404 11976
INFO 2025-09-09 02:41:13,725 autoreload 40308 36492 C:\Users\ASHISH KUMAR\OneDrive\Documents\Desktop\KJSCE\kj stuff\trae\backend\apps\challenges\models.py changed, reloading.
INFO 2025-09-09 02:41:15,894 autoreload 12740 36588 Watching for file changes with StatReloader
INFO 2025-09-09 03:04:13,360 autoreload 19216 32644 Watching for file changes with StatReloader
WARNING 2025-09-09 03:04:19,659 log 19216 9324 Not Found: /
WARNING 2025-09-09 03:04:19,659 basehttp 19216 9324 "GET /?ide_webview_request_time=1757363783296 HTTP/1.1" 404 3189
WARNING 2025-09-09 03:04:19,833 log 19216 9324 Not Found: /@vite/client
WARNING 2025-09-09 03:04:19,833 basehttp 19216 9324 "GET /@vite/client HTTP/1.1" 404 3204
WARNING 2025-09-09 03:04:24,708 log 19216 38972 Not Found: /api/v1/lessons/
WARNING 2025-09-09 03:04:24,708 basehttp 19216 38972 "GET /api/v1/lessons/?page=1 HTTP/1.1" 404 11976
WARNING 2025-09-09 03:04:25,773 log 19216 38972 Not Found: /api/v1/lessons/
WARNING 2025-09-09 03:04:25,773 basehttp 19216 38972 "GET /api/v1/lessons/?page=1 HTTP/1.1" 404 11976
WARNING 2025-09-09 03:04:27,805 log 19216 38972 Not Found: /api/v1/lessons/
WARNING 2025-09-09 03:04:27,806 basehttp 19216 38972 "GET /api/v1/lessons/?page=1 HTTP/1.1" 404 11976
WARNING 2025-09-09 03:04:32,130 log 19216 14492 Not Found: /api/v1/lessons/
WARNING 2025-09-09 03:04:32,130 basehttp 19216 14492 "GET /api/v1/lessons/?page=1 HTTP/1.1" 404 11976
WARNING 2025-09-09 03:29:50,572 log 19216 39796 Not Found: /api/v1/lessons/
WARNING 2025-09-09 03:29:50,582 basehttp 19216 39796 "GET /api/v1/lessons/?page=1 HTTP/1.1" 404 11976
WARNING 2025-09-09 03:29:51,612 log 19216 39796 Not Found: /api/v1/lessons/
WARNING 2025-09-09 03:29:51,612 basehttp 19216 39796 "GET /api/v1/lessons/?page=1 HTTP/1.1" 404 11976
WARNING 2025-09-09 03:29:53,627 log 19216 39796 Not Found: /api/v1/lessons/
WARNING 2025-09-09 03:29:53,627 basehttp 19216 39796 "GET /api/v1/lessons/?page=1 HTTP/1.1" 404 11976
WARNING 2025-09-09 03:29:57,973 log 19216 39840 Not Found: /api/v1/lessons/
WARNING 2025-09-09 03:29:57,973 basehttp 19216 39840 "GET /api/v1/lessons/?page=1 HTTP/1.1" 404 11976
INFO 2025-09-09 10:02:38,524 autoreload 39720 30444 Watching for file changes with StatReloader
WARNING 2025-09-09 10:02:47,714 log 39720 40000 Not Found: /
WARNING 2025-09-09 10:02:47,715 basehttp 39720 40000 "GET /?ide_webview_request_time=1757363783296 HTTP/1.1" 404 3189
WARNING 2025-09-09 10:02:47,894 log 39720 40000 Not Found: /@vite/client
WARNING 2025-09-09 10:02:47,894 basehttp 39720 40000 "GET /@vite/client HTTP/1.1" 404 3204
INFO 2025-09-09 10:03:30,936 basehttp 39720 28220 "GET /api/v1/content/lessons/ HTTP/1.1" 200 3877
WARNING 2025-09-09 10:43:25,628 log 39720 12132 Not Found: /
WARNING 2025-09-09 10:43:25,644 basehttp 39720 12132 "GET / HTTP/1.1" 404 3150
WARNING 2025-09-09 10:43:25,976 log 39720 12132 Not Found: /favicon.ico
WARNING 2025-09-09 10:43:25,977 basehttp 39720 12132 "GET /favicon.ico HTTP/1.1" 404 3201
WARNING 2025-09-09 11:02:28,551 log 39720 41124 Not Found: /
WARNING 2025-09-09 11:02:28,561 basehttp 39720 41124 "GET / HTTP/1.1" 404 3150
INFO 2025-09-09 11:03:02,004 basehttp 39720 3780 "OPTIONS /api/v1/auth/login/ HTTP/1.1" 200 0
INFO 2025-09-09 11:03:02,721 basehttp 39720 3780 "POST /api/v1/auth/login/ HTTP/1.1" 200 826
WARNING 2025-09-09 11:03:23,643 log 39720 39852 Not Found: /
WARNING 2025-09-09 11:03:23,644 basehttp 39720 39852 "GET / HTTP/1.1" 404 3150
INFO 2025-09-09 11:31:44,340 autoreload 6504 8948 Watching for file changes with StatReloader
WARNING 2025-09-09 11:31:47,647 log 6504 16744 Not Found: /
WARNING 2025-09-09 11:31:47,647 basehttp 6504 16744 "GET / HTTP/1.1" 404 3150
WARNING 2025-09-09 11:31:47,777 log 6504 16744 Not Found: /favicon.ico
WARNING 2025-09-09 11:31:47,778 basehttp 6504 16744 "GET /favicon.ico HTTP/1.1" 404 3201
WARNING 2025-09-09 11:33:42,313 log 6504 15256 Not Found: /
WARNING 2025-09-09 11:33:42,314 basehttp 6504 15256 "GET / HTTP/1.1" 404 3150
WARNING 2025-09-09 11:34:54,852 log 6504 5884 Not Found: /
WARNING 2025-09-09 11:34:54,852 basehttp 6504 5884 "GET / HTTP/1.1" 404 3150
INFO 2025-09-09 11:35:08,384 autoreload 14376 23116 Watching for file changes with StatReloader
WARNING 2025-09-09 11:35:10,563 log 14376 7460 Not Found: /
WARNING 2025-09-09 11:35:10,566 basehttp 14376 7460 "GET / HTTP/1.1" 404 3150
INFO 2025-09-09 11:36:23,362 autoreload 14376 23116 C:\Users\aswin\Documents\Sih_website\EcoLearn\backend\config\urls.py changed, reloading.
INFO 2025-09-09 11:36:25,040 autoreload 5180 18712 Watching for file changes with StatReloader
INFO 2025-09-09 11:36:33,871 basehttp 5180 9532 "GET / HTTP/1.1" 200 328
INFO 2025-09-09 11:40:31,487 basehttp 5180 21216 "OPTIONS /api/v1/auth/register/ HTTP/1.1" 200 0
WARNING 2025-09-09 11:40:31,549 log 5180 21216 Not Found: /api/v1/auth/register/
WARNING 2025-09-09 11:40:31,550 basehttp 5180 21216 "POST /api/v1/auth/register/ HTTP/1.1" 404 12105
INFO 2025-09-09 11:43:59,892 autoreload 21456 20128 Watching for file changes with StatReloader
INFO 2025-09-09 11:44:35,265 basehttp 5180 21240 "GET /?id=ce9d2735-9444-4dd9-80ac-161075ec7c72&vscodeBrowserReqId=1757398474927 HTTP/1.1" 200 328
INFO 2025-09-09 11:44:44,379 basehttp 5180 17548 "GET /api/docs/?id=ce9d2735-9444-4dd9-80ac-161075ec7c72&vscodeBrowserReqId=1757398483814 HTTP/1.1" 200 4478
WARNING 2025-09-09 11:44:59,333 log 5180 19296 Not Found: /api/v1/auth/register/
WARNING 2025-09-09 11:44:59,334 basehttp 5180 19296 "POST /api/v1/auth/register/ HTTP/1.1" 404 12105
INFO 2025-09-09 11:45:02,155 autoreload 21456 20128 C:\Users\aswin\Documents\Sih_website\EcoLearn\backend\config\urls.py changed, reloading.
INFO 2025-09-09 11:45:02,443 autoreload 5180 18712 C:\Users\aswin\Documents\Sih_website\EcoLearn\backend\config\urls.py changed, reloading.
INFO 2025-09-09 11:45:03,938 autoreload 17548 14356 Watching for file changes with StatReloader
INFO 2025-09-09 11:45:04,326 autoreload 22760 12580 Watching for file changes with StatReloader
INFO 2025-09-09 11:46:00,798 basehttp 22824 20004 "OPTIONS /api/v1/auth/register/ HTTP/1.1" 200 0
WARNING 2025-09-09 11:46:08,113 log 22824 19324 Not Found: /health/
WARNING 2025-09-09 11:46:08,114 basehttp 22824 19324 "GET /health/?id=ce9d2735-9444-4dd9-80ac-161075ec7c72&vscodeBrowserReqId=1757398567740 HTTP/1.1" 404 3383
INFO 2025-09-09 12:08:35,259 autoreload 23352 6672 Watching for file changes with StatReloader
INFO 2025-09-09 12:09:11,190 autoreload 1976 13392 Watching for file changes with StatReloader
INFO 2025-09-09 12:09:13,289 basehttp 1976 21348 "GET / HTTP/1.1" 200 328
WARNING 2025-09-09 12:11:46,761 log 1976 17228 Not Found: /api/v1/auth/register/
WARNING 2025-09-09 12:11:46,761 basehttp 1976 17228 "POST /api/v1/auth/register/ HTTP/1.1" 404 12233
INFO 2025-09-09 12:13:10,568 autoreload 1976 13392 C:\Users\aswin\Documents\Sih_website\EcoLearn\backend\apps\users\urls.py changed, reloading.
INFO 2025-09-09 12:13:12,656 autoreload 9604 21896 Watching for file changes with StatReloader
INFO 2025-09-09 12:13:28,793 autoreload 9604 21896 C:\Users\aswin\Documents\Sih_website\EcoLearn\backend\apps\users\views.py changed, reloading.
INFO 2025-09-09 12:13:30,423 autoreload 20736 21424 Watching for file changes with StatReloader
WARNING 2025-09-09 12:14:05,795 log 20736 4712 Bad Request: /api/v1/auth/register/
WARNING 2025-09-09 12:14:05,800 basehttp 20736 4712 "POST /api/v1/auth/register/ HTTP/1.1" 400 53
WARNING 2025-09-09 12:14:30,369 log 20736 21244 Bad Request: /api/v1/auth/register/
WARNING 2025-09-09 12:14:30,371 basehttp 20736 21244 "POST /api/v1/auth/register/ HTTP/1.1" 400 53
INFO 2025-09-09 12:16:00,402 autoreload 20736 21424 C:\Users\aswin\Documents\Sih_website\EcoLearn\backend\apps\users\views.py changed, reloading.
INFO 2025-09-09 12:16:02,039 autoreload 18800 19188 Watching for file changes with StatReloader
INFO 2025-09-09 12:18:13,727 autoreload 18800 19188 C:\Users\aswin\Documents\Sih_website\EcoLearn\backend\apps\users\views.py changed, reloading.
INFO 2025-09-09 12:18:15,374 autoreload 20860 6296 Watching for file changes with StatReloader
INFO 2025-09-09 12:19:47,717 basehttp 20860 13516 "POST /api/v1/auth/register/ HTTP/1.1" 201 640
INFO 2025-09-09 12:26:09,552 basehttp 20860 23264 "OPTIONS /api/v1/auth/login/ HTTP/1.1" 200 0
INFO 2025-09-09 12:26:10,568 basehttp 20860 23264 "POST /api/v1/auth/login/ HTTP/1.1" 200 757
INFO 2025-09-09 12:48:50,185 basehttp 20860 3232 "OPTIONS /api/v1/users/me/ HTTP/1.1" 200 0
INFO 2025-09-09 12:48:50,201 basehttp 20860 9956 "OPTIONS /api/v1/users/me/ HTTP/1.1" 200 0
INFO 2025-09-09 12:48:50,437 basehttp 20860 3232 "GET /api/v1/users/me/ HTTP/1.1" 200 537
INFO 2025-09-09 12:48:50,474 basehttp 20860 3232 "GET /api/v1/users/me/ HTTP/1.1" 200 537
INFO 2025-09-09 12:50:25,640 basehttp 20860 9320 "GET /api/v1/users/me/ HTTP/1.1" 200 537
INFO 2025-09-09 12:50:25,661 basehttp 20860 9320 "GET /api/v1/users/me/ HTTP/1.1" 200 537
INFO 2025-09-09 12:52:27,922 basehttp 20860 4812 "GET /api/v1/users/me/ HTTP/1.1" 200 537
INFO 2025-09-09 12:52:27,943 basehttp 20860 4812 "GET /api/v1/users/me/ HTTP/1.1" 200 537
INFO 2025-09-09 12:54:14,215 basehttp 20860 4576 "POST /api/v1/auth/login/ HTTP/1.1" 200 757
INFO 2025-09-09 13:00:50,760 autoreload 20860 6296 C:\Users\aswin\Documents\Sih_website\EcoLearn\backend\apps\users\views.py changed, reloading.
INFO 2025-09-09 13:00:54,050 autoreload 23652 11224 Watching for file changes with StatReloader
INFO 2025-09-09 13:01:11,162 autoreload 23652 11224 C:\Users\aswin\Documents\Sih_website\EcoLearn\backend\apps\users\views.py changed, reloading.
INFO 2025-09-09 13:01:13,312 autoreload 22140 9316 Watching for file changes with StatReloader
INFO 2025-09-09 13:01:32,512 basehttp 22140 18000 "GET /api/v1/users/me/ HTTP/1.1" 200 537
INFO 2025-09-09 13:01:32,531 basehttp 22140 18000 "GET /api/v1/users/me/ HTTP/1.1" 200 537
INFO 2025-09-09 13:02:44,013 basehttp 22140 19836 "GET /api/v1/users/me/ HTTP/1.1" 200 537
INFO 2025-09-09 13:02:44,043 basehttp 22140 19836 "GET /api/v1/users/me/ HTTP/1.1" 200 537
INFO 2025-09-09 13:05:57,588 basehttp 22140 12964 "GET / HTTP/1.1" 200 328
INFO 2025-09-09 13:05:59,944 basehttp 22140 6948 "GET /api/v1/users/me/ HTTP/1.1" 200 537
INFO 2025-09-09 13:05:59,981 basehttp 22140 6948 "GET /api/v1/users/me/ HTTP/1.1" 200 537
INFO 2025-09-09 13:06:11,774 basehttp 22140 19140 "GET /api/v1/users/me/ HTTP/1.1" 200 537
INFO 2025-09-09 13:06:11,790 basehttp 22140 19140 "GET /api/v1/users/me/ HTTP/1.1" 200 537
INFO 2025-09-09 13:06:40,213 basehttp 22140 19216 "GET /api/v1/users/me/ HTTP/1.1" 200 537
INFO 2025-09-09 13:06:40,232 basehttp 22140 19216 "GET /api/v1/users/me/ HTTP/1.1" 200 537
INFO 2025-09-09 13:09:56,257 autoreload 21884 18456 Watching for file changes with StatReloader
INFO 2025-09-09 13:12:03,624 autoreload 328 19152 Watching for file changes with StatReloader
INFO 2025-09-09 13:59:56,346 basehttp 328 12832 "OPTIONS /api/v1/auth/register/ HTTP/1.1" 200 0
INFO 2025-09-09 13:59:58,365 basehttp 328 12832 "POST /api/v1/auth/register/ HTTP/1.1" 201 643
INFO 2025-09-09 14:01:48,688 basehttp 328 25932 "GET /api/v1/users/me/ HTTP/1.1" 200 540
INFO 2025-09-09 14:01:48,717 basehttp 328 25932 "GET /api/v1/users/me/ HTTP/1.1" 200 540
INFO 2025-09-09 14:01:55,325 basehttp 328 25932 "GET /api/v1/users/me/ HTTP/1.1" 200 540
INFO 2025-09-09 14:01:55,344 basehttp 328 25932 "GET /api/v1/users/me/ HTTP/1.1" 200 540
INFO 2025-09-09 14:03:44,117 basehttp 328 19628 "GET /api/v1/users/me/ HTTP/1.1" 200 540
INFO 2025-09-09 14:03:44,133 basehttp 328 19628 "GET /api/v1/users/me/ HTTP/1.1" 200 540
INFO 2025-09-09 14:03:52,756 basehttp 328 19628 "GET /api/v1/users/me/ HTTP/1.1" 200 540
INFO 2025-09-09 14:03:52,774 basehttp 328 19628 "GET /api/v1/users/me/ HTTP/1.1" 200 540
INFO 2025-09-09 14:13:13,052 basehttp 328 13804 "GET /api/v1/users/me/ HTTP/1.1" 200 540
INFO 2025-09-09 14:13:13,083 basehttp 328 13804 "GET /api/v1/users/me/ HTTP/1.1" 200 540
INFO 2025-09-09 14:16:00,871 basehttp 328 23872 "GET /api/v1/users/me/ HTTP/1.1" 200 540
INFO 2025-09-09 14:16:00,890 basehttp 328 23872 "GET /api/v1/users/me/ HTTP/1.1" 200 540
INFO 2025-09-09 14:18:25,802 autoreload 328 19152 C:\Users\aswin\Documents\Sih_website\EcoLearn\backend\apps\challenges\models.py changed, reloading.
INFO 2025-09-09 14:18:30,895 autoreload 19912 19172 Watching for file changes with StatReloader
INFO 2025-09-09 14:18:45,411 autoreload 19912 19172 C:\Users\aswin\Documents\Sih_website\EcoLearn\backend\apps\challenges\serializers.py changed, reloading.
INFO 2025-09-09 14:18:47,244 autoreload 25476 12396 Watching for file changes with StatReloader
INFO 2025-09-09 14:18:59,222 autoreload 25476 12396 C:\Users\aswin\Documents\Sih_website\EcoLearn\backend\apps\challenges\serializers.py changed, reloading.
INFO 2025-09-09 14:19:01,316 autoreload 21044 25340 Watching for file changes with StatReloader
INFO 2025-09-09 14:19:19,885 autoreload 21044 25340 C:\Users\aswin\Documents\Sih_website\EcoLearn\backend\apps\challenges\views.py changed, reloading.
INFO 2025-09-09 14:19:21,554 autoreload 1692 26052 Watching for file changes with StatReloader
INFO 2025-09-09 14:19:26,992 autoreload 1692 26052 C:\Users\aswin\Documents\Sih_website\EcoLearn\backend\apps\challenges\views.py changed, reloading.
INFO 2025-09-09 14:19:28,696 autoreload 26976 25352 Watching for file changes with StatReloader
INFO 2025-09-09 14:19:35,303 autoreload 26976 25352 C:\Users\aswin\Documents\Sih_website\EcoLearn\backend\apps\challenges\views.py changed, reloading.
INFO 2025-09-09 14:19:36,920 autoreload 25320 20420 Watching for file changes with StatReloader
INFO 2025-09-09 14:19:54,542 autoreload 25320 20420 C:\Users\aswin\Documents\Sih_website\EcoLearn\backend\apps\challenges\views.py changed, reloading.
INFO 2025-09-09 14:19:56,293 autoreload 23932 13704 Watching for file changes with StatReloader
INFO 2025-09-09 14:20:12,706 autoreload 23932 13704 C:\Users\aswin\Documents\Sih_website\EcoLearn\backend\apps\challenges\urls.py changed, reloading.
INFO 2025-09-09 14:20:14,683 autoreload 27712 27964 Watching for file changes with StatReloader
INFO 2025-09-09 14:20:20,336 autoreload 27712 27964 C:\Users\aswin\Documents\Sih_website\EcoLearn\backend\apps\challenges\urls.py changed, reloading.
INFO 2025-09-09 14:20:22,137 autoreload 26812 9320 Watching for file changes with StatReloader
INFO 2025-09-09 14:21:27,662 autoreload 25816 24636 Watching for file changes with StatReloader
INFO 2025-09-09 14:21:35,454 basehttp 25816 21308 "GET /api/v1/users/me/ HTTP/1.1" 200 540
INFO 2025-09-09 14:21:35,500 basehttp 25816 21308 "GET /api/v1/users/me/ HTTP/1.1" 200 540
INFO 2025-09-09 14:21:43,263 basehttp 25816 27708 "OPTIONS /api/v1/content/challenges/1/ HTTP/1.1" 200 0
WARNING 2025-09-09 14:21:43,878 log 25816 27708 Not Found: /api/v1/content/challenges/1/
WARNING 2025-09-09 14:21:43,879 basehttp 25816 27708 "GET /api/v1/content/challenges/1/ HTTP/1.1" 404 24149
WARNING 2025-09-09 14:21:44,918 log 25816 27708 Not Found: /api/v1/content/challenges/1/
WARNING 2025-09-09 14:21:44,920 basehttp 25816 27708 "GET /api/v1/content/challenges/1/ HTTP/1.1" 404 24149
INFO 2025-09-09 14:23:50,584 basehttp 25816 26192 "OPTIONS /api/v1/challenges/challenges/1/ HTTP/1.1" 200 0
INFO 2025-09-09 14:23:50,605 basehttp 25816 1976 "GET /api/v1/users/me/ HTTP/1.1" 200 540
INFO 2025-09-09 14:23:50,628 basehttp 25816 1976 "GET /api/v1/users/me/ HTTP/1.1" 200 540
INFO 2025-09-09 14:23:50,635 basehttp 25816 26192 "GET /api/v1/challenges/challenges/1/ HTTP/1.1" 200 1910
INFO 2025-09-09 14:24:01,544 basehttp 25816 17900 "GET /api/v1/users/me/ HTTP/1.1" 200 540
INFO 2025-09-09 14:24:01,557 basehttp 25816 17900 "GET /api/v1/users/me/ HTTP/1.1" 200 540
INFO 2025-09-09 14:24:01,559 basehttp 25816 1856 "GET /api/v1/challenges/challenges/1/ HTTP/1.1" 200 1910
INFO 2025-09-09 14:24:36,251 autoreload 23844 1384 Watching for file changes with StatReloader
INFO 2025-09-09 14:24:38,016 basehttp 23844 20272 "GET /api/v1/users/me/ HTTP/1.1" 200 540
INFO 2025-09-09 14:24:38,028 basehttp 23844 3592 "GET /api/v1/challenges/challenges/1/ HTTP/1.1" 200 1910
INFO 2025-09-09 14:24:38,032 basehttp 23844 20272 "GET /api/v1/users/me/ HTTP/1.1" 200 540
INFO 2025-09-09 14:29:36,602 autoreload 11368 16812 Watching for file changes with StatReloader
INFO 2025-09-09 14:29:38,478 basehttp 11368 11628 "GET /api/v1/users/me/ HTTP/1.1" 200 540
INFO 2025-09-09 14:29:38,496 basehttp 11368 11628 "GET /api/v1/users/me/ HTTP/1.1" 200 540
INFO 2025-09-09 14:29:40,923 basehttp 11368 28404 "GET /api/v1/challenges/challenges/1/ HTTP/1.1" 200 1910
INFO 2025-09-09 14:30:09,199 basehttp 11368 1540 "OPTIONS /api/v1/challenges/carbon-footprint/ HTTP/1.1" 200 0
INFO 2025-09-09 14:30:09,232 basehttp 11368 1540 "POST /api/v1/challenges/carbon-footprint/ HTTP/1.1" 201 909
INFO 2025-09-09 14:31:21,460 basehttp 11368 17884 "POST /api/v1/challenges/carbon-footprint/ HTTP/1.1" 201 929
INFO 2025-09-09 14:35:55,289 basehttp 11368 20940 "POST /api/v1/challenges/carbon-footprint/ HTTP/1.1" 201 758
INFO 2025-09-09 14:36:57,073 basehttp 11368 20940 "GET /api/v1/challenges/challenges/1/ HTTP/1.1" 200 1910
INFO 2025-09-09 14:36:57,907 autoreload 11368 16812 C:\Users\aswin\Documents\Sih_website\EcoLearn\backend\apps\challenges\models.py changed, reloading.
INFO 2025-09-09 14:37:00,577 autoreload 28184 26300 Watching for file changes with StatReloader
INFO 2025-09-09 14:37:03,191 autoreload 28184 26300 C:\Users\aswin\Documents\Sih_website\EcoLearn\backend\apps\users\urls.py changed, reloading.
INFO 2025-09-09 14:37:05,164 autoreload 19136 16476 Watching for file changes with StatReloader
INFO 2025-09-09 14:37:07,683 basehttp 19136 14880 "GET /api/v1/users/me/ HTTP/1.1" 200 540
INFO 2025-09-09 14:37:07,715 basehttp 19136 18088 "GET /api/v1/challenges/challenges/1/ HTTP/1.1" 200 1910
INFO 2025-09-09 14:37:07,796 basehttp 19136 14880 "GET /api/v1/users/me/ HTTP/1.1" 200 540
INFO 2025-09-09 14:37:09,526 basehttp 19136 18088 "GET /api/v1/users/me/ HTTP/1.1" 200 540
INFO 2025-09-09 14:37:09,541 basehttp 19136 14880 "GET /api/v1/challenges/challenges/1/ HTTP/1.1" 200 1910
INFO 2025-09-09 14:37:09,545 basehttp 19136 18088 "GET /api/v1/users/me/ HTTP/1.1" 200 540
INFO 2025-09-09 14:49:46,631 basehttp 19136 24796 "OPTIONS /api/v1/users/me/ HTTP/1.1" 200 0
INFO 2025-09-09 14:49:46,631 basehttp 19136 27896 "OPTIONS /api/v1/users/me/ HTTP/1.1" 200 0
INFO 2025-09-09 14:49:46,864 basehttp 19136 27896 "GET /api/v1/users/me/ HTTP/1.1" 200 540
INFO 2025-09-09 14:49:46,880 basehttp 19136 27896 "GET /api/v1/users/me/ HTTP/1.1" 200 540
INFO 2025-09-09 14:50:51,681 basehttp 19136 25532 "GET /api/v1/users/me/ HTTP/1.1" 200 540
INFO 2025-09-09 14:50:51,701 basehttp 19136 25532 "GET /api/v1/users/me/ HTTP/1.1" 200 540
INFO 2025-09-09 14:53:56,957 basehttp 19136 15884 "GET /api/v1/users/me/ HTTP/1.1" 200 540
INFO 2025-09-09 14:53:56,976 basehttp 19136 15884 "GET /api/v1/users/me/ HTTP/1.1" 200 540
INFO 2025-09-09 14:54:06,377 basehttp 19136 23284 "GET /api/v1/users/me/ HTTP/1.1" 200 540
INFO 2025-09-09 14:54:06,400 basehttp 19136 23284 "GET /api/v1/users/me/ HTTP/1.1" 200 540
INFO 2025-09-09 14:55:32,754 basehttp 19136 26768 "GET /api/v1/challenges/challenges/ HTTP/1.1" 200 2759
INFO 2025-09-09 14:56:14,483 basehttp 19136 27520 "GET /api/v1/users/me/ HTTP/1.1" 200 540
INFO 2025-09-09 14:56:14,503 basehttp 19136 27520 "GET /api/v1/users/me/ HTTP/1.1" 200 540
INFO 2025-09-09 14:57:47,435 basehttp 19136 27520 "GET /api/v1/users/me/ HTTP/1.1" 200 540
INFO 2025-09-09 14:57:47,456 basehttp 19136 27520 "GET /api/v1/users/me/ HTTP/1.1" 200 540
INFO 2025-09-09 14:58:10,093 basehttp 19136 23704 "GET /api/v1/challenges/challenges/1/ HTTP/1.1" 200 1910
WARNING 2025-09-09 15:04:12,479 log 19136 9316 Unauthorized: /api/v1/challenges/challenges/1/
WARNING 2025-09-09 15:04:12,484 log 19136 16768 Unauthorized: /api/v1/users/me/
WARNING 2025-09-09 15:04:12,484 basehttp 19136 9316 "GET /api/v1/challenges/challenges/1/ HTTP/1.1" 401 183
WARNING 2025-09-09 15:04:12,486 basehttp 19136 16768 "GET /api/v1/users/me/ HTTP/1.1" 401 183
WARNING 2025-09-09 15:04:12,497 log 19136 16768 Unauthorized: /api/v1/users/me/
WARNING 2025-09-09 15:04:12,497 basehttp 19136 16768 "GET /api/v1/users/me/ HTTP/1.1" 401 183
INFO 2025-09-09 15:04:12,548 basehttp 19136 16768 "OPTIONS /api/v1/auth/token/refresh/ HTTP/1.1" 200 0
INFO 2025-09-09 15:04:12,548 basehttp 19136 9316 "OPTIONS /api/v1/auth/token/refresh/ HTTP/1.1" 200 0
INFO 2025-09-09 15:04:12,564 basehttp 19136 16768 "OPTIONS /api/v1/auth/token/refresh/ HTTP/1.1" 200 0
WARNING 2025-09-09 15:04:12,732 log 19136 9316 Not Found: /api/v1/auth/token/refresh/
WARNING 2025-09-09 15:04:12,736 log 19136 16768 Not Found: /api/v1/auth/token/refresh/
WARNING 2025-09-09 15:04:12,742 basehttp 19136 16768 "POST /api/v1/auth/token/refresh/ HTTP/1.1" 404 12936
WARNING 2025-09-09 15:04:12,745 basehttp 19136 9316 "POST /api/v1/auth/token/refresh/ HTTP/1.1" 404 12936
WARNING 2025-09-09 15:04:12,775 log 19136 5192 Not Found: /api/v1/auth/token/refresh/
WARNING 2025-09-09 15:04:12,776 basehttp 19136 5192 "POST /api/v1/auth/token/refresh/ HTTP/1.1" 404 12936
INFO 2025-09-09 15:04:43,497 basehttp 19136 5192 "OPTIONS /api/v1/auth/login/ HTTP/1.1" 200 0
INFO 2025-09-09 15:04:44,337 basehttp 19136 5192 "POST /api/v1/auth/login/ HTTP/1.1" 200 757
INFO 2025-09-09 15:05:38,524 basehttp 19136 28488 "GET /api/v1/challenges/challenges/1/ HTTP/1.1" 200 1910
INFO 2025-09-09 15:09:54,810 basehttp 19136 28488 "POST /api/v1/auth/login/ HTTP/1.1" 200 757
INFO 2025-09-09 15:28:29,244 basehttp 19136 27672 "GET /api/v1/users/me/ HTTP/1.1" 200 537
INFO 2025-09-09 15:28:29,333 basehttp 19136 27672 "GET /api/v1/users/me/ HTTP/1.1" 200 537
INFO 2025-09-09 15:28:29,360 basehttp 19136 25392 "GET /api/v1/challenges/challenges/1/ HTTP/1.1" 200 1910
INFO 2025-09-09 15:44:40,208 basehttp 19136 10836 "GET /api/v1/challenges/challenges/1/ HTTP/1.1" 200 1910
INFO 2025-09-09 15:47:32,069 autoreload 26136 19148 Watching for file changes with StatReloader
INFO 2025-09-09 15:54:25,732 basehttp 26136 11016 "GET /api/v1/users/me/ HTTP/1.1" 200 537
INFO 2025-09-09 15:54:25,750 basehttp 26136 11628 "GET /api/v1/challenges/challenges/1/ HTTP/1.1" 200 1910
INFO 2025-09-09 15:54:25,769 basehttp 26136 11016 "GET /api/v1/users/me/ HTTP/1.1" 200 537
WARNING 2025-09-09 16:12:47,014 log 26136 5884 Unauthorized: /api/v1/auth/login/
WARNING 2025-09-09 16:12:47,014 basehttp 26136 5884 "POST /api/v1/auth/login/ HTTP/1.1" 401 63
INFO 2025-09-09 16:12:56,925 basehttp 26136 8980 "POST /api/v1/auth/login/ HTTP/1.1" 200 757
INFO 2025-09-09 16:13:32,677 basehttp 26136 8980 "POST /api/v1/auth/login/ HTTP/1.1" 200 757
INFO 2025-09-09 16:14:32,482 basehttp 26136 25404 "GET /api/v1/challenges/challenges/1/ HTTP/1.1" 200 1910
INFO 2025-09-09 16:14:58,105 basehttp 26136 25404 "POST /api/v1/challenges/carbon-footprint/ HTTP/1.1" 201 920
INFO 2025-09-09 16:18:10,362 basehttp 26136 26404 "POST /api/v1/auth/login/ HTTP/1.1" 200 757
INFO 2025-09-09 16:20:55,768 basehttp 26136 12076 "GET /api/v1/users/me/ HTTP/1.1" 200 537
INFO 2025-09-09 16:20:55,789 basehttp 26136 12076 "GET /api/v1/users/me/ HTTP/1.1" 200 537
INFO 2025-09-09 16:31:37,300 basehttp 26136 27360 "OPTIONS /api/v1/challenges/challenges/1/ HTTP/1.1" 200 0
INFO 2025-09-09 16:31:37,381 basehttp 26136 27360 "GET /api/v1/challenges/challenges/1/ HTTP/1.1" 200 1910
INFO 2025-09-09 16:45:09,351 basehttp 26136 24272 "GET /api/v1/users/me/ HTTP/1.1" 200 537
INFO 2025-09-09 16:45:09,392 basehttp 26136 24272 "GET /api/v1/users/me/ HTTP/1.1" 200 537
INFO 2025-09-09 16:45:09,396 basehttp 26136 12368 "GET /api/v1/challenges/challenges/1/ HTTP/1.1" 200 1910
INFO 2025-09-09 16:45:28,578 basehttp 26136 12368 "GET /api/v1/users/me/ HTTP/1.1" 200 537
INFO 2025-09-09 16:45:28,605 basehttp 26136 12368 "GET /api/v1/users/me/ HTTP/1.1" 200 537
INFO 2025-09-09 16:45:45,727 basehttp 26136 23720 "GET /api/v1/users/me/ HTTP/1.1" 200 537
INFO 2025-09-09 16:45:45,750 basehttp 26136 23720 "GET /api/v1/users/me/ HTTP/1.1" 200 537
INFO 2025-09-09 16:47:15,342 basehttp 26136 10060 "GET /api/v1/users/me/ HTTP/1.1" 200 537
INFO 2025-09-09 16:47:15,362 basehttp 26136 10060 "GET /api/v1/users/me/ HTTP/1.1" 200 537
INFO 2025-09-09 16:48:34,693 basehttp 26136 19344 "GET /api/v1/users/me/ HTTP/1.1" 200 537
INFO 2025-09-09 16:48:34,724 basehttp 26136 19344 "GET /api/v1/users/me/ HTTP/1.1" 200 537
INFO 2025-09-09 16:48:35,878 basehttp 26136 19344 "GET /api/v1/users/me/ HTTP/1.1" 200 537
INFO 2025-09-09 16:48:35,898 basehttp 26136 19344 "GET /api/v1/users/me/ HTTP/1.1" 200 537
INFO 2025-09-09 16:48:51,818 basehttp 26136 27460 "GET /api/v1/users/me/ HTTP/1.1" 200 537
INFO 2025-09-09 16:48:51,836 basehttp 26136 27460 "GET /api/v1/users/me/ HTTP/1.1" 200 537
INFO 2025-09-09 16:49:05,157 basehttp 26136 13740 "GET /api/v1/users/me/ HTTP/1.1" 200 537
INFO 2025-09-09 16:49:05,170 basehttp 26136 13740 "GET /api/v1/users/me/ HTTP/1.1" 200 537
WARNING 2025-09-09 16:51:08,600 log 26136 12196 Unauthorized: /api/v1/auth/login/
WARNING 2025-09-09 16:51:08,610 basehttp 26136 12196 "POST /api/v1/auth/login/ HTTP/1.1" 401 63
INFO 2025-09-09 16:51:17,764 basehttp 26136 12196 "POST /api/v1/auth/login/ HTTP/1.1" 200 757
INFO 2025-09-09 16:52:57,376 basehttp 26136 15416 "GET /api/v1/challenges/challenges/1/ HTTP/1.1" 200 1910
INFO 2025-09-09 16:53:34,881 basehttp 26136 11348 "OPTIONS /api/v1/challenges/carbon-footprint/ HTTP/1.1" 200 0
INFO 2025-09-09 16:53:34,955 basehttp 26136 11348 "POST /api/v1/challenges/carbon-footprint/ HTTP/1.1" 201 921
INFO 2025-09-09 16:56:17,551 basehttp 26136 7448 "OPTIONS /api/v1/users/me/ HTTP/1.1" 200 0
INFO 2025-09-09 16:56:17,551 basehttp 26136 21596 "OPTIONS /api/v1/users/me/ HTTP/1.1" 200 0
INFO 2025-09-09 16:56:17,651 basehttp 26136 7448 "GET /api/v1/users/me/ HTTP/1.1" 200 537
INFO 2025-09-09 16:56:17,731 basehttp 26136 7448 "GET /api/v1/users/me/ HTTP/1.1" 200 537
INFO 2025-09-09 16:58:36,065 basehttp 26136 5632 "GET /api/v1/users/me/ HTTP/1.1" 200 537
INFO 2025-09-09 16:58:36,103 basehttp 26136 5632 "GET /api/v1/users/me/ HTTP/1.1" 200 537
INFO 2025-09-09 19:01:16,198 basehttp 26136 14864 "OPTIONS /api/v1/users/me/ HTTP/1.1" 200 0
INFO 2025-09-09 19:01:16,198 basehttp 26136 10512 "OPTIONS /api/v1/users/me/ HTTP/1.1" 200 0
WARNING 2025-09-09 19:01:16,259 log 26136 10512 Unauthorized: /api/v1/users/me/
WARNING 2025-09-09 19:01:16,281 basehttp 26136 10512 "GET /api/v1/users/me/ HTTP/1.1" 401 183
WARNING 2025-09-09 19:01:16,308 log 26136 10512 Unauthorized: /api/v1/users/me/
INFO 2025-09-09 19:01:16,310 basehttp 26136 14864 "OPTIONS /api/v1/auth/token/refresh/ HTTP/1.1" 200 0
WARNING 2025-09-09 19:01:16,316 basehttp 26136 10512 "GET /api/v1/users/me/ HTTP/1.1" 401 183
WARNING 2025-09-09 19:01:17,410 log 26136 10512 Not Found: /api/v1/auth/token/refresh/
WARNING 2025-09-09 19:01:17,410 log 26136 14864 Not Found: /api/v1/auth/token/refresh/
WARNING 2025-09-09 19:01:17,434 basehttp 26136 14864 "POST /api/v1/auth/token/refresh/ HTTP/1.1" 404 12936
WARNING 2025-09-09 19:01:17,438 basehttp 26136 10512 "POST /api/v1/auth/token/refresh/ HTTP/1.1" 404 12936
INFO 2025-09-09 19:02:41,019 basehttp 26136 1040 "OPTIONS /api/v1/auth/register/ HTTP/1.1" 200 0
INFO 2025-09-09 19:02:42,133 basehttp 26136 1040 "POST /api/v1/auth/register/ HTTP/1.1" 201 639
INFO 2025-09-09 19:03:13,002 basehttp 26136 20768 "OPTIONS /api/v1/auth/register/ HTTP/1.1" 200 0
INFO 2025-09-09 19:03:13,863 basehttp 26136 20768 "POST /api/v1/auth/register/ HTTP/1.1" 201 657
INFO 2025-09-09 19:09:27,623 basehttp 26136 24264 "GET /api/v1/users/me/ HTTP/1.1" 200 558
INFO 2025-09-09 19:09:27,654 basehttp 26136 24264 "GET /api/v1/users/me/ HTTP/1.1" 200 558
INFO 2025-09-09 19:14:41,735 basehttp 26136 6076 "GET /api/v1/users/me/ HTTP/1.1" 200 558
INFO 2025-09-09 19:14:41,757 basehttp 26136 6076 "GET /api/v1/users/me/ HTTP/1.1" 200 558
INFO 2025-09-09 19:14:54,162 basehttp 26136 23876 "GET /api/v1/users/me/ HTTP/1.1" 200 558
INFO 2025-09-09 19:14:54,175 basehttp 26136 23876 "GET /api/v1/users/me/ HTTP/1.1" 200 558
INFO 2025-09-09 19:15:06,304 basehttp 26136 17020 "GET /api/v1/users/me/ HTTP/1.1" 200 558
INFO 2025-09-09 19:15:06,321 basehttp 26136 17020 "GET /api/v1/users/me/ HTTP/1.1" 200 558
INFO 2025-09-09 19:16:45,602 autoreload 26136 19148 C:\Users\aswin\Documents\Sih_website\EcoLearn\backend\apps\users\views.py changed, reloading.
INFO 2025-09-09 19:16:48,132 autoreload 8216 5844 Watching for file changes with StatReloader
INFO 2025-09-09 19:17:19,342 autoreload 8216 5844 C:\Users\aswin\Documents\Sih_website\EcoLearn\backend\apps\users\views.py changed, reloading.
INFO 2025-09-09 19:17:21,637 autoreload 7888 10964 Watching for file changes with StatReloader
INFO 2025-09-09 19:19:21,283 basehttp 7888 24132 "GET /api/v1/users/me/ HTTP/1.1" 200 558
INFO 2025-09-09 19:19:21,324 basehttp 7888 24132 "GET /api/v1/users/me/ HTTP/1.1" 200 558
INFO 2025-09-09 19:19:21,539 basehttp 7888 24132 "GET /api/v1/users/me/ HTTP/1.1" 200 558
INFO 2025-09-09 19:19:21,556 basehttp 7888 24132 "GET /api/v1/users/me/ HTTP/1.1" 200 558
INFO 2025-09-09 19:19:21,847 basehttp 7888 24132 "GET /api/v1/users/me/ HTTP/1.1" 200 558
INFO 2025-09-09 19:19:21,867 basehttp 7888 24132 "GET /api/v1/users/me/ HTTP/1.1" 200 558
INFO 2025-09-09 19:19:22,087 basehttp 7888 24132 "GET /api/v1/users/me/ HTTP/1.1" 200 558
INFO 2025-09-09 19:19:22,105 basehttp 7888 24132 "GET /api/v1/users/me/ HTTP/1.1" 200 558
INFO 2025-09-09 19:19:22,316 basehttp 7888 24132 "GET /api/v1/users/me/ HTTP/1.1" 200 558
INFO 2025-09-09 19:19:22,348 basehttp 7888 24132 "GET /api/v1/users/me/ HTTP/1.1" 200 558
INFO 2025-09-09 19:19:22,542 basehttp 7888 24132 "GET /api/v1/users/me/ HTTP/1.1" 200 558
INFO 2025-09-09 19:19:22,563 basehttp 7888 24132 "GET /api/v1/users/me/ HTTP/1.1" 200 558
INFO 2025-09-09 19:20:34,567 autoreload 7888 10964 C:\Users\aswin\Documents\Sih_website\EcoLearn\backend\apps\users\views.py changed, reloading.
INFO 2025-09-09 19:20:37,277 autoreload 21576 26812 Watching for file changes with StatReloader
INFO 2025-09-09 19:33:41,637 basehttp 21576 20660 "GET /api/v1/users/me/ HTTP/1.1" 200 558
INFO 2025-09-09 19:33:41,656 basehttp 21576 20660 "GET /api/v1/users/me/ HTTP/1.1" 200 558
INFO 2025-09-09 19:34:11,342 basehttp 21576 24252 "OPTIONS /api/v1/challenges/challenges/ HTTP/1.1" 200 0
INFO 2025-09-09 19:34:11,342 basehttp 21576 27096 "OPTIONS /api/v1/challenges/challenges/ HTTP/1.1" 200 0
INFO 2025-09-09 19:34:11,384 basehttp 21576 18008 "GET /api/v1/users/me/ HTTP/1.1" 200 558
INFO 2025-09-09 19:34:11,416 basehttp 21576 18008 "GET /api/v1/users/me/ HTTP/1.1" 200 558
INFO 2025-09-09 19:34:11,438 basehttp 21576 24252 "GET /api/v1/challenges/challenges/ HTTP/1.1" 200 2759
INFO 2025-09-09 19:34:11,471 basehttp 21576 24252 "GET /api/v1/challenges/challenges/ HTTP/1.1" 200 2759
INFO 2025-09-09 19:34:32,350 basehttp 21576 23420 "GET /api/v1/challenges/challenges/ HTTP/1.1" 200 2759
INFO 2025-09-09 19:34:42,332 basehttp 21576 12720 "GET /api/v1/challenges/challenges/ HTTP/1.1" 200 2759
INFO 2025-09-09 19:35:19,323 basehttp 21576 23188 "GET /api/v1/challenges/challenges/ HTTP/1.1" 200 2759
INFO 2025-09-09 19:35:30,337 basehttp 21576 24368 "GET /api/v1/challenges/challenges/ HTTP/1.1" 200 2759
INFO 2025-09-09 19:35:37,021 basehttp 21576 24368 "GET /api/v1/challenges/challenges/ HTTP/1.1" 200 2759
INFO 2025-09-09 19:35:56,344 basehttp 21576 23872 "GET /api/v1/challenges/challenges/ HTTP/1.1" 200 2759
INFO 2025-09-09 19:36:06,794 basehttp 21576 27248 "GET /api/v1/challenges/challenges/ HTTP/1.1" 200 2759
INFO 2025-09-09 19:36:15,757 basehttp 21576 25992 "GET /api/v1/challenges/challenges/ HTTP/1.1" 200 2759
INFO 2025-09-09 19:36:22,011 basehttp 21576 25992 "GET /api/v1/challenges/challenges/ HTTP/1.1" 200 2759
INFO 2025-09-09 19:36:45,016 basehttp 21576 6796 "GET /api/v1/challenges/challenges/ HTTP/1.1" 200 2759
INFO 2025-09-09 19:36:45,980 basehttp 21576 24660 "GET /api/v1/challenges/challenges/ HTTP/1.1" 200 2759
INFO 2025-09-09 19:36:46,711 basehttp 21576 24660 "GET /api/v1/challenges/challenges/ HTTP/1.1" 200 2759
INFO 2025-09-09 19:36:47,010 basehttp 21576 24660 "GET /api/v1/challenges/challenges/ HTTP/1.1" 200 2759
INFO 2025-09-09 19:36:47,260 basehttp 21576 24660 "GET /api/v1/challenges/challenges/ HTTP/1.1" 200 2759
INFO 2025-09-09 19:36:47,648 basehttp 21576 24660 "GET /api/v1/challenges/challenges/ HTTP/1.1" 200 2759
INFO 2025-09-09 19:38:29,717 basehttp 21576 16552 "OPTIONS /api/v1/auth/login/ HTTP/1.1" 200 0
WARNING 2025-09-09 19:38:30,564 log 21576 16552 Unauthorized: /api/v1/auth/login/
WARNING 2025-09-09 19:38:30,564 basehttp 21576 16552 "POST /api/v1/auth/login/ HTTP/1.1" 401 63
INFO 2025-09-09 19:38:42,217 basehttp 21576 16552 "POST /api/v1/auth/login/ HTTP/1.1" 200 757
INFO 2025-09-09 19:38:45,285 basehttp 21576 13044 "OPTIONS /api/v1/challenges/challenges/ HTTP/1.1" 200 0
INFO 2025-09-09 19:38:45,286 basehttp 21576 16552 "OPTIONS /api/v1/challenges/challenges/ HTTP/1.1" 200 0
INFO 2025-09-09 19:38:45,366 basehttp 21576 16552 "GET /api/v1/challenges/challenges/ HTTP/1.1" 200 2759
INFO 2025-09-09 19:38:45,432 basehttp 21576 16552 "GET /api/v1/challenges/challenges/ HTTP/1.1" 200 2759
INFO 2025-09-09 19:38:46,862 basehttp 21576 16552 "GET /api/v1/challenges/challenges/ HTTP/1.1" 200 2759
INFO 2025-09-09 19:38:47,374 basehttp 21576 16552 "GET /api/v1/challenges/challenges/ HTTP/1.1" 200 2759
INFO 2025-09-09 19:38:47,964 basehttp 21576 16552 "GET /api/v1/challenges/challenges/ HTTP/1.1" 200 2759
INFO 2025-09-09 19:38:48,319 basehttp 21576 16552 "GET /api/v1/challenges/challenges/ HTTP/1.1" 200 2759
INFO 2025-09-09 19:39:41,315 basehttp 21576 15216 "OPTIONS /api/v1/challenges/carbon-footprint/latest/ HTTP/1.1" 200 0
INFO 2025-09-09 19:39:41,316 basehttp 21576 2904 "OPTIONS /api/v1/challenges/carbon-footprint/latest/ HTTP/1.1" 200 0
WARNING 2025-09-09 19:39:41,336 log 21576 2904 Not Found: /api/v1/challenges/carbon-footprint/latest/
WARNING 2025-09-09 19:39:41,336 basehttp 21576 2904 "GET /api/v1/challenges/carbon-footprint/latest/ HTTP/1.1" 404 53
INFO 2025-09-09 19:39:41,352 basehttp 21576 2904 "GET /api/v1/challenges/carbon-footprint/latest/ HTTP/1.1" 200 921
INFO 2025-09-09 19:39:41,360 basehttp 21576 15216 "OPTIONS /api/v1/challenges/carbon-footprint/statistics/ HTTP/1.1" 200 0
INFO 2025-09-09 19:39:41,398 basehttp 21576 15216 "GET /api/v1/challenges/carbon-footprint/statistics/ HTTP/1.1" 200 1132
INFO 2025-09-09 19:39:41,409 basehttp 21576 2904 "GET /api/v1/challenges/challenges/ HTTP/1.1" 200 2759
INFO 2025-09-09 19:39:41,461 basehttp 21576 2904 "GET /api/v1/challenges/challenges/ HTTP/1.1" 200 2759
WARNING 2025-09-09 19:39:58,314 log 21576 26012 Not Found: /api/v1/challenges/carbon-footprint/latest/
WARNING 2025-09-09 19:39:58,314 basehttp 21576 26012 "GET /api/v1/challenges/carbon-footprint/latest/ HTTP/1.1" 404 53
INFO 2025-09-09 19:39:58,328 basehttp 21576 26012 "GET /api/v1/challenges/carbon-footprint/latest/ HTTP/1.1" 200 921
INFO 2025-09-09 19:39:58,357 basehttp 21576 26012 "GET /api/v1/challenges/challenges/ HTTP/1.1" 200 2759
INFO 2025-09-09 19:39:58,368 basehttp 21576 26012 "GET /api/v1/challenges/carbon-footprint/statistics/ HTTP/1.1" 200 1132
INFO 2025-09-09 19:39:58,420 basehttp 21576 26012 "GET /api/v1/challenges/challenges/ HTTP/1.1" 200 2759
INFO 2025-09-09 19:40:09,344 basehttp 21576 5052 "GET /api/v1/challenges/carbon-footprint/latest/ HTTP/1.1" 200 921
WARNING 2025-09-09 19:40:09,355 log 21576 5052 Not Found: /api/v1/challenges/carbon-footprint/latest/
WARNING 2025-09-09 19:40:09,356 basehttp 21576 5052 "GET /api/v1/challenges/carbon-footprint/latest/ HTTP/1.1" 404 53
INFO 2025-09-09 19:40:09,440 basehttp 21576 5052 "GET /api/v1/challenges/challenges/ HTTP/1.1" 200 2759
INFO 2025-09-09 19:40:09,450 basehttp 21576 5052 "GET /api/v1/challenges/carbon-footprint/statistics/ HTTP/1.1" 200 1132
INFO 2025-09-09 19:40:09,517 basehttp 21576 5052 "GET /api/v1/challenges/challenges/ HTTP/1.1" 200 2759
INFO 2025-09-09 19:40:33,177 basehttp 21576 27156 "OPTIONS /api/v1/users/me/ HTTP/1.1" 200 0
INFO 2025-09-09 19:40:33,179 basehttp 21576 28400 "OPTIONS /api/v1/users/me/ HTTP/1.1" 200 0
INFO 2025-09-09 19:40:33,195 basehttp 21576 28400 "GET /api/v1/users/me/ HTTP/1.1" 200 537
INFO 2025-09-09 19:40:33,210 basehttp 21576 28400 "GET /api/v1/users/me/ HTTP/1.1" 200 537
INFO 2025-09-09 19:40:33,223 basehttp 21576 28400 "GET /api/v1/users/me/ HTTP/1.1" 200 558
INFO 2025-09-09 19:40:33,234 basehttp 21576 28400 "GET /api/v1/users/me/ HTTP/1.1" 200 558
INFO 2025-09-09 19:42:05,095 basehttp 21576 23164 "GET /api/v1/users/me/ HTTP/1.1" 200 537
INFO 2025-09-09 19:42:05,209 basehttp 21576 23164 "GET /api/v1/users/me/ HTTP/1.1" 200 537
INFO 2025-09-09 19:44:45,272 basehttp 21576 16416 "OPTIONS /api/v1/challenges/challenges/1/ HTTP/1.1" 200 0
INFO 2025-09-09 19:44:45,405 basehttp 21576 16416 "GET /api/v1/challenges/challenges/1/ HTTP/1.1" 200 1910
INFO 2025-09-09 19:48:09,446 basehttp 21576 28252 "OPTIONS /api/v1/auth/login/ HTTP/1.1" 200 0
INFO 2025-09-09 19:48:10,360 basehttp 21576 28252 "POST /api/v1/auth/login/ HTTP/1.1" 200 757
INFO 2025-09-09 19:54:20,181 basehttp 21576 4928 "GET / HTTP/1.1" 200 328
INFO 2025-09-09 19:59:32,125 autoreload 5564 21312 Watching for file changes with StatReloader
INFO 2025-09-09 19:59:38,920 basehttp 5564 6104 "GET / HTTP/1.1" 200 328
INFO 2025-09-09 19:59:44,905 basehttp 5564 20708 "GET /api/v1/users/me/ HTTP/1.1" 200 537
INFO 2025-09-09 19:59:44,920 basehttp 5564 20708 "GET /api/v1/users/me/ HTTP/1.1" 200 537
INFO 2025-09-09 20:00:04,025 basehttp 5564 20708 "OPTIONS /api/v1/challenges/challenges/2/ HTTP/1.1" 200 0
INFO 2025-09-09 20:00:04,101 basehttp 5564 20708 "GET /api/v1/challenges/challenges/2/ HTTP/1.1" 200 1981
INFO 2025-09-09 20:14:03,705 basehttp 5564 24104 "OPTIONS /api/v1/challenges/challenges/ HTTP/1.1" 200 0
INFO 2025-09-09 20:14:03,710 basehttp 5564 24828 "OPTIONS /api/v1/challenges/challenges/ HTTP/1.1" 200 0
INFO 2025-09-09 20:14:03,897 basehttp 5564 24828 "GET /api/v1/challenges/challenges/ HTTP/1.1" 200 2759
INFO 2025-09-09 20:14:03,974 basehttp 5564 24828 "GET /api/v1/challenges/challenges/ HTTP/1.1" 200 2759
INFO 2025-09-09 20:14:10,612 basehttp 5564 24828 "GET /api/v1/challenges/challenges/ HTTP/1.1" 200 2759
INFO 2025-09-09 20:14:10,659 basehttp 5564 24828 "GET /api/v1/challenges/challenges/ HTTP/1.1" 200 2759
INFO 2025-09-09 20:14:10,920 basehttp 5564 25144 "GET /api/v1/users/me/ HTTP/1.1" 200 537
INFO 2025-09-09 20:14:10,936 basehttp 5564 25144 "GET /api/v1/users/me/ HTTP/1.1" 200 537
INFO 2025-09-09 20:16:58,169 basehttp 5564 27216 "GET /api/v1/challenges/challenges/ HTTP/1.1" 200 2759
INFO 2025-09-09 20:16:58,229 basehttp 5564 27216 "GET /api/v1/challenges/challenges/ HTTP/1.1" 200 2759
INFO 2025-09-09 20:16:58,455 basehttp 5564 21184 "GET /api/v1/users/me/ HTTP/1.1" 200 537
INFO 2025-09-09 20:16:58,458 basehttp 5564 21184 "GET /api/v1/users/me/ HTTP/1.1" 200 537
INFO 2025-09-09 20:17:01,442 basehttp 5564 26968 "GET /api/v1/users/me/ HTTP/1.1" 200 537
INFO 2025-09-09 20:17:01,458 basehttp 5564 26968 "GET /api/v1/users/me/ HTTP/1.1" 200 537
INFO 2025-09-09 20:17:01,485 basehttp 5564 26964 "GET /api/v1/challenges/challenges/ HTTP/1.1" 200 2759
INFO 2025-09-09 20:17:01,533 basehttp 5564 26964 "GET /api/v1/challenges/challenges/ HTTP/1.1" 200 2759
INFO 2025-09-09 20:19:46,557 basehttp 5564 27360 "GET /api/v1/challenges/challenges/ HTTP/1.1" 200 2759
INFO 2025-09-09 20:19:46,668 basehttp 5564 27360 "GET /api/v1/challenges/challenges/ HTTP/1.1" 200 2759
INFO 2025-09-09 20:19:46,788 basehttp 5564 15072 "GET /api/v1/users/me/ HTTP/1.1" 200 537
INFO 2025-09-09 20:19:46,822 basehttp 5564 15072 "GET /api/v1/users/me/ HTTP/1.1" 200 537
INFO 2025-09-09 20:19:47,459 basehttp 5564 15072 "GET /api/v1/users/me/ HTTP/1.1" 200 537
INFO 2025-09-09 20:19:47,503 basehttp 5564 15072 "GET /api/v1/users/me/ HTTP/1.1" 200 537
INFO 2025-09-09 20:19:47,535 basehttp 5564 27360 "GET /api/v1/challenges/challenges/ HTTP/1.1" 200 2759
INFO 2025-09-09 20:19:47,642 basehttp 5564 27360 "GET /api/v1/challenges/challenges/ HTTP/1.1" 200 2759
INFO 2025-09-09 20:19:48,144 basehttp 5564 15072 "GET /api/v1/users/me/ HTTP/1.1" 200 537
INFO 2025-09-09 20:19:48,186 basehttp 5564 15072 "GET /api/v1/users/me/ HTTP/1.1" 200 537
INFO 2025-09-09 20:19:48,220 basehttp 5564 27360 "GET /api/v1/challenges/challenges/ HTTP/1.1" 200 2759
INFO 2025-09-09 20:19:48,304 basehttp 5564 27360 "GET /api/v1/challenges/challenges/ HTTP/1.1" 200 2759
INFO 2025-09-09 20:19:49,049 basehttp 5564 15072 "GET /api/v1/users/me/ HTTP/1.1" 200 537
INFO 2025-09-09 20:19:49,087 basehttp 5564 26600 "GET /api/v1/users/me/ HTTP/1.1" 200 537
INFO 2025-09-09 20:19:49,115 basehttp 5564 27360 "GET /api/v1/challenges/challenges/ HTTP/1.1" 200 2759
INFO 2025-09-09 20:19:49,215 basehttp 5564 27360 "GET /api/v1/challenges/challenges/ HTTP/1.1" 200 2759
INFO 2025-09-09 20:20:17,855 basehttp 5564 25508 "GET /api/v1/challenges/challenges/ HTTP/1.1" 200 2759
INFO 2025-09-09 20:20:17,901 basehttp 5564 25508 "GET /api/v1/challenges/challenges/ HTTP/1.1" 200 2759
INFO 2025-09-09 20:20:18,164 basehttp 5564 25552 "GET /api/v1/users/me/ HTTP/1.1" 200 537
INFO 2025-09-09 20:20:18,190 basehttp 5564 25552 "GET /api/v1/users/me/ HTTP/1.1" 200 537
INFO 2025-09-09 20:20:22,632 basehttp 5564 25552 "GET /api/v1/users/me/ HTTP/1.1" 200 537
INFO 2025-09-09 20:20:22,642 basehttp 5564 25552 "GET /api/v1/users/me/ HTTP/1.1" 200 537
INFO 2025-09-09 20:29:02,752 basehttp 5564 17904 "GET /api/v1/users/me/ HTTP/1.1" 200 537
INFO 2025-09-09 20:29:02,875 basehttp 5564 17904 "GET /api/v1/users/me/ HTTP/1.1" 200 537
INFO 2025-09-09 21:55:20,277 basehttp 5564 8356 "OPTIONS /api/v1/users/me/ HTTP/1.1" 200 0
INFO 2025-09-09 21:55:20,281 basehttp 5564 24048 "OPTIONS /api/v1/users/me/ HTTP/1.1" 200 0
WARNING 2025-09-09 21:55:20,377 log 5564 8356 Unauthorized: /api/v1/users/me/
WARNING 2025-09-09 21:55:20,384 basehttp 5564 8356 "GET /api/v1/users/me/ HTTP/1.1" 401 183
WARNING 2025-09-09 21:55:20,384 log 5564 8356 Unauthorized: /api/v1/users/me/
WARNING 2025-09-09 21:55:20,384 basehttp 5564 8356 "GET /api/v1/users/me/ HTTP/1.1" 401 183
INFO 2025-09-09 21:55:20,408 basehttp 5564 24048 "OPTIONS /api/v1/auth/token/refresh/ HTTP/1.1" 200 0
INFO 2025-09-09 21:55:20,424 basehttp 5564 8356 "OPTIONS /api/v1/auth/token/refresh/ HTTP/1.1" 200 0
WARNING 2025-09-09 21:55:20,613 log 5564 8356 Not Found: /api/v1/auth/token/refresh/
WARNING 2025-09-09 21:55:20,623 log 5564 24048 Not Found: /api/v1/auth/token/refresh/
WARNING 2025-09-09 21:55:20,623 basehttp 5564 8356 "POST /api/v1/auth/token/refresh/ HTTP/1.1" 404 12936
WARNING 2025-09-09 21:55:20,623 basehttp 5564 24048 "POST /api/v1/auth/token/refresh/ HTTP/1.1" 404 12936
INFO 2025-09-09 22:04:10,038 autoreload 12976 26796 Watching for file changes with StatReloader
